Workbook

Sheet Dados
A1: NUMERO_SS | B1: ANO | C1: SIGLAORGAO | D1: DEPARTCODE | E1: LOCATIONID | F1: PLACEMENTDESC | G1: CRITICIDADE_SS | H1: SITUACAO_SS | I1: DATA_OCORRENCIA_SS | J1: DATA_ABERTURA_SS | K1: DATA_TERMINO_SS | L1: DATA_LIMITE_SS | M1: DESCRICAO_DO_ATIVO | N1: OBJSPECDESC | O1: LOCALIDADE | P1: RURA_URBANO | Q1: HRNAME | R1: TIPOSS | S1: ABRANGENCIA
A2: ETO-COEP 00092/2023 | B2: 2023 | C2: COI | D2: ETO-COEP | E2: AL05010004 | F2: 5902839004 | G2: PROGRAMAVEL | H2: SS PENDENTE | I2: 44822.053 | J2: 45230.789 | L2: 45630.789 | M2: BANCO CAPACITOR DE DISTRIBUIÇÃO GIS | N2: BANCO CAPACITOR - 13.8 | O2: ARAGUAINA | P2: URBANO | Q2: CLEBSON ALVES DUARTE | R2: INDISPONIBILIDADE PARA OPERAÇÃO
A3: ETO-COEP 00013/2023 | B3: 2023 | C3: COI | D3: ETO-COEP | E3: AL01040003 | F3: 7915029003 | G3: EMERGENCIAL | H3: SS PENDENTE | I3: 44933.08 | J3: 44953.653 | L3: 44956.653 | M3: RELIGADOR DE REDE GIS | N3: RELIGADOR DE LINHA - 27kV | O3: GURUPI | P3: URBANO | Q3: Euzilan Mateus Barreira Santos | R3: OBRAS (NOVOS EQUIPAMENTOS) | S3: 7915029003
A4: ETO-COEP 00011/2023 | B4: 2023 | D4: ETO-COEP | E4: AL02096004 | F4: 7923674004 | G4: ALTA | H4: SS PENDENTE | I4: 44936.382 | J4: 44951.737 | L4: 45011.737 | M4: LOCAL INSTAL RELIGADOR DE LINHA GIS | N4: BLOCO RELIGADOR DE LINHA | O4: ARAGUAINA | P4: RURAL | Q4: Euzilan Mateus Barreira Santos | R4: EM OPERAÇÃO COM ANOMALIA | S4: 9023675004
A5: ETO-COEP 00030/2023 | B5: 2023 | C5: COI | D5: ETO-COEP | E5: AL02003036 | F5: 5900438097 | G5: EMERGENCIAL | H5: SS PENDENTE | I5: 44948.821 | J5: 45003.563 | L5: 45006.563 | M5: BANCO CAPACITOR DE DISTRIBUIÇÃO GIS | N5: BANCO CAPACITOR - 13.8 | O5: TALISMA | P5: RURAL | Q5: CLEBSON ALVES DUARTE | R5: INDISPONIBILIDADE PARA OPERAÇÃO
A6: ETO-COEP 00063/2023 | B6: 2023 | C6: COI | D6: ETO-COEP | E6: AL01040003 | F6: 7915029003 | G6: EMERGENCIAL | H6: SS PENDENTE | I6: 45092.172 | J6: 45104.502 | L6: 45107.502 | M6: RELIGADOR DE REDE GIS | N6: RELIGADOR DE LINHA - 27kV | O6: GURUPI | P6: URBANO | Q6: Euzilan Mateus Barreira Santos | R6: OBRAS (NOVOS EQUIPAMENTOS) | S6: 7915029003
A7: ETO-COEP 00148/2025 | B7: 2025 | C7: COI | D7: ETO-COEP | E7: AL07010004 | F7: 5703627004 | G7: ALTA | H7: SS PENDENTE | I7: 45297.624 | J7: 45848.622 | L7: 45908.622 | M7: TRANSFORMADOR DE DISTRIBUIÇÃO GIS | N7: TRANSFORMADOR DE DISTRIBUIÇÃO ENERGISA 13.8Kv | O7: ARAGUAINA | P7: URBANO | Q7: LEONARDO SANTOS DA SILVA | R7: AVISO DE EMERGÊNCIA | S7: 5703627004
A8: ETO-COEP 00018/2024 | B8: 2024 | C8: COI | D8: ETO-COEP | E8: AL04059122 | F8: 5952243122 | G8: EMERGENCIAL | H8: SS PENDENTE | I8: 45340.239 | J8: 45341.67 | L8: 45344.67 | M8: BANCO CAPACITOR DE DISTRIBUIÇÃO GIS | N8: BANCO CAPACITOR - 13.8 | O8: PALMAS | P8: URBANO | Q8: CLEBSON ALVES DUARTE | R8: INDISPONIBILIDADE PARA OPERAÇÃO | S8: 0352243122
A9: ETO-COEP 00082/2025 | B9: 2025 | C9: COI | D9: ETO-COEP | E9: AL02113003 | F9: 5901886003 | G9: EMERGENCIAL | H9: SS PENDENTE | I9: 45397.508 | J9: 45785.375 | L9: 45788.375 | M9: BANCO CAPACITOR DE DISTRIBUIÇÃO GIS | N9: BANCO CAPACITOR - 13.8 | O9: GURUPI | P9: URBANO | Q9: JULIO CESAR RODRIGUES SANTANA | R9: INDISPONIBILIDADE PARA OPERAÇÃO | S9: 0301886003
A10: ETO-COEP 00058/2024 | B10: 2024 | C10: COI | D10: ETO-COEP | E10: AL03103004 | F10: 5924849004 | G10: ALTA | H10: SS PENDENTE | I10: 45406.727 | J10: 45412.487 | L10: 45472.487 | M10: BANCO CAPACITOR DE DISTRIBUIÇÃO GIS | N10: BANCO CAPACITOR - 13.8 | O10: ARAGUAINA | P10: URBANO | Q10: CLEBSON ALVES DUARTE | R10: INDISPONIBILIDADE PARA OPERAÇÃO | S10: 0324849004
A11: ETO-COEP 00060/2024 | B11: 2024 | C11: COI | D11: ETO-COEP | E11: AL05010004 | F11: 5913313004 | G11: EMERGENCIAL | H11: SS PENDENTE | I11: 45408.244 | J11: 45412.488 | L11: 45415.488 | M11: BANCO CAPACITOR DE DISTRIBUIÇÃO GIS | N11: BANCO CAPACITOR - 13.8 | O11: ARAGUAINA | P11: URBANO | Q11: Euzilan Mateus Barreira Santos | R11: INDISPONIBILIDADE PARA OPERAÇÃO | S11: 0313313004
A12: ETO-COEP 00085/2025 | B12: 2025 | C12: COI | D12: ETO-COEP | E12: AL01010004 | F12: 5903718004 | G12: EMERGENCIAL | H12: SS PENDENTE | I12: 45429.543 | J12: 45786.621 | L12: 45789.621 | M12: BANCO CAPACITOR DE DISTRIBUIÇÃO GIS | N12: BANCO CAPACITOR - 13.8 | O12: ARAGUAINA | P12: URBANO | Q12: LEONARDO SANTOS DA SILVA | R12: INDISPONIBILIDADE PARA OPERAÇÃO
A13: ETO-COEP 00084/2025 | B13: 2025 | C13: COI | D13: ETO-COEP | E13: AL02010004 | F13: 5900470004 | G13: ALTA | H13: SS PENDENTE | I13: 45429.543 | J13: 45786.62 | L13: 45846.62 | M13: BANCO CAPACITOR DE DISTRIBUIÇÃO GIS | N13: BANCO CAPACITOR - 13.8 | O13: ARAGUAINA | P13: URBANO | Q13: LEONARDO SANTOS DA SILVA | R13: INDISPONIBILIDADE PARA OPERAÇÃO
A14: ETO-COEP 00083/2024 | B14: 2024 | C14: COI | D14: ETO-COEP | E14: AL01061029 | F14: 5900064029 | G14: ALTA | H14: SS PENDENTE | I14: 45432.497 | J14: 45469.694 | L14: 45529.694 | M14: BANCO CAPACITOR DE DISTRIBUIÇÃO GIS | N14: BANCO CAPACITOR - 13.8 | O14: PALMEIROPOLIS | P14: URBANO | Q14: CLEBSON ALVES DUARTE | R14: INDISPONIBILIDADE PARA OPERAÇÃO | S14: 0300064029
A15: ETO-COEP 00109/2026 | B15: 2026 | C15: COPC | D15: ETO-COEP | E15: LD01059122 | F15: 5852775092 | G15: ALTA | H15: SS PENDENTE | I15: 45447.64 | J15: 46182.426 | L15: 46242.426 | M15: REGULADOR DE TENSÃO DE DISTRIBUIÇÃO GIS | N15: REGULADOR DE TENSAO DE DIST. - 34.5 | O15: NOVO ACORDO | P15: RURAL | Q15: Lorrane Sousa Gonçalves | R15: OBRAS (NOVOS EQUIPAMENTOS) | S15: 9007536092
A16: ETO-COEP 00146/2024 | B16: 2024 | C16: COI | D16: ETO-COEP | E16: AL03062013 | F16: 5900003013 | G16: ALTA | H16: SS PENDENTE | I16: 45537.337 | J16: 45615.441 | L16: 45675.441 | M16: BANCO CAPACITOR DE DISTRIBUIÇÃO GIS | N16: BANCO CAPACITOR - 13.8 | O16: PARAISO DO TOCANTINS | P16: RURAL | Q16: VALDENISIO FILHO RAMOS DE JESUS | R16: INDISPONIBILIDADE PARA OPERAÇÃO | S16: 0300003013
A17: ETO-COEP 00086/2026 | B17: 2026 | C17: COI | D17: ETO-COEP | E17: LD02025012 | F17: 7908686014 | G17: EMERGENCIAL | H17: SS PENDENTE | I17: 45580.697 | J17: 46136.68 | L17: 46139.68 | M17: RELIGADOR DE REDE GIS | N17: RELIGADOR DE LINHA - 38kV | O17: PIUM | P17: URBANO | Q17: VINICIUS CAMARGO COSTA | R17: INDISPONIBILIDADE PARA OPERAÇÃO | S17: 7908686014
A18: ETO-COEP 00119/2025 | B18: 2025 | C18: COPO | D18: ETO-COEP | E18: AL01048007 | F18: 7925573007 | G18: ALTA | H18: SS PENDENTE | I18: 45595.356 | J18: 45839.392 | L18: 45899.392 | M18: RELIGADOR DE REDE GIS | N18: RELIGADOR DE LINHA - 13,8kV | O18: MIRACEMA DO TOCANTINS | P18: URBANO | Q18: JULIA GRAZYELLE BRITO OLIVEIRA | R18: EM OPERAÇÃO COM ANOMALIA | S18: 7925573007
A19: ETO-COEP 00025/2026 | B19: 2026 | C19: COPC | D19: ETO-COEP | E19: AL01018071 | F19: 5854681071 | G19: ALTA | H19: SS PENDENTE | I19: 45617.606 | J19: 46051.354 | L19: 46111.354 | M19: REGULADOR DE TENSÃO DE DISTRIBUIÇÃO GIS | N19: REGULADOR DE TENSAO DE DIST. - 13.8 | O19: BREJINHO DE NAZARE | P19: URBANO | Q19: BOAVENTURA JUNIOR FERREIRA LOPE | R19: OBRAS (NOVOS EQUIPAMENTOS) | S19: 9000001071
A20: ETO-COEP 00162/2024 | B20: 2024 | C20: COI | D20: ETO-COEP | E20: AL02003036 | F20: 7936753097 | G20: EMERGENCIAL | H20: SS PENDENTE | I20: 45628.562 | J20: 45635.713 | L20: 45638.713 | M20: LOCAL INSTAL RELIGADOR DE LINHA GIS | N20: BLOCO RELIGADOR DE LINHA | O20: TALISMA | P20: RURAL | Q20: CLEBSON ALVES DUARTE | R20: OBRAS (NOVOS EQUIPAMENTOS) | S20: 9000457097
A21: ETO-COEP 00138/2025 | B21: 2025 | C21: COI | D21: ETO-COEP | E21: LD03105019 | F21: 5700008077 | G21: URGENTE | H21: SS PENDENTE | I21: 45704.365 | J21: 45841.67 | L21: 45848.67 | M21: POSTE RD GIS | N21: POSTE Concreto Duplo T | O21: GOIATINS | P21: URBANO | Q21: LEONARDO SANTOS DA SILVA | R21: SOLICITAÇÃO DE SERVIÇO | S21: 5755363077
A22: ETO-COEP 00100/2025 | B22: 2025 | C22: COI | D22: ETO-COEP | E22: LD01065015 | F22: 7900001227 | G22: EMERGENCIAL | H22: SS PENDENTE | I22: 45705.51 | J22: 45799.672 | L22: 45802.672 | M22: LOCAL INSTAL RELIGADOR DE LINHA GIS | N22: BLOCO RELIGADOR DE LINHA | O22: RECURSOLANDIA | P22: URBANO | Q22: Lorrane Sousa Gonçalves | R22: AVISO PROTEÇÃO & SELETIVIDADE | S22: 9000001227
A23: ETO-COEP 00133/2025 | B23: 2025 | C23: DEOP | D23: ETO-COEP | E23: LD04010004 | F23: 5700008159 | G23: URGENTE | H23: SS PENDENTE | I23: 45729.425 | J23: 45841.611 | L23: 45848.611 | M23: POSTE RD GIS | N23: POSTE Concreto Duplo T | O23: MURICILANDIA | P23: URBANO | Q23: LEONARDO SANTOS DA SILVA | R23: AVISO DE ANOMALIA | S23: 5700008159
A24: ETO-COEP 00158/2025 | B24: 2025 | C24: COI | D24: ETO-COEP | E24: LD03046026 | F24: 7942485096 | G24: EMERGENCIAL | H24: SS PENDENTE | I24: 45730.788 | J24: 45861.444 | L24: 45864.444 | M24: LOCAL INSTAL RELIGADOR DE LINHA GIS | N24: BLOCO RELIGADOR DE LINHA | O24: PINDORAMA DO TOCANTINS | P24: RURAL | Q24: BOAVENTURA JUNIOR FERREIRA LOPE | R24: INDISPONIBILIDADE PARA OPERAÇÃO | S24: 8800153096
A25: ETO-COEP 00089/2025 | B25: 2025 | C25: COI | D25: ETO-COEP | E25: AL02054060 | F25: 5719217060 | G25: EMERGENCIAL | H25: SS PENDENTE | I25: 45734.78 | J25: 45786.716 | L25: 45789.716 | M25: POSTE RD GIS | N25: POSTE Concreto Duplo T | O25: NOVA OLINDA | P25: URBANO | Q25: LEONARDO SANTOS DA SILVA | R25: AVISO DE ANOMALIA | S25: 5719217060
... A40: ETO-COEP 00145/2025 | B40: 2025 | C40: MANUT | D40: ETO-COEP | E40: AL04040004 | F40: 8804228004 | G40: ALTA | H40: SS PENDENTE | I40: 45769.553 | J40: 45848.621 | L40: 45908.621 | M40: POSTE RD GIS | N40: POSTE Concreto Duplo T | O40: ARAGUAINA | P40: URBANO | Q40: LEONARDO SANTOS DA SILVA | R40: AVISO DE ANOMALIA | S40: 8804228004
A41: ETO-COEP 00073/2025 | B41: 2025 | C41: COI | D41: ETO-COEP | E41: AL02060122 | F41: 5900489122 | G41: EMERGENCIAL | H41: SS PENDENTE | I41: 45770.159 | J41: 45775.684 | L41: 45778.684 | M41: BANCO CAPACITOR DE DISTRIBUIÇÃO GIS | N41: BANCO CAPACITOR - 13.8 | O41: PALMAS | P41: URBANO | Q41: CLEBSON ALVES DUARTE | R41: INDISPONIBILIDADE PARA OPERAÇÃO
A42: ETO-COEP 00074/2025 | B42: 2025 | C42: COI | D42: ETO-COEP | E42: AL06059122 | F42: 5952202122 | G42: EMERGENCIAL | H42: SS PENDENTE | I42: 45771.194 | J42: 45775.699 | L42: 45778.699 | M42: BANCO CAPACITOR DE DISTRIBUIÇÃO GIS | N42: BANCO CAPACITOR - 13.8 | O42: PALMAS | P42: URBANO | Q42: CLEBSON ALVES DUARTE | R42: INDISPONIBILIDADE PARA OPERAÇÃO | S42: 8800388122
A43: ETO-COEP 00075/2025 | B43: 2025 | C43: COI | D43: ETO-COEP | E43: AL07060122 | F43: 5952327122 | G43: EMERGENCIAL | H43: SS PENDENTE | I43: 45771.216 | J43: 45775.701 | L43: 45778.701 | M43: BANCO CAPACITOR DE DISTRIBUIÇÃO GIS | N43: BANCO CAPACITOR - 13.8 | O43: PALMAS | P43: URBANO | Q43: CLEBSON ALVES DUARTE | R43: INDISPONIBILIDADE PARA OPERAÇÃO | S43: 0352228122
A44: ETO-COEP 00076/2025 | B44: 2025 | C44: COI | D44: ETO-COEP | E44: AL08059122 | F44: 5951650122 | G44: EMERGENCIAL | H44: SS PENDENTE | I44: 45772.238 | J44: 45775.702 | L44: 45778.702 | M44: BANCO CAPACITOR DE DISTRIBUIÇÃO GIS | N44: BANCO CAPACITOR - 13.8 | O44: PALMAS | P44: URBANO | Q44: CLEBSON ALVES DUARTE | R44: INDISPONIBILIDADE PARA OPERAÇÃO | S44: 8800777122
A45: ETO-COEP 00079/2025 | B45: 2025 | C45: COI | D45: ETO-COEP | E45: LD02059122 | F45: 7923927122 | G45: EMERGENCIAL | H45: SS PENDENTE | I45: 45774.462 | J45: 45776.576 | L45: 45779.576 | M45: LOCAL INSTAL RELIGADOR DE LINHA GIS | N45: BLOCO RELIGADOR DE LINHA | O45: PALMAS | P45: RURAL | Q45: CLEBSON ALVES DUARTE | R45: INDISPONIBILIDADE PARA OPERAÇÃO | S45: 9023928122
A46: ETO-COEP 00147/2025 | B46: 2025 | C46: COI | D46: ETO-COEP | E46: AL01040004 | F46: 5703750004 | G46: ALTA | H46: SS PENDENTE | I46: 45775.601 | J46: 45848.622 | L46: 45908.622 | M46: POSTE RD GIS | N46: POSTE Concreto Duplo T | O46: ARAGUAINA | P46: URBANO | Q46: LEONARDO SANTOS DA SILVA | R46: AVISO DE ANOMALIA | S46: 5703750004
A47: ETO-COEP 00077/2025 | B47: 2025 | C47: COCM | D47: ETO-COEP | E47: AL05060122 | F47: 5907243122 | G47: EMERGENCIAL | H47: SS PENDENTE | I47: 45775.706 | J47: 45775.706 | L47: 45778.706 | M47: BANCO CAPACITOR DE DISTRIBUIÇÃO GIS | N47: BANCO CAPACITOR - 13.8 | O47: PALMAS | P47: URBANO | Q47: CLEBSON ALVES DUARTE | R47: INDISPONIBILIDADE PARA OPERAÇÃO | S47: 0307243122
A48: ETO-COEP 00103/2025 | B48: 2025 | C48: COI | D48: ETO-COEP | E48: LD02059122 | F48: 7910027196 | G48: EMERGENCIAL | H48: SS PENDENTE | I48: 45785.415 | J48: 45804.75 | L48: 45807.75 | M48: LOCAL INSTAL RELIGADOR DE LINHA GIS | N48: BLOCO RELIGADOR DE LINHA | O48: LAGOA DO TOCANTINS | P48: URBANO | Q48: ZENILSON MOREIRA SANTOS | R48: INDISPONIBILIDADE PARA OPERAÇÃO | S48: 9000347196
A49: ETO-COEP 00095/2025 | B49: 2025 | C49: COI | D49: ETO-COEP | E49: AL02010004 | F49: 5955192004 | G49: EMERGENCIAL | H49: SS PENDENTE | I49: 45790.172 | J49: 45790.313 | L49: 45793.313 | M49: BANCO CAPACITOR DE DISTRIBUIÇÃO GIS | N49: BANCO CAPACITOR - 13.8 | O49: ARAGUAINA | P49: URBANO | Q49: LEONARDO SANTOS DA SILVA | R49: NOTA DE SERVIÇO (NS) - LINHA VIVA | S49: 0355192004
A50: ETO-COEP 00101/2025 | B50: 2025 | C50: MANUT | D50: ETO-COEP | E50: LD02066094 | F50: 5855776094 | G50: URGENTE | H50: SS PENDENTE | I50: 45803.466 | J50: 45803.466 | L50: 45810.466 | M50: REGULADOR DE TENSÃO DE DISTRIBUIÇÃO GIS | N50: REGULADOR DE TENSAO DE DIST. - 34.5 | O50: PEIXE | P50: RURAL | Q50: Lorrane Sousa Gonçalves | R50: SOLICITAÇÃO DE SERVIÇO | S50: 8800173094
A51: ETO-COEP 00102/2025 | B51: 2025 | C51: MANUT | D51: ETO-COEP | E51: LD02010004 | F51: 7900532053 | G51: ALTA | H51: SS PENDENTE | I51: 45803.621 | J51: 45803.621 | L51: 45863.621 | M51: RELIGADOR DE REDE GIS | N51: RELIGADOR DE LINHA - 38kV | O51: PIRAQUE | P51: URBANO | Q51: EDNA MARIA DOS SANTOS PINTO | R51: INDISPONIBILIDADE PARA OPERAÇÃO
A52: ETO-COEP 00179/2025 | B52: 2025 | C52: MANUT | D52: ETO-COEP | E52: AL03109039 | F52: 7922995039 | G52: PROGRAMAVEL | H52: SS PENDENTE | I52: 45806.446 | J52: 45902.449 | L52: 46302.449 | M52: RELIGADOR DE REDE GIS | N52: RELIGADOR DE LINHA - 13,8kV | O52: ARAGUATINS | P52: RURAL | Q52: Allan Pereira de Souza | R52: INDISPONIBILIDADE PARA OPERAÇÃO | S52: 7922995039
A53: ETO-COEP 00162/2025 | B53: 2025 | C53: MANUT | D53: ETO-COEP | E53: LD02109039 | F53: 7928564039 | G53: ALTA | H53: SS PENDENTE | I53: 45806.453 | J53: 45866.659 | L53: 45926.659 | M53: RELIGADOR DE REDE GIS | N53: RELIGADOR DE LINHA - 38kV | O53: ARAGUATINS | P53: RURAL | Q53: Allan Pereira de Souza | R53: INDISPONIBILIDADE PARA OPERAÇÃO | S53: 7928564039
A54: ETO-COEP 00120/2025 | B54: 2025 | C54: COI | D54: ETO-COEP | E54: LD01084002 | F54: 7920024127 | G54: EMERGENCIAL | H54: SS PENDENTE | I54: 45810.34 | J54: 45839.597 | L54: 45842.597 | M54: LOCAL INSTAL RELIGADOR DE LINHA GIS | N54: BLOCO RELIGADOR DE LINHA | O54: PALMEIRAS DO TOCANTINS | P54: URBANO | Q54: Allan Pereira de Souza | R54: INDISPONIBILIDADE PARA OPERAÇÃO | S54: 9001177127
...

Sheet Planilha1

Sheet Dados Tratados
A1: SS | B1: Ano | C1: Descrição | D1: DataOcorrência | E1: Abrangencia | F1: Instalação | G1: Trecho | H1: Localização | I1: Complemento | J1: Sigla Orgao | K1: SolicNome | L1: DescPrioridade | M1: SS-Estados | N1: Data/Hora Limite | O1: Ativos | P1: Qtd_Clientes | Q1: Espécies | R1: SS-Tipos | S1: Término | T1: OSNumero | U1: OS-Estados | V1: PlanDataInicio | W1: PlanDataFinal | X1: DescOrigem | Y1: Condição Operativa COI | Z1: Descrição do Defeito | AA1: Lida | AB1: Processo | AC1: DEPARTCODE | AD1: UF | AE1: Bairro | AF1: Logradouro | AG1: OS SIATT | AH1: SS PRINCIPAL | AI1: SOMA | AJ1: COORDENADA UTM Y | AK1: LOCALIDADE | AL1: COORDENADA UTM X | AM1: EST PRIMÁRIA | AN1: EST SECUNDÁRIA | AO1: EQUIPAMENTO/CATEGORIA | AP1: STATUS | AQ1: ANÁLISE TÉCNICA | AR1: GRUPO ANÁLISE | AS1: EQUIPAMENTO PRINCIPAL | AT1: OBSERVAÇÕES | AU1: POSSÍVEL REPETIÇÃO | AV1: mm | AW1: metros | AX1: ou | AY1: mm2 | AZ1: metros2 | BA1: Atualizações
A2: ETO-COEP 00002/2026 | B2: 2026 | C2: SEGUE SOLICITAÇÃO DE SERVIÇO PARA BANCO CAPACITOR COM CÉLULA DA FASE B QUEIMADA EQUIPE 047OP01 INFORMOU QUE JA FIZERAM TESTE E NÃO ACEITOU ID#81133777 RDU DE FIGUEIROPOLIS | D2: 06/01/2026 09:26:14 | E2: 0300697047 | F2: AL01033047 | G2: 3 | H2: 5900038047 | I2: 190-16323937 | J2: COI | K2: JONATAN ALVES DE SOUZA | L2: EMERGENCIAL | M2: SS PENDENTE | N2: 09/01/2026 09:45:30 | O2: 190.02318 | P2: 0 | Q2: BANCO CAPACITOR DE DISTRIBUIÇÃO GIS | R2: INDISPONIBILIDADE PARA OPERAÇÃO | X2: CORPO (CÉLULA) | Z2: CURTO CIRCUITO | AA2: NÃO | AC2: ETO-COEP | AH2: ETO-RD-GU 00023/2026 | AI2: Não | AJ2: 8657782 | AK2: FIGUEIROPOLIS | AL2: 698997 | AO2: EQUIPAMENTO ESPECIAL | AP2: PENDÊNCIA DCMD | AQ2: REPASSAR DMSL | AR2: ANÁLISE | AS2: A DEFINIR (REPASSE)
A3: ETO-COEP 00005/2026 | B3: 2026 | C3: TROCAR BARRAMENTO DO TRAFO 5700440004 PARA 70MM | D3: 05/09/2025 09:26:08 | E3: 5700440004 | F3: AL02010004 | G3: 3 | H3: 5700440004 | I3: 190-15833293 | J3: COCM | K3: LEONARDO SANTOS DA SILVA | L3: ALTA | M3: SS PENDENTE | N3: 15/03/2026 15:40:18 | O3: 190.0239 | P3: 40 | Q3: TRANSFORMADOR DE DISTRIBUIÇÃO GIS | R3: AVISO DE ANOMALIA | X3: SOBRECARGA PREVENTIVA | Z3: SOBRECARGA | AA3: NÃO | AC3: ETO-COEP | AH3: ETO-RD-AR 01312/2025 | AI3: Não | AJ3: 9204397 | AK3: ARAGUAINA | AL3: 806192 | AO3: PLANO DE MEDIDAS | AP3: PENDÊNCIA DCMD | AQ3: REPASSAR COCM | AR3: REPASSE | AS3: A DEFINIR (REPASSE)
A4: ETO-COEP 00006/2026 | B4: 2026 | C4: FAVOR SUBSTITUIR 150 MTS DE CABO CONVENCIONAL DETERIORADO E CHEIO DE EMENDAS POR CADO MULTIPLEX NO TRAFO 5700244004 ENTRE OS ID : 63111183 AO ID :63239363 SEGUE FOTOS EM ANEXO | D4: 10/09/2025 17:08:23 | E4: 5700244004 | F4: AL03010004 | G4: 3 | H4: 5700244004 | I4: 190-1648091 | J4: DEOP | K4: WESLEY FRANCISCO DE ASSIS ROCH | L4: ALTA | M4: SS PENDENTE | N4: 15/03/2026 15:40:49 | O4: 190.00487 | P4: 90 | Q4: POSTE RD GIS | R4: AVISO DE ANOMALIA | X4: CABOS BT | Z4: DETERIORADA | AA4: NÃO | AC4: ETO-COEP | AD4: Tocantins | AH4: ETO-RD-AR 01339/2025 | AI4: Não | AJ4: 9203692 | AK4: ARAGUAINA | AL4: 806862 | AN4: S1 | AO4: CABOS FORA COEP | AP4: PENDÊNCIA DCMD | AQ4: CABOS | AR4: MANUTENÇÃO | AS4: CABOS | AV4: 35/70 | AW4: 150
A5: ETO-COEP 00007/2026 | B5: 2026 | C5: Bom Dia Segue SS Senhores enviar equipe de manutenção para trocar cabo deteriorado a RDU de Araguaína ID: 76492244 Trafo 5704265004 Instalar cabo entre os ID: 76492244 e 76492235 Endereço: Rua QE21 Lt 64 Jardim Boa sorte Levar: 150 metros de cabo 35mm multiplex Equipe: 004op07 Contato da equipe:99216-8451 | D5: 27/10/2025 11:12:10 | E5: 5704265004 | F5: AL07010004 | G5: 3 | H5: 5704265004 | I5: 190-1842256 | J5: MANUT | K5: ERLAN PEREIRA DE SOUSA | L5: ALTA | M5: SS PENDENTE | N5: 16/03/2026 13:30:16 | O5: 190.00959 | P5: 66 | Q5: POSTE RD GIS | R5: AVISO DE ANOMALIA | X5: CABOS BT | Z5: DETERIORADA | AA5: NÃO | AC5: ETO-COEP | AD5: Tocantins | AH5: ETO-RD-AR 01611/2025 | AI5: Não | AJ5: 9205274 | AK5: ARAGUAINA | AL5: 804541 | AN5: SI-3 | AO5: CABOS FORA COEP | AP5: PENDÊNCIA DCMD | AQ5: CABOS | AR5: MANUTENÇÃO | AS5: CABOS | AV5: 35 | AW5: 150
A6: ETO-COEP 00009/2026 | B6: 2026 | C6: Segue SS para instalar chave faca para manobra na quadra 1203 Sul. ID 57429768 Estrutura N4 Chave de referencia 0300953122. Serviço a ser executado com linha viva ********************************* PARECER COCM COEP gentileza verificar solicitação da operação. Sendo interessante para ETO, gentileza direcionar atendimento ao COCM informando de onde o custo será debitado. | D6: 13/01/2026 22:44:13 | E6: 0300953122 | F6: AL07097122 | G6: 3 | H6: 6800953122 | I6: 190-399314 | J6: COI | K6: HERIK BUARQUE DOS SANTOS | L6: EMERGENCIAL | M6: SS PENDENTE | N6: 19/01/2026 14:33:47 | O6: 190.00993 | P6: 1,097 | Q6: POSTE RD GIS | R6: AVISO DE CADASTRO | X6: CHAVE | Z6: INEXISTENTE | AA6: NÃO | AC6: ETO-COEP | AD6: Tocantins | AH6: ETO-RD-PA 00026/2026 | AI6: Não | AJ6: 8864791 | AK6: PALMAS | AL6: 791175 | AM6: N4 | AN6: S4 | AO6: PLANO DE MEDIDAS | AP6: PENDÊNCIA DCMD | AQ6: CHAVE- FACA | AR6: ANÁLISE | AS6: CHAVE
A7: ETO-COEP 00011/2026 | B7: 2026 | C7: Remover chave 0306784122 para estrutura N4, poste ID#59387277 . Ação oriunda ocorrências relevantes realizada em 16/01 ( desarme AL 4 SE Palmas II). ********************************* PARECER COCM COEP gentileza verificar solicitação da operação. Sendo interessante para ETO, gentileza direcionar atendimento ao COCM informando de onde o custo será debitado. | D7: 16/01/2026 16:08:28 | E7: 8806782122 | F7: AL04059122 | G7: 3 | H7: 8806782122 | I7: 190-441396 | J7: COPO | K7: MIGUEL FRANCISCO PEREIRA | L7: URGENTE | M7: SS PENDENTE | N7: 23/01/2026 16:55:04 | O7: 190.00667 | P7: 582 | Q7: POSTE RD GIS | R7: NOTA DE SERVIÇO (NS) - LINHA VIVA | AA7: NÃO | AC7: ETO-COEP | AD7: Tocantins | AH7: ETO-RD-PA 00044/2026 | AI7: Não | AJ7: 8869067 | AK7: PALMAS | AL7: 794173 | AM7: N4 | AN7: S3 | AO7: EQUIPAMENTO ESPECIAL | AP7: PENDÊNCIA DCMD | AQ7: REPASSAR COCM | AR7: REPASSE | AS7: A DEFINIR (REPASSE)
A8: ETO-COEP 00013/2026 | B8: 2026 | C8: TRAFO ANTIGO com sobrecarga. Potência: 112,5 kVA - Substituir por um de 150 kVA. Tensão: 13,8 kV. *********************************** PARECER COCM CENTRO COEP favor verificar ações para constatações de sobrecarga e direcionar atendimento de substituição se for o caso. | D8: 19/01/2026 21:07:34 | E8: 0300587122 | F8: AL04059122 | G8: 3 | H8: 5702635122 | I8: 190-13722315 | J8: COI | K8: ASTROGILDO PIRES BERNARDO | L8: EMERGENCIAL | M8: SS PENDENTE | N8: 23/01/2026 08:18:40 | O8: 190.02385 | P8: 69 | Q8: LOCAL INSTAL TRANSFORMADOR DE DISTRIBUIÇÃO GIS | R8: AVISO DE ANOMALIA | X8: SOBRECARGA PREVENTIVA | Z8: SOBRECARGA | AA8: NÃO | AC8: ETO-COEP | AH8: DOLP-RD-PA 00097/2026 | AI8: Não | AJ8: 8868117 | AK8: PALMAS | AL8: 792975 | AO8: PLANO DE MEDIDAS | AP8: PENDÊNCIA DCMD | AQ8: REPASSAR COCM | AR8: REPASSE | AS8: A DEFINIR (REPASSE)
A9: ETO-COEP 00015/2026 | B9: 2026 | C9: Segue nota para envia equipe LV instala jogo de chave faca no poste ID-57357485 estrutura N4, Tensão 13.8kv, Cabo AA / 2/0, Acesso livre, Circuito do AL-01 de Luzimangues. Obs. CH para facilitar manobras no trecho. ******************************** PARECER DO COCM COEP favor analisar solicitação da operação de melhoria na rede e se validada retornar demanda ao COCM informando aonde será lançado o custo. | D9: 18/11/2025 10:38:14 | E9: 8803678271 | F9: AL01101271 | G9: 1 | H9: 8803678271 | I9: 190-411989 | J9: COI | K9: SAMUEL PINTO GOMES | L9: PROGRAMAVEL | M9: SS PENDENTE | N9: 24/02/2027 18:25:18 | O9: 190.01019 | P9: 955 | Q9: POSTE RD GIS | R9: NOTA DE SERVIÇO (NS) - LINHA VIVA | X9: OUTROS | Z9: INSPEÇÃO VISUAL | AA9: NÃO | AC9: ETO-COEP | AD9: Tocantins | AH9: ETO-RD-PA 00778/2025 | AI9: Não | AJ9: 8872214 | AK9: PORTO NACIONAL | AL9: 775561 | AM9: N4 | AO9: MELHORIA DE REDE | AP9: PENDÊNCIA DCMD | AQ9: REPASSAR COCM | AR9: REPASSE | AS9: A DEFINIR (REPASSE)
A10: ETO-COEP 00016/2026 | B10: 2026 | C10: rdu Palmas proximo Unimed e hospital Cristo rei id 57403822 sj 57404949 estrutura N4 istalar jogo de chave faca 13,8 NF para manobra id 42151836 sj 57404952 estruutra N4/N3 ch 0300839122 substituir jogo chave lamina po jogo de chave faca 13,8 ************************ PARECER DO COCM COEP favor analisar solicitação da operação de melhoria na rede e se validada retornar demanda ao COCM informando aonde será lançado o custo. | D10: 26/09/2025 18:40:52 | E10: 8801117122 | F10: AL08097122 | G10: 2 | H10: 0300839122 | I10: 190-17402150 | J10: COI | K10: CLEONE PEREIRA DE SOUZA LIMA | L10: EMERGENCIAL | M10: SS PENDENTE | N10: 23/01/2026 18:34:35 | O10: 190.00091 | P10: 718 | Q10: LOCAL INSTAL CHAVE FUSÍVEL GIS | R10: NOTA DE SERVIÇO (NS) - LINHA VIVA | X10: PORTA FUSÍVEL | Z10: INSPEÇÃO VISUAL | AA10: NÃO | AC10: ETO-COEP | AD10: Tocantins | AH10: ETO-RD-PA 00654/2025 | AI10: Não | AJ10: 8869375 | AK10: PALMAS | AL10: 791764 | AO10: MELHORIA DE REDE | AP10: PENDÊNCIA DCMD | AQ10: ENTENDER | AR10: ANÁLISE | AS10: A DEFINIR (análise) | AT10: rdu Palmas proximo Unimed e hospital Cristo rei id 57403822 sj 57404949 estrutura N4 istalar jogo de chave faca 13,8 NF para manobra id 42151836 sj 57404952 estruutra N4/N3 ch 0300839122 substituir jogo chave lamina po jogo de chave faca 13,8 ************************ PARECER DO COCM COEP favor analisar solicitação da operação de melhoria na rede e se validada retornar demanda ao COCM informando aonde será lançado o custo. | AU10: REPETIDA
A11: ETO-COEP 00017/2026 | B11: 2026 | C11: rdu Palmas proximo Unimed e hospital Cristo rei id 57403822 sj 57404949 estrutura N4 istalar jogo de chave faca 13,8 NF para manobra id 42151836 sj 57404952 estruutra N4/N3 ch 0300839122 substituir jogo chave lamina po jogo de chave faca 13,8 **************************** PARECER DO COCM COEP favor analisar solicitação da operação de melhoria na rede e se validada retornar demanda ao COCM informando aonde será lançado o custo. | D11: 26/09/2025 18:40:52 | E11: 8804511122 | F11: AL08097122 | G11: 2 | H11: 8804511122 | I11: 190-398539 | J11: COI | K11: CLEONE PEREIRA DE SOUZA LIMA | L11: EMERGENCIAL | M11: SS PENDENTE | N11: 23/01/2026 18:34:57 | O11: 190.0099 | P11: 437 | Q11: POSTE RD GIS | R11: NOTA DE SERVIÇO (NS) - LINHA VIVA | X11: PORTA FUSÍVEL | Z11: INSPEÇÃO VISUAL | AA11: NÃO | AC11: ETO-COEP | AD11: Tocantins | AH11: ETO-RD-PA 00655/2025 | AI11: Não | AJ11: 8869976 | AK11: PALMAS | AL11: 791764 | AM11: N4 | AN11: S3 | AO11: MELHORIA DE REDE | AP11: PENDÊNCIA DCMD | AQ11: ENTENDER | AR11: ANÁLISE | AS11: A DEFINIR (análise) | AT11: rdu Palmas proximo Unimed e hospital Cristo rei id 57403822 sj 57404949 estrutura N4 istalar jogo de chave faca 13,8 NF para manobra id 42151836 sj 57404952 estruutra N4/N3 ch 0300839122 substituir jogo chave lamina po jogo de chave faca 13,8 ************************ PARECER DO COCM COEP favor analisar solicitação da operação de melhoria na rede e se validada retornar demanda ao COCM informando aonde será lançado o custo.
A12: ETO-COEP 00018/2024 | B12: 2024 | C12: Favor enviar equipe para verificar banco de capacitor :5952243122 danificado fase B e C na quadra 606 Sul | D12: 18/02/2024 05:44:18 | E12: 0352243122 | F12: AL04059122 | G12: 3 | H12: 5952243122 | I12: 190-49522936 | J12: COI | K12: NATANAEL MELQUIADES DOS SANTOS | L12: EMERGENCIAL | M12: SS PENDENTE | N12: 22/02/2024 16:05:01 | O12: 190.02684 | P12: 0 | Q12: BANCO CAPACITOR DE DISTRIBUIÇÃO GIS | R12: INDISPONIBILIDADE PARA OPERAÇÃO | X12: OUTROS | Z12: QUEIMADO | AA12: SIM | AC12: ETO-COEP | AH12: DOLP-RD-PA 00205/2024 | AI12: Não | AJ12: 8868932 | AK12: PALMAS | AL12: 793345 | AO12: EQUIPAMENTO ESPECIAL | AP12: PENDÊNCIA DCMD | AQ12: BANCO DE CAPACITOR | AR12: MANUTENÇÃO | AS12: BANCO DE CAPACITOR
A13: ETO-COEP 00020/2026 | B13: 2026 | C13: Substituição de tanque e controle, os mesmos estão com defeitos. | D13: 22/01/2026 11:05:26 | E13: 7908708116 | F13: LD04002091 | G13: 2 | H13: 7908708116 | I13: 190-17512824 | J13: SCADA | K13: LARA SOARES FARIAS | L13: PROGRAMAVEL | M13: SS PENDENTE | N13: 26/02/2027 11:05:26 | O13: 190.02296 | P13: 219 | Q13: RELIGADOR DE REDE GIS | R13: INDISPONIBILIDADE PARA OPERAÇÃO | AA13: NÃO | AC13: ETO-COEP | AI13: Não | AJ13: 8722032 | AK13: CHAPADA DA NATIVIDADE | AL13: 849089 | AO13: EQUIPAMENTO ESPECIAL | AP13: PENDÊNCIA DCMD | AQ13: TANQUE E CONTROLE | AR13: MANUTENÇÃO | AS13: TANQUE
A14: ETO-COEP 00021/2026 | B14: 2026 | C14: Regulador 5803327001 fora de operação, by passado em campo com painel de comunicação com cabos desconectados tensão 13.8. parecer DMSL: Feedback Equip. Especiais RT 5803327001 RELÉ RUA Sid: 4844 Data: 19/09/2025 Serviço realizado: *Equipamento foi remanejado, 7 km da sua localização sentido Palmas necessário comissionamento completo *Equipamento com um dos cabos umbilicais danificado. * aterramento bucha FC não esta interligada corretamente * para-raios estão no mesmo aterramento da bucha FC. * Tranques muito alto e próximo da rede não permitindo o comissionamento com segurança. * Controle alto demais tem que baixar Equipamento ficou em operação?: não Pendência: sim, precisa comissionar completo OBS; reprogramar equipamento. Bateria(s) substituída(s) NÃO Equipe: Ellisfran, Ana Maria PARECER DMSL: Data 03/12/2025-Equipe: Carliel e Benvindo Serviço executado foi ensaiado as três células Equipamento ficou em operação: Não Pendência: sim, Instalar controle completo, e fazer melhoria na malhar de aterramento | D14: 04/09/2025 21:36:22 | E14: 8851077001 | F14: AL01102271 | G14: 2 | H14: 5803327001 | I14: 190-15851809 | J14: COI | K14: HELDER SILVA CARVALHO | L14: EMERGENCIAL | M14: SS PENDENTE | N14: 25/01/2026 11:48:23 | O14: 190.02318 | P14: 39 | Q14: REGULADOR DE TENSÃO DE DISTRIBUIÇÃO GIS | R14: INDISPONIBILIDADE PARA OPERAÇÃO | X14: FORA DE SERVIÇO | Z14: RELÉ REGULADOR DE TENSÃO | AA14: NÃO | AC14: ETO-COEP | AH14: ETO-DEOP 00014/2025 | AI14: Não | AJ14: 8872358 | AK14: PORTO NACIONAL | AL14: 770823 | AO14: EQUIPAMENTO ESPECIAL | AP14: PENDÊNCIA DCMD | AQ14: INSTALAR CONTROLE E MELHORIA DE ATERRAMENTO | AR14: MANUTENÇÃO | AS14: ATERRAMENTO
A15: ETO-COEP 00024/2026 | B15: 2026 | C15: REALIZAR SUBSTITUIÇÃO DO TANQUE, O MESMO ESTÁ COM DEFEITO. | D15: 27/01/2026 16:33:07 | E15: 7933585074 | F15: LD03028074 | G15: 2 | H15: 7933585074 | I15: 190-59145750 | J15: SCADA | K15: LARA SOARES FARIAS | L15: EMERGENCIAL | M15: SS PENDENTE | N15: 30/01/2026 16:33:07 | O15: 190.02765 | P15: 0 | Q15: RELIGADOR DE REDE GIS | R15: INDISPONIBILIDADE PARA OPERAÇÃO | AA15: NÃO | AC15: ETO-COEP | AI15: Não | AJ15: 8726425 | AK15: DIANOPOLIS | AL15: 986342 | AO15: EQUIPAMENTO ESPECIAL | AP15: PENDÊNCIA DCMD | AQ15: TANQUE | AR15: MANUTENÇÃO | AS15: TANQUE
A16: ETO-COEP 00025/2026 | B16: 2026 | C16: COEP: equipamentos fornecidos. Repasse ao COCM para correção. PARACER DA PROTEÇÃO: Recebemos a solicitação de elaboração de ajustes do RT 5854681071, nota repassada pelo COEP. Duvidas: As pendencias apontadas pelo DMSL foram sanadas? Pois não registro descritivo na SS. Se foram sanadas, a SS não seguiu o fluxo norma, pois não há repassa da nota para o COEP. Podemos seguir com os estudos e comissionamento do ativo? PARECER DMSL: Equipe esteve no RT 5854681071 dia 18/02/2025 porém, as fases A e B estão com a ligação carga/fase invertidas, não contém antena, não contém suporte de antena e não contém rádio GE. Favor, sanar pendências para possibilitar o comissonamento. REGULADOR DE TENSAO N° 5854681071 INSTALADO NA OBRA 0302100570 GENTILEZA, REALIZAR O COMISSIONAMENTO. LAUDO EM ANEXO. COORD EO: 766351, 8781674 PARECER DA PROTEÇÃO ESTUDO DO EQUIPAMENTO DISPONIVEL NO APP DA PROTEÇÃO, NOTA REPASSADA PARA O DMSL COMISSIONAR O EQUIPAMENTO. TEC° EUZILAN MATEUS BARREIRA SANTOS | D16: 21/11/2024 14:32:44 | E16: 9000001071 | F16: AL01018071 | G16: 2 | H16: 5854681071 | I16: 190-26073406 | J16: COPC | K16: Thais Jordanna Jesus Silva | L16: ALTA | M16: SS PENDENTE | N16: 30/03/2026 08:30:03 | O16: 190.02747 | P16: 2,391 | Q16: REGULADOR DE TENSÃO DE DISTRIBUIÇÃO GIS | R16: OBRAS (NOVOS EQUIPAMENTOS) | X16: REGULADOR DE TENSÃO | AA16: NÃO | AC16: ETO-COEP | AH16: ETO-PROT 00437/2024 | AI16: Não | AJ16: 8781673 | AK16: BREJINHO DE NAZARE | AL16: 766351 | AO16: EQUIPAMENTO ESPECIAL | AP16: PENDÊNCIA DMSL | AQ16: REPASSAR DMSL | AR16: REPASSE | AS16: A DEFINIR (REPASSE)
A17: ETO-COEP 00028/2026 | B17: 2026 | C17: FEITO O PRIMEIRO ATAQUE NO RL 7954668084 E O DISPLAY ESTÁ QUEIMADO, NÃO LIGA. OS (99) 106230846 | D17: 03/02/2026 13:31:14 | E17: 6820041084 | F17: LD04062013 | G17: 3 | H17: 7954668084 | I17: 190-37207659 | J17: COI | K17: EVA RAIANE CASTELO BONFIM DA S | L17: EMERGENCIAL | M17: SS PENDENTE | N17: 06/02/2026 17:25:20 | O17: 190.02714 | P17: 142 | Q17: LOCAL INSTAL RELIGADOR DE LINHA GIS | R17: INDISPONIBILIDADE PARA OPERAÇÃO | X17: RELÉ | Z17: QUEIMADO | AA17: NÃO | AC17: ETO-COEP | AH17: ENC-RD-PS 00188/2026 | AI17: Não | AJ17: 8908376 | AK17: DIVINOPOLIS DO TOCANTINS | AL17: 700668 | AO17: EQUIPAMENTO ESPECIAL | AP17: PENDÊNCIA DMSL | AQ17: REPASSAR DMSL | AR17: REPASSE | AS17: A DEFINIR (REPASSE)
A18: ETO-COEP 00029/2026 | B18: 2026 | C18: RELIGADOR BY PASSADO POR DEFEITO, NECESSÁRIO AVALIAÇÃO DO PROBLEMA. parecer dmsl:O religador apresenta defeito no tanque, sendo necessário substituir o tanque o mesmo está tirando a linha, e troca os isoladores. Quando retornar, trazer uma fonte para o equipamento, a mesma foi removida. FICOU EM OPERAÇÃO? Não PENDÊNCIA: Sim, aguardando peças para substituição. | D18: 09/01/2026 09:09:54 | E18: 7927646026 | F18: LD03046026 | G18: 2 | H18: 7927646026 | I18: 190-37070331 | J18: COI | K18: ZENILSON MOREIRA SANTOS | L18: EMERGENCIAL | M18: SS PENDENTE | N18: 07/02/2026 08:52:01 | O18: 190.02703 | P18: 2,201 | Q18: RELIGADOR DE REDE GIS | R18: INDISPONIBILIDADE PARA OPERAÇÃO | AA18: NÃO | AC18: ETO-COEP | AH18: ETO-TELE 00143/2026 | AI18: Não | AJ18: 8841819 | AK18: PONTE ALTA DO TOCANTINS | AL18: 918776 | AO18: EQUIPAMENTO ESPECIAL | AP18: PENDÊNCIA DCMD | AQ18: TANQUE | AR18: MANUTENÇÃO | AS18: TANQUE
A19: ETO-COEP 00031/2026 | B19: 2026 | C19: POR GENTILEZA PROGRAMAR PARA SUBSTITUIÇÃO DO BARRAMENTO DO TRAFO DEVIDO NÃO SER COMPATIVEL COM A POTÊNCIA DO MESMO, NECESSIDADE DE SUBSTITUIÇÃO SE 7 VÃOS | D19: 10/02/2026 08:52:01 | E19: 8804224004 | F19: AL03010004 | G19: 1 | H19: 5701123004 | I19: 190-13659315 | K19: GERCILIO PEDROZA JUNIOR | L19: URGENTE | M19: SS PENDENTE | N19: 17/02/2026 10:15:28 | O19: 190.0234 | P19: 85 | Q19: LOCAL INSTAL TRANSFORMADOR DE DISTRIBUIÇÃO GIS | R19: MELHORIA POSTO DE TRANSFORMAÇÃO | AA19: NÃO | AC19: ETO-COEP | AH19: ETO-RD-AR 00277/2026 | AI19: Não | AJ19: 9203556 | AK19: ARAGUAINA | AL19: 806816 | AO19: PLANO DE MEDIDAS | AP19: PENDÊNCIA DCMD | AQ19: BARRAMENTO | AR19: MANUTENÇÃO | AS19: BARRAMENTO
A20: ETO-COEP 00033/2026 | B20: 2026 | C20: favor verificar RL 7947203070, sem comunicaçao, feito 1° ataque pela equipe 070OP01 e nao retornou a comunicaçao , linformaçao no Scada de bateria. PARECER DMSL: Foi feito análise técnica, a placa do equipamento está queimada nessesario subistituir o equipamento completo -Carliel e Benvindo-05/02 | D20: 23/11/2025 21:48:23 | E20: 8800157070 | F20: LD02065015 | G20: 3 | H20: 7947203070 | I20: 190-68154393 | J20: COI | K20: LAISON OLIVEIRA CARVALHO | L20: EMERGENCIAL | M20: SS PENDENTE | N20: 16/02/2026 08:58:15 | O20: 190.02641 | P20: 1,764 | Q20: LOCAL INSTAL RELIGADOR DE LINHA GIS | R20: INDISPONIBILIDADE PARA OPERAÇÃO | X20: RELIGADOR | Z20: INSPEÇÃO VISUAL | AA20: NÃO | AC20: ETO-COEP | AH20: ETO-TELE 01381/2025 | AI20: Não | AJ20: 8950905 | AK20: RIO SONO | AL20: 851948 | AO20: EQUIPAMENTO ESPECIAL | AP20: PENDÊNCIA DCMD | AQ20: RELIGADOR | AR20: MANUTENÇÃO | AS20: RELIGADOR
A21: ETO-COEP 00035/2026 | B21: 2026 | C21: NOTA PARA EQUIPE DE LINHA VIVA INSTALAR CHAVE FACA PARA MANOBRA ENTRE SANTAFE E DERIVAÇÃO PA COCALANDIA NO ID.: 63243178 EST N4 ACESSO BOM NECESSARIO URGENCIA REFERENCIA AO LADO DA CH 8800521159- | D21: 16/02/2026 05:35:05 | E21: 8800416159 | F21: LD03010004 | G21: 2 | H21: 8800416159 | I21: 190-552234 | J21: COI | K21: ARTHUR MAGALHAES DAS DORES | L21: EMERGENCIAL | M21: SS PENDENTE | N21: 21/02/2026 15:19:06 | O21: 190.00481 | P21: 3,115 | Q21: POSTE RD GIS | R21: NOTA DE SERVIÇO (NS) - LINHA VIVA | X21: CHAVE | Z21: FALTANDO | AA21: NÃO | AC21: ETO-COEP | AD21: Tocantins | AH21: ETO-RD-AR 00317/2026 | AI21: Não | AJ21: 9208353 | AK21: MURICILANDIA | AL21: 762298 | AM21: N4 | AO21: PLANO DE MEDIDAS | AP21: PENDÊNCIA DCMD | AQ21: REPASSAR COCM | AR21: REPASSE | AS21: A DEFINIR (REPASSE)
A22: ETO-COEP 00036/2026 | B22: 2026 | C22: SS ANTIGA: 1500/2025 PARECER DMSL: Serviço Executado: Foi verificado que o tanque do equipamento está danificado, sendo necessário substituir o tanque do equipamento. Equipamento ficou em operação?: Não Pendência: Sim, instalar fonte, disjuntor e DPS, e substituir o tanque. | D22: 16/01/2026 09:24:40 | E22: 7927169001 | F22: AL01102271 | G22: 1 | H22: 7927169001 | I22: 190-17421624 | J22: MANUT | K22: JULIA GRAZYELLE BRITO OLIVEIRA | L22: EMERGENCIAL | M22: SS PENDENTE | N22: 27/02/2026 09:24:40 | O22: 190.0221 | P22: 420 | Q22: RELIGADOR DE REDE GIS | R22: INDISPONIBILIDADE PARA OPERAÇÃO | AA22: NÃO | AC22: ETO-COEP | AI22: Não | AJ22: 8872437 | AK22: PORTO NACIONAL | AL22: 766063 | AO22: EQUIPAMENTO ESPECIAL | AP22: PENDÊNCIA DCMD | AQ22: TANQUE DISJUNTOR DPS | AR22: MANUTENÇÃO | AS22: TANQUE
A23: ETO-COEP 00038/2026 | B23: 2026 | C23: DMSL:Serviço Executado: Houve um curto no equipamento danificando a parte ativa, será necessário fazer a substituição do equipamento completo ( parte ativa e controle) colocar o um cabo pp novo do trafo até o Dj pois o mesmo está sem condições de uso. Obs:. Foi retirado rádio e rele Equipamento ficou em operação?: Não Pendência: Sim, substituir o equipamento completo. | D23: 22/01/2026 11:28:09 | E23: 7908249152 | F23: LD02072001 | G23: 3 | H23: 7908249152 | I23: 190-17512853 | J23: MANUT | K23: JULIA GRAZYELLE BRITO OLIVEIRA | L23: ALTA | M23: SS PENDENTE | N23: 25/04/2026 11:28:09 | O23: 190.02207 | P23: 234 | Q23: RELIGADOR DE REDE GIS | R23: INDISPONIBILIDADE PARA OPERAÇÃO | AA23: NÃO | AC23: ETO-COEP | AI23: Não | AJ23: 8737798 | AK23: SANTA ROSA DO TOCANTINS | AL23: 805385 | AO23: EQUIPAMENTO ESPECIAL | AP23: PENDÊNCIA DCMD | AQ23: RELIGADOR | AR23: MANUTENÇÃO | AS23: RELIGADOR
A24: ETO-COEP 00039/2026 | B24: 2026 | C24: DMSL:Serviço Executado: Foi feita análise técnica a qual foi identificado que o tanque do equipamento entrou em curto o mesmo necessário substituir o tanque | D24: 24/02/2026 11:37:29 | E24: 7926089013 | F24: LD03062013 | G24: 3 | H24: 7926089013 | I24: 190-17512949 | J24: MANUT | K24: JULIA GRAZYELLE BRITO OLIVEIRA | L24: ALTA | M24: SS PENDENTE | N24: 25/04/2026 11:37:29 | O24: 190.02203 | P24: 1,042 | Q24: RELIGADOR DE REDE GIS | R24: INDISPONIBILIDADE PARA OPERAÇÃO | AA24: NÃO | AC24: ETO-COEP | AI24: Não | AJ24: 8867765 | AK24: PARAISO DO TOCANTINS | AL24: 718799 | AO24: EQUIPAMENTO ESPECIAL | AP24: PENDÊNCIA DCMD | AQ24: TANQUE | AR24: MANUTENÇÃO | AS24: TANQUE | AU24: REPETIDA
A25: ETO-COEP 00040/2026 | B25: 2026 | C25: DMSL:Serviço Executado: Foi feita uma análise técnica no equipamento, devido à falta de comunicação. Também foi identificado que o tanque do equipamento está danificado, sendo assim, necessário substituir o tanque e o rádio do equipamento, que está queimado, sendo necessário substituir também. | D25: 28/01/2026 11:41:25 | E25: 7931608059 | F25: AL08099059 | G25: 2 | H25: 7931608059 | I25: 190-17421389 | J25: MANUT | K25: JULIA GRAZYELLE BRITO OLIVEIRA | L25: EMERGENCIAL | M25: SS PENDENTE | N25: 27/02/2026 11:41:25 | O25: 190.02208 | P25: 0 | Q25: RELIGADOR DE REDE GIS | R25: INDISPONIBILIDADE PARA OPERAÇÃO | AA25: NÃO | AC25: ETO-COEP | AI25: Não | AJ25: 8854562 | AK25: PALMAS | AL25: 796501 | AO25: EQUIPAMENTO ESPECIAL | AP25: PENDÊNCIA DCMD | AQ25: TANQUE E RÁDIO | AR25: MANUTENÇÃO | AS25: TANQUE
A26: ETO-COEP 00042/2026 | B26: 2026 | C26: PARECER DMSL: FAVOR REALIZAR A SUBSTITUIÇÃO DO EQUIOAMENTO COMPLETO, FALHA DE ABERTURA PARA PROTEÇÃO | D26: 26/02/2026 10:28:59 | E26: 7900505026 | F26: LD03046026 | G26: 2 | H26: 7900505026 | I26: 190-17512769 | J26: MANUT | K26: JULIA GRAZYELLE BRITO OLIVEIRA | L26: ALTA | M26: SS PENDENTE | N26: 27/04/2026 10:28:59 | O26: 190.02223 | P26: 334 | Q26: RELIGADOR DE REDE GIS | R26: EM OPERAÇÃO COM ANOMALIA | AA26: NÃO | AC26: ETO-COEP | AI26: Não | AJ26: 8796235 | AK26: PONTE ALTA DO TOCANTINS | AL26: 882036 | AO26: EQUIPAMENTO ESPECIAL | AP26: PENDÊNCIA DCMD | AQ26: RELIGADOR | AR26: MANUTENÇÃO | AS26: RELIGADOR
A27: ETO-COEP 00043/2026 | B27: 2026 | C27: Por gentileza instalar Chave Faca com referência ao ID# E.O: 44271354; | D27: 27/02/2026 14:53:22 | E27: 8801170015 | F27: LD02065015 | G27: 1 | H27: 8801170015 | I27: 190-44271354 | J27: COPO | K27: Camila Mell Prado | L27: ALTA | M27: SS PENDENTE | N27: 01/05/2026 15:18:45 | O27: 190.02658 | P27: 257 | Q27: POSTE RD GIS | R27: SOLICITAÇÃO DE SERVIÇO | X27: CHAVE | Z27: INEXISTENTE | AA27: NÃO | AC27: ETO-COEP | AH27: ETO-RD-GR 00294/2026 | AI27: Não | AJ27: 9004568 | AK27: PEDRO AFONSO | AL27: 811516 | AM27: N1 | AN27: SI1 | AO27: PLANO DE MEDIDAS | AP27: PENDÊNCIA DCMD | AQ27: REPASSAR COCM | AR27: REPASSE | AS27: A DEFINIR (REPASSE)
A28: ETO-COEP 00044/2026 | B28: 2026 | C28: Tanque do RLG 7936038076 queimado, favor substituir o mesmo. NS do tanque: 0320118112616 | D28: 02/03/2026 15:56:19 | E28: 7936038076 | F28: LD02040003 | G28: 3 | H28: 7936038076 | I28: 190-17512614 | J28: MANUT | K28: EDNA MARIA DOS SANTOS PINTO | L28: EMERGENCIAL | M28: SS PENDENTE | N28: 05/03/2026 15:56:19 | O28: 190.02209 | P28: 17 | Q28: RELIGADOR DE REDE GIS | R28: INDISPONIBILIDADE PARA OPERAÇÃO | AA28: NÃO | AC28: ETO-COEP | AI28: Não | AJ28: 8742101 | AK28: DUERE | AL28: 666106 | AO28: EQUIPAMENTO ESPECIAL | AP28: PENDÊNCIA DCMD | AQ28: RELIGADOR | AR28: MANUTENÇÃO | AS28: RELIGADOR
A29: ETO-COEP 00045/2026 | B29: 2026 | C29: religador foi bay passado devido mesmo esta saindo fumaca do painel e sem comunicação 7927396052. PARECER DMSL: Após testes, equipe DMSL constatou que apenas o tanque do RLG 7927396052 encontra-se queimado. Favor, substituir parte ativa do equipamento. NS Tanque: 0320123040198 | D29: 17/02/2026 19:02:33 | E29: 9001632052 | F29: LD03036052 | G29: 3 | H29: 7927396052 | I29: 190-21148967 | J29: COI | K29: ZELITO ALVES DELGADO | L29: EMERGENCIAL | M29: SS PENDENTE | N29: 05/03/2026 21:25:22 | O29: 190.02667 | P29: 0 | Q29: LOCAL INSTAL RELIGADOR DE LINHA GIS | R29: INDISPONIBILIDADE PARA OPERAÇÃO | X29: RELIGADOR | Z29: INSPEÇÃO VISUAL | AA29: NÃO | AC29: ETO-COEP | AH29: ETO-TELE 00295/2026 | AI29: Não | AJ29: 8723116 | AK29: FORMOSO DO ARAGUAIA | AL29: 645739 | AO29: EQUIPAMENTO ESPECIAL | AP29: PENDÊNCIA DCMD | AQ29: REPASSAR DMSL | AR29: REPASSE | AS29: A DEFINIR (REPASSE)
A30: ETO-COEP 00046/2026 | B30: 2026 | C30: Acionar equipe de manutencao para subsituir 2 vao de rede do trafo 5739148227 na RDU de Recurssolandia equipe 0227op01 obs. troca cabo por multiplex e inspecioar os flytap que estao com ponto quente nos conector na Rua 02 de outubro | D30: 03/03/2026 20:21:49 | E30: 0300002227 | F30: LD01065015 | G30: 3 | H30: 5739148227 | I30: 190-13671793 | J30: COI | K30: CLEIBER DA SILVA | L30: EMERGENCIAL | M30: SS PENDENTE | N30: 08/03/2026 07:47:09 | O30: 190.02338 | P30: 24 | Q30: LOCAL INSTAL TRANSFORMADOR DE DISTRIBUIÇÃO GIS | R30: AVISO DE ANOMALIA | X30: AVARIADO | Z30: NÃO IDENTIFICADO | AA30: NÃO | AC30: ETO-COEP | AH30: ETO-RD-GR 00311/2026 | AI30: Não | AJ30: 9032221 | AK30: RECURSOLANDIA | AL30: 913609 | AO30: PLANO DE MEDIDAS | AP30: PENDÊNCIA DCMD | AQ30: REPASSAR COCM | AR30: REPASSE | AS30: A DEFINIR (REPASSE)
A31: ETO-COEP 00047/2025 | B31: 2025 | C31: PLANO DE MEDIDA - Transformador 5700078015 com 153 de carregamento para analise de divisão de circuito. Após análise, foi identificado que o transformador 5753469015 possivelmente está a vazio e nas informações fornecidas pela OS de inspeção não foram suficientes para definição. | D31: 21/03/2025 14:31:03 | E31: 0300077015 | F31: AL01065015 | G31: 3 | H31: 5700078015 | I31: 190-13697857 | J31: COEP | K31: Andresa da Silva Lima | L31: URGENTE | M31: SS PENDENTE | N31: 04/04/2025 14:28:22 | O31: 190.02338 | P31: 165 | Q31: LOCAL INSTAL TRANSFORMADOR DE DISTRIBUIÇÃO GIS | R31: PM TRANSFORMADOR | X31: SOBRECARGA PREVENTIVA | Z31: SOBRECARGA | AA31: SIM | AC31: ETO-COEP | AH31: ETO-COPC 00024/2025 | AI31: Não | AJ31: 9006069 | AK31: PEDRO AFONSO | AL31: 811652 | AO31: PLANO DE MEDIDAS | AP31: PENDÊNCIA DCMD | AQ31: FALAR COM A ANDRESSA | AR31: ANÁLISE | AS31: A DEFINIR (análise)
A32: ETO-COEP 00047/2026 | B32: 2026 | C32: favor verificar banco de capacitor 5950106122, com defeito interno, o mesmo nao foi indentificado aparentemente, porem foi a causa da ocorrencia 20253842360922 | D32: 20/09/2025 21:03:12 | E32: 0350106122 | F32: AL05097122 | G32: 3 | H32: 5950106122 | I32: 190-51584304 | J32: COI | K32: LAISON OLIVEIRA CARVALHO | L32: EMERGENCIAL | M32: SS PENDENTE | N32: 14/03/2026 08:15:19 | O32: 190.02661 | P32: 0 | Q32: BANCO CAPACITOR DE DISTRIBUIÇÃO GIS | R32: AVISO DE ANOMALIA | X32: CORPO (CÉLULA) | Z32: CURTO CIRCUITO | AA32: NÃO | AC32: ETO-COEP | AH32: DOLP-RD-PA 01250/2025 | AI32: Não | AJ32: 8868642 | AK32: PALMAS | AL32: 792093 | AO32: EQUIPAMENTO ESPECIAL | AP32: PENDÊNCIA DCMD | AQ32: REPASSAR DMSL | AR32: REPASSE | AS32: A DEFINIR (REPASSE)
A33: ETO-COEP 00048/2026 | B33: 2026 | C33: PARECER DMSL: A PEDIDO DA PCM DO NORTE LARA SOARES REALIZEI A CRIAÇÃO DESSA SS, EM RAZAO DA ANTIGAETO-TELE 337/2026 QUE FOI BAIXADA POR ENGANO DE TAL FORMA SEGUE A MESMA PARA REALIZAR AS TRATATIVAS. PENDENCIA: Religador continua by passado , equipamento está com defeito na parte ativa | D33: 16/03/2026 13:55:26 | E33: 7925871077 | F33: LD03105019 | G33: 2 | H33: 7925871077 | I33: 190-17512510 | J33: MANUT | K33: JULIA GRAZYELLE BRITO OLIVEIRA | L33: PROGRAMAVEL | M33: SS PENDENTE | N33: 20/04/2027 13:55:26 | O33: 190.02205 | P33: 2,846 | Q33: RELIGADOR DE REDE GIS | R33: INDISPONIBILIDADE PARA OPERAÇÃO | AA33: NÃO | AC33: ETO-COEP | AI33: Não | AJ33: 9145475 | AK33: GOIATINS | AL33: 905716 | AO33: EQUIPAMENTO ESPECIAL | AP33: PENDÊNCIA DCMD | AQ33: PARTE ATIVA | AR33: MANUTENÇÃO | AS33: PARTE ATIVA
A34: ETO-COEP 00049/2026 | B34: 2026 | C34: PARECER DMSL: *DATA*16/03/2026 Serviço Executado: É NECESSARIO REALIZAR A SUBSTITUIÇAO COMPLETA DO CONTROLE, EQUIPAMENTO DANIFICADO - FABRICANTE NOJA Equipamento ficou em operação?: Não Pendência: Sim, FAVOR REALIZAR AS CORREÇOES Bateria(s) Substituída(s): Não Data Fabricação/Instalação da(s) bateria(s): 07/2025 Equipe: Benvindo e Kaique PARECER DMSL : Solicitação já cumprida. Chamado 3047281 aberto em caráter emergencial, com comissionamento programado a partir de 02/02/2026. PARECER DA PROTEÇÃO: NOTA REPASSADA PARA DMSL, ABRIR CHAMADOS DE SCADA E COMISSIONAMENTO DO EQUIPAMENTO. ENG° IRLLEY CASTELO BRANCO. RELIGADOR N° 7963661046 INSTALADO NA OBRA 0202500503 GENTILEZA, REALIZAR O COMISSIONAMENTO. LAUDO EM ANEXO. COORD EO: 728315, 8830256 | D34: 30/01/2026 07:59:51 | E34: 8863660046 | F34: LD01056046 | G34: 2 | H34: 7963661046 | I34: 190-53434837 | J34: COPC | K34: Leonardo Sousa de Lima | L34: ALTA | M34: SS PENDENTE | N34: 17/05/2026 16:05:26 | O34: 190.02824 | P34: 1 | Q34: LOCAL INSTAL RELIGADOR DE LINHA GIS | R34: COMISSIONAMENTO | X34: RELIGADOR | AA34: NÃO | AC34: ETO-COEP | AH34: ETO-PROT 00033/2026 | AI34: Não | AJ34: 8830255 | AK34: NOVA ROSALANDIA | AL34: 728313 | AO34: EQUIPAMENTO ESPECIAL | AP34: PENDÊNCIA DMSL | AQ34: REPASSAR DMSL | AR34: REPASSE | AS34: A DEFINIR (REPASSE)
A35: ETO-COEP 00050/2026 | B35: 2026 | C35: PARECER DMSL: Data: 10/03/2026,Serviço Executado: Foi substituído o relé do equipamento, o mesmo estava danificado. Trocado o DPS, o mesmo estava queimado devido ao tanque estar furado. O equipamento ficou em bypass. Equipamento ficou em operação? Não Pendência? Sim, substituir a parte ativa com cordão umbilical.Equipe: Carliel e João Vitor SEGUE SS PARA REGULARIZAR AUTOMAÇÃO DO RL 7953610256 NA INTERLIGAÇÃO COM A COELBA (CHAPADA DA MANGABEIRA) - EQUIPE INFOMOU CURTO INTERNO NO GABINETE DJ AC NÃO FECHA | D35: 16/02/2026 05:43:10 | E35: 8800246256 | F35: LD03046026 | G35: 3 | H35: 7953610256 | I35: 190-43820334 | J35: COI | K35: DIONES COSTA SILVA | L35: EMERGENCIAL | M35: SS PENDENTE | N35: 21/03/2026 16:08:39 | O35: 190.02706 | P35: 5 | Q35: LOCAL INSTAL RELIGADOR DE LINHA GIS | R35: INDISPONIBILIDADE PARA OPERAÇÃO | X35: RELIGADOR | Z35: INSPEÇÃO VISUAL | AA35: NÃO | AC35: ETO-COEP | AH35: ETO-TELE 00292/2026 | AI35: Não | AJ35: 8855553 | AK35: MATEIROS | AL35: 1068871 | AO35: EQUIPAMENTO ESPECIAL | AP35: PENDÊNCIA DMSL | AQ35: REPASSAR DMSL | AR35: REPASSE | AS35: A DEFINIR (REPASSE)
A36: ETO-COEP 00051/2026 | B36: 2026 | C36: PARECER DMSL: Data: 12/03/2026 Serviço Executado: - Análise técnica constatou: - Parte ativa do equipamento danificada: necessita substituição - Trafo danificado: foi feitos testes nas buchas secundárias o mesmo não chega tensão - Vazamento de óleo - Necessita substituição Equipamento ficou em operação? Não Pendências: - Solicitar limpeza de faixa para acesso ao equipamento - Trocar parte ativa do equipamento - Substituir o trafo Equipe: Carliel e João Vitor Segue nota para envia equipe verificar falha de comunicação e automação no RL-7926442035 feito primeiro ataque com equipe 035OP02, porém sem sucesso. | D36: 18/02/2026 16:24:37 | E36: 7926442035 | F36: LD01051035 | G36: 3 | H36: 7926442035 | I36: 190-17513078 | J36: COI | K36: SAMUEL PINTO GOMES | L36: EMERGENCIAL | M36: SS PENDENTE | N36: 21/03/2026 16:15:05 | O36: 190.02206 | P36: 230 | Q36: RELIGADOR DE REDE GIS | R36: INDISPONIBILIDADE PARA OPERAÇÃO | X36: RELIGADOR | Z36: OUTROS | AA36: NÃO | AC36: ETO-COEP | AH36: ETO-TELE 00298/2026 | AI36: Não | AJ36: 8782076 | AK36: MONTE DO CARMO | AL36: 819553 | AO36: EQUIPAMENTO ESPECIAL | AP36: PENDÊNCIA DMSL | AQ36: REPASSAR DMSL | AR36: REPASSE | AS36: A DEFINIR (REPASSE)
A37: ETO-COEP 00054/2026 | B37: 2026 | C37: PARECER DMSL: PENDÊNCIA: Realizar melhoria no aterramento por ser tratar de um terreno muito arenoso, e há pendências por parte do time da proteção, os ajustes do RT não estão disponíveis para inserção no referido equipamento. DATA DA MANUTENÇÃO: 12/03/202 EQUIPE: Brunno e Edeglan. *********************** PARECER DA PROTEÇÃO: FAVOR COMISSIONAR REGULADOR 5865120195 – LD Santa Maria Ramal Centenário e Recursolândia – 34,5kV. AJUSTE REALIZADO, DISPONÍVEL NO APP DA PROTEÇÃO. *********************** INSTALADO NA OBRA 0702400720 GENTILEZA, REALIZAR O COMISSIONAMENTO. LAUDO EM ANEXO. COORD EO: 889017, 9016857 | D37: 11/02/2026 15:21:44 | E37: 8800183195 | F37: LD01065015 | G37: 3 | H37: 5865120195 | I37: 190-38281711 | J37: COPC | K37: Leonardo Sousa de Lima | L37: ALTA | M37: SS PENDENTE | N37: 23/05/2026 15:04:52 | O37: 190.02813 | P37: 2,628 | Q37: REGULADOR DE TENSÃO DE DISTRIBUIÇÃO GIS | R37: COMISSIONAMENTO | X37: REGULADOR DE TENSÃO | AA37: NÃO | AC37: ETO-COEP | AH37: ETO-PROT 00041/2026 | AI37: Não | AJ37: 9016857 | AK37: CENTENARIO | AL37: 889017 | AO37: EQUIPAMENTO ESPECIAL | AP37: PENDÊNCIA DMSL | AQ37: REPASSAR DMSL | AR37: REPASSE | AS37: A DEFINIR (REPASSE) | BA37: Melhoria da malha de aterramento Repassado para ETO-RD-GR- Novo número é 00538/2026
A38: ETO-COEP 00055/2025 | B38: 2025 | C38: substituir 7 vão de rede deteriorados de QP-35 mm multiplex no circuito do trafo 5703610004 - bairro Jardim dos Ipês II- rua 55 qd. 63 lt 34 - RDU Araguaina | D38: 07/11/2024 13:22:39 | E38: 5703610004 | F38: AL06010004 | G38: 3 | H38: 5703610004 | I38: 190-1657490 | J38: COI | K38: VALERIA DE JESUS BORGES CARVAL | L38: URGENTE | M38: SS PENDENTE | N38: 10/04/2025 17:27:50 | O38: 190.00955 | P38: 66 | Q38: POSTE RD GIS | R38: AVISO DE ANOMALIA | X38: CABOS BT | Z38: DETERIORADA | AA38: NÃO | AC38: ETO-COEP | AD38: Tocantins | AH38: ETO-RD-AR 01903/2024 | AI38: Não | AJ38: 9205890 | AK38: ARAGUAINA | AL38: 804712 | AN38: SI-3 | AO38: CABOS FORA COEP | AP38: PENDÊNCIA DCMD | AQ38: CABOS | AR38: MANUTENÇÃO | AS38: CABOS | AU38: REPETIDA | AV38: 0 | AW38: 0
A39: ETO-COEP 00055/2026 | B39: 2026 | C39: DCMD 26.03.2026. SS REPASSADA PARA COEP PROVIDENCIAR MATERIAL. NÃO TEMOS O MATERIAL EM ESTOQUE PARA SUBSTITUIÇÃO. COEP: Equipamento fornecido ao COCM-S para regularização. PARECER DA PROTEÇÃO: EQUIPAMENTOS FURTADOS. PARA AQUISIÇÃO DAS CELULAS DE REPOSIÇÃO, FAVOR CONSULTAR OS DADOS DE PLACA EM ANEXO. PARECER DA PROTEÇÃO: COMISISONAR RT 5856156091 LD DIANOPOLIS A NATIVIDADE. NECESSARIO REALIZAR MEDIÇÕES DA RESISTENCIA DA MALHA DE ATERRAMENTO. AJUSTES DISPONIVEIS NO APP DA PROTEÇÃO. RELIGADOR N° 5856156091 INSTALADO NA OBRA 0502400526 GENTILEZA, REALIZAR O COMISSIONAMENTO. LAUDO EM ANEXO. COORD EO: 899501, 8714782 | D39: 16/06/2025 15:50:51 | E39: 8832258091 | F39: LD04002091 | G39: 1 | H39: 5856156091 | I39: 190-38238593 | J39: COPC | K39: Leonardo Sousa de Lima | L39: PROGRAMAVEL | M39: SS PENDENTE | N39: 30/04/2027 11:42:48 | O39: 190.02786 | P39: 1,586 | Q39: REGULADOR DE TENSÃO DE DISTRIBUIÇÃO GIS | R39: INDISPONIBILIDADE PARA OPERAÇÃO | X39: REGULADOR DE TENSÃO | AA39: NÃO | AC39: ETO-COEP | AH39: ETO-PROT 00198/2025 | AI39: Não | AJ39: 8714782 | AK39: ALMAS | AL39: 899501 | AO39: EQUIPAMENTO ESPECIAL | AP39: PENDÊNCIA DMSL | AQ39: REPASSAR DMSL | AR39: REPASSE | AS39: A DEFINIR (REPASSE)
A40: ETO-COEP 00056/2025 | B40: 2025 | C40: PARECER DMSL: Religador está com o tanque danificado. Não responde a comandos abertura e fechamento local ou remoto, pois está com sinal de curto circuito. Necessário trocar o equipamento. Para raio do trafo está queimado. Chave de saída da fase C está com o olhal quebrado, necessário substituir a chave. Equipamento ficou bypassado em campo. Aberto entrada e saída, com exceção da fase C de saída que ficou fechada. Favor, substituir equipamento completo por NOJA RC10 e sanar demais pendencias. Senhores Favor verificar RL 7900230155 o mesmo sinalizou aberto no SCADA porem a cidade de Palmeirante estava normal , feito um reset no rl e o mesmo subiu fechado. | D40: 29/03/2025 18:25:59 | E40: 9000231155 | F40: LD02105019 | G40: 2 | H40: 7900230155 | I40: 190-17408809 | J40: COI | K40: CLEONE PEREIRA DE SOUZA LIMA | L40: EMERGENCIAL | M40: SS PENDENTE | N40: 07/04/2025 14:14:07 | O40: 190.00019 | P40: 992 | Q40: LOCAL INSTAL RELIGADOR DE LINHA GIS | R40: INDISPONIBILIDADE PARA OPERAÇÃO | X40: RELIGADOR | Z40: INSPEÇÃO VISUAL | AA40: SIM | AC40: ETO-COEP | AD40: Tocantins | AH40: ETO-TELE 00307/2025 | AI40: Não | AJ40: 9129950 | AK40: PALMEIRANTE | AL40: 834706 | AO40: EQUIPAMENTO ESPECIAL | AP40: PENDÊNCIA DCMD | AQ40: REPASSAR DMSL | AR40: REPASSE | AS40: A DEFINIR (REPASSE)
...

Sheet Dashboard
B2: RELATÓRIO DE SOLICITAÇÕES DE SERVIÇO PENDENTES
B4: DCMD • Energisa Tocantins
B6: TOTAL SS | D6: PEND. DCMD | F6: PEND. DMSL | H6: REPETIDAS | J6: CONCLUÍDAS
B7: 183 | D7: 148 | F7: 34 | H7: 20 | J7: 1
B11: POR EQUIPAMENTO / CATEGORIA | G11: POR STATUS
B12: Categoria | C12: Qtd | D12: % | G12: Status | H12: Qtd | I12: %
B13: EQUIPAMENTO ESPECIAL | C13: 136 | D13: 0.7431694 | G13: PENDÊNCIA DCMD | H13: 148 | I13: 0.80874317
B14: CABOS FORA COEP | C14: 30 | D14: 0.16393443 | G14: PENDÊNCIA DMSL | H14: 34 | I14: 0.18579235
B15: PLANO DE MEDIDAS | C15: 12 | D15: 0.06557377 | G15: CONCLUÍDO | H15: 1 | I15: 0.0054644809
B16: MELHORIA DE REDE | C16: 3 | D16: 0.016393443
B17: LIMPEZA DE FAIXA | C17: 2 | D17: 0.010928962
B20: POR GRUPO DE ANÁLISE | G20: GRUPO × STATUS
B21: Grupo | C21: Qtd | D21: % | G21: Grupo | H21: CONCLUÍDO | I21: PENDÊNCIA DCMD | J21: PENDÊNCIA DMSL | K21: Total
B22: MANUTENÇÃO | C22: 107 | D22: 0.58469945 | G22: ANÁLISE | H22: 0 | I22: 19 | J22: 1 | K22: 20
B23: REPASSE | C23: 54 | D23: 0.29508197 | G23: COMPRA | H23: 0 | I23: 2 | J23: 0 | K23: 2
B24: ANÁLISE | C24: 20 | D24: 0.10928962 | G24: MANUTENÇÃO | H24: 1 | I24: 104 | J24: 2 | K24: 107
B25: COMPRA | C25: 2 | D25: 0.010928962 | G25: REPASSE | H25: 0 | I25: 23 | J25: 31 | K25: 54
G26: Total | H26: 1 | I26: 148 | J26: 34 | K26: 183

Sheet Análise Detalhada
B2: ANÁLISE DETALHADA — LACUNAS DE INFORMAÇÃO E SUBGRUPOS
B3: Detalhamento do que falta em cada categoria e subgrupos por tipo de equipamento
B5: 1. STATUS DO CADASTRO — O QUE FALTA | L5: 2. RELIGADOR — DETALHAMENTO POR SUBGRUPO
B6: Categoria | C6: Qtd | L6: Categoria | M6: Qtd
B7: Equipamento identificado | C7: 80 | F7: Equipamento identificado | I7: 80 (44.2%) | L7: Religador (genérico) | M7: 19 | P7: Religador (genérico) | S7: 19 (70.4%)
B8: CABOS sem bitola/vão/tensão | C8: 30 | F8: CABOS sem bitola/vão/tensão | I8: 30 (16.6%) | L8: Bucha | M8: 1 | P8: Bucha | S8: 1 (3.7%)
B9: A definir (repasse) | C9: 54 | F9: A definir (repasse) | I9: 54 (29.8%) | L9: Compra | M9: 1 | P9: Compra | S9: 1 (3.7%)
B10: A definir (análise) | C10: 7 | F10: A definir (análise) | I10: 7 (3.9%) | L10: Controle/Caixa | M10: 1 | P10: Controle/Caixa | S10: 1 (3.7%)
B11: Possíveis repetidas | C11: 10 | F11: Possíveis repetidas | I11: 10 (5.5%) | L11: Tanque + Módulo | M11: 1 | P11: Tanque + Módulo | S11: 1 (3.7%)
L12: Sistema Comunicação | M12: 1 | P12: Sistema Comunicação | S12: 1 (3.7%)
F13: TOTAL | I13: 181 | L13: Tanque + Cabo umbilical | M13: 1 | P13: Tanque + Cabo umbilical | S13: 1 (3.7%)
L14: Obra gerada | M14: 1 | P14: Obra gerada | S14: 1 (3.7%)
L15: Parte Ativa | M15: 1 | P15: Parte Ativa | S15: 1 (3.7%)
P17: TOTAL | S17: 27
B22: 3. CABOS — LACUNAS DE INFORMAÇÃO TÉCNICA | L22: 4. REPASSES — DESTINOS
B23: Categoria | C23: Qtd | L23: Categoria | M23: Qtd
B24: Únicas - sem detalhe técnico | C24: 18 | F24: Únicas - sem detalhe técnico | I24: 18 (60.0%) | L24: Repassar DMSL | M24: 39 | P24: Repassar DMSL | S24: 39 (72.2%)
B25: Possíveis repetidas | C25: 12 | F25: Possíveis repetidas | I25: 12 (40.0%) | L25: Repassar COCM | M25: 12 | P25: Repassar COCM | S25: 12 (22.2%)
L26: OG existente | M26: 2 | P26: OG existente | S26: 2 (3.7%)
F27: TOTAL | I27: 30 | L27: Outros | M27: 1 | P27: Outros | S27: 1 (1.9%)
P29: TOTAL | S29: 54
B39: INSIGHTS PRINCIPAIS
B40: • 30 SS de CABOS (16%) estão sem nenhuma informação técnica (bitola, vãos, tensão) — bloqueio para orçamento preciso
B41: • 54 SS estão em REPASSE (30%) — depende de outras coordenações para evoluir
B42: • 10 SS marcadas como possivelmente repetidas — requerem revisão antes de tratar
B43: • 19 das 27 SS de RELIGADOR estão sem detalhamento do componente a substituir
B44: • Equipamento identificado com clareza: 80 de 183 SS (44%)

Sheet Pendências DMSL
C2: PENDÊNCIAS DO DMSL
C3: Tipo de equipamento extraído da Descrição (Parecer DMSL) | Nº Equipamento e Nº Obra identificados
C5: TOTAIS POR TIPO DE EQUIPAMENTO (extraído da Descrição)
C6: TOTAL DMSL | F6: RELIGADOR | I6: REGULADOR TENSÃO | K6: TANQUE | L6: TRANSFORMADOR | M6: OUTROS
C7: 33 | F7: 17 | I7: 8 | K7: 1 | L7: 1 | M7: 6
C11: DISTRIBUIÇÃO POR TIPO DE EQUIPAMENTO | P11: TOP LOCALIDADES
C12: Tipo | E12: Qtd | P12: Localidade | U12: Qtd
C13: RELIGADOR | D13: PARECER DA PROTEÇÃO: COMISSIONAR DO RT 5855606027 LD SERRA GERAIS E TAGUATINGA. NECESSARIO CONFERRIR MEDIÇÕES DA MALHA DE ATERRAMENTO ANTES DE INSERIR O ATIVO EM OPERAÇÃO. AJUSTES DISPONIVIEIS NO APP DA PROTEÇÃO. REGULADOR DE TENSAO N° 5855606027 REMANEJADO NA OBRA 0502500015 GENTILEZA, REALIZAR O COMISSIONAMENTO. LAUDO EM ANEXO. COORD EO: 990668, 8661389 TOP ANTIGA: 5838182027 PARECER DMSL: Realizado o comissionamento do RT nas fases A e C e na fase B foi constatado um curto elétrico na parte da caixa de comando. Foi feita toda parte de comunicação e configuração do rádio, inserindo ajustes de proteção. Número de série da placa fase B 017153. | E13: 17 | J13: RELIGADOR | M13: 17 (50.0%) | P13: ARAGUAINA | U13: 3
C14: REGULADOR TENSÃO | E14: 8 | J14: REGULADOR TENSÃO | M14: 8 (23.5%) | P14: PALMEIRAS DO TOCANTINS | U14: 2
C15: REPASSAR DMSL | E15: 4 | J15: REPASSAR DMSL | M15: 4 (11.8%) | P15: MIRACEMA DO TOCANTINS | U15: 2
C16: TANQUE | E16: 1 | J16: TANQUE | M16: 1 (2.9%) | P16: DIVINOPOLIS DO TOCANTINS | U16: 2
C17: TRANSFORMADOR | E17: 1 | J17: TRANSFORMADOR | M17: 1 (2.9%) | P17: PARAISO DO TOCANTINS | U17: 2
C18: ATERRAMENTO | E18: 1 | J18: ATERRAMENTO | M18: 1 (2.9%) | P18: FIGUEIROPOLIS | U18: 2
C19: CONTROLE | E19: 1 | J19: CONTROLE | M19: 1 (2.9%) | P19: ARAPOEMA | U19: 1
C20: BANCO CAPACITOR | E20: 1 | J20: BANCO CAPACITOR | M20: 1 (2.9%) | P20: SANTA ROSA DO TOCANTINS | U20: 1
F23: ⚡ RELIGADOR (17 SS)
C24: Código SS | D24: Descrição | E24: Ano | F24: Localidade | G24: Nº Equipamento | I24: Nº Obra | J24: Abrangência | K24: Instalação | L24: Análise Técnica | M24: Data Ocorrência | N24: Repetida? | O24: Observações
