Workbook

Sheet Gerencial
A1: DESTINO_SS | B1: (Vários itens) | F1: Criticidade | G1: Quantidade | I1: Total
G2: RL | H2: RT
A3: Qtd | B3: Cód | F3: Muito Alta | G3: 9 | H3: 2 | I3: =SUM(G3:H3) -> 11
A4: Criticidade | B4: 58 | C4: 79 | D4: Total Geral | F4: Alta | G4: 9 | H4: 3 | I4: =SUM(G4:H4) -> 12
A5: Muito Alta | B5: 3 | C5: 11 | D5: 14 | F5: Média | G5: 9 | H5: 4 | I5: =SUM(G5:H5) -> 13
A6: Alta | B6: 3 | C6: 6 | D6: 9 | F6: Baixa | G6: 9 | H6: 5 | I6: =SUM(G6:H6) -> 14
A7: Média | B7: 5 | C7: 9 | D7: 14 | F7: Em definição | G7: 28 | H7: 9 | I7: =SUM(G7:H7) -> 37
A8: Baixa | B8: 4 | C8: 11 | D8: 15 | F8: Total Geral | G8: 64 | H8: 23 | I8: =SUM(I3:I7) -> 87
A9: Em definição | C9: 3 | D9: 3
A10: Total Geral | B10: 15 | C10: 40 | D10: 55

Sheet Pendentes
A1: ANO_SS | B1: SS_ORIGINAL | C1: DESTINO_SS | D1: COD_RELIGADOR | E1: TIPO | F1: DTA_ABERTURA | G1: COD_LOC | H1: LOCALIDADE | I1: POLO | J1: REGIONAL | K1: ALIMENTADOR | L1: DESCRICAO | M1: Premissa 1 | N1: Premissa 2 | O1: Premissa 3 | P1: Premissa 4 | Q1: Premissa 5 | R1: Premissa 6 | S1: Premissa 7 | T1: Premissa 8 | U1: Priorização | V1: Criticidade | W1: Observação após análise
A2: 2026 | B2: ETO-RD-PO 00213/2026 | C2: ETO-RD-PO | D2: 5854566043 | E2: 58 | F2: 46225 | G2: 43 | H2: SILVANOPOLIS | I2: PORTO NACIONAL | J2: CENTRO | K2: LD02072001 | L2: 22/07/2026 PARECER COEP: EQUIPAMENTO ENTREGUE AOS COCM´SPRAZO DE 7 DIAS CONTANDO O SLA.PARECER COEP: EQUIPAMENTO ENTREGUE AOS COCM´S FAVOR SUSBSTTUIR , E AGUARDO O PRAZO DE PREVISÃO DE SUBSTIUIÇÃOboa noite,segue SS para as devidas tratativas com equipe de manutenção com apoio de equipe de linha viva substituir regulador de tensão 5854566043 queimado célula fase c, LD Porto / Silvanópolis mesmo deverá ser substituído com apoio de equipe de linha viva PARECER DMSL: Foi realizado inspeção visual e ensaios de isolação, relação de transformação e resistência de enrolamento. A fase B está danificada e será necessário substituir a mesma. Malha de aterramento está relativamente boa e conectada. Fase A e C passaram nos ensaios. Substituir fase B. | M2: 40 | N2: 20 | O2: 20 | P2: 10 | Q2: 20 | R2: - | S2: - | T2: - | U2: 110 | V2: Muito Alta | W2: Aumento de reclamações no atendimento de Silvanópolis por Porto Nacional no período seco (Outra fonte com defeito também)
A3: 2026 | B3: ETO-RD-GR 00735/2026 | C3: ETO-RD-GR | D3: 5800859011 | E3: 58 | F3: 46219 | G3: 11 | H3: TUPIRAMA | I3: GUARAI | J3: NORTE | K3: AL01065015 | L3: 16/07/2026 PARECER COEP: ALINHADO COM O JEAN DO DMSL E O KELLITON , KELLITON IRÁ FAZER A INSTALAÇÃO DO CONTROLE RUA E O JEAN IRÁ REALIZAR O COMISSIONAMENTO , FAZENDO A COMPATIBILIZAÇÃO DOS CABOS ASSIM COMO FICARÁ UM CONTROLE RUA NO NOSSO ESTOQUE SOBRESSALENTE PARA ATENDER O DE ARAPOEMA, ATÉ A CHEGADA DOS CABOS QUE O JEAN ME DEU REPORTE DE QUE SERIA ATÉ O DIA 16/08 , FAVOR COCM'S REALIZAREM A INSTALAÇÃO E GUARDAR CONTROLE RUA SOBRESSALENTE PARA ARAPOEMAPEÇA ENVIADA: CONTROLEPARECER DMSL: *FEEDBACK EQUIP. ESPECIAIS**Nº DO EQUIPAMENTO:* 5800859011*TIPO EQUIPAMENTO:* RT ITB *TIPO DE COMUNICAÇÃO:* Não *DATA DA MANUTENÇÃO:* 09/06/2026*SID:* 3195/2026*DESCRIÇÃO:* _ Foi identificado relé da fase C com defeito conforme orientação da supervisão e necessário realiza retrofit para instalação de controle rua.*FICOU EM OPERAÇÃO* Não*PENDÊNCIA:* Realizado Retrofit *DADOS DIVERGENTES DA PROGRAMAÇÃO:* Não*BATERIA SUBSTITUÍDA?:* Não*TIPO DE BATERIA:**EQUIPE:* Edeglan e Brunno.Observação: trocar por um controle RUA.------------------------------------------------------------------------------------------Enviar equipe do DMSL, para fazer correção no RT 5800859011, o mesmo está com o displey da fase C apagado , dificutando realizar manobras no mesmo, emvirtude disso o mesmo ficou BAY PASSADO EM CAMPO | M3: 40 | N3: 20 | O3: 20 | P3: 10 | Q3: 20 | R3: - | S3: - | T3: - | U3: 110 | V3: Muito Alta | W3: Atendimento de parte da RDU Guaraí por fonte alternativa
A4: 2026 | B4: ETO-COEP 00124/2026 | C4: ETO-COEP | D4: 7923673004 | E4: 79 | F4: 46210 | G4: 4 | H4: ARAGUAINA | I4: ARAGUAINA | J4: NORTE | K4: AL04010004 | L4: PARECER COEP: Verificar Disponibilidade de equipamento no Scada e enviar modelo e tensão para a compra.RELIGADOR COM RELÉ DANIFICADO, REALIZAR SUBSTITUIÇÃO | M4: 15 | N4: 20 | O4: 15 | P4: 15 | Q4: 15 | R4: 10 | S4: 0 | T4: 15 | U4: 105 | V4: Muito Alta | W4: Transferência de cargas na RDU de Araguaína (2797 UCs)
A5: 2026 | B5: ETO-COEP 00040/2026 | C5: ETO-COEP | D5: 7931608059 | E5: 79 | F5: 46077 | G5: 59 | H5: TAQUARALTO | I5: TAQUARALTO | J5: CENTRO | K5: AL05099059 | L5: PARECER COEP: EQUIPAMENTO SELECIONADO PARA COMPRADMSL:Serviço Executado: Foi feita uma análise técnica no equipamento, devido à falta de comunicação. Também foi identificado que o tanque do equipamento está danificado, sendo assim, necessário substituir o tanque e o rádio do equipamento, que está queimado, sendo necessário substituir também. | M5: 15 | N5: 20 | O5: 15 | P5: 15 | Q5: 15 | R5: 10 | S5: 0 | T5: 15 | U5: 105 | V5: Muito Alta | W5: Transferência dos bairros Morada do Sol, Vale do Sol, Morada do Sol II, Nova Esperança, Sõa João, Araras I e II e Jardim Laila em Taquaralto (6033 UCs)
A6: 2026 | B6: ETO-TELE 01025/2026 | C6: ETO-TELE | D6: 7931610122 | E6: 79 | F6: 46225 | G6: 122 | H6: PALMAS | I6: PALMAS | J6: CENTRO | K6: AL08060122 | L6: PARECER DA PROTEÇÃO:FAVOR COMISSIONAR RELIGADOR. AJUSTES PERMANECEM OS MESMOS E DISPONÍVEIS NO APP DA PROTEÇÃO.Estagiário Rafael P Marques.******************30/06 PARECER COEP: EQUIPAMENTO ENTREGUE, SEGUE SS PARA O COCM´S , PARA REALIZAR O ATENDIMENTO,FAVOR ADICIONAR O PARECER PARA MANDAR PARA PROTEÇÃOBom dia,Segue SS para verificação RL sem comunicação com painel apagado equipe DEOP fez primeiro ataque sem sucesso RL 7931610122 RDU de Palmas.Feedback Equipamentos Especiais DMSL: *RLG 7931610122 RDU Palmas*Noja rc10 Data: 14/10/2025SID: 5412Dados de comunicação divergentes da programação: Não. Serviço Executado: Houve um curto no equipamento danificando a parte ativa, e antena! Será necessário fazer a substituição somente da parte ativa (tanque) e da antena.Equipamento ficou em operação?: Não Pendência: Sim, substituir a parte ativa.Bateria(s) substituída(s)?: NãoData Fabricação/Instalação da(s) bateria(s): 2024Equipe: Benvindo, Juliano e Sérgio.***** Parecer do COCM CENTRO*****Equipamento Substituido em campo pela Ordem de ServiÇO DLP-MPPA01 243/2026, ONDE OS RELATORIO ESTÃO ANEXADO.--------------------------------------------------------Parecer DMSL:Equipamento substituído porém não informado se antena também foi substituída. Levar antena para caso da mesmo não ter sido substituída. | M6: 15 | N6: 20 | O6: 15 | P6: 15 | Q6: 15 | R6: 10 | S6: 0 | T6: 15 | U6: 105 | V6: Muito Alta | W6: Transferência entre 284R SE Palmas IV e 2294R SE Palmas II
A7: 2026 | B7: ETO-RD-DP 00479/2026 | C7: ETO-RD-DP | D7: 5856070091 | E7: 58 | F7: 46230 | G7: 91 | H7: ALMAS | I7: DIANOPOLIS | J7: SUL | K7: LD04002091 | L7: PARECER DMSL: não foi regularizado a instalação do equipamento, nota repassada conforme alinhado com o supervisor.____________________________________________COCMS 26.03.26. SS REPASSADA PARA COEP PROVIDENCIAR MATERIAL. NÃO TEMOS AS PÇ EM ESTOQUE PARA FAZER A SUBSTITUIÇÃO. Solicitação de serviço para reposição de equipamentos furtados .COEP: Equipamento fornecido ao COCM-S para regularização.COCMS: Equipamento substituido conforme solicitado. Gentileza comissionar.PARECER DA PROTEÇÃO:SEGUE NOTA REPASSADA PARA DMSL COMISSIONAR.ENG° IRLLEY CASTELO BRANCOPARECER DMSL(23/09/2025): Feito a parte de comunicação, fechando enlace, configuração do rádio GE. Feito a medição de aterramento. Após uma inspeção, foi identificado que o regulador de tensão está instalado errado, carga está para o lado de fonte e fonte está do lado de carga. O certo é a fonte vim de almas, atualmente está vindo de natividade. Favor fazer a instalação correta. | M7: 40 | N7: 20 | O7: 20 | P7: 20 | Q7: 0 | R7: - | S7: - | T7: - | U7: 100 | V7: Muito Alta | W7: Atendimento da região da Engegold, Nativa, cidade Natividade e Chapada da Natividade
A8: 2026 | B8: ETO-COEP 00131/2026 | C8: ETO-COEP | D8: 7947203070 | E8: 79 | F8: 46211 | G8: 70 | H8: RIO SONO | I8: TAQUARALTO | J8: CENTRO | K8: LD02424015 | L8: 13/07 PARECER COEP: SELECIONADO PARA COMPRA CONTROLE favor verificar RL 7947203070, sem comunicaçao, feito 1° ataque pela equipe 070OP01 e nao retornou a comunicaçao , linformaçao no Scada de bateria.PARECER DMSL: Foi feito análise técnica, a placa do equipamento está queimada nessesario subistituir o equipamento completo -Carliel e Benvindo-05/02 | M8: 10 | N8: 20 | O8: 15 | P8: 15 | Q8: 15 | R8: 10 | S8: 0 | T8: 15 | U8: 100 | V8: Muito Alta | W8: Transferência da RDU de Lizarda (1650 UCs) para fonte alternativa
A9: 2026 | B9: ETO-RD-DP 00409/2026 | C9: ETO-RD-DP | D9: 7908705049 | E9: 79 | F9: 46209 | G9: 49 | H9: AURORA DO TOCANTINS | I9: DIANOPOLIS | J9: SUL | K9: AL01015049 | L9: EQUIPAMENTO ENTREGUE, SOLICITO PREVISÃO PARA SUBSTITUIÇÃO:PARECER COEP: PREVISÃO DE ENTREGA AOS COCM'S 01/07Manutenção no RL 7908705049PARECER DMSL(28/08/2025): Equipe foi fazer manutenção no RL e constatou que o tanque e o relé do mesmo se encontra queimado, providenciar substituição.PARECER COCMS 30/04/2026CRIADO OBRA 0512600135 PARA REQUISIÇÃO MATERIAL | M9: 15 | N9: 20 | O9: 5 | P9: 15 | Q9: 15 | R9: 0 | S9: 10 | T9: 15 | U9: 95 | V9: Muito Alta | W9: Proteção da baixa do TF de força da SE Aurora
A10: 2026 | B10: ETO-COEP 00059/2026 | C10: ETO-COEP | D10: 7925744087 | E10: 79 | F10: 46111 | G10: 87 | H10: GOIANORTE | I10: GUARAI | J10: NORTE | K10: LD02022033 | L10: PARECER COEP: EQUIPAMENTO SELECIONADO PARA COMPRAPARECER DMSL: FEEDBACK EQUIP. ESPECIAISNº DO EQUIPAMENTO: 7925744087TIPO EQUIPAMENTO: Noja RC 10TIPO DE COMUNICAÇÃO: Radio GE IPDATA DA MANUTENÇÃO: 19/02/2026SID: 735/2026 DESCRIÇÃO: foi identificado água dentro da parte interna do tanque e cabo umbilical encharcado de água foi passado essas informações para COS.FICOU EM OPERAÇÃO?: Não PENDÊNCIA: Sim substituir tanque e cabo umbilicalDADOS DIVERGENTES DA PROGRAMAÇÃO: NãoBATERIA SUBSTITUÍDA?: Não DATA DA BATERIA: 07/05/2025TIPO DE BATERIA: Lítio EQUIPE: Edeglan e Janio-------------------------------------------------------------------------------------------------RELIGADOR SEM COMUNICAÇÃO, APOS PRIMEIRO ATAQUE RETORNA E FICAR INDEFINIDO. | M10: 15 | N10: 20 | O10: 5 | P10: 15 | Q10: 15 | R10: 10 | S10: 0 | T10: 15 | U10: 95 | V10: Muito Alta | W10: Transferência de Goianorte, fonte principal operando
A11: 2026 | B11: ETO-PROT 00154/2026 | C11: ETO-PROT | D11: 7900117013 | E11: 79 | F11: 46224 | G11: 13 | H11: PARAISO DO TOCANTINS | I11: PARAISO DO TOCANTINS | J11: CENTRO | K11: AL01062013 | L11: 15/07 PARECER COCM: EQUIPAMENTO FOI SUBSTITUÍDO OBRA 021260042210/07 PARECER COEP: EQUIPAMENTO ENTREGUE AOS COCM´S FAVOR INFORMAR PRAZO DE SUBSTUIÇÃO PARA O DMSL E REPASSAR DEPOIS PARA PROTEÇÃO REALIZAR OS AJUSTES E DESCREVER NA SS O SERVIÇO REALIZADOPARECER COEP: PREVISÃO DE ENTREGA AOS COCM'S 01/07Segue nota para correção de anomalia e provável substituição de religador , religador 7900117013 -RDU - Paraiso .OBS: equipe DMSL Elisfran estava atualizando firmware no equipamento , porém relé parou de funcionar devido essa atualização , sendo necessário sua substituição .em campo o modelo e cooper Form6 , segundo tecnico deve ser substituído por um Noja .Repassado para o COEP para aquisição do equipamento e posterior repasse para o COCM. | M11: 15 | N11: 20 | O11: 15 | P11: 15 | Q11: 15 | R11: 0 | S11: 0 | T11: 15 | U11: 95 | V11: Muito Alta | W11: Transferência do 214R de Paraíso I, Centro Comercial de Paraíso
A12: 2026 | B12: ETO-COEP 00120/2026 | C12: ETO-COEP | D12: 7929376022 | E12: 79 | F12: 46203 | G12: 22 | H12: BABACULANDIA | I12: ARAGUAINA | J12: NORTE | K12: LD05010004 | L12: PARECER COEP: PROBLEMA NO ENVIO COCM'S CONTROLE ENVIADO FOI O NOJA , DEVIDO A FALTA DO MODELO NA SS (GRAVE)PARECER DMSL: *FEEDBACK EQUIP. ESPECIAIS**Nº DO EQUIPAMENTO:* 7929376022 *DATA DA MANUTENÇÃO:* 02/04/2026*SID:* 1677/2026*DESCRIÇÃO:* Trocar controle completo*PENDÊNCIA:* Sim.*DADOS DIVERGENTES DA PROGRAMAÇÃO:* Não*BATERIA SUBSTITUÍDA?:* Não*EQUIPE:* Adeilton e Edicleber __________________________________________________________POR GENTILEZA ATENDER SOLICITAÇÃO PRIMEIRO ATAQUE IDENTIFICOU QUE RELE ESTA EM CURTO NOTA ABERTA 224/2026 FOI BAIXADA POREM NÃO FOI CORRIGIDO PROBLEMA EM CAMPO. | M12: 15 | N12: 20 | O12: 5 | P12: 15 | Q12: 15 | R12: 10 | S12: 0 | T12: 15 | U12: 95 | V12: Muito Alta | W12: Transferência de Babaçulândia, fonte principal operando
A13: 2026 | B13: ETO-PROT 00145/2026 | C13: ETO-PROT | D13: 7933726256 | E13: 79 | F13: 46212 | G13: 256 | H13: MATEIROS | I13: PONTE ALTA TOCANTINS | J13: CENTRO | K13: LD03046026 | L13: 07/07 Equipamento foi substituido na OS: ETO-RD-PO 1859/2026 OBRA 031260035101/07 PARECER COEP: REDIRECIONADO PARA O POSTO DO COCM´S EQUIPAMENTO CHEGOU NO LOCAL, FAVOR ENTRAR EM CONTATO COM O DMSL, DEVIDO A URGÊNCIA DO EQUIPAMENTO EM OPERAÇÃO.30/06 PARECER COEP: DEVIDO A ALINHAMENTO COM COI UTILIZAREMOS PARTE ATIVA QUE ORIGINALMENTE FOI ENCOMENDADA PARA 7933726256PARECER DMSL: N° do Equipamento: _RLG 7933726256 MateirosTipo de Equipamento: _RLG NOJA RC 10 REL IIData: _06/05/2026SID: _2288/2026-Serviço Executado: _Equipamento com defeito na parte ativa, será necessário fazer a substituição da parte ativa e fazer melhoria na malha de terra!Equipamento ficou em operação?: _NaoPendência: _SimBateria(s) substituída(s)? NÃOData Fabricação/Instalação da(s) bateria(s):_06/2025Equipe: _Benvindo e Almir-------------------------------------------------------------------------------Religador 7933726256, sem comunicação apos primeiroa ataque não retornou as comunicação. | M13: 15 | N13: 10 | O13: 15 | P13: 15 | Q13: 15 | R13: 10 | S13: 0 | T13: 15 | U13: 95 | V13: Muito Alta | W13: Transferência da cidade de Mateiros (733 UCs) para o gerador
A14: 2026 | B14: ETO-TELE 01024/2026 | C14: ETO-TELE | D14: 7933766059 | E14: 79 | F14: 46225 | G14: 59 | H14: TAQUARALTO | I14: TAQUARALTO | J14: CENTRO | K14: AL01099059 | L14: PARECER DA PROTEÇÃO:RECOMISSIONAR RELIGADOR, AJUSTES DE PROTEÇÃO PERMANECEM OS MESMOS.Estagiário Rafael P Marques****************************PARECER COEP: EQUIPAMENTO ENTREGUE, SEGUE SS PARA O COCM´S , PARA REALIZAR O ATENDIMENTO,FAVOR ADICIONAR O PARECER PARA MANDAR PARA PROTEÇÃOSegue SS para verficar religador de poste 7933766059.Religador esta com defeito na parte ativa no tanque Porte gentilezaenviar equipe verificar.Endereço: TaquariPARECER DMSL: RLG 7933766059 RELÉ NOJA RC 10Mestre 2 Rep. taquaruçu GESID: 5457/2025Data: 15/10/2025Serviço Executado: Houve um curto na parte ativa do equipamento danificando a mesma, será necessário fazer a substituição somente do tanque, parte ativa.*Equipamento ficou em operação?:*Nao Pendência: Sim, substituir parte ativa.Equipe: Benvindo, Juliano e Sérgio.****** Parecer do COCM Centro***Equipámento Substituido em Campo pela Ordem de ServIÇO DLP-MPPA01 244/2026, ONDE OS RELATORIO ESTÃO ANEXADO.. | M14: 15 | N14: 20 | O14: 5 | P14: 15 | Q14: 15 | R14: 0 | S14: 10 | T14: 15 | U14: 95 | V14: Muito Alta | W14: Seccionamento de trecho do Setor Taquari
A15: 2026 | B15: ETO-SE-PA 00107/2026 | C15: ETO-SE-PA | D15: 7900594026 | E15: 79 | F15: 46219 | G15: 26 | H15: PONTE ALTA TOCANTINS | I15: PONTE ALTA TOCANTINS | J15: CENTRO | K15: LD03046026 | L15: PARECER DA PROTEÇÃO:16/07/2026 AJUSTES DISPONIBILIZADOS NO APP DA PROTEÇÃO15/07/2026 EQUIPAMENTO SUBSTITUIDO NA OS ETO-RD-PO 1860 OBRA 031260035414/07/2026 PARECER COCM/ COEP: DE ACORDO COM O EDSON CURCINO FOI FEITA S SUBSTITUIÇÃO DO EQUIPAMENTO , SEGUE PARA PROTEÇÃO ELABORAR AJUSTE10/07 PARECER COEP: EQUIPAMENTO DESLOCADO QUE ESTAVA EM GUARAÍ FOI ALINHADO COM O VALMOR QUE SERIA SUBSTITUIDO DIA 07/07/2026 , FAVOR PASSAR PARA PROTEÇÃO 7900594026PARECER COEP: AGUARDANDO COCM'S PARA ABRIR REQUISIÇÃOPARECER DMSL 10/06/2026: Tem uma nota aberta para esse equipamento solicitando a substituição desde 20/10/2025, como a nota não foi atendida estamos repassando para área responsável. Nota em aberto repassada ETO-COEP 210/2025.Segue nota para verificar intermitência de comunicação nos religadores 7908301026 , 7911120026, 7947959026 , 7908692026, 7900594026 rural- Ponte Alta . | M15: 15 | N15: 20 | O15: 15 | P15: 15 | Q15: 15 | R15: 0 | S15: 0 | T15: 15 | U15: 95 | V15: Muito Alta | W15: Religador responsável pela proteção da barra da SE Ponte Alta (2381 UCs)
A16: 2026 | B16: ETO-COEP 00141/2026 | C16: ETO-COEP | D16: 7927413001 | E16: 79 | F16: 46216 | G16: 1 | H16: PORTO NACIONAL | I16: PORTO NACIONAL | J16: CENTRO | K16: LD01072001 | L16: 22/07/2026 EQUIPAMENTO SLEECIONADO PARA COMPRAPARECER DMSL: *Segue feedback**Equipamento:* RLG 7927413001 *RELÉ TAVRIDA*Data:* 16/04/2026*SID:* 1817/2026*Serviço executado:* Placa de alimentação do equipamento com defeito, VERIFICAR SE É POSSIVEL substituir o equipamento completo.*Equipamento ficou em operação?*_Não*Pendência:*_Sim*Bateria(s) substituída(s)?*_Nao *Equipe:* Benvindo e Kaique-------------------------------------------------------------------------------------------------Religador 7927413001 sem comunicação foi realizado primeiro ataque porem a comunicação não retornou. Favor enviar equipe para devidas trattivas | M16: 15 | N16: 5 | O16: 15 | P16: 15 | Q16: 15 | R16: 10 | S16: 0 | T16: 15 | U16: 90 | V16: Muito Alta | W16: Transferência do Distrito Ind de Porto Nacional e GAs
A17: 2026 | B17: ETO-RD-PS 00302/2026 | C17: ETO-RD-PS | D17: 7908686014 | E17: 79 | F17: 46213 | G17: 14 | H17: PIUM | I17: PARAISO DO TOCANTINS | J17: CENTRO | K17: LD02025012 | L17: 10/07 PARECER COEP: EQUIPAMENTO ENTREGUE AOS COCM´S FAVOR INFORMAR PRAZO DE SUBSTUIÇÃO PARA O DMSL E REPASSAR DEPOIS PARA PROTEÇÃO REALIZAR OS AJUSTES E DESCREVER NA SS O SERVIÇO REALIZADO06/07 PARECER COEP: PREVISÃO DE ENTREGA DE ACORDO COM CALENDÁRIO LOGISITCO NOVO 06/07NOTA DMSL: Favor substituir o tanque, ele não está efetuando os comandos enviados. Não substituir o controle pois o mesmo funciona como repetidor de outros equipamentos.Segue nota para verificar falha de fechamento religador 7908686014- Pium .OBS: equipamento não fechou local e remoto , fica sinalizando no painel para verificar alarmes ! | M17: 15 | N17: 20 | O17: 0 | P17: 15 | Q17: 15 | R17: 10 | S17: 0 | T17: 15 | U17: 90 | V17: Muito Alta | W17: Fonte principal de Pium, RL de transferência operando
A18: 2026 | B18: ETO-TELE 00896/2026 | C18: ETO-TELE | D18: 7943790134 | E18: 79 | F18: 46183 | G18: 134 | H18: ESPERANTINA | I18: AUGUSTINOPOLIS | J18: NORTE | K18: LD02109039 | L18: PARECER DCMD:Serviço realizado , substituição da parte ativa do RELIGADOR 7943790134 - Favor realizar comissionamento | M18: 15 | N18: 10 | O18: 5 | P18: 15 | Q18: 15 | R18: 10 | S18: 0 | T18: 15 | U18: 85 | V18: Muito Alta | W18: Transferência de Esperantina, fonte principal operando
A19: 2026 | B19: ETO-COEP 00087/2026 | C19: ETO-COEP | D19: 7900453110 | E19: 79 | F19: 46139 | G19: 110 | H19: SANTA RITA DO TOCANTINS | I19: PORTO NACIONAL | J19: CENTRO | K19: LD03040003 | L19: 10/07/2026 EQUIPAMENTO SELECIONADO PARA COMPRA PARTE ATIVA30/06.PARECER COEP: ALINHADO COM O ALLAN REMANEJAMOS PARTE ATIVA PARA ATENDER 7933726256PARECER COEP: Aproveitar controle cooper se possível em outro local, previsão de chegada do material dia 01/07 para substituiçãoFavor verificar o RL 7900453110, pois o mesmo aceita comando de fechamento, porém fecha em campo e no SCADA continua aberto e só abre através de equipe em campo. Parecer Dmsl:Equipamento está com defeito na parte ativa, não aceita o comando de fechamento. Será necessário substituir o equipamento completo.Equipamento ficou em operação?: _SIM_a pedido do COS ficou em operação, a operação está ciente da necessidade de substituir.Pendência: Sim, será necessário substituir o equipamento. | M19: 15 | N19: 10 | O19: 5 | P19: 15 | Q19: 15 | R19: 10 | S19: 0 | T19: 15 | U19: 85 | V19: Muito Alta | W19: Transferência de Santa Rita, fonte principal operando
... A21: 2026 | B21: ETO-COEP 00048/2026 | C21: ETO-COEP | D21: 7925871077 | E21: 79 | F21: 46097 | G21: 77 | H21: GOIATINS | I21: ARAGUAINA | J21: NORTE | K21: LD03105019 | L21: 30/06 PARECER COEP: AGUARDANDO RETORNO DO DMSLPARECER DMSL: A PEDIDO DA PCM DO NORTE LARA SOARES REALIZEI A CRIAÇÃO DESSA SS, EM RAZAO DA ANTIGAETO-TELE 337/2026 QUE FOI BAIXADA POR ENGANO DE TAL FORMA SEGUE A MESMA PARA REALIZAR AS TRATATIVAS. PENDENCIA: Religador continua by passado, equipamento está com defeito na parte ativa | M21: 15 | N21: 10 | O21: 15 | P21: 15 | Q21: 15 | R21: 10 | S21: 0 | T21: 0 | U21: 80 | V21: Muito Alta | W21: Transferência de Goiatins e GAs (2492 UCs)
A22: 2026 | B22: ETO-COEP 00149/2026 | C22: ETO-COEP | D22: 5803327001 | E22: 58 | F22: 46223 | G22: 1 | H22: PORTO NACIONAL | I22: PORTO NACIONAL | J22: CENTRO | K22: AL01102271 | L22: 01/07 PARECER COEP: FOI CONFIRMADO COM A OPERAÇÃO QUE O EQUIPAMENTO SEGUIU O FLUXO INTEIRO DE COMISSIONAMENTO, PROTEÇÃO, FAVOR EXPLICAR O QUE FOI REALIZADO E SE EQUIPAMENTO ESTÁ OPERANDO, SENÃO ESTIVER EXPLICAR O QUE FOI FEITO NELE30/06PARECER COEP: REPASSAR DIRETAMENTE PARA OS COCM'SRegulador 5803327001 fora de operação, by passado em campo com painel de comunicação com cabos desconectados tensão 13.8.parecer DMSL: Feedback Equip. EspeciaisRT 5803327001RELÉ RUASid: 4844Data: 19/09/2025Serviço realizado:*Equipamento foi remanejado, 7 km da sua localização sentido Palmas necessário comissionamento completo*Equipamento com um dos cabos umbilicais danificado.* aterramento bucha FC não esta interligada corretamente * para-raios estão no mesmo aterramento da bucha FC.* Tranques muito alto e próximo da rede não permitindo o comissionamento com segurança.* Controle alto demais tem que baixar Equipamento ficou em operação?: nãoPendência: sim, precisa comissionar completoOBS | M22: 40 | N22: 0 | O22: 0 | P22: 20 | Q22: 20 | R22: - | S22: - | T22: - | U22: 80 | V22: Alta | W22: Em caso de perca da fonte principal é necessário esse RT para alimentação da Frísia
A23: 2026 | B23: ETO-PROT 00143/2026 | C23: ETO-PROT | D23: 7900230155 | E23: 79 | F23: 46211 | G23: 155 | H23: PALMEIRANTE | I23: COLINAS DO TOCANTINS | J23: NORTE | K23: LD02105019 | L23: 07/07/2026 PARECER COEP: MATERIAL ENVIADO , CONFORME ALINHANDO COM O WANDER REALIZAR SUBSTIUIÇÂO DO EQUIPAMENTO, FAVOR ESCREVER PARECER COCM ANTES DE PASSAR PARA PROTEÇÂO, DO QUE FOI REALIZADO01/07/2026 PARECER COEP: PROBLEMA NO ENVIO DO MATERIAL PARECER DMSL: Religador está com o tanque danificado. Não responde a comandos abertura e fechamento local ou remoto, pois está com sinal de curto circuito. Necessário trocar o equipamento. Para raio do trafo está queimado. Chave de saída da fase C está com o olhal quebrado, necessário substituir a chave. Equipamento ficou bypassado em campo. Aberto entrada e saída, com exceção da fase C de saída que ficou fechada. Favor, substituir equipamento completo por NOJA RC10 e sanar demais pendencias.Senhores Favor verificar RL 7900230155 o mesmo sinalizou aberto no SCADA porem a cidade de Palmeirante estava normal , feito um reset no rl e o mesmo subiu fechado.08/07/2026 PARECER DCMD: EQUIPE ETO-LVGR01 DE GUARAI ESTEVE NO RL 7900230155 DIA 25-06-2026 E FEZ TODAS A PENDENCIAS DO RL, OBS: EQUIPE SO NAO CONECTOU O CABO DO TRAFO NO RL. RL ESTA PRONTO PARA O COMISSIONAMENTO | M23: 15 | N23: 20 | O23: 5 | P23: 15 | Q23: 0 | R23: 10 | S23: 0 | T23: 15 | U23: 80 | V23: Muito Alta | W23: Fonte principal de Palmeirante, RL de transferência operando
A24: 2026 | B24: ETO-TELE 00997/2026 | C24: ETO-TELE | D24: 7908302256 | E24: 79 | F24: 46213 | G24: 256 | H24: MATEIROS | I24: PONTE ALTA TOCANTINS | J24: CENTRO | K24: LD03046026 | L24: RL teve nota baixada (ETO-TELE 970/2026) pore´m eqp continua fora de operação, solicito programação para equipe verificar em campo | M24: 5 | N24: 10 | O24: 5 | P24: 15 | Q24: 15 | R24: 10 | S24: 0 | T24: 15 | U24: 75 | V24: Alta | W24: Isolação de trecho e transferência das cidades de São Felix e Mateiros para gerador, além de atendimento de clientes rurais
A25: 2026 | B25: ETO-RD-GR 00766/2026 | C25: ETO-RD-GR | D25: 5800371025 | E25: 58 | F25: 46230 | G25: 25 | H25: ARAPOEMA | I25: COLINAS DO TOCANTINS | J25: NORTE | K25: LD02010153 | L25: 16/07/2026 PARECER COEP: ALINHADO COM O KELLITON REALIZAR SUBSTITUIÇÃO DO CONTROLE DE TUPIRAMA, ALINHADO COM O JEAN QUE OS CABOS COMPATIBILIZADORES VÃO CHEGAR 16/08 , ATÉ ESSA DATA MANTER ESSA SS E CONTROLE RUA, DEPOIS REPASSAR PARA O DMSLPARECER COEP: AVALIAR COM O LEANDRO, PROVAVELMENTE SÓ COMPRAPARECER DMSL: Após testes foi constatado defeito nos relés da fase A e B, Modelo Toshiba TBR 1000. Se possível, substituir os relés das 3 fases por controle RUA, disponibilizar os cabos de ligação entre o tanque e o controle para possibilitar a compatibilização do equipamento. Fornecer kit de comunicação, rádio, antena, etc.Segue nota para veriifcar falha em regulador de tensão N: 5800371025 dentro S/E Arapoema , equipamento esta com 2 reles com falha marca toshiba . | M25: 0 | N25: 20 | O25: 20 | P25: 10 | Q25: 20 | R25: - | S25: - | T25: - | U25: 70 | V25: Alta | W25: Aumento de reclamações no atendimento de Arapoema no período seco
A26: 2026 | B26: ETO-PROT 00144/2026 | C26: ETO-PROT | D26: 5865120195 | E26: 58 | F26: 46211 | G26: 195 | H26: CENTENARIO | I26: GUARAI | J26: NORTE | K26: LD01065015 | L26: PARECER DMSL:PENDÊNCIA: Realizar melhoria no aterramento por ser tratar de um terreno muito arenoso, e há pendências por parte do time da proteção, os ajustes do RT não estão disponíveis para inserção no referido equipamento.DATA DA MANUTENÇÃO: 12/03/202EQUIPE: Brunno e Edeglan.***********************PARECER DA PROTEÇÃO:FAVOR COMISSIONAR REGULADOR 5865120195 – LD Santa Maria Ramal Centenário e Recursolândia – 34,5kV. AJUSTE REALIZADO, DISPONÍVEL NO APP DA PROTEÇÃO.*********************** INSTALADO NA OBRA 0702400720 GENTILEZA, REALIZAR O COMISSIONAMENTO.LAUDO EM ANEXO.COORD EO: 889017, 901685708-07-2026 PARECER: FOI FEITO A MELHORIA NO REGULADOR CONFORME FOTOS EM ANEXO. | M26: 20 | N26: 20 | O26: 20 | P26: 10 | Q26: 0 | R26: - | S26: - | T26: - | U26: 70 | V26: Alta | W26: Atendimento das RDUs de Centenário, Recursolândia e clientes rurais
A27: 2026 | B27: ETO-COEP 00078/2026 | C27: ETO-COEP | D27: 7926089013 | E27: 79 | F27: 46135 | G27: 13 | H27: PARAISO DO TOCANTINS | I27: PARAISO DO TOCANTINS | J27: CENTRO | K27: LD03062013 | L27: PARECER COEP: EQUIPAMENTO SELECIONADO PARA COMPRAPARECER DMSL: Feedback Equip. EspeciaisRLG 7926089013,RELÉ NOJA RC10SID 1805/2026DATA 15/04/2026Serviço Executado: Favor realizar a troca da parte ativa do equipamento --reprogramar para atualizar a base juntamente com escada Equipamento ficou em operação: Não Pendência: sim atualizar a base e subistituir o tanque Bateria(s) substituída(s)? Não Data de Fabricação/Instalação da(s) bateria(s): Equipe: Carliel e João Vitor Fernando e Elson---------------------------------------------------------------------------------ATUALIZAR AJUSTES DO RL 7926089013 LD PARAISO I A PIUM. IMPLEMENTAÇÃO DA FUNÇÃO 27, SUBTENSÃO.AJUSTES DISPONIVEIS NO APP DA PROTEÇÃO. | M27: 15 | N27: 10 | O27: 5 | P27: 15 | Q27: 15 | R27: 10 | S27: 0 | T27: 0 | U27: 70 | V27: Alta | W27: Transferência da RDU de Chapada de Areia (937 UCs) para fonte alternativa
A28: 2026 | B28: ETO-PROT 00152/2026 | C28: ETO-PROT | D28: 7925087021 | E28: 79 | F28: 46223 | G28: 21 | H28: PARANA | I28: PEIXE | J28: SUL | K28: LD01010021 | L28: 10/07 PARECER COEP: EQUIPAMENTO ENTREGUE AOS COCM´S FAVOR INFORMAR PRAZO DE SUBSTUIÇÃO PARA O DMSL E REPASSAR DEPOIS PARA PROTEÇÃO REALIZAR OS AJUSTES E DESCREVER NA SS O SERVIÇO REALIZADOPARECER COEP: EM ROTA DE ENTREGA, VERIFICAR PREVISÃO DE CHEGADARealizar a substituição do tanque do equipamento. | M28: 15 | N28: 10 | O28: 5 | P28: 0 | Q28: 15 | R28: 10 | S28: 0 | T28: 15 | U28: 70 | V28: Alta | W28: Primeiro RL do 414R de Paranã, RL a jusante na LD também está bay-passado (630 UCs)
A29: 2026 | B29: ETO-PROT 00151/2026 | C29: ETO-PROT | D29: 5801866013 | E29: 58 | F29: 46220 | G29: 13 | H29: PARAISO DO TOCANTINS | I29: PARAISO DO TOCANTINS | J29: CENTRO | K29: AL03062013 | L29: 15/07 PARECER COCM, FOI ATENDIDA PELA OS ETO-RD-PS 1616/2026 OBRA-021260053910/07 PARECER COEP: EQUIPAMENTO ENTREGUE AOS COCM´S FAVOR INFORMAR PRAZO DE SUBSTUIÇÃO PARA O DMSL E REPASSAR DEPOIS PARA PROTEÇÃO REALIZAR OS AJUSTES E DESCREVER NA SS O SERVIÇO REALIZADOPARECER COEP: EM PROCESSO DE ENTREGAPARECER DMSL: RT 5801866013Serviço Executado: Feito a medição da malha de terra. Identificado infiltração na caixa de passagem da célula da fase C do banco regulador de tensão, será necessário fazer a substituição da mesma! Ficar atento na hora da substituição, deverá ser substituída a célula do lado da BR.Obs.: Será necessário baixar todo o banco pelo menos um metro, as buchas estão muito próximas a parte energizada não oferecem segurança para equipe no momento do ensaio elétrico.Equipamento ficou em operação?: Não Possui nobreak: SimPossui antena: SimPossui rádio:SimPendência: SimData da bateria: Equipe: Benvindo e Kaique._______________________________________________RT 5801866013BY PASSADO DEVIDO DEFEITO EM CELULA BEMVINDO ESTEVE NO LOCAL JUNTO AO COD .NECESSARIO TRATATIVA PARA MESMA .FASE DANIFICADO C | M29: 0 | N29: 20 | O29: 20 | P29: 20 | Q29: 10 | R29: - | S29: - | T29: - | U29: 70 | V29: Alta | W29: Atendimento da RDU Luzimangues Industrial por fonte alternativa
A30: 2025 | B30: ETO-RD-PS 00323/2025 | C30: ETO-RD-PS | D30: 5853360007 | E30: 58 | F30: 45946 | G30: 7 | H30: MIRACEMA DO TOCANTINS | I30: MIRACEMA DO TOCANTINS | J30: CENTRO | K30: LD05050008 | L30: REALIZAR TESTES NO EQUIPAMENTO E CONFERIR MEDIÇÕES DA MALHA DE ATERRAMENTO. ESTANDO OK, COMISSIONAR EQUIPAMENTO E COLOCA-LO EM OPERAÇÃO.AJUSTES DISPONIVEIS NO APP DA PROTEÇÃdmsl : N° do Equipamento:*RT 5853360007 MIRACEMASID: 2493/2025Data: 13/05/2025Serviço Executado Provavelmente ocorreu uma descarga no equipamento comprometendo a malha!Será necessário fazer melhoria da malha de aterramento, fazer toda interligação da mesma! Feito ensaios de isolação das 3 células do equipamento, isolação está ok, quando retornar para colocar em operação levar 3 baterias de 7a.Equipamento ficou em operação?: Não Equipe: Benvindo e Jardel | M30: 0 | N30: 20 | O30: 20 | P30: 10 | Q30: 20 | R30: - | S30: - | T30: - | U30: 70 | V30: Alta | W30: Aumento de reclamações no atendimento de Miracema no período seco
A31: 2026 | B31: ETO-PROT 00153/2026 | C31: ETO-PROT | D31: 7900573047 | E31: 79 | F31: 46223 | G31: 47 | H31: FIGUEIROPOLIS | I31: FORMOSO DO ARAGUAIA | J31: SUL | K31: AL02033047 | L31: 10/07 PARECER COEP: EQUIPAMENTO ENTREGUE AOS COCM´S FAVOR INFORMAR PRAZO DE SUBSTUIÇÃO PARA O DMSL E REPASSAR DEPOIS PARA PROTEÇÃO REALIZAR OS AJUSTES E DESCREVER NA SS O SERVIÇO REALIZADOPARECER COEP: AGUARDANDO COCM'S GERAREM AS OBRAS PARA PODER ENTREGAR MATERIALFavor providenciar manutenção no RL 7900573047, o mesmo estar em curto conforme fotos anexadas. Equipamento ficou bay passado em campo.PARECER DMSL: Equipe: FABIO AP./JOÃO MARCOSData Executada: 15/10/2025Serviço Executado:Foi constatado que o equipamento esta queimado na parte ativa placa, tanque e relé. Por favor fazer a substituição pelo Noja RC10. | M31: 5 | N31: 5 | O31: 15 | P31: 0 | Q31: 15 | R31: 10 | S31: 0 | T31: 15 | U31: 65 | V31: Alta | W31: Transferência da Bunge, Saneatins e secadora
A32: 2026 | B32: ETO-RD-PO 00208/2026 | C32: ETO-RD-PO | D32: 7953610256 | E32: 79 | F32: 46219 | G32: 256 | H32: MATEIROS | I32: PONTE ALTA TOCANTINS | J32: CENTRO | K32: LD03046026 | L32: 14/07/2026 - PARECER COEP: REALOCAR TANQUE 34,5 SOBRESSALENTE DE PARAÍSO PARA ATENDER PARECER DMSL: Data: 10/03/2026,Serviço Executado: Foi substituído o relé do equipamento, o mesmo estava danificado. Trocado o DPS, o mesmo estava queimado devido ao tanque estar furado. O equipamento ficou em bypass.Equipamento ficou em operação? NãoPendência? Sim, substituir a parte ativa com cordão umbilical.Equipe: Carliel e João VitorSEGUE SS PARA REGULARIZAR AUTOMAÇÃO DO RL 7953610256 NA INTERLIGAÇÃO COM A COELBA (CHAPADA DA MANGABEIRA) - EQUIPE INFOMOU CURTO INTERNO NO GABINETE DJ AC NÃO FECHA | M32: 5 | N32: 5 | O32: 15 | P32: 15 | Q32: 0 | R32: 0 | S32: 10 | T32: 15 | U32: 65 | V32: Alta | W32: Atenidmento da COELBA (Alto potencial de compensação)
A33: 2026 | B33: ETO-RD-DP 00404/2026 | C33: ETO-RD-DP | D33: 5800438116 | E33: 58 | F33: 46204 | G33: 116 | H33: CHAPADA DA NATIVIDADE | I33: DIANOPOLIS | J33: SUL | K33: LD04002091 | L33: 01/07 PARECER COEP: DENER INFORMOU QUE TEM AS PEÇAS SOBRESSALENTES DE OBRA PARA UTILIZAR, REPASSEREI AO POSTO DO ETO-RD-DP PARA AS TRATATIVAS, FAVOR INFORMAR PREVISÃO DE SUBSTIUIÇÃO E PREENCHER A PLANILHA ASSIM COMO PREENCHER A DESCRIÃO ANTES DE PASSAR PARA PROTEÇÃO FAZER OS AJUSTES30/06PARECER COEP: AGUARDANDO COCM'S CRIAREM OBRA PARA ENTREGA DO MATERIALSegue nota para normalizar falha em regulador N:5800438116 - Chapada da natividade .equipamento está com fase B e C travada .OBS: a fase B esta sinalizando falha , equipamento não insere TAP negativo na fase B e C , o mesmo ficou no TAP zerado e bloqueado .PARECER DMSL (18/08/2025): Foi feito teste de elevar e abaixar nas fases B e C e o mesmo só aceita elevar os taps, constatando que o mercanismo da chave reversoura polaridade está com defeito. Número de série fase B EI7030 e Número de série fase C EI7040. Substituir as fases B e C.Foi constatado que a placa F do controle está com defeito. | M33: 0 | N33: 20 | O33: 20 | P33: 20 | Q33: 0 | R33: - | S33: - | T33: - | U33: 60 | V33: Média | W33: Atendimento da região da Engegold, Nativa, cidade Natividade e Chapada da Natividade (Fonte alternativa)
A34: 2026 | B34: ETO-COEP 00151/2026 | C34: ETO-COEP | D34: 5840227063 | E34: 58 | F34: 46223 | G34: 63 | H34: BANDEIRANTES DO TOCANTINS | I34: COLINAS DO TOCANTINS | J34: NORTE | K34: LD01054060 | L34: PARECER DMSL 13/07/2026: Realizados ensaios de isolação nas três células, e foi identificado curto na fase A, sendo necessário a sua substituição. Os cabos das buchas ficaram desconectados para melhor identificação no momento da sua substituiçãSEGUE PARA O DMSL AVALIAR ANTES DE SEGUIRMOS COM O SERVIÇOSEGUE PARA REALIZAR TROCA---------------------------------------------------------Boa noite,Segue SS para tratativas regulador de tensão 5840227063 fase C em curto | M34: 0 | N34: 20 | O34: 20 | P34: 10 | Q34: 10 | R34: - | S34: - | T34: - | U34: 60 | V34: Média | W34: Atendimento da RDU Bandeirantes e clientes rurais
A35: 2026 | B35: ETO-TELE 00881/2026 | C35: ETO-TELE | D35: 5851753086 | E35: 58 | F35: 46175 | G35: 86 | H35: MARIANOPOLIS | I35: DIVINOPOLIS | J35: CENTRO | K35: LD05062013 | L35: PARECER DMSL: FAVOR SOLUCIONAR PENDENCIAS RT: 5851753086Relé R.U.A Data: _19/05/2026Sid: 2740/2026Possui rádio?: SimPossui antena?: SimPossui módulo nobreak?: SimServiço Executado: * Feito testes no equipamento,o mesmo está normal.* Será necessário fazer melhorias na malha de terra e colocar em operação.Equipamento ficou em operação? Não Pendência: Sim. É necessário fazer melhorias na malha de aterramento.Bateria(s) substituída(s)? _nao Data Fabricação/Instalação da(s) bateria(s): 12/2025Equipe: Jean e BenvindoPARECER DCMD: FEITO MELHORIA NA MALHA DO ATERRAMENTO, FAVOR ENVIAR EQUIPE PARA COLOCA-LO EM OPERAÇÃORT 5851753086MESMO ESTA BY-PASSADO EM CAMPO EQUIPE SINERGIA 086OP01 ESTEVE NO LOCAL APARENTIMENTE SEM DEFEITO APARENTE MESMO FOI BY PASSADO POR TER TIRADO LINHA.DESDE ENTAO MESMO NAO VOLTOU PARA OPERAÇÃO .FAVOR VERIFICAR PARA TESTES POSSIVEIS .PARA QUE O MESMO VOLTA COM DISPONIBILIDADE PARA OPERAÇÃO . | M35: 0 | N35: 20 | O35: 20 | P35: 10 | Q35: 10 | R35: - | S35: - | T35: - | U35: 60 | V35: Média | W35: Atendimento da RDU Marianópolis e clientes rurais
A36: 2026 | B36: ETO-TELE 00986/2026 | C36: ETO-TELE | D36: 5846328094 | E36: 58 | F36: 46211 | G36: 94 | H36: PEIXE | I36: PEIXE | J36: SUL | K36: LD04040003 | L36: COCM SUL - 07/07/2026 - FOI REALIZADO MELHORIA DE ATERRAMENTO E FEITO A MANUTENÇÕES E TODAS AS CHAVES E SUBSTITUIDO OS CONECTORES.PARECER COEP: MELHORIA DE ATERRAMENTO É COCM'S, FAVOR ENCAMINHAR DIRETAMENTE PARA ELES, COCM'S REALIZAR MELHORIA DE ATERRAMENTO POR FAVORPor genteliiza verificar RT 5846328094 situação de equipamento, se encontra by passado em campoPARECER DMSL:Favor, realizar melhoria de aterramento que se encontra alta e substituir todos os conectores das buchas por conectores estrangulador. | M36: 0 | N36: 20 | O36: 20 | P36: 10 | Q36: 10 | R36: - | S36: - | T36: - | U36: 60 | V36: Média | W36: Atendimento da RDU Sucupira e clientes rurais
A37: 2025 | B37: ETO-COEP 00184/2025 | C37: ETO-COEP | D37: 7903112004 | E37: 79 | F37: 45903 | G37: 4 | H37: ARAGUAINA | I37: ARAGUAINA | J37: NORTE | K37: LD05010004 | L37: 20/07 PARECER COEP: EQUIPAMENTO SELECIONADO PARA COMPRAApós testes no RLG 7903112004 foi constatado defeito no mesmo e como se trata de um modelo COOPER FORM6 que está obsoleto e não possuímos peças sobressalentes, faz-se necessária substituição completa por modelo NOJA RC10. | M37: 15 | N37: 10 | O37: 5 | P37: 15 | Q37: 0 | R37: 10 | S37: 0 | T37: 0 | U37: 55 | V37: Alta | W37: Transferência de Babaçulândia, 4 RLs sendo 2 operando
A38: 2025 | B38: ETO-COEP 00120/2025 | C38: ETO-COEP | D38: 7920024127 | E38: 79 | F38: 45839 | G38: 127 | H38: PALMEIRAS DO TOCANTINS | I38: TOCANTINOPOLIS | J38: NORTE | K38: LD01084002 | L38: 30/06 PARECER COEP: AGUARDANDO O RETORNO DO DMSL , PARA ENTENDER SE O PROBLEMA É NA COMUNICAÇÃO OU PARTE ATIVA, JÁ QUE O EQUIPAMENTO EM QUESTÃO SEGUE COMUNICANDOPARECER DMSL: Após testes, equipe DMSL constatou que o relé e a parte ativa do equipamento 7920024127 estão com defeito, sendo necessária a substituição completa por um modelo NOJA RC 10. Favor, subsituir também a chave de saída da fase A que está com o anel de abertura quebrado.RL 7920024127 está desarmando em campo e no SCADA continua fechado, só sinaliza aberto no SCADA quando a equipe faz o resert no equipamento em campo. | M38: 15 | N38: 10 | O38: 5 | P38: 15 | Q38: 0 | R38: 10 | S38: 0 | T38: 0 | U38: 55 | V38: Alta | W38: Transferência de Palmeiras, 3 fontes operando
A39: 2026 | B39: ETO-COEP 00029/2026 | C39: ETO-COEP | D39: 7927646026 | E39: 79 | F39: 46057 | G39: 26 | H39: PONTE ALTA TOCANTINS | I39: PONTE ALTA TOCANTINS | J39: CENTRO | K39: LD03046026 | L39: PARECER COEP: EQUIPAMENTO SELECIONADO PARA COMPRARELIGADOR BY PASSADO POR DEFEITO, NECESSÁRIO AVALIAÇÃO DO PROBLEMA.parecer dmsl:O religador apresenta defeito no tanque, sendo necessário substituir o tanque o mesmo está tirando a linha, e troca os isoladores. Quando retornar, trazer uma fonte para o equipamento, a mesma foi removida.FICOU EM OPERAÇÃO? NãoPENDÊNCIA: Sim, aguardando peças para substituição. | M39: 15 | N39: 10 | O39: 5 | P39: 0 | Q39: 15 | R39: 0 | S39: 10 | T39: 0 | U39: 55 | V39: Alta | W39: Opção de isolação de São Félix e Mateiros para alimentação por gerador
A40: 2026 | B40: ETO-PROT 00156/2026 | C40: ETO-PROT | D40: 7927169001 | E40: 79 | F40: 46224 | G40: 1 | H40: PORTO NACIONAL | I40: PORTO NACIONAL | J40: CENTRO | K40: AL01102271 | L40: PARECER COEP: EQUIPAMENTO ENTREGUE, SEGUE SS PARA O COCM´S , PARA REALIZAR O ATENDIMENTO,FAVOR ADICIONAR O PARECER PARA MANDAR PARA PROTEÇÃOSS ANTIGA: 1500/2025 PARECER DMSL: Serviço Executado: Foi verificado que o tanque do equipamento está danificado, sendo necessário substituir o tanque do equipamento.Equipamento ficou em operação?: NãoPendência: Sim, instalar fonte, disjuntor e DPS, e substituir o tanque.***** Parecer COCM******Subsituido Tranque do RL pela Ordem de Serviço DLP-MPPA01 247/2026 RELATORIO EM ANEXO DA O.S EXECUTORA | M40: 5 | N40: 5 | O40: 15 | P40: 0 | Q40: 15 | R40: 0 | S40: 0 | T40: 15 | U40: 55 | V40: Alta | W40: Transferência dos Grupos A - VLI e Frisia
A41: 2026 | B41: ETO-RD-PO 00097/2026 | C41: ETO-RD-PO | D41: 5800291035 | E41: 58 | F41: 46112 | G41: 35 | H41: MONTE DO CARMO | I41: PONTE ALTA TOCANTINS | J41: CENTRO | K41: LD01051035 | L41: PARECER DMSL: Feito testes funcionais nas 3 células do banco as mesmas corresponderam aos testes. Será necessário fazer a correção da malha de terra, baixar o banco completo pois está muito alto dificultando as atividades da equipe, substituir as 3 chaves facas do lado Fonte e as 3 do lado Carga instalar suporte inclinado das chaves para facilitar as manobras. Colocar cinta no controle RUA abaixar o mesmo, pois está muito alto e fixado com um mosquetão oval, quando retornar para colocar em operação levar 3 baterias de 7a e rele rua.Obs.: Fizeram melhoria na malha de terra, mas não está dentro do aceitável! As outras pendências continuam, favor corrigir. Equipamento ficou em operação?: Não - Equipe: Benvindo e Kaique- SS ANTIGA ETO-TELE 358/2026 | M41: 0 | N41: 20 | O41: 20 | P41: 10 | Q41: 0 | R41: - | S41: - | T41: - | U41: 50 | V41: Média | W41: Aumento de reclamações no atendimento de Silvanópolis por Monte do Carmo no período seco
...

Sheet Premissas por Equipamento
A1: Ativo | B1: Tipo | C1: Localidade | D1: Polo | E1: Regional | F1: SS aberta | G1: Parecer COEP | H1: Observação | I1: Check de concluídas | J1: Defeito identificado | K1: Quantidade | L1: Descrição SS | M1: Premissa 1 | N1: Premissa 2 | O1: Premissa 3 | P1: Premissa 4 | Q1: Premissa 5 | R1: Premissa 6 | S1: Premissa 7 | T1: Premissa 8 | U1: Priorização | V1: Criticidade | W1: Observação após análise
A2: 5800291077 | B2: 58 | C2: GOIATINS | D2: ARAGUAINA | E2: NORTE | F2: CONCLUÍDA | I2: Ok | M2: 40 | N2: 20 | O2: 20 | P2: 20 | Q2: 20 | R2: - | S2: - | T2: - | U2: 120 | V2: Muito Alta | W2: Aumento de reclamações no atendimento de Goiatins e GAs relevantes na região
A3: 5854566043 | B3: 58 | C3: SILVANOPOLIS | D3: PORTO NACIONAL | E3: CENTRO | F3: ETO-RD-PO 00213/2026 | G3: Substituido 24/07/2026 | H3: Laudo da empreteira | I3: Em andamento | J3: Célula | K3: 1 | L3: 22/07/2026 PARECER COEP: EQUIPAMENTO ENTREGUE AOS COCM´SPRAZO DE 7 DIAS CONTANDO O SLA.PARECER COEP: EQUIPAMENTO ENTREGUE AOS COCM´S FAVOR SUSBSTTUIR , E AGUARDO O PRAZO DE PREVISÃO DE SUBSTIUIÇÃOboa noite,segue SS para as devidas tratativas com equipe de manutenção com apoio de equipe de linha viva substituir regulador de tensão 5854566043 queimado célula fase c, LD Porto / Silvanópolis mesmo deverá ser substituído com apoio de equipe de linha viva PARECER DMSL: Foi realizado inspeção visual e ensaios de isolação, relação de transformação e resistência de enrolamento. A fase B está danificada e será necessário substituir a mesma. Malha de aterramento está relativamente boa e conectada. Fase A e C passaram nos ensaios. Substituir fase B. | M3: 40 | N3: 20 | O3: 20 | P3: 10 | Q3: 20 | R3: - | S3: - | T3: - | U3: 110 | V3: Muito Alta | W3: Aumento de reclamações no atendimento de Silvanópolis por Porto Nacional no período seco (Outra fonte com defeito também)
A4: 5800859011 | B4: 58 | C4: TUPIRAMA | D4: GUARAI | E4: NORTE | F4: ETO-RD-GR 00735/2026 | G4: Equipamento entregue ao COCM | H4: Previsão de Substituição 28/07 | I4: Em andamento | J4: Controle | K4: 1 | L4: 16/07/2026 PARECER COEP: ALINHADO COM O JEAN DO DMSL E O KELLITON , KELLITON IRÁ FAZER A INSTALAÇÃO DO CONTROLE RUA E O JEAN IRÁ REALIZAR O COMISSIONAMENTO , FAZENDO A COMPATIBILIZAÇÃO DOS CABOS ASSIM COMO FICARÁ UM CONTROLE RUA NO NOSSO ESTOQUE SOBRESSALENTE PARA ATENDER O DE ARAPOEMA, ATÉ A CHEGADA DOS CABOS QUE O JEAN ME DEU REPORTE DE QUE SERIA ATÉ O DIA 16/08 , FAVOR COCM'S REALIZAREM A INSTALAÇÃO E GUARDAR CONTROLE RUA SOBRESSALENTE PARA ARAPOEMAPEÇA ENVIADA: CONTROLEPARECER DMSL: *FEEDBACK EQUIP. ESPECIAIS**Nº DO EQUIPAMENTO:* 5800859011*TIPO EQUIPAMENTO:* RT ITB *TIPO DE COMUNICAÇÃO:* Não *DATA DA MANUTENÇÃO:* 09/06/2026*SID:* 3195/2026*DESCRIÇÃO:* _ Foi identificado relé da fase C com defeito conforme orientação da supervisão e necessário realiza retrofit para instalação de controle rua.*FICOU EM OPERAÇÃO* Não*PENDÊNCIA:* Realizado Retrofit *DADOS DIVERGENTES DA PROGRAMAÇÃO:* Não*BATERIA SUBSTITUÍDA?:* Não*TIPO DE BATERIA:**EQUIPE:* Edeglan e Brunno.Observação: trocar por um controle RUA.------------------------------------------------------------------------------------------Enviar equipe do DMSL, para fazer correção no RT 5800859011, o mesmo está com o displey da fase C apagado , dificutando realizar manobras no mesmo, emvirtude disso o mesmo ficou BAY PASSADO EM CAMPO | M4: 40 | N4: 20 | O4: 20 | P4: 10 | Q4: 20 | R4: - | S4: - | T4: - | U4: 110 | V4: Muito Alta | W4: Atendimento de parte da RDU Guaraí por fonte alternativa
A5: 5836764032 | B5: 58 | C5: ARAGUACU | D5: ALVORADA | E5: SUL | F5: CONCLUÍDA | I5: Ok | M5: 40 | N5: 20 | O5: 20 | P5: 10 | Q5: 20 | R5: - | S5: - | T5: - | U5: 110 | V5: Muito Alta | W5: Aumento de reclamações no atendimento de Araguaçu no período seco
A6: 7923673004 | B6: 79 | C6: ARAGUAINA | D6: ARAGUAINA | E6: NORTE | F6: ETO-COEP 00124/2026 | G6: Em processo de aquisição | H6: Estava aguardando retorno DMSL | J6: Completo | K6: 1 | L6: PARECER COEP: Verificar Disponibilidade de equipamento no Scada e enviar modelo e tensão para a compra.RELIGADOR COM RELÉ DANIFICADO, REALIZAR SUBSTITUIÇÃO | M6: 15 | N6: 20 | O6: 15 | P6: 15 | Q6: 15 | R6: 10 | S6: 0 | T6: 15 | U6: 105 | V6: Muito Alta | W6: Transferência de cargas na RDU de Araguaína (2797 UCs)
A7: 7931608059 | B7: 79 | C7: TAQUARALTO | D7: TAQUARALTO | E7: CENTRO | F7: ETO-COEP 00040/2026 | G7: Em processo de aquisição | J7: Tanque e rádio | K7: 1 | L7: PARECER COEP: EQUIPAMENTO SELECIONADO PARA COMPRADMSL:Serviço Executado: Foi feita uma análise técnica no equipamento, devido à falta de comunicação. Também foi identificado que o tanque do equipamento está danificado, sendo assim, necessário substituir o tanque e o rádio do equipamento, que está queimado, sendo necessário substituir também. | M7: 15 | N7: 20 | O7: 15 | P7: 15 | Q7: 15 | R7: 10 | S7: 0 | T7: 15 | U7: 105 | V7: Muito Alta | W7: Transferência dos bairros Morada do Sol, Vale do Sol, Morada do Sol II, Nova Esperança, Sõa João, Araras I e II e Jardim Laila em Taquaralto (6033 UCs)
A8: 7931610122 | B8: 79 | C8: PALMAS | D8: PALMAS | E8: CENTRO | F8: ETO-TELE 01025/2026 | G8: Concluído DCMD | H8: Previsão de substituição 16/07 | I8: Em andamento | J8: Tanque e antena | K8: 1 | L8: PARECER DA PROTEÇÃO:FAVOR COMISSIONAR RELIGADOR. AJUSTES PERMANECEM OS MESMOS E DISPONÍVEIS NO APP DA PROTEÇÃO.Estagiário Rafael P Marques.******************30/06 PARECER COEP: EQUIPAMENTO ENTREGUE, SEGUE SS PARA O COCM´S , PARA REALIZAR O ATENDIMENTO,FAVOR ADICIONAR O PARECER PARA MANDAR PARA PROTEÇÃOBom dia,Segue SS para verificação RL sem comunicação com painel apagado equipe DEOP fez primeiro ataque sem sucesso RL 7931610122 RDU de Palmas.Feedback Equipamentos Especiais DMSL: *RLG 7931610122 RDU Palmas*Noja rc10 Data: 14/10/2025SID: 5412Dados de comunicação divergentes da programação: Não. Serviço Executado: Houve um curto no equipamento danificando a parte ativa, e antena! Será necessário fazer a substituição somente da parte ativa (tanque) e da antena.Equipamento ficou em operação?: Não Pendência: Sim, substituir a parte ativa.Bateria(s) substituída(s)?: NãoData Fabricação/Instalação da(s) bateria(s): 2024Equipe: Benvindo, Juliano e Sérgio.***** Parecer do COCM CENTRO*****Equipamento Substituido em campo pela Ordem de ServiÇO DLP-MPPA01 243/2026, ONDE OS RELATORIO ESTÃO ANEXADO.--------------------------------------------------------Parecer DMSL:Equipamento substituído porém não informado se antena também foi substituída. Levar antena para caso da mesmo não ter sido substituída. | M8: 15 | N8: 20 | O8: 15 | P8: 15 | Q8: 15 | R8: 10 | S8: 0 | T8: 15 | U8: 105 | V8: Muito Alta | W8: Transferência entre 284R SE Palmas IV e 2294R SE Palmas II
A9: 7900648055 | B9: 79 | C9: ARAGUACEMA | D9: DIVINOPOLIS | E9: CENTRO | F9: CONCLUÍDA | M9: 15 | N9: 20 | O9: 15 | P9: 15 | Q9: 15 | R9: 10 | S9: 0 | T9: 15 | U9: 105 | V9: Muito Alta | W9: Transferência da RDU de Araguacema (1506 UCs)
A10: 7947203070 | B10: 79 | C10: RIO SONO | D10: TAQUARALTO | E10: CENTRO | F10: ETO-COEP 00131/2026 | G10: Em processo de aquisição | H10: Estava aguardando retorno DMSL | J10: Controle | K10: 1 | L10: 13/07 PARECER COEP: SELECIONADO PARA COMPRA CONTROLE favor verificar RL 7947203070, sem comunicaçao, feito 1° ataque pela equipe 070OP01 e nao retornou a comunicaçao , linformaçao no Scada de bateria.PARECER DMSL: Foi feito análise técnica, a placa do equipamento está queimada nessesario subistituir o equipamento completo -Carliel e Benvindo-05/02 | M10: 10 | N10: 20 | O10: 15 | P10: 15 | Q10: 15 | R10: 10 | S10: 0 | T10: 15 | U10: 100 | V10: Muito Alta | W10: Transferência da RDU de Lizarda (1650 UCs) para fonte alternativa
A11: 5856070091 | B11: 58 | C11: ALMAS | D11: DIANOPOLIS | E11: SUL | F11: ETO-RD-DP 00479/2026 | G11: Equipamento entregue ao COCM | H11: Previsão de instalação 30/07/2026 | I11: Em andamento | J11: Células + controle | K11: 3 | L11: PARECER DMSL: não foi regularizado a instalação do equipamento, nota repassada conforme alinhado com o supervisor.____________________________________________COCMS 26.03.26. SS REPASSADA PARA COEP PROVIDENCIAR MATERIAL. NÃO TEMOS AS PÇ EM ESTOQUE PARA FAZER A SUBSTITUIÇÃO. Solicitação de serviço para reposição de equipamentos furtados .COEP: Equipamento fornecido ao COCM-S para regularização.COCMS: Equipamento substituido conforme solicitado. Gentileza comissionar.PARECER DA PROTEÇÃO:SEGUE NOTA REPASSADA PARA DMSL COMISSIONAR.ENG° IRLLEY CASTELO BRANCOPARECER DMSL(23/09/2025): Feito a parte de comunicação, fechando enlace, configuração do rádio GE. Feito a medição de aterramento. Após uma inspeção, foi identificado que o regulador de tensão está instalado errado, carga está para o lado de fonte e fonte está do lado de carga. O certo é a fonte vim de almas, atualmente está vindo de natividade. Favor fazer a instalação correta. | M11: 40 | N11: 20 | O11: 20 | P11: 20 | Q11: 0 | R11: - | S11: - | T11: - | U11: 100 | V11: Muito Alta | W11: Atendimento da região da Engegold, Nativa, cidade Natividade e Chapada da Natividade
A12: 7903569004 | B12: 79 | C12: ARAGUAINA | D12: ARAGUAINA | E12: NORTE | F12: CONCLUÍDA | M12: 15 | N12: 20 | O12: 5 | P12: 15 | Q12: 15 | R12: 10 | S12: 0 | T12: 15 | U12: 95 | V12: Muito Alta | W12: Transferência dos bairros JD Santa Helena, Jd Filadelfiae Setor Caraja em Araguaína (2053 UCs), AL 254R de AR I e AL 214R de AR III
A13: 7925744087 | B13: 79 | C13: GOIANORTE | D13: GUARAI | E13: NORTE | F13: ETO-COEP 00059/2026 | G13: Em processo de aquisição | H13: Mandar reformar | J13: Tanque e cabo umbilical | K13: 1 | L13: PARECER COEP: EQUIPAMENTO SELECIONADO PARA COMPRAPARECER DMSL: FEEDBACK EQUIP. ESPECIAISNº DO EQUIPAMENTO: 7925744087TIPO EQUIPAMENTO: Noja RC 10TIPO DE COMUNICAÇÃO: Radio GE IPDATA DA MANUTENÇÃO: 19/02/2026SID: 735/2026 DESCRIÇÃO: foi identificado água dentro da parte interna do tanque e cabo umbilical encharcado de água foi passado essas informações para COS.FICOU EM OPERAÇÃO?: Não PENDÊNCIA: Sim substituir tanque e cabo umbilicalDADOS DIVERGENTES DA PROGRAMAÇÃO: NãoBATERIA SUBSTITUÍDA?: Não DATA DA BATERIA: 07/05/2025TIPO DE BATERIA: Lítio EQUIPE: Edeglan e Janio-------------------------------------------------------------------------------------------------RELIGADOR SEM COMUNICAÇÃO, APOS PRIMEIRO ATAQUE RETORNA E FICAR INDEFINIDO. | M13: 15 | N13: 20 | O13: 5 | P13: 15 | Q13: 15 | R13: 10 | S13: 0 | T13: 15 | U13: 95 | V13: Muito Alta | W13: Transferência de Goianorte, fonte principal operando
A14: 7900117013 | B14: 79 | C14: PARAISO DO TOCANTINS | D14: PARAISO DO TOCANTINS | E14: CENTRO | F14: ETO-PROT 00154/2026 | G14: Concluído DCMD | H14: Previsão de entrega 15/07 | I14: Em andamento | J14: Controle | K14: 1 | L14: 15/07 PARECER COCM: EQUIPAMENTO FOI SUBSTITUÍDO OBRA 021260042210/07 PARECER COEP: EQUIPAMENTO ENTREGUE AOS COCM´S FAVOR INFORMAR PRAZO DE SUBSTUIÇÃO PARA O DMSL E REPASSAR DEPOIS PARA PROTEÇÃO REALIZAR OS AJUSTES E DESCREVER NA SS O SERVIÇO REALIZADOPARECER COEP: PREVISÃO DE ENTREGA AOS COCM'S 01/07Segue nota para correção de anomalia e provável substituição de religador , religador 7900117013 -RDU - Paraiso .OBS: equipe DMSL Elisfran estava atualizando firmware no equipamento , porém relé parou de funcionar devido essa atualização , sendo necessário sua substituição .em campo o modelo e cooper Form6 , segundo tecnico deve ser substituído por um Noja .Repassado para o COEP para aquisição do equipamento e posterior repasse para o COCM. | M14: 15 | N14: 20 | O14: 15 | P14: 15 | Q14: 15 | R14: 0 | S14: 0 | T14: 15 | U14: 95 | V14: Muito Alta | W14: Transferência do 214R de Paraíso I, Centro Comercial de Paraíso
A15: 7929376022 | B15: 79 | C15: BABACULANDIA | D15: ARAGUAINA | E15: NORTE | F15: ETO-COEP 00120/2026 | G15: Em processo logístico | H15: Previsão de entrega 16/07 | I15: Em andamento | J15: Tanque + controle | K15: 1 | L15: PARECER COEP: PROBLEMA NO ENVIO COCM'S CONTROLE ENVIADO FOI O NOJA , DEVIDO A FALTA DO MODELO NA SS (GRAVE)PARECER DMSL: *FEEDBACK EQUIP. ESPECIAIS**Nº DO EQUIPAMENTO:* 7929376022 *DATA DA MANUTENÇÃO:* 02/04/2026*SID:* 1677/2026*DESCRIÇÃO:* Trocar controle completo*PENDÊNCIA:* Sim.*DADOS DIVERGENTES DA PROGRAMAÇÃO:* Não*BATERIA SUBSTITUÍDA?:* Não*EQUIPE:* Adeilton e Edicleber __________________________________________________________POR GENTILEZA ATENDER SOLICITAÇÃO PRIMEIRO ATAQUE IDENTIFICOU QUE RELE ESTA EM CURTO NOTA ABERTA 224/2026 FOI BAIXADA POREM NÃO FOI CORRIGIDO PROBLEMA EM CAMPO. | M15: 15 | N15: 20 | O15: 5 | P15: 15 | Q15: 15 | R15: 10 | S15: 0 | T15: 15 | U15: 95 | V15: Muito Alta | W15: Transferência de Babaçulândia, fonte principal operando
A16: 7908705049 | B16: 79 | C16: AURORA DO TOCANTINS | D16: DIANOPOLIS | E16: SUL | F16: ETO-RD-DP 00409/2026 | G16: Equipamento entregue ao COCM | H16: Previsão de substituição 20/07 | I16: Em andamento | J16: Tanque + controle | K16: 1 | L16: EQUIPAMENTO ENTREGUE, SOLICITO PREVISÃO PARA SUBSTITUIÇÃO:PARECER COEP: PREVISÃO DE ENTREGA AOS COCM'S 01/07Manutenção no RL 7908705049PARECER DMSL(28/08/2025): Equipe foi fazer manutenção no RL e constatou que o tanque e o relé do mesmo se encontra queimado, providenciar substituição.PARECER COCMS 30/04/2026CRIADO OBRA 0512600135 PARA REQUISIÇÃO MATERIAL | M16: 15 | N16: 20 | O16: 5 | P16: 15 | Q16: 15 | R16: 0 | S16: 10 | T16: 15 | U16: 95 | V16: Muito Alta | W16: Proteção da baixa do TF de força da SE Aurora
A17: 7933726256 | B17: 79 | C17: MATEIROS | D17: PONTE ALTA TOCANTINS | E17: CENTRO | F17: ETO-PROT 00145/2026 | G17: Em fase de ajustes | H17: Destinada parte ativa do RL 7900453110 | I17: Em andamento | J17: Tanque | K17: 1 | L17: 07/07 Equipamento foi substituido na OS: ETO-RD-PO 1859/2026 OBRA 031260035101/07 PARECER COEP: REDIRECIONADO PARA O POSTO DO COCM´S EQUIPAMENTO CHEGOU NO LOCAL, FAVOR ENTRAR EM CONTATO COM O DMSL, DEVIDO A URGÊNCIA DO EQUIPAMENTO EM OPERAÇÃO.30/06 PARECER COEP: DEVIDO A ALINHAMENTO COM COI UTILIZAREMOS PARTE ATIVA QUE ORIGINALMENTE FOI ENCOMENDADA PARA 7933726256PARECER DMSL: N° do Equipamento: _RLG 7933726256 MateirosTipo de Equipamento: _RLG NOJA RC 10 REL IIData: _06/05/2026SID: _2288/2026-Serviço Executado: _Equipamento com defeito na parte ativa, será necessário fazer a substituição da parte ativa e fazer melhoria na malha de terra!Equipamento ficou em operação?: _NaoPendência: _SimBateria(s) substituída(s)? NÃOData Fabricação/Instalação da(s) bateria(s):_06/2025Equipe: _Benvindo e Almir-------------------------------------------------------------------------------Religador 7933726256, sem comunicação apos primeiroa ataque não retornou as comunicação. | M17: 15 | N17: 10 | O17: 15 | P17: 15 | Q17: 15 | R17: 10 | S17: 0 | T17: 15 | U17: 95 | V17: Muito Alta | W17: Transferência da cidade de Mateiros (733 UCs) para o gerador
A18: 7933766059 | B18: 79 | C18: TAQUARALTO | D18: TAQUARALTO | E18: CENTRO | F18: ETO-TELE 01024/2026 | G18: Equipamento entregue ao COCM | H18: Previsão de substituição 16/07 | I18: Em andamento | J18: Tanque | K18: 1 | L18: PARECER DA PROTEÇÃO:RECOMISSIONAR RELIGADOR, AJUSTES DE PROTEÇÃO PERMANECEM OS MESMOS.Estagiário Rafael P Marques****************************PARECER COEP: EQUIPAMENTO ENTREGUE, SEGUE SS PARA O COCM´S , PARA REALIZAR O ATENDIMENTO,FAVOR ADICIONAR O PARECER PARA MANDAR PARA PROTEÇÃOSegue SS para verficar religador de poste 7933766059.Religador esta com defeito na parte ativa no tanque Porte gentilezaenviar equipe verificar.Endereço: TaquariPARECER DMSL: RLG 7933766059 RELÉ NOJA RC 10Mestre 2 Rep. taquaruçu GESID: 5457/2025Data: 15/10/2025Serviço Executado: Houve um curto na parte ativa do equipamento danificando a mesma, será necessário fazer a substituição somente do tanque, parte ativa.*Equipamento ficou em operação?:*Nao Pendência: Sim, substituir parte ativa.Equipe: Benvindo, Juliano e Sérgio.****** Parecer do COCM Centro***Equipámento Substituido em Campo pela Ordem de ServIÇO DLP-MPPA01 244/2026, ONDE OS RELATORIO ESTÃO ANEXADO.. | M18: 15 | N18: 20 | O18: 5 | P18: 15 | Q18: 15 | R18: 0 | S18: 10 | T18: 15 | U18: 95 | V18: Muito Alta | W18: Seccionamento de trecho do Setor Taquari
A19: 7900594026 | B19: 79 | C19: PONTE ALTA TOCANTINS | D19: PONTE ALTA TOCANTINS | E19: CENTRO | F19: ETO-PROT 000148/2026 | G19: Equipamento entregue ao COCM | H19: Previsão de substituição 10/07 | I19: Em andamento | J19: Tanque + controle | K19: 1 | L19: PARECER DA PROTEÇÃO:16/07/2026 AJUSTES DISPONIBILIZADOS NO APP DA PROTEÇÃO15/07/2026 EQUIPAMENTO SUBSTITUIDO NA OS ETO-RD-PO 1860 OBRA 031260035414/07/2026 PARECER COCM/ COEP: DE ACORDO COM O EDSON CURCINO FOI FEITA S SUBSTITUIÇÃO DO EQUIPAMENTO , SEGUE PARA PROTEÇÃO ELABORAR AJUSTE10/07 PARECER COEP: EQUIPAMENTO DESLOCADO QUE ESTAVA EM GUARAÍ FOI ALINHADO COM O VALMOR QUE SERIA SUBSTITUIDO DIA 07/07/2026 , FAVOR PASSAR PARA PROTEÇÃO 7900594026PARECER COEP: AGUARDANDO COCM'S PARA ABRIR REQUISIÇÃOPARECER DMSL 10/06/2026: Tem uma nota aberta para esse equipamento solicitando a substituição desde 20/10/2025, como a nota não foi atendida estamos repassando para área responsável. Nota em aberto repassada ETO-COEP 210/2025.Segue nota para verificar intermitência de comunicação nos religadores 7908301026 , 7911120026, 7947959026 , 7908692026, 7900594026 rural- Ponte Alta . | M19: 15 | N19: 20 | O19: 15 | P19: 15 | Q19: 15 | R19: 0 | S19: 0 | T19: 15 | U19: 95 | V19: Muito Alta | W19: Religador responsável pela proteção da barra da SE Ponte Alta (2381 UCs)
A20: 7921040031 | B20: 79 | C20: RIO DOS BOIS | D20: MIRACEMA DO TOCANTINS | E20: CENTRO | F20: CONCLUÍDA | I20: Ok | M20: 15 | N20: 20 | O20: 5 | P20: 15 | Q20: 15 | R20: 10 | S20: 0 | T20: 15 | U20: 95 | V20: Muito Alta | W20: Fonte principal de Rio dos Bois, RL de transferência operando
A21: 7957620015 | B21: 79 | C21: PEDRO AFONSO | D21: GUARAI | E21: NORTE | F21: CONCLUÍDA | I21: Ok | M21: 15 | N21: 20 | O21: 15 | P21: 15 | Q21: 15 | R21: 0 | S21: 0 | T21: 15 | U21: 95 | V21: Muito Alta | W21: Atendimento da RDU de Bom Jesus e parcial da RDU de Pedro Afonso
