Workbook

Sheet Gerencial
A1: DESTINO_SS | B1: (Vários itens) | F1: Criticidade | G1: Quantidade | I1: Total
G2: RL | H2: RT
A3: Qtd | B3: Cód | F3: Muito Alta | G3: 9 | H3: 2 | I3: =SUM(G3:H3) -> 11
A4: Criticidade | B4: 58 | C4: 79 | D4: Total Geral | F4: Alta | G4: 9 | H4: 3 | I4: =SUM(G4:H4) -> 12
A5: Muito Alta | B5: 3 | C5: 11 | D5: 14 | F5: Média | G5: 9 | H5: 4 | I5: =SUM(G5:H5) -> 13
A6: Alta | B6: 3 | C6: 6 | D6: 9 | F6: Baixa | G6: 9 | H6: 5 | I6: =SUM(G6:H6) -> 14
A7: Média | B7: 5 | C7: 10 | D7: 15 | F7: Em definição | G7: 28 | H7: 9 | I7: =SUM(G7:H7) -> 37
A8: Baixa | B8: 4 | C8: 11 | D8: 15 | F8: Total Geral | G8: 64 | H8: 23 | I8: =SUM(I3:I7) -> 87
A9: Em definição | C9: 2 | D9: 2
A10: Total Geral | B10: 15 | C10: 40 | D10: 55

Sheet Pendentes
A1: ANO_SS | B1: SS_ORIGINAL | C1: DESTINO_SS | D1: COD_RELIGADOR | E1: TIPO | F1: DTA_ABERTURA | G1: COD_LOC | H1: LOCALIDADE | I1: POLO | J1: REGIONAL | K1: ALIMENTADOR | L1: DESCRICAO | M1: Premissa 1 | N1: Premissa 2 | O1: Premissa 3 | P1: Premissa 4 | Q1: Premissa 5 | R1: Premissa 6 | S1: Premissa 7 | T1: Premissa 8 | U1: Priorização | V1: Criticidade | W1: Observação após análise
A2: 2026 | B2: ETO-RD-DP 00479/2026 | C2: ETO-RD-DP | D2: 5856070091 | E2: 58 | F2: 46230 | G2: 91 | H2: ALMAS | I2: DIANOPOLIS | J2: SUL | K2: LD04002091 | L2: PARECER DMSL: não foi regularizado a instalação do equipamento, nota repassada conforme alinhado com o supervisor.____________________________________________COCMS 26.03.26. SS REPASSADA PARA COEP PROVIDENCIAR MATERIAL. NÃO TEMOS AS PÇ EM ESTOQUE PARA FAZER A SUBSTITUIÇÃO. Solicitação de serviço para reposição de equipamentos furtados .COEP: Equipamento fornecido ao COCM-S para regularização.COCMS: Equipamento substituido conforme solicitado. Gentileza comissionar.PARECER DA PROTEÇÃO:SEGUE NOTA REPASSADA PARA DMSL COMISSIONAR.ENG° IRLLEY CASTELO BRANCOPARECER DMSL(23/09/2025): Feito a parte de comunicação, fechando enlace, configuração do rádio GE. Feito a medição de aterramento. Após uma inspeção, foi identificado que o regulador de tensão está instalado errado, carga está para o lado de fonte e fonte está do lado de carga. O certo é a fonte vim de almas, atualmente está vindo de natividade. Favor fazer a instalação correta. | M2: 40 | N2: 20 | O2: 20 | P2: 20 | Q2: 0 | R2: - | S2: - | T2: - | U2: 100 | V2: Muito Alta | W2: Atendimento da região da Engegold, Nativa, cidade Natividade e Chapada da Natividade
A3: 2026 | B3: ETO-PROT 00158/2026 | C3: ETO-PROT | D3: 5854566043 | E3: 58 | F3: 46231 | G3: 43 | H3: SILVANOPOLIS | I3: PORTO NACIONAL | J3: CENTRO | K3: LD02072001 | L3: 24/07/2026 - PARECE COCM: EQUIPAMENTO SUBSTITUIDO NA OBRA 0312600352 OS: ETO-RD-PO 1873/202622/07/2026 PARECER COEP: EQUIPAMENTO ENTREGUE AOS COCM´SPRAZO DE 7 DIAS CONTANDO O SLA.PARECER COEP: EQUIPAMENTO ENTREGUE AOS COCM´S FAVOR SUSBSTTUIR , E AGUARDO O PRAZO DE PREVISÃO DE SUBSTIUIÇÃOboa noite,segue SS para as devidas tratativas com equipe de manutenção com apoio de equipe de linha viva substituir regulador de tensão 5854566043 queimado célula fase c, LD Porto / Silvanópolis mesmo deverá ser substituído com apoio de equipe de linha viva PARECER DMSL: Foi realizado inspeção visual e ensaios de isolação, relação de transformação e resistência de enrolamento. A fase B está danificada e será necessário substituir a mesma. Malha de aterramento está relativamente boa e conectada. Fase A e C passaram nos ensaios. Substituir fase B. | M3: 40 | N3: 20 | O3: 20 | P3: 10 | Q3: 20 | R3: - | S3: - | T3: - | U3: 110 | V3: Muito Alta | W3: Aumento de reclamações no atendimento de Silvanópolis por Porto Nacional no período seco (Outra fonte com defeito também)
A4: 2026 | B4: ETO-COEP 00123/2026 | C4: ETO-COEP | D4: 7928564039 | E4: 79 | F4: 46210 | G4: 39 | H4: ARAGUATINS | I4: AUGUSTINOPOLIS | J4: NORTE | K4: LD02109039 | L4: PARECER COEP: EQUIPAMENTO SELECIONADO PARA COMPRATroca do sistema de comunicação do equipamentoDMSL 28/07/2025: Equipamento com tanque, modulo e rele com defeito, solicitar troca do equipamento ao DCMD.Fotos vão ser enviadas por e-mail | M4: 5 | N4: 10 | O4: 5 | P4: 0 | Q4: 0 | R4: 10 | S4: 0 | T4: 0 | U4: 30 | V4: Média | W4: Transferência entre 424R Araguatins e 434R Augustinópolis
A5: 2026 | B5: ETO-RD-DP 00409/2026 | C5: ETO-RD-DP | D5: 7908705049 | E5: 79 | F5: 46209 | G5: 49 | H5: AURORA DO TOCANTINS | I5: DIANOPOLIS | J5: SUL | K5: AL01015049 | L5: EQUIPAMENTO ENTREGUE, SOLICITO PREVISÃO PARA SUBSTITUIÇÃO:PARECER COEP: PREVISÃO DE ENTREGA AOS COCM'S 01/07Manutenção no RL 7908705049PARECER DMSL(28/08/2025): Equipe foi fazer manutenção no RL e constatou que o tanque e o relé do mesmo se encontra queimado, providenciar substituição.PARECER COCMS 30/04/2026CRIADO OBRA 0512600135 PARA REQUISIÇÃO MATERIAL | M5: 15 | N5: 20 | O5: 5 | P5: 15 | Q5: 15 | R5: 0 | S5: 10 | T5: 15 | U5: 95 | V5: Muito Alta | W5: Proteção da baixa do TF de força da SE Aurora
A6: 2026 | B6: ETO-COEP 00124/2026 | C6: ETO-COEP | D6: 7923673004 | E6: 79 | F6: 46210 | G6: 4 | H6: ARAGUAINA | I6: ARAGUAINA | J6: NORTE | K6: AL04010004 | L6: PARECER COEP: Verificar Disponibilidade de equipamento no Scada e enviar modelo e tensão para a compra.RELIGADOR COM RELÉ DANIFICADO, REALIZAR SUBSTITUIÇÃO | M6: 15 | N6: 20 | O6: 15 | P6: 15 | Q6: 15 | R6: 10 | S6: 0 | T6: 15 | U6: 105 | V6: Muito Alta | W6: Transferência de cargas na RDU de Araguaína (2797 UCs)
A7: 2026 | B7: ETO-COEP 00040/2026 | C7: ETO-COEP | D7: 7931608059 | E7: 79 | F7: 46077 | G7: 59 | H7: TAQUARALTO | I7: TAQUARALTO | J7: CENTRO | K7: AL05099059 | L7: PARECER COEP: EQUIPAMENTO SELECIONADO PARA COMPRADMSL:Serviço Executado: Foi feita uma análise técnica no equipamento, devido à falta de comunicação. Também foi identificado que o tanque do equipamento está danificado, sendo assim, necessário substituir o tanque e o rádio do equipamento, que está queimado, sendo necessário substituir também. | M7: 15 | N7: 20 | O7: 15 | P7: 15 | Q7: 15 | R7: 10 | S7: 0 | T7: 15 | U7: 105 | V7: Muito Alta | W7: Transferência dos bairros Morada do Sol, Vale do Sol, Morada do Sol II, Nova Esperança, Sõa João, Araras I e II e Jardim Laila em Taquaralto (6033 UCs)
A8: 2025 | B8: ETO-COEP 00184/2025 | C8: ETO-COEP | D8: 7903112004 | E8: 79 | F8: 45903 | G8: 4 | H8: ARAGUAINA | I8: ARAGUAINA | J8: NORTE | K8: LD05010004 | L8: 20/07 PARECER COEP: EQUIPAMENTO SELECIONADO PARA COMPRAApós testes no RLG 7903112004 foi constatado defeito no mesmo e como se trata de um modelo COOPER FORM6 que está obsoleto e não possuímos peças sobressalentes, faz-se necessária substituição completa por modelo NOJA RC10. | M8: 15 | N8: 10 | O8: 5 | P8: 15 | Q8: 0 | R8: 10 | S8: 0 | T8: 0 | U8: 55 | V8: Alta | W8: Transferência de Babaçulândia, 4 RLs sendo 2 operando
A9: 2026 | B9: ETO-COEP 00152/2026 | C9: ETO-COEP | D9: 7903569004 | E9: 79 | F9: 46223 | G9: 4 | H9: ARAGUAINA | I9: ARAGUAINA | J9: NORTE | K9: AL05010004 | L9: PARECER COEP 28/07/2026 : EQUIPAMENTO SELECIONADO PARA COMPRAEquipamento baypassado PARECER DMSL em 12/03: Realizar substituição do equipamento todo e parte ativa. | M9: 15 | N9: 20 | O9: 5 | P9: 15 | Q9: 15 | R9: 10 | S9: 0 | T9: 15 | U9: 95 | V9: Muito Alta | W9: Transferência dos bairros JD Santa Helena, Jd Filadelfiae Setor Caraja em Araguaína (2053 UCs), AL 254R de AR I e AL 214R de AR III
A10: 2026 | B10: ETO-COEP 00131/2026 | C10: ETO-COEP | D10: 7947203070 | E10: 79 | F10: 46211 | G10: 70 | H10: RIO SONO | I10: TAQUARALTO | J10: CENTRO | K10: LD02424015 | L10: 13/07 PARECER COEP: SELECIONADO PARA COMPRA CONTROLE favor verificar RL 7947203070, sem comunicaçao, feito 1° ataque pela equipe 070OP01 e nao retornou a comunicaçao , linformaçao no Scada de bateria.PARECER DMSL: Foi feito análise técnica, a placa do equipamento está queimada nessesario subistituir o equipamento completo -Carliel e Benvindo-05/02 | M10: 10 | N10: 20 | O10: 15 | P10: 15 | Q10: 15 | R10: 10 | S10: 0 | T10: 15 | U10: 100 | V10: Muito Alta | W10: Transferência da RDU de Lizarda (1650 UCs) para fonte alternativa
A11: 2026 | B11: ETO-TELE 01040/2026 | C11: ETO-TELE | D11: 5800371025 | E11: 58 | F11: 46233 | G11: 25 | H11: ARAPOEMA | I11: COLINAS DO TOCANTINS | J11: NORTE | K11: LD02010153 | L11: 16/07/2026 PARECER COEP: ALINHADO COM O KELLITON REALIZAR SUBSTITUIÇÃO DO CONTROLE DE TUPIRAMA, ALINHADO COM O JEAN QUE OS CABOS COMPATIBILIZADORES VÃO CHEGAR 16/08 , ATÉ ESSA DATA MANTER ESSA SS E CONTROLE RUA, DEPOIS REPASSAR PARA O DMSLPARECER COEP: AVALIAR COM O LEANDRO, PROVAVELMENTE SÓ COMPRAPARECER DMSL: Após testes foi constatado defeito nos relés da fase A e B, Modelo Toshiba TBR 1000. Se possível, substituir os relés das 3 fases por controle RUA, disponibilizar os cabos de ligação entre o tanque e o controle para possibilitar a compatibilização do equipamento. Fornecer kit de comunicação, rádio, antena, etc.Segue nota para veriifcar falha em regulador de tensão N: 5800371025 dentro S/E Arapoema , equipamento esta com 2 reles com falha marca toshiba .Parecer DCMD: foi substituido célula 30/07/2026. o mesmo está liberado para ser colocado em operação | M11: 0 | N11: 20 | O11: 20 | P11: 10 | Q11: 20 | R11: - | S11: - | T11: - | U11: 70 | V11: Alta | W11: Aumento de reclamações no atendimento de Arapoema no período seco
A12: 2026 | B12: ETO-COEP 00156/2026 | C12: ETO-COEP | D12: 5855411017 | E12: 58 | F12: 46227 | G12: 17 | H12: BARROLANDIA | I12: MIRACEMA DO TOCANTINS | J12: CENTRO | K12: AL02017017 | L12: 20/07 PARECER COCM: NÃO RECEBEMOS MATERIAL10/07 PARECER COEP: EQUIPAMENTO ENTREGUE AOS COCM´S FAVOR INFORMAR PRAZO DE SUBSTUIÇÃO PARA O DMSL E REPASSAR DEPOIS PARA PROTEÇÃO REALIZAR OS AJUSTES E DESCREVER NA SS O SERVIÇO REALIZADOPARECER COEP: EQUIPAMENTO EM ROTA DE ENTREGASEM COMUNICAÇÃO, FALHA DE ALIMENTAÇÃO - REALIZADO PRIMEIRO ATAQUE SEM SUCESSO.PARECER DMSL: 17/09/2025 Equipamento ficou em operação? Não Pendência: sim. Equipamento ficou Bay passado levar controle COMPLETO para trocar. ellisfran | M12: 0 | N12: 0 | O12: 0 | P12: 10 | Q12: 20 | R12: - | S12: - | T12: - | U12: 30 | V12: Baixa | W12: Atendimento do Assentamento Irmã Adelaide
A13: 2026 | B13: ETO-COEP 00059/2026 | C13: ETO-COEP | D13: 7925744087 | E13: 79 | F13: 46111 | G13: 87 | H13: GOIANORTE | I13: GUARAI | J13: NORTE | K13: LD02022033 | L13: PARECER COEP: EQUIPAMENTO SELECIONADO PARA COMPRAPARECER DMSL: FEEDBACK EQUIP. ESPECIAISNº DO EQUIPAMENTO: 7925744087TIPO EQUIPAMENTO: Noja RC 10TIPO DE COMUNICAÇÃO: Radio GE IPDATA DA MANUTENÇÃO: 19/02/2026SID: 735/2026 DESCRIÇÃO: foi identificado água dentro da parte interna do tanque e cabo umbilical encharcado de água foi passado essas informações para COS.FICOU EM OPERAÇÃO?: Não PENDÊNCIA: Sim substituir tanque e cabo umbilicalDADOS DIVERGENTES DA PROGRAMAÇÃO: NãoBATERIA SUBSTITUÍDA?: Não DATA DA BATERIA: 07/05/2025TIPO DE BATERIA: Lítio EQUIPE: Edeglan e Janio-------------------------------------------------------------------------------------------------RELIGADOR SEM COMUNICAÇÃO, APOS PRIMEIRO ATAQUE RETORNA E FICAR INDEFINIDO. | M13: 15 | N13: 20 | O13: 5 | P13: 15 | Q13: 15 | R13: 10 | S13: 0 | T13: 15 | U13: 95 | V13: Muito Alta | W13: Transferência de Goianorte, fonte principal operando
A14: 2026 | B14: ETO-COEP 00168/2026 | C14: ETO-COEP | D14: 7908196047 | E14: 79 | F14: 46237 | G14: 47 | H14: FIGUEIROPOLIS | I14: FORMOSO DO ARAGUAIA | J14: SUL | K14: AL02033047 | L14: 03/08/2026 PARECER DMSL: FOI CONFIRMADO PELO VONES DO DCMD QUE O EQUIPAMENTO AINDA NÃO FOI SUBSTITUÍDO. FAVOR, APÓS SUBSTITUIÇÃO, REPASSAR A NOTA PARA A PROTEÇÃO PARA REVISAR OS AJUSTES, POIS TRATA-SE DE ALTERAÇÃO DO MODELO DO EQUIPAMENTO.13/07/2026 PARECER COEP: EQUIPAMENTO REMANEJADO FAVOR FAZER O COMISSIONAMENTORELIGADOR N° 7908196047 REMANEJADO NA OBRA 0402401150 GENTILEZA, REALIZAR O COMISSIONAMENTO. LAUDO EM ANEXO. COORD EO: 698485, 8657287PARECER DA PROTEÇÃO:AJUSTE DISPONIBILIZADO NO APP DA PROTEÇÃO, NOTA REPASSADA PARA DMSL COMISSIONAR, POLO GURUPI, RL APENAS REMANEJADO DA REDE VELHA PARA REDE NOVA, EQUIPAMENTO COOPER, SE MANTEVE O MESMO NÚMERO DE ATIVO.ENG° IRLLEY CASTELO BRANCO.PARECER DMSL: Constatado curto-circuito no tanque do religador, impedindo as operações de abertura e fechamento do equipamento. Solicita-se a substituição completa do religador, incluindo tanque e unidade de controle. | M14: 5 | N14: 5 | O14: 5 | P14: 0 | Q14: 0 | R14: 0 | S14: 10 | T14: 0 | U14: 25 | V14: Baixa | W14: Seccionamento do Rural e energização do 224R
A15: 2026 | B15: ETO-PROT 00154/2026 | C15: ETO-PROT | D15: 7900117013 | E15: 79 | F15: 46224 | G15: 13 | H15: PARAISO DO TOCANTINS | I15: PARAISO DO TOCANTINS | J15: CENTRO | K15: AL01062013 | L15: 15/07 PARECER COCM: EQUIPAMENTO FOI SUBSTITUÍDO OBRA 021260042210/07 PARECER COEP: EQUIPAMENTO ENTREGUE AOS COCM´S FAVOR INFORMAR PRAZO DE SUBSTUIÇÃO PARA O DMSL E REPASSAR DEPOIS PARA PROTEÇÃO REALIZAR OS AJUSTES E DESCREVER NA SS O SERVIÇO REALIZADOPARECER COEP: PREVISÃO DE ENTREGA AOS COCM'S 01/07Segue nota para correção de anomalia e provável substituição de religador , religador 7900117013 -RDU - Paraiso .OBS: equipe DMSL Elisfran estava atualizando firmware no equipamento , porém relé parou de funcionar devido essa atualização , sendo necessário sua substituição .em campo o modelo e cooper Form6 , segundo tecnico deve ser substituído por um Noja .Repassado para o COEP para aquisição do equipamento e posterior repasse para o COCM. | M15: 15 | N15: 20 | O15: 15 | P15: 15 | Q15: 15 | R15: 0 | S15: 0 | T15: 15 | U15: 95 | V15: Muito Alta | W15: Transferência do 214R de Paraíso I, Centro Comercial de Paraíso
A16: 2026 | B16: ETO-PROT 00153/2026 | C16: ETO-PROT | D16: 7900573047 | E16: 79 | F16: 46223 | G16: 47 | H16: FIGUEIROPOLIS | I16: FORMOSO DO ARAGUAIA | J16: SUL | K16: AL02033047 | L16: 10/07 PARECER COEP: EQUIPAMENTO ENTREGUE AOS COCM´S FAVOR INFORMAR PRAZO DE SUBSTUIÇÃO PARA O DMSL E REPASSAR DEPOIS PARA PROTEÇÃO REALIZAR OS AJUSTES E DESCREVER NA SS O SERVIÇO REALIZADOPARECER COEP: AGUARDANDO COCM'S GERAREM AS OBRAS PARA PODER ENTREGAR MATERIALFavor providenciar manutenção no RL 7900573047, o mesmo estar em curto conforme fotos anexadas. Equipamento ficou bay passado em campo.PARECER DMSL: Equipe: FABIO AP./JOÃO MARCOSData Executada: 15/10/2025Serviço Executado:Foi constatado que o equipamento esta queimado na parte ativa placa, tanque e relé. Por favor fazer a substituição pelo Noja RC10. | M16: 5 | N16: 5 | O16: 15 | P16: 0 | Q16: 15 | R16: 10 | S16: 0 | T16: 15 | U16: 65 | V16: Alta | W16: Transferência da Bunge, Saneatins e secadora
A17: 2026 | B17: ETO-TELE 01107/2026 | C17: ETO-TELE | D17: 7929376022 | E17: 79 | F17: 46247 | G17: 22 | H17: BABACULANDIA | I17: ARAGUAINA | J17: NORTE | K17: LD05010004 | L17: 13/08/2026 PARECER COEP: EQUIPAMENTO FOI TROCADO A PEÇA , CONFIRMAMOS COM O LEONARDO DE ARAGUAÍNA , LAUDO EM ANEXO , FAVOR REALIZAR COMISSIONAMENTOPARECER COEP: PROBLEMA NO ENVIO COCM'S CONTROLE ENVIADO FOI O NOJA , DEVIDO A FALTA DO MODELO NA SS (GRAVE)PARECER DMSL: *FEEDBACK EQUIP. ESPECIAIS**Nº DO EQUIPAMENTO:* 7929376022 *DATA DA MANUTENÇÃO:* 02/04/2026*SID:* 1677/2026*DESCRIÇÃO:* Trocar controle completo*PENDÊNCIA:* Sim.*DADOS DIVERGENTES DA PROGRAMAÇÃO:* Não*BATERIA SUBSTITUÍDA?:* Não*EQUIPE:* Adeilton e Edicleber __________________________________________________________POR GENTILEZA ATENDER SOLICITAÇÃO PRIMEIRO ATAQUE IDENTIFICOU QUE RELE ESTA EM CURTO NOTA ABERTA 224/2026 FOI BAIXADA POREM NÃO FOI CORRIGIDO PROBLEMA EM CAMPO. | M17: 15 | N17: 20 | O17: 5 | P17: 15 | Q17: 15 | R17: 10 | S17: 0 | T17: 15 | U17: 95 | V17: Muito Alta | W17: Transferência de Babaçulândia, fonte principal operando
A18: 2025 | B18: ETO-COEP 00221/2025 | C18: ETO-COEP | D18: 5800961074 | E18: 58 | F18: 45996 | G18: 74 | H18: DIANOPOLIS | I18: DIANOPOLIS | J18: SUL | K18: LD03028074 | L18: PARECER COEP: EQUIPAMENTO SELECIONADO PARA COMPRASubstituir as 3 células- Melhoria na malha de aterramento - Melhoria no circuito de aterramento qua aterra as células.- Substituir conectores paralelos | M18: 20 | N18: 0 | O18: 0 | P18: 20 | Q18: 0 | R18: - | S18: - | T18: - | U18: 40 | V18: Média | W18: Atendimento da COELBA e GA Alessandro Maurício (1600 kVA)
A19: 2026 | B19: ETO-SE-PCM 00092/2026 | C19: ETO-SE-PCM | D19: 7933726256 | E19: 79 | F19: 46251 | G19: 256 | H19: MATEIROS | I19: PONTE ALTA TOCANTINS | J19: CENTRO | K19: LD03046026 | L19: 17/08/2026 PARECER DA PROTEÇÃO:NOTA REPASSADA PARA DMSL COMISSIONARENG° IRLLEY CASTELO BRANCO07/07 Equipamento foi substituido na OS: ETO-RD-PO 1859/2026 OBRA 031260035101/07 PARECER COEP: REDIRECIONADO PARA O POSTO DO COCM´S EQUIPAMENTO CHEGOU NO LOCAL, FAVOR ENTRAR EM CONTATO COM O DMSL, DEVIDO A URGÊNCIA DO EQUIPAMENTO EM OPERAÇÃO.30/06 PARECER COEP: DEVIDO A ALINHAMENTO COM COI UTILIZAREMOS PARTE ATIVA QUE ORIGINALMENTE FOI ENCOMENDADA PARA 7933726256PARECER DMSL: N° do Equipamento: _RLG 7933726256 MateirosTipo de Equipamento: _RLG NOJA RC 10 REL IIData: _06/05/2026SID: _2288/2026-Serviço Executado: _Equipamento com defeito na parte ativa, será necessário fazer a substituição da parte ativa e fazer melhoria na malha de terra!Equipamento ficou em operação?: _NaoPendência: _SimBateria(s) substituída(s)? NÃOData Fabricação/Instalação da(s) bateria(s):_06/2025Equipe: _Benvindo e Almir-------------------------------------------------------------------------------Religador 7933726256, sem comunicação apos primeiroa ataque não retornou as comunicação. | M19: 15 | N19: 10 | O19: 15 | P19: 15 | Q19: 15 | R19: 10 | S19: 0 | T19: 15 | U19: 95 | V19: Muito Alta | W19: Transferência da cidade de Mateiros (733 UCs) para o gerador
A20: 2026 | B20: ETO-COEP 00024/2026 | C20: ETO-COEP | D20: 7933585074 | E20: 79 | F20: 46049 | G20: 74 | H20: DIANOPOLIS | I20: DIANOPOLIS | J20: SUL | K20: LD03028074 | L20: 30/06 PARECER COEP: EQUIPAMENTO SELECIONADO PARA COMPRAREALIZAR SUBSTITUIÇÃO DO TANQUE, O MESMO ESTÁ COM DEFEITO. | M20: 5 | N20: 5 | O20: 15 | P20: 0 | Q20: 0 | R20: 0 | S20: 10 | T20: 0 | U20: 35 | V20: Média | W20: Atendimento da COELBA
A21: 2026 | B21: ETO-SE-PA 00107/2026 | C21: ETO-SE-PA | D21: 7900594026 | E21: 79 | F21: 46219 | G21: 26 | H21: PONTE ALTA TOCANTINS | I21: PONTE ALTA TOCANTINS | J21: CENTRO | K21: LD03046026 | L21: PARECER DA PROTEÇÃO:16/07/2026 AJUSTES DISPONIBILIZADOS NO APP DA PROTEÇÃO15/07/2026 EQUIPAMENTO SUBSTITUIDO NA OS ETO-RD-PO 1860 OBRA 031260035414/07/2026 PARECER COCM/ COEP: DE ACORDO COM O EDSON CURCINO FOI FEITA S SUBSTITUIÇÃO DO EQUIPAMENTO , SEGUE PARA PROTEÇÃO ELABORAR AJUSTE10/07 PARECER COEP: EQUIPAMENTO DESLOCADO QUE ESTAVA EM GUARAÍ FOI ALINHADO COM O VALMOR QUE SERIA SUBSTITUIDO DIA 07/07/2026 , FAVOR PASSAR PARA PROTEÇÃO 7900594026PARECER COEP: AGUARDANDO COCM'S PARA ABRIR REQUISIÇÃOPARECER DMSL 10/06/2026: Tem uma nota aberta para esse equipamento solicitando a substituição desde 20/10/2025, como a nota não foi atendida estamos repassando para área responsável. Nota em aberto repassada ETO-COEP 210/2025.Segue nota para verificar intermitência de comunicação nos religadores 7908301026 , 7911120026, 7947959026 , 7908692026, 7900594026 rural- Ponte Alta . | M21: 15 | N21: 20 | O21: 15 | P21: 15 | Q21: 15 | R21: 0 | S21: 0 | T21: 15 | U21: 95 | V21: Muito Alta | W21: Religador responsável pela proteção da barra da SE Ponte Alta (2381 UCs)
A22: 2026 | B22: ETO-COEP 00151/2026 | C22: ETO-COEP | D22: 5840227063 | E22: 58 | F22: 46223 | G22: 63 | H22: BANDEIRANTES DO TOCANTINS | I22: COLINAS DO TOCANTINS | J22: NORTE | K22: LD01054060 | L22: PARECER COEP 27/07/2026 : EM PROCESSO DE AQUISIÇÃOPARECER DMSL 13/07/2026: Realizados ensaios de isolação nas três células, e foi identificado curto na fase A, sendo necessário a sua substituição. Os cabos das buchas ficaram desconectados para melhor identificação no momento da sua substituiçãSEGUE PARA O DMSL AVALIAR ANTES DE SEGUIRMOS COM O SERVIÇOSEGUE PARA REALIZAR TROCA---------------------------------------------------------Boa noite,Segue SS para tratativas regulador de tensão 5840227063 fase C em curto | M22: 0 | N22: 20 | O22: 20 | P22: 10 | Q22: 10 | R22: - | S22: - | T22: - | U22: 60 | V22: Média | W22: Atendimento da RDU Bandeirantes e clientes rurais
A23: 2026 | B23: ETO-COEP 00061/2026 | C23: ETO-COEP | D23: 7901110084 | E23: 79 | F23: 46112 | G23: 84 | H23: DIVINOPOLIS | I23: DIVINOPOLIS | J23: CENTRO | K23: LD04062013 | L23: PARECER COEP: EQUIPAMENTO SELECIONADO PARA COMPRAPARECER DMSL: Serviço Executado: Foi feito análise técnica, testes funcionais e identificado que a parte ativa do equipamento está com defeito. Necessário substituir a parte ativa.FICOU EM OPERAÇÃO? Não- EQUIPE: Carliel e BenvindoSegue SS para verificaçao Rl esta danificado dando passagem de tensão mesmo aberto Sim, quando retornar trazer uma fonte pois a mesma foi removida. | M23: 5 | N23: 5 | O23: 0 | P23: 0 | Q23: 0 | R23: 0 | S23: 10 | T23: 0 | U23: 20 | V23: Baixa | W23: Localizado na fonte principal de atendimento de Divinópolis e Abreulândia
A24: 2026 | B24: ETO-COEP 00133/2026 | C24: ETO-COEP | D24: 7955986084 | E24: 79 | F24: 46211 | G24: 84 | H24: DIVINOPOLIS | I24: DIVINOPOLIS | J24: CENTRO | K24: LD04062013 | L24: 14/07/2026 PARECER COEP : SUBSTIUIR CONTROLE COMPLETOPARECER DMSL: Equipamento com a placa de alimentação ca em curto, será necessário substituir a placa do equipamento. (Antiga nota era pra ter sido repassada porém foi baixada indevidamente pela equipe) | M24: 5 | N24: 5 | O24: 0 | P24: 0 | Q24: 15 | R24: 10 | S24: 0 | T24: 0 | U24: 35 | V24: Média | W24: Transferência de cargas do 444R da SE Paraíso I
A25: 2026 | B25: ETO-COEP 00141/2026 | C25: ETO-COEP | D25: 7927413001 | E25: 79 | F25: 46216 | G25: 1 | H25: PORTO NACIONAL | I25: PORTO NACIONAL | J25: CENTRO | K25: LD01072001 | L25: 22/07/2026 EQUIPAMENTO SLEECIONADO PARA COMPRAPARECER DMSL: *Segue feedback**Equipamento:* RLG 7927413001 *RELÉ TAVRIDA*Data:* 16/04/2026*SID:* 1817/2026*Serviço executado:* Placa de alimentação do equipamento com defeito, VERIFICAR SE É POSSIVEL substituir o equipamento completo.*Equipamento ficou em operação?*_Não*Pendência:*_Sim*Bateria(s) substituída(s)?*_Nao *Equipe:* Benvindo e Kaique-------------------------------------------------------------------------------------------------Religador 7927413001 sem comunicação foi realizado primeiro ataque porem a comunicação não retornou. Favor enviar equipe para devidas trattivas | M25: 15 | N25: 5 | O25: 15 | P25: 15 | Q25: 15 | R25: 10 | S25: 0 | T25: 15 | U25: 90 | V25: Muito Alta | W25: Transferência do Distrito Ind de Porto Nacional e GAs
A26: 2026 | B26: ETO-PROT 00159/2026 | C26: ETO-PROT | D26: 7908686014 | E26: 79 | F26: 46231 | G26: 14 | H26: PIUM | I26: PARAISO DO TOCANTINS | J26: CENTRO | K26: LD02025012 | L26: 24/07 PARECER COCM: EQUIPAMENTO FOI SUBSTITUIDO OBRA 021260042510/07 PARECER COEP: EQUIPAMENTO ENTREGUE AOS COCM´S FAVOR INFORMAR PRAZO DE SUBSTUIÇÃO PARA O DMSL E REPASSAR DEPOIS PARA PROTEÇÃO REALIZAR OS AJUSTES E DESCREVER NA SS O SERVIÇO REALIZADO06/07 PARECER COEP: PREVISÃO DE ENTREGA DE ACORDO COM CALENDÁRIO LOGISITCO NOVO 06/07NOTA DMSL: Favor substituir o tanque, ele não está efetuando os comandos enviados. Não substituir o controle pois o mesmo funciona como repetidor de outros equipamentos.Segue nota para verificar falha de fechamento religador 7908686014- Pium .OBS: equipamento não fechou local e remoto , fica sinalizando no painel para verificar alarmes ! | M26: 15 | N26: 20 | O26: 0 | P26: 15 | Q26: 15 | R26: 10 | S26: 0 | T26: 15 | U26: 90 | V26: Muito Alta | W26: Fonte principal de Pium, RL de transferência operando
A27: 2026 | B27: ETO-SE-PCM 00091/2026 | C27: ETO-SE-PCM | D27: 5865120195 | E27: 58 | F27: 46251 | G27: 195 | H27: CENTENARIO | I27: GUARAI | J27: NORTE | K27: LD01065015 | L27: PARECER DMSL:PENDÊNCIA: Realizar melhoria no aterramento por ser tratar de um terreno muito arenoso, e há pendências por parte do time da proteção, os ajustes do RT não estão disponíveis para inserção no referido equipamento.DATA DA MANUTENÇÃO: 12/03/202EQUIPE: Brunno e Edeglan.***********************PARECER DA PROTEÇÃO - 17/08/2026:FAVOR COMISSIONAR REGULADOR 5865120195 – LD Santa Maria Ramal Centenário e Recursolândia – 34,5kV. AJUSTE REALIZADO, DISPONÍVEL NO APP DA PROTEÇÃO.*********************** INSTALADO NA OBRA 0702400720 GENTILEZA, REALIZAR O COMISSIONAMENTO.LAUDO EM ANEXO.COORD EO: 889017, 901685708-07-2026 PARECER: FOI FEITO A MELHORIA NO REGULADOR CONFORME FOTOS EM ANEXO. | M27: 20 | N27: 20 | O27: 20 | P27: 10 | Q27: 0 | R27: - | S27: - | T27: - | U27: 70 | V27: Alta | W27: Atendimento das RDUs de Centenário, Recursolândia e clientes rurais
A28: 2026 | B28: ETO-COEP 00169/2026 | C28: ETO-COEP | D28: 5800440256 | E28: 58 | F28: 46240 | G28: 256 | H28: MATEIROS | I28: PONTE ALTA TOCANTINS | J28: CENTRO | K28: LD03046026 | L28: PARECER DMSL 06/08: Substituir célula da Fase B do banco de Regulador de tensão e realizar melhorias na malha de aterramento do ReguladorBoa noite,Segue SS para as devidas tratativas, verificar flutuação de tensão do regulador 5800440256 pois a tensão está oscilando de 16kv a 23kv favor verificar esta anomalia pois cliente BRK está abrindo reclamação todas as noites. | M28: 20 | N28: 20 | O28: 20 | P28: 10 | Q28: 20 | R28: - | S28: - | T28: - | U28: 90 | V28: Muito Alta | W28: Aumento de reclamações no atendimento de São Felix e Mateiros no período seco
A29: 2026 | B29: ETO-TELE 00896/2026 | C29: ETO-TELE | D29: 7943790134 | E29: 79 | F29: 46183 | G29: 134 | H29: ESPERANTINA | I29: AUGUSTINOPOLIS | J29: NORTE | K29: LD02109039 | L29: PARECER DCMD:Serviço realizado , substituição da parte ativa do RELIGADOR 7943790134 - Favor realizar comissionamento | M29: 15 | N29: 10 | O29: 5 | P29: 15 | Q29: 15 | R29: 10 | S29: 0 | T29: 15 | U29: 85 | V29: Muito Alta | W29: Transferência de Esperantina, fonte principal operando
A30: 2026 | B30: ETO-COEP 00045/2026 | C30: ETO-COEP | D30: 7927396052 | E30: 79 | F30: 46083 | G30: 52 | H30: FORMOSO DO ARAGUAIA | I30: FORMOSO DO ARAGUAIA | J30: SUL | K30: LD03036052 | L30: PARECER COEP: EQUIPAMENTO SELECIONADO PARA COMPRAreligador foi bay passado devido mesmo esta saindo fumaca do painel e sem comunicação 7927396052.PARECER DMSL: Após testes, equipe DMSL constatou que apenas o tanque do RLG 7927396052 encontra-se queimado. Favor, substituir parte ativa do equipamento.NS Tanque: 0320123040198 | M30: 5 | N30: 5 | O30: 0 | P30: 0 | Q30: 15 | R30: 10 | S30: 0 | T30: 0 | U30: 35 | V30: Média | W30: Equipamento localizado Fonte principal de atendimento a SE Cobrape
A31: 2026 | B31: ETO-COEP 00087/2026 | C31: ETO-COEP | D31: 7900453110 | E31: 79 | F31: 46139 | G31: 110 | H31: SANTA RITA DO TOCANTINS | I31: PORTO NACIONAL | J31: CENTRO | K31: LD03040003 | L31: 10/07/2026 EQUIPAMENTO SELECIONADO PARA COMPRA PARTE ATIVA30/06.PARECER COEP: ALINHADO COM O ALLAN REMANEJAMOS PARTE ATIVA PARA ATENDER 7933726256PARECER COEP: Aproveitar controle cooper se possível em outro local, previsão de chegada do material dia 01/07 para substituiçãoFavor verificar o RL 7900453110, pois o mesmo aceita comando de fechamento, porém fecha em campo e no SCADA continua aberto e só abre através de equipe em campo. Parecer Dmsl:Equipamento está com defeito na parte ativa, não aceita o comando de fechamento. Será necessário substituir o equipamento completo.Equipamento ficou em operação?: _SIM_a pedido do COS ficou em operação, a operação está ciente da necessidade de substituir.Pendência: Sim, será necessário substituir o equipamento. | M31: 15 | N31: 10 | O31: 5 | P31: 15 | Q31: 15 | R31: 10 | S31: 0 | T31: 15 | U31: 85 | V31: Muito Alta | W31: Transferência de Santa Rita, fonte principal operando
A32: 2026 | B32: ETO-COEP 00048/2026 | C32: ETO-COEP | D32: 7925871077 | E32: 79 | F32: 46097 | G32: 77 | H32: GOIATINS | I32: ARAGUAINA | J32: NORTE | K32: LD03105019 | L32: 27/07 PARECER COEP: EM PROCESSO DE AQUISIÇÃOPARECER DMSL: A PEDIDO DA PCM DO NORTE LARA SOARES REALIZEI A CRIAÇÃO DESSA SS, EM RAZAO DA ANTIGAETO-TELE 337/2026 QUE FOI BAIXADA POR ENGANO DE TAL FORMA SEGUE A MESMA PARA REALIZAR AS TRATATIVAS. PENDENCIA: Religador continua by passado, equipamento está com defeito na parte ativa | M32: 15 | N32: 10 | O32: 15 | P32: 15 | Q32: 15 | R32: 10 | S32: 0 | T32: 0 | U32: 80 | V32: Muito Alta | W32: Transferência de Goiatins e GAs (2492 UCs)
A33: 2026 | B33: ETO-COEP 00063/2026 | C33: ETO-COEP | D33: 7944559149 | E33: 79 | F33: 46112 | G33: 149 | H33: CASEARA | I33: DIVINOPOLIS | J33: CENTRO | K33: LD01434149 | L33: 14/07/2026 PARECER COEP: EQUIPAMENTO SELECIONADO PARA COMPRA Equipamento ficou em operação?: NãoPendência: Sim será necessário substituir a placaServiço Executado: curto na placa foi tentando recuperar a mesma porém não teve sucesso!Bateria(s)substituída(s)? NÃOEquipe: Kaique e benvido | M33: 5 | N33: 10 | O33: 0 | P33: 0 | Q33: 15 | R33: 10 | S33: 0 | T33: 0 | U33: 40 | V33: Média | W33: Atendimento de cargas rurais entre Caseara e Araguacema (221 UCs)
A34: 2026 | B34: ETO-COEP 00149/2026 | C34: ETO-COEP | D34: 5803327001 | E34: 58 | F34: 46223 | G34: 1 | H34: PORTO NACIONAL | I34: PORTO NACIONAL | J34: CENTRO | K34: AL01102271 | L34: 01/07 PARECER COEP: FOI CONFIRMADO COM A OPERAÇÃO QUE O EQUIPAMENTO SEGUIU O FLUXO INTEIRO DE COMISSIONAMENTO, PROTEÇÃO, FAVOR EXPLICAR O QUE FOI REALIZADO E SE EQUIPAMENTO ESTÁ OPERANDO, SENÃO ESTIVER EXPLICAR O QUE FOI FEITO NELE30/06PARECER COEP: REPASSAR DIRETAMENTE PARA OS COCM'SRegulador 5803327001 fora de operação, by passado em campo com painel de comunicação com cabos desconectados tensão 13.8.parecer DMSL: Feedback Equip. EspeciaisRT 5803327001RELÉ RUASid: 4844Data: 19/09/2025Serviço realizado:*Equipamento foi remanejado, 7 km da sua localização sentido Palmas necessário comissionamento completo*Equipamento com um dos cabos umbilicais danificado.* aterramento bucha FC não esta interligada corretamente * para-raios estão no mesmo aterramento da bucha FC.* Tranques muito alto e próximo da rede não permitindo o comissionamento com segurança.* Controle alto demais tem que baixar Equipamento ficou em operação?: nãoPendência: sim, precisa comissionar completoOBS | M34: 40 | N34: 0 | O34: 0 | P34: 20 | Q34: 20 | R34: - | S34: - | T34: - | U34: 80 | V34: Alta | W34: Em caso de perca da fonte principal é necessário esse RT para alimentação da Frísia
A35: 2026 | B35: ETO-SE-PCM 00090/2026 | C35: ETO-SE-PCM | D35: 7900230155 | E35: 79 | F35: 46251 | G35: 155 | H35: PALMEIRANTE | I35: COLINAS DO TOCANTINS | J35: NORTE | K35: LD02105019 | L35: PARECER DA PROTEÇÃO - 17/08/2026:SEGUE NOTA PARA COMISSIONAMENTO JUNTO COM TIME SCADA, EQUIPAMENTO JA NO DESENHO ADMS.ENG° IRLLEY CASTELO BRANCO07/07/2026 PARECER COEP: MATERIAL ENVIADO , CONFORME ALINHANDO COM O WANDER REALIZAR SUBSTIUIÇÂO DO EQUIPAMENTO, FAVOR ESCREVER PARECER COCM ANTES DE PASSAR PARA PROTEÇÂO, DO QUE FOI REALIZADO01/07/2026 PARECER COEP: PROBLEMA NO ENVIO DO MATERIAL PARECER DMSL: Religador está com o tanque danificado. Não responde a comandos abertura e fechamento local ou remoto, pois está com sinal de curto circuito. Necessário trocar o equipamento. Para raio do trafo está queimado. Chave de saída da fase C está com o olhal quebrado, necessário substituir a chave. Equipamento ficou bypassado em campo. Aberto entrada e saída, com exceção da fase C de saída que ficou fechada. Favor, substituir equipamento completo por NOJA RC10 e sanar demais pendencias.Senhores Favor verificar RL 7900230155 o mesmo sinalizou aberto no SCADA porem a cidade de Palmeirante estava normal , feito um reset no rl e o mesmo subiu fechado.08/07/2026 PARECER DCMD: EQUIPE ETO-LVGR01 DE GUARAI ESTEVE NO RL 7900230155 DIA 25-06-2026 E FEZ TODAS A PENDENCIAS DO RL, OBS: EQUIPE SO NAO CONECTOU O CABO DO TRAFO NO RL. RL ESTA PRONTO PARA O COMISSIONAMENTO | M35: 15 | N35: 20 | O35: 5 | P35: 15 | Q35: 0 | R35: 10 | S35: 0 | T35: 15 | U35: 80 | V35: Muito Alta | W35: Fonte principal de Palmeirante, RL de transferência operando
A36: 2026 | B36: ETO-COEP 00114/2026 | C36: ETO-COEP | D36: 7913662076 | E36: 79 | F36: 46183 | G36: 76 | H36: DUERE | I36: GURUPI | J36: SUL | K36: AL01031076 | L36: 27/07 PARECER COEP: TANQUE DANIFICADO DA 13,5Aberto nota para substituir tanque danificado e chave de entrada fase B danificadaPARECER DMSL: Foi confirmado pela equipe DMSL o defeito do tanque, favor seguir com a substituição e correção da chave de entrada fase B danificada. | M36: 5 | N36: 5 | O36: 0 | P36: 0 | Q36: 0 | R36: 10 | S36: 0 | T36: 0 | U36: 20 | V36: Baixa | W36: Atendimento do Ramal do Bacuri (168 UCs)
A37: 2026 | B37: ETO-PROT 00165/2026 | C37: ETO-PROT | D37: 7908708116 | E37: 79 | F37: 46246 | G37: 116 | H37: CHAPADA DA NATIVIDADE | I37: DIANOPOLIS | J37: SUL | K37: LD04002091 | L37: COCMS: 12/08/2026PART ATIVA DO RELIGADOR FOI SUBSTITUIDA.GENTILEZA COMISSIONAR EQUIPAMENTO. SUBSTITUIR PARTE ATIVA DO RELIGADOR 7908708116. LV. ABRIR JUNTE DE ENTRADA E SAIDA DO RELIGADOR PARA POSSIBILITAR SUBSTITUIÇÃO DO MESMO. | M37: 5 | N37: 5 | O37: 0 | P37: 0 | Q37: 0 | R37: 0 | S37: 10 | T37: 0 | U37: 20 | V37: Baixa | W37: Atendimento do PA Xobo (194 UCs)
A38: 2026 | B38: ETO-COEP 00078/2026 | C38: ETO-COEP | D38: 7926089013 | E38: 79 | F38: 46135 | G38: 13 | H38: PARAISO DO TOCANTINS | I38: PARAISO DO TOCANTINS | J38: CENTRO | K38: LD03062013 | L38: PARECER COEP: EQUIPAMENTO SELECIONADO PARA COMPRAPARECER DMSL: Feedback Equip. EspeciaisRLG 7926089013,RELÉ NOJA RC10SID 1805/2026DATA 15/04/2026Serviço Executado: Favor realizar a troca da parte ativa do equipamento --reprogramar para atualizar a base juntamente com escada Equipamento ficou em operação: Não Pendência: sim atualizar a base e subistituir o tanque Bateria(s) substituída(s)? Não Data de Fabricação/Instalação da(s) bateria(s): Equipe: Carliel e João Vitor Fernando e Elson---------------------------------------------------------------------------------ATUALIZAR AJUSTES DO RL 7926089013 LD PARAISO I A PIUM. IMPLEMENTAÇÃO DA FUNÇÃO 27, SUBTENSÃO.AJUSTES DISPONIVEIS NO APP DA PROTEÇÃO. | M38: 15 | N38: 10 | O38: 5 | P38: 15 | Q38: 15 | R38: 10 | S38: 0 | T38: 0 | U38: 70 | V38: Alta | W38: Transferência da RDU de Chapada de Areia (937 UCs) para fonte alternativa
A39: 2026 | B39: ETO-PROT 00152/2026 | C39: ETO-PROT | D39: 7925087021 | E39: 79 | F39: 46223 | G39: 21 | H39: PARANA | I39: PEIXE | J39: SUL | K39: LD01010021 | L39: 10/07 PARECER COEP: EQUIPAMENTO ENTREGUE AOS COCM´S FAVOR INFORMAR PRAZO DE SUBSTUIÇÃO PARA O DMSL E REPASSAR DEPOIS PARA PROTEÇÃO REALIZAR OS AJUSTES E DESCREVER NA SS O SERVIÇO REALIZADOPARECER COEP: EM ROTA DE ENTREGA, VERIFICAR PREVISÃO DE CHEGADARealizar a substituição do tanque do equipamento. | M39: 15 | N39: 10 | O39: 5 | P39: 0 | Q39: 15 | R39: 10 | S39: 0 | T39: 15 | U39: 70 | V39: Alta | W39: Primeiro RL do 414R de Paranã, RL a jusante na LD também está bay-passado (630 UCs)
A40: 2026 | B40: ETO-PROT 00151/2026 | C40: ETO-PROT | D40: 5801866013 | E40: 58 | F40: 46220 | G40: 13 | H40: PARAISO DO TOCANTINS | I40: PARAISO DO TOCANTINS | J40: CENTRO | K40: AL03062013 | L40: 15/07 PARECER COCM, FOI ATENDIDA PELA OS ETO-RD-PS 1616/2026 OBRA-021260053910/07 PARECER COEP: EQUIPAMENTO ENTREGUE AOS COCM´S FAVOR INFORMAR PRAZO DE SUBSTUIÇÃO PARA O DMSL E REPASSAR DEPOIS PARA PROTEÇÃO REALIZAR OS AJUSTES E DESCREVER NA SS O SERVIÇO REALIZADOPARECER COEP: EM PROCESSO DE ENTREGAPARECER DMSL: RT 5801866013Serviço Executado: Feito a medição da malha de terra. Identificado infiltração na caixa de passagem da célula da fase C do banco regulador de tensão, será necessário fazer a substituição da mesma! Ficar atento na hora da substituição, deverá ser substituída a célula do lado da BR.Obs.: Será necessário baixar todo o banco pelo menos um metro, as buchas estão muito próximas a parte energizada não oferecem segurança para equipe no momento do ensaio elétrico.Equipamento ficou em operação?: Não Possui nobreak: SimPossui antena: SimPossui rádio:SimPendência: SimData da bateria: Equipe: Benvindo e Kaique._______________________________________________RT 5801866013BY PASSADO DEVIDO DEFEITO EM CELULA BEMVINDO ESTEVE NO LOCAL JUNTO AO COD .NECESSARIO TRATATIVA PARA MESMA .FASE DANIFICADO C | M40: 0 | N40: 20 | O40: 20 | P40: 20 | Q40: 10 | R40: - | S40: - | T40: - | U40: 70 | V40: Alta | W40: Atendimento da RDU Luzimangues Industrial por fonte alternativa
...

Sheet Premissas por Equipamento
A1: Ativo | B1: Tipo | C1: Localidade | D1: Polo | E1: Regional | F1: SS aberta | G1: Parecer COEP | H1: SS DCMD | I1: Status DCMD | J1: Previsão DCMD | K1: SS Proteção | L1: Status Proteção | M1: Previsão Proteção | N1: SS DMSL | O1: Status DMSL | P1: Previsão DMSL | Q1: Status COI | R1: Observação | S1: Check de concluídas | T1: Defeito identificado | U1: Quantidade | V1: Descrição SS | W1: Premissa 1 | X1: Premissa 2 | Y1: Premissa 3 | Z1: Premissa 4 | AA1: Premissa 5 | AB1: Premissa 6 | AC1: Premissa 7 | AD1: Premissa 8 | AE1: Priorização | AF1: Criticidade | AG1: Observação após análise
A2: 5800291077 | B2: 58 | C2: GOIATINS | D2: ARAGUAINA | E2: NORTE | F2: CONCLUÍDA | S2: Ok | W2: 40 | X2: 20 | Y2: 20 | Z2: 20 | AA2: 20 | AB2: - | AC2: - | AD2: - | AE2: 120 | AF2: Muito Alta | AG2: Aumento de reclamações no atendimento de Goiatins e GAs relevantes na região
A3: 5854566043 | B3: 58 | C3: SILVANOPOLIS | D3: PORTO NACIONAL | E3: CENTRO | F3: ETO-RD-PO 00213/2026 | G3: Em fase de ajustes | R3: Pendente laudo da empreteira | S3: Em andamento | T3: Célula | U3: 1 | V3: 22/07/2026 PARECER COEP: EQUIPAMENTO ENTREGUE AOS COCM´SPRAZO DE 7 DIAS CONTANDO O SLA.PARECER COEP: EQUIPAMENTO ENTREGUE AOS COCM´S FAVOR SUSBSTTUIR , E AGUARDO O PRAZO DE PREVISÃO DE SUBSTIUIÇÃOboa noite,segue SS para as devidas tratativas com equipe de manutenção com apoio de equipe de linha viva substituir regulador de tensão 5854566043 queimado célula fase c, LD Porto / Silvanópolis mesmo deverá ser substituído com apoio de equipe de linha viva PARECER DMSL: Foi realizado inspeção visual e ensaios de isolação, relação de transformação e resistência de enrolamento. A fase B está danificada e será necessário substituir a mesma. Malha de aterramento está relativamente boa e conectada. Fase A e C passaram nos ensaios. Substituir fase B. | W3: 40 | X3: 20 | Y3: 20 | Z3: 10 | AA3: 20 | AB3: - | AC3: - | AD3: - | AE3: 110 | AF3: Muito Alta | AG3: Aumento de reclamações no atendimento de Silvanópolis por Porto Nacional no período seco (Outra fonte com defeito também)
A4: 5800859011 | B4: 58 | C4: TUPIRAMA | D4: GUARAI | E4: NORTE | F4: ETO-RD-GR 00735/2026 | G4: Aguardando comissionamento | R4: Previsão de substituição 27/08 | S4: Em andamento | T4: Controle | U4: 1 | V4: 16/07/2026 PARECER COEP: ALINHADO COM O JEAN DO DMSL E O KELLITON , KELLITON IRÁ FAZER A INSTALAÇÃO DO CONTROLE RUA E O JEAN IRÁ REALIZAR O COMISSIONAMENTO , FAZENDO A COMPATIBILIZAÇÃO DOS CABOS ASSIM COMO FICARÁ UM CONTROLE RUA NO NOSSO ESTOQUE SOBRESSALENTE PARA ATENDER O DE ARAPOEMA, ATÉ A CHEGADA DOS CABOS QUE O JEAN ME DEU REPORTE DE QUE SERIA ATÉ O DIA 16/08 , FAVOR COCM'S REALIZAREM A INSTALAÇÃO E GUARDAR CONTROLE RUA SOBRESSALENTE PARA ARAPOEMAPEÇA ENVIADA: CONTROLEPARECER DMSL: *FEEDBACK EQUIP. ESPECIAIS**Nº DO EQUIPAMENTO:* 5800859011*TIPO EQUIPAMENTO:* RT ITB *TIPO DE COMUNICAÇÃO:* Não *DATA DA MANUTENÇÃO:* 09/06/2026*SID:* 3195/2026*DESCRIÇÃO:* _ Foi identificado relé da fase C com defeito conforme orientação da supervisão e necessário realiza retrofit para instalação de controle rua.*FICOU EM OPERAÇÃO* Não*PENDÊNCIA:* Realizado Retrofit *DADOS DIVERGENTES DA PROGRAMAÇÃO:* Não*BATERIA SUBSTITUÍDA?:* Não*TIPO DE BATERIA:**EQUIPE:* Edeglan e Brunno.Observação: trocar por um controle RUA.------------------------------------------------------------------------------------------Enviar equipe do DMSL, para fazer correção no RT 5800859011, o mesmo está com o displey da fase C apagado , dificutando realizar manobras no mesmo, emvirtude disso o mesmo ficou BAY PASSADO EM CAMPO | W4: 40 | X4: 20 | Y4: 20 | Z4: 10 | AA4: 20 | AB4: - | AC4: - | AD4: - | AE4: 110 | AF4: Muito Alta | AG4: Atendimento de parte da RDU Guaraí por fonte alternativa
A5: 5836764032 | B5: 58 | C5: ARAGUACU | D5: ALVORADA | E5: SUL | F5: CONCLUÍDA | S5: Ok | W5: 40 | X5: 20 | Y5: 20 | Z5: 10 | AA5: 20 | AB5: - | AC5: - | AD5: - | AE5: 110 | AF5: Muito Alta | AG5: Aumento de reclamações no atendimento de Araguaçu no período seco
A6: 7923673004 | B6: 79 | C6: ARAGUAINA | D6: ARAGUAINA | E6: NORTE | F6: ETO-COEP 00124/2026 | G6: Em processo de aquisição | R6: Estava aguardando retorno DMSL | S6: Pendente | T6: Tanque + controle | U6: 1 | V6: PARECER COEP: Verificar Disponibilidade de equipamento no Scada e enviar modelo e tensão para a compra.RELIGADOR COM RELÉ DANIFICADO, REALIZAR SUBSTITUIÇÃO | W6: 15 | X6: 20 | Y6: 15 | Z6: 15 | AA6: 15 | AB6: 10 | AC6: 0 | AD6: 15 | AE6: 105 | AF6: Muito Alta | AG6: Transferência de cargas na RDU de Araguaína (2797 UCs)
A7: 7931608059 | B7: 79 | C7: TAQUARALTO | D7: TAQUARALTO | E7: CENTRO | F7: ETO-COEP 00040/2026 | G7: Em processo de aquisição | S7: Pendente | T7: Tanque e rádio | U7: 1 | V7: PARECER COEP: EQUIPAMENTO SELECIONADO PARA COMPRADMSL:Serviço Executado: Foi feita uma análise técnica no equipamento, devido à falta de comunicação. Também foi identificado que o tanque do equipamento está danificado, sendo assim, necessário substituir o tanque e o rádio do equipamento, que está queimado, sendo necessário substituir também. | W7: 15 | X7: 20 | Y7: 15 | Z7: 15 | AA7: 15 | AB7: 10 | AC7: 0 | AD7: 15 | AE7: 105 | AF7: Muito Alta | AG7: Transferência dos bairros Morada do Sol, Vale do Sol, Morada do Sol II, Nova Esperança, Sõa João, Araras I e II e Jardim Laila em Taquaralto (6033 UCs)
A8: 7931610122 | B8: 79 | C8: PALMAS | D8: PALMAS | E8: CENTRO | F8: ETO-TELE 01025/2026 | G8: Aguardando comissionamento | O8: SS ATENDIDA | S8: Em andamento | T8: Tanque e antena | U8: 1 | V8: PARECER DA PROTEÇÃO:FAVOR COMISSIONAR RELIGADOR. AJUSTES PERMANECEM OS MESMOS E DISPONÍVEIS NO APP DA PROTEÇÃO.Estagiário Rafael P Marques.******************30/06 PARECER COEP: EQUIPAMENTO ENTREGUE, SEGUE SS PARA O COCM´S , PARA REALIZAR O ATENDIMENTO,FAVOR ADICIONAR O PARECER PARA MANDAR PARA PROTEÇÃOBom dia,Segue SS para verificação RL sem comunicação com painel apagado equipe DEOP fez primeiro ataque sem sucesso RL 7931610122 RDU de Palmas.Feedback Equipamentos Especiais DMSL: *RLG 7931610122 RDU Palmas*Noja rc10 Data: 14/10/2025SID: 5412Dados de comunicação divergentes da programação: Não. Serviço Executado: Houve um curto no equipamento danificando a parte ativa, e antena! Será necessário fazer a substituição somente da parte ativa (tanque) e da antena.Equipamento ficou em operação?: Não Pendência: Sim, substituir a parte ativa.Bateria(s) substituída(s)?: NãoData Fabricação/Instalação da(s) bateria(s): 2024Equipe: Benvindo, Juliano e Sérgio.***** Parecer do COCM CENTRO*****Equipamento Substituido em campo pela Ordem de ServiÇO DLP-MPPA01 243/2026, ONDE OS RELATORIO ESTÃO ANEXADO.--------------------------------------------------------Parecer DMSL:Equipamento substituído porém não informado se antena também foi substituída. Levar antena para caso da mesmo não ter sido substituída. | W8: 15 | X8: 20 | Y8: 15 | Z8: 15 | AA8: 15 | AB8: 10 | AC8: 0 | AD8: 15 | AE8: 105 | AF8: Muito Alta | AG8: Transferência entre 284R SE Palmas IV e 2294R SE Palmas II
A9: 7900648055 | B9: 79 | C9: ARAGUACEMA | D9: DIVINOPOLIS | E9: CENTRO | F9: CONCLUÍDA | S9: Ok | W9: 15 | X9: 20 | Y9: 15 | Z9: 15 | AA9: 15 | AB9: 10 | AC9: 0 | AD9: 15 | AE9: 105 | AF9: Muito Alta | AG9: Transferência da RDU de Araguacema (1506 UCs)
A10: 7947203070 | B10: 79 | C10: RIO SONO | D10: TAQUARALTO | E10: CENTRO | F10: ETO-COEP 00131/2026 | G10: Em processo de aquisição | S10: Pendente | T10: Controle | U10: 1 | V10: 13/07 PARECER COEP: SELECIONADO PARA COMPRA CONTROLE favor verificar RL 7947203070, sem comunicaçao, feito 1° ataque pela equipe 070OP01 e nao retornou a comunicaçao , linformaçao no Scada de bateria.PARECER DMSL: Foi feito análise técnica, a placa do equipamento está queimada nessesario subistituir o equipamento completo -Carliel e Benvindo-05/02 | W10: 10 | X10: 20 | Y10: 15 | Z10: 15 | AA10: 15 | AB10: 10 | AC10: 0 | AD10: 15 | AE10: 100 | AF10: Muito Alta | AG10: Transferência da RDU de Lizarda (1650 UCs) para fonte alternativa
A11: 5856070091 | B11: 58 | C11: ALMAS | D11: DIANOPOLIS | E11: SUL | F11: ETO-RD-DP 00479/2026 | G11: Equipamento entregue ao COCM | R11: Previsão de substituição 07/08// Nova previsão de entrega 21/08 se a DB Machado for para o Sul | S11: Em andamento | T11: Células + controle | U11: 3 | V11: PARECER DMSL: não foi regularizado a instalação do equipamento, nota repassada conforme alinhado com o supervisor.____________________________________________COCMS 26.03.26. SS REPASSADA PARA COEP PROVIDENCIAR MATERIAL. NÃO TEMOS AS PÇ EM ESTOQUE PARA FAZER A SUBSTITUIÇÃO. Solicitação de serviço para reposição de equipamentos furtados .COEP: Equipamento fornecido ao COCM-S para regularização.COCMS: Equipamento substituido conforme solicitado. Gentileza comissionar.PARECER DA PROTEÇÃO:SEGUE NOTA REPASSADA PARA DMSL COMISSIONAR.ENG° IRLLEY CASTELO BRANCOPARECER DMSL(23/09/2025): Feito a parte de comunicação, fechando enlace, configuração do rádio GE. Feito a medição de aterramento. Após uma inspeção, foi identificado que o regulador de tensão está instalado errado, carga está para o lado de fonte e fonte está do lado de carga. O certo é a fonte vim de almas, atualmente está vindo de natividade. Favor fazer a instalação correta. | W11: 40 | X11: 20 | Y11: 20 | Z11: 20 | AA11: 0 | AB11: - | AC11: - | AD11: - | AE11: 100 | AF11: Muito Alta | AG11: Atendimento da região da Engegold, Nativa, cidade Natividade e Chapada da Natividade
A12: 7903569004 | B12: 79 | C12: ARAGUAINA | D12: ARAGUAINA | E12: NORTE | F12: CONCLUÍDA | W12: 15 | X12: 20 | Y12: 5 | Z12: 15 | AA12: 15 | AB12: 10 | AC12: 0 | AD12: 15 | AE12: 95 | AF12: Muito Alta | AG12: Transferência dos bairros JD Santa Helena, Jd Filadelfiae Setor Caraja em Araguaína (2053 UCs), AL 254R de AR I e AL 214R de AR III
A13: 7925744087 | B13: 79 | C13: GOIANORTE | D13: GUARAI | E13: NORTE | F13: ETO-COEP 00059/2026 | G13: Em processo de aquisição | R13: Mandar reformar | S13: Pendente | T13: Tanque e cabo umbilical | U13: 1 | V13: PARECER COEP: EQUIPAMENTO SELECIONADO PARA COMPRAPARECER DMSL: FEEDBACK EQUIP. ESPECIAISNº DO EQUIPAMENTO: 7925744087TIPO EQUIPAMENTO: Noja RC 10TIPO DE COMUNICAÇÃO: Radio GE IPDATA DA MANUTENÇÃO: 19/02/2026SID: 735/2026 DESCRIÇÃO: foi identificado água dentro da parte interna do tanque e cabo umbilical encharcado de água foi passado essas informações para COS.FICOU EM OPERAÇÃO?: Não PENDÊNCIA: Sim substituir tanque e cabo umbilicalDADOS DIVERGENTES DA PROGRAMAÇÃO: NãoBATERIA SUBSTITUÍDA?: Não DATA DA BATERIA: 07/05/2025TIPO DE BATERIA: Lítio EQUIPE: Edeglan e Janio-------------------------------------------------------------------------------------------------RELIGADOR SEM COMUNICAÇÃO, APOS PRIMEIRO ATAQUE RETORNA E FICAR INDEFINIDO. | W13: 15 | X13: 20 | Y13: 5 | Z13: 15 | AA13: 15 | AB13: 10 | AC13: 0 | AD13: 15 | AE13: 95 | AF13: Muito Alta | AG13: Transferência de Goianorte, fonte principal operando
A14: 7900117013 | B14: 79 | C14: PARAISO DO TOCANTINS | D14: PARAISO DO TOCANTINS | E14: CENTRO | F14: ETO-PROT 00154/2026 | G14: Em fase de ajustes | S14: Em andamento | T14: Controle | U14: 1 | V14: 15/07 PARECER COCM: EQUIPAMENTO FOI SUBSTITUÍDO OBRA 021260042210/07 PARECER COEP: EQUIPAMENTO ENTREGUE AOS COCM´S FAVOR INFORMAR PRAZO DE SUBSTUIÇÃO PARA O DMSL E REPASSAR DEPOIS PARA PROTEÇÃO REALIZAR OS AJUSTES E DESCREVER NA SS O SERVIÇO REALIZADOPARECER COEP: PREVISÃO DE ENTREGA AOS COCM'S 01/07Segue nota para correção de anomalia e provável substituição de religador , religador 7900117013 -RDU - Paraiso .OBS: equipe DMSL Elisfran estava atualizando firmware no equipamento , porém relé parou de funcionar devido essa atualização , sendo necessário sua substituição .em campo o modelo e cooper Form6 , segundo tecnico deve ser substituído por um Noja .Repassado para o COEP para aquisição do equipamento e posterior repasse para o COCM. | W14: 15 | X14: 20 | Y14: 15 | Z14: 15 | AA14: 15 | AB14: 0 | AC14: 0 | AD14: 15 | AE14: 95 | AF14: Muito Alta | AG14: Transferência do 214R de Paraíso I, Centro Comercial de Paraíso
A15: 7929376022 | B15: 79 | C15: BABACULANDIA | D15: ARAGUAINA | E15: NORTE | F15: ETO-COEP 00120/2026 | G15: Concuído DCMD | R15: Construir Reporte | S15: Em andamento | T15: Tanque + controle | U15: 1 | V15: PARECER COEP: PROBLEMA NO ENVIO COCM'S CONTROLE ENVIADO FOI O NOJA , DEVIDO A FALTA DO MODELO NA SS (GRAVE)PARECER DMSL: *FEEDBACK EQUIP. ESPECIAIS**Nº DO EQUIPAMENTO:* 7929376022 *DATA DA MANUTENÇÃO:* 02/04/2026*SID:* 1677/2026*DESCRIÇÃO:* Trocar controle completo*PENDÊNCIA:* Sim.*DADOS DIVERGENTES DA PROGRAMAÇÃO:* Não*BATERIA SUBSTITUÍDA?:* Não*EQUIPE:* Adeilton e Edicleber __________________________________________________________POR GENTILEZA ATENDER SOLICITAÇÃO PRIMEIRO ATAQUE IDENTIFICOU QUE RELE ESTA EM CURTO NOTA ABERTA 224/2026 FOI BAIXADA POREM NÃO FOI CORRIGIDO PROBLEMA EM CAMPO. | W15: 15 | X15: 20 | Y15: 5 | Z15: 15 | AA15: 15 | AB15: 10 | AC15: 0 | AD15: 15 | AE15: 95 | AF15: Muito Alta | AG15: Transferência de Babaçulândia, fonte principal operando
A16: 7908705049 | B16: 79 | C16: AURORA DO TOCANTINS | D16: DIANOPOLIS | E16: SUL | F16: ETO-RD-DP 00409/2026 | G16: Equipamento entregue ao COCM | R16: Previsão de substituição 07/08 // 22/08 Se a DB Machado for pro Sul | S16: Em andamento | T16: Tanque + controle | U16: 1 | V16: EQUIPAMENTO ENTREGUE, SOLICITO PREVISÃO PARA SUBSTITUIÇÃO:PARECER COEP: PREVISÃO DE ENTREGA AOS COCM'S 01/07Manutenção no RL 7908705049PARECER DMSL(28/08/2025): Equipe foi fazer manutenção no RL e constatou que o tanque e o relé do mesmo se encontra queimado, providenciar substituição.PARECER COCMS 30/04/2026CRIADO OBRA 0512600135 PARA REQUISIÇÃO MATERIAL | W16: 15 | X16: 20 | Y16: 5 | Z16: 15 | AA16: 15 | AB16: 0 | AC16: 10 | AD16: 15 | AE16: 95 | AF16: Muito Alta | AG16: Proteção da baixa do TF de força da SE Aurora
A17: 7933726256 | B17: 79 | C17: MATEIROS | D17: PONTE ALTA TOCANTINS | E17: CENTRO | F17: ETO-PROT 00145/2026 | G17: Em fase de ajustes | R17: Destinada parte ativa do RL 7900453110 | S17: Em andamento | T17: Tanque | U17: 1 | V17: 07/07 Equipamento foi substituido na OS: ETO-RD-PO 1859/2026 OBRA 031260035101/07 PARECER COEP: REDIRECIONADO PARA O POSTO DO COCM´S EQUIPAMENTO CHEGOU NO LOCAL, FAVOR ENTRAR EM CONTATO COM O DMSL, DEVIDO A URGÊNCIA DO EQUIPAMENTO EM OPERAÇÃO.30/06 PARECER COEP: DEVIDO A ALINHAMENTO COM COI UTILIZAREMOS PARTE ATIVA QUE ORIGINALMENTE FOI ENCOMENDADA PARA 7933726256PARECER DMSL: N° do Equipamento: _RLG 7933726256 MateirosTipo de Equipamento: _RLG NOJA RC 10 REL IIData: _06/05/2026SID: _2288/2026-Serviço Executado: _Equipamento com defeito na parte ativa, será necessário fazer a substituição da parte ativa e fazer melhoria na malha de terra!Equipamento ficou em operação?: _NaoPendência: _SimBateria(s) substituída(s)? NÃOData Fabricação/Instalação da(s) bateria(s):_06/2025Equipe: _Benvindo e Almir-------------------------------------------------------------------------------Religador 7933726256, sem comunicação apos primeiroa ataque não retornou as comunicação. | W17: 15 | X17: 10 | Y17: 15 | Z17: 15 | AA17: 15 | AB17: 10 | AC17: 0 | AD17: 15 | AE17: 95 | AF17: Muito Alta | AG17: Transferência da cidade de Mateiros (733 UCs) para o gerador
A18: 7933766059 | B18: 79 | C18: TAQUARALTO | D18: TAQUARALTO | E18: CENTRO | F18: ETO-TELE 01024/2026 | G18: Aguardando comissionamento | O18: SS ATENDIDA | S18: Em andamento | T18: Tanque | U18: 1 | V18: PARECER DA PROTEÇÃO:RECOMISSIONAR RELIGADOR, AJUSTES DE PROTEÇÃO PERMANECEM OS MESMOS.Estagiário Rafael P Marques****************************PARECER COEP: EQUIPAMENTO ENTREGUE, SEGUE SS PARA O COCM´S , PARA REALIZAR O ATENDIMENTO,FAVOR ADICIONAR O PARECER PARA MANDAR PARA PROTEÇÃOSegue SS para verficar religador de poste 7933766059.Religador esta com defeito na parte ativa no tanque Porte gentilezaenviar equipe verificar.Endereço: TaquariPARECER DMSL: RLG 7933766059 RELÉ NOJA RC 10Mestre 2 Rep. taquaruçu GESID: 5457/2025Data: 15/10/2025Serviço Executado: Houve um curto na parte ativa do equipamento danificando a mesma, será necessário fazer a substituição somente do tanque, parte ativa.*Equipamento ficou em operação?:*Nao Pendência: Sim, substituir parte ativa.Equipe: Benvindo, Juliano e Sérgio.****** Parecer do COCM Centro***Equipámento Substituido em Campo pela Ordem de ServIÇO DLP-MPPA01 244/2026, ONDE OS RELATORIO ESTÃO ANEXADO.. | W18: 15 | X18: 20 | Y18: 5 | Z18: 15 | AA18: 15 | AB18: 0 | AC18: 10 | AD18: 15 | AE18: 95 | AF18: Muito Alta | AG18: Seccionamento de trecho do Setor Taquari
A19: 7900594026 | B19: 79 | C19: PONTE ALTA TOCANTINS | D19: PONTE ALTA TOCANTINS | E19: CENTRO | F19: ETO-SE-PA 00107/2026 | G19: Aguardando comissionamento | S19: Em andamento | T19: Tanque + controle | U19: 1 | V19: PARECER DA PROTEÇÃO:16/07/2026 AJUSTES DISPONIBILIZADOS NO APP DA PROTEÇÃO15/07/2026 EQUIPAMENTO SUBSTITUIDO NA OS ETO-RD-PO 1860 OBRA 031260035414/07/2026 PARECER COCM/ COEP: DE ACORDO COM O EDSON CURCINO FOI FEITA S SUBSTITUIÇÃO DO EQUIPAMENTO , SEGUE PARA PROTEÇÃO ELABORAR AJUSTE10/07 PARECER COEP: EQUIPAMENTO DESLOCADO QUE ESTAVA EM GUARAÍ FOI ALINHADO COM O VALMOR QUE SERIA SUBSTITUIDO DIA 07/07/2026 , FAVOR PASSAR PARA PROTEÇÃO 7900594026PARECER COEP: AGUARDANDO COCM'S PARA ABRIR REQUISIÇÃOPARECER DMSL 10/06/2026: Tem uma nota aberta para esse equipamento solicitando a substituição desde 20/10/2025, como a nota não foi atendida estamos repassando para área responsável. Nota em aberto repassada ETO-COEP 210/2025.Segue nota para verificar intermitência de comunicação nos religadores 7908301026 , 7911120026, 7947959026 , 7908692026, 7900594026 rural- Ponte Alta . | W19: 15 | X19: 20 | Y19: 15 | Z19: 15 | AA19: 15 | AB19: 0 | AC19: 0 | AD19: 15 | AE19: 95 | AF19: Muito Alta | AG19: Religador responsável pela proteção da barra da SE Ponte Alta (2381 UCs)
A20: 7921040031 | B20: 79 | C20: RIO DOS BOIS | D20: MIRACEMA DO TOCANTINS | E20: CENTRO | F20: CONCLUÍDA | S20: Ok | W20: 15 | X20: 20 | Y20: 5 | Z20: 15 | AA20: 15 | AB20: 10 | AC20: 0 | AD20: 15 | AE20: 95 | AF20: Muito Alta | AG20: Fonte principal de Rio dos Bois, RL de transferência operando
A21: 7957620015 | B21: 79 | C21: PEDRO AFONSO | D21: GUARAI | E21: NORTE | F21: CONCLUÍDA | S21: Ok | W21: 15 | X21: 20 | Y21: 15 | Z21: 15 | AA21: 15 | AB21: 0 | AC21: 0 | AD21: 15 | AE21: 95 | AF21: Muito Alta | AG21: Atendimento da RDU de Bom Jesus e parcial da RDU de Pedro Afonso
A22: 7927413001 | B22: 79 | C22: PORTO NACIONAL | D22: PORTO NACIONAL | E22: CENTRO | F22: ETO-COEP 00141/2026 | G22: Em processo de aquisição | S22: Pendente | T22: Tanque + controle | U22: 1 | V22: 22/07/2026 EQUIPAMENTO SLEECIONADO PARA COMPRAPARECER DMSL: *Segue feedback**Equipamento:* RLG 7927413001 *RELÉ TAVRIDA*Data:* 16/04/2026*SID:* 1817/2026*Serviço executado:* Placa de alimentação do equipamento com defeito, VERIFICAR SE É POSSIVEL substituir o equipamento completo.*Equipamento ficou em operação?*_Não*Pendência:*_Sim*Bateria(s) substituída(s)?*_Nao *Equipe:* Benvindo e Kaique-------------------------------------------------------------------------------------------------Religador 7927413001 sem comunicação foi realizado primeiro ataque porem a comunicação não retornou. Favor enviar equipe para devidas trattivas | W22: 15 | X22: 5 | Y22: 15 | Z22: 15 | AA22: 15 | AB22: 10 | AC22: 0 | AD22: 15 | AE22: 90 | AF22: Muito Alta | AG22: Transferência do Distrito Ind de Porto Nacional e GAs
A23: 7908686014 | B23: 79 | C23: PIUM | D23: PARAISO DO TOCANTINS | E23: CENTRO | F23: ETO-RD-PS 00302/2026 | G23: Concluído DCMD | R23: Verificar se já foi repassado | S23: Em andamento | T23: Tanque | U23: 1 | V23: 10/07 PARECER COEP: EQUIPAMENTO ENTREGUE AOS COCM´S FAVOR INFORMAR PRAZO DE SUBSTUIÇÃO PARA O DMSL E REPASSAR DEPOIS PARA PROTEÇÃO REALIZAR OS AJUSTES E DESCREVER NA SS O SERVIÇO REALIZADO06/07 PARECER COEP: PREVISÃO DE ENTREGA DE ACORDO COM CALENDÁRIO LOGISITCO NOVO 06/07NOTA DMSL: Favor substituir o tanque, ele não está efetuando os comandos enviados. Não substituir o controle pois o mesmo funciona como repetidor de outros equipamentos.Segue nota para verificar falha de fechamento religador 7908686014- Pium .OBS: equipamento não fechou local e remoto , fica sinalizando no painel para verificar alarmes ! | W23: 15 | X23: 20 | Y23: 0 | Z23: 15 | AA23: 15 | AB23: 10 | AC23: 0 | AD23: 15 | AE23: 90 | AF23: Muito Alta | AG23: Fonte principal de Pium, RL de transferência operando
A24: 5800440256 | B24: 58 | C24: MATEIROS | D24: PONTE ALTA TOCANTINS | E24: CENTRO | F24: CONCLUÍDA | S24: Ok | W24: 20 | X24: 20 | Y24: 20 | Z24: 10 | AA24: 20 | AB24: - | AC24: - | AD24: - | AE24: 90 | AF24: Muito Alta | AG24: Aumento de reclamações no atendimento de São Felix e Mateiros no período seco
A25: 7943790134 | B25: 79 | C25: ESPERANTINA | D25: AUGUSTINOPOLIS | E25: NORTE | F25: ETO-TELE 00896/2026 | G25: Aguardando comissionamento | O25: SS PENDENTE | P25: 46261 | S25: Em andamento | T25: Tanque | U25: 1 | V25: PARECER DCMD:Serviço realizado , substituição da parte ativa do RELIGADOR 7943790134 - Favor realizar comissionamento | W25: 15 | X25: 10 | Y25: 5 | Z25: 15 | AA25: 15 | AB25: 10 | AC25: 0 | AD25: 15 | AE25: 85 | AF25: Muito Alta | AG25: Transferência de Esperantina, fonte principal operando
A26: 7900453110 | B26: 79 | C26: SANTA RITA DO TOCANTINS | D26: PORTO NACIONAL | E26: CENTRO | F26: ETO-COEP 00087/2026 | G26: Em processo de aquisição | R26: Previsão de entrega 20/10 | S26: Pendente | T26: Tanque | U26: 1 | V26: 10/07/2026 EQUIPAMENTO SELECIONADO PARA COMPRA PARTE ATIVA30/06.PARECER COEP: ALINHADO COM O ALLAN REMANEJAMOS PARTE ATIVA PARA ATENDER 7933726256PARECER COEP: Aproveitar controle cooper se possível em outro local, previsão de chegada do material dia 01/07 para substituiçãoFavor verificar o RL 7900453110, pois o mesmo aceita comando de fechamento, porém fecha em campo e no SCADA continua aberto e só abre através de equipe em campo. Parecer Dmsl:Equipamento está com defeito na parte ativa, não aceita o comando de fechamento. Será necessário substituir o equipamento completo.Equipamento ficou em operação?: _SIM_a pedido do COS ficou em operação, a operação está ciente da necessidade de substituir.Pendência: Sim, será necessário substituir o equipamento. | W26: 15 | X26: 10 | Y26: 5 | Z26: 15 | AA26: 15 | AB26: 10 | AC26: 0 | AD26: 15 | AE26: 85 | AF26: Muito Alta | AG26: Transferência de Santa Rita, fonte principal operando
A27: 7925871077 | B27: 79 | C27: GOIATINS | D27: ARAGUAINA | E27: NORTE | F27: ETO-COEP 00048/2026 | G27: Em processo de aquisição | R27: Previsão de entrega 20/10 | S27: Pendente | T27: Tanque | U27: 1 | V27: 30/06 PARECER COEP: AGUARDANDO RETORNO DO DMSLPARECER DMSL: A PEDIDO DA PCM DO NORTE LARA SOARES REALIZEI A CRIAÇÃO DESSA SS, EM RAZAO DA ANTIGAETO-TELE 337/2026 QUE FOI BAIXADA POR ENGANO DE TAL FORMA SEGUE A MESMA PARA REALIZAR AS TRATATIVAS. PENDENCIA: Religador continua by passado, equipamento está com defeito na parte ativa | W27: 15 | X27: 10 | Y27: 15 | Z27: 15 | AA27: 15 | AB27: 10 | AC27: 0 | AD27: 0 | AE27: 80 | AF27: Muito Alta | AG27: Transferência de Goiatins e GAs (2492 UCs)
