Workbook
Name embs4: 'Ajustes Reguladores de Tensão'!$L$140
Name embs4: 'Ajustes Reguladores de Tensão'!$L$63

Sheet 1007ALLan
A1: Ativo | B1: Tipo | C1: Localidade | D1: Polo | E1: Regional | F1: SS aberta | G1: Parecer COEP | H1: Observação | I1: Check de concluídas | J1: Defeito identificado | K1: Descrição SS | L1: Premissa 1 | M1: Premissa 2 | N1: Premissa 3 | O1: Premissa 4 | P1: Premissa 5 | Q1: Premissa 6 | R1: Premissa 7 | S1: Premissa 8 | T1: Priorização | U1: Criticidade | V1: Observação após análise | X1: Legenda
A2: 7923673004 | B2: =MID(Table12[[#This Row],[Ativo]],1,2) -> 79 | C2: ARAGUAINA | D2: ARAGUAINA | E2: NORTE | F2: =IFERROR(_xlfn.XLOOKUP(Table12[[#This Row],[Ativo]],[2]!Pendentes[COD_RELIGADOR],[2]!Pendentes[SS_ORIGINAL]),"CONCLUÍDA") -> ETO-COEP 00124/2026 | G2: Aguardando atualização de informação DMSL | K2: =IFERROR(_xlfn.XLOOKUP(Table12[[#This Row],[Ativo]],[2]!Pendentes[COD_RELIGADOR],[2]!Pendentes[DESCRICAO]),"") -> PARECER COEP: Verificar Disponibilidade de equipamento no Scada e enviar modelo e tensão para a compra.RELIGADOR COM RELÉ DANIFICADO, REALIZAR SUBSTITUIÇÃO | L2: 15 | M2: 20 | N2: 15 | O2: 15 | P2: 15 | Q2: 10 | R2: 0 | S2: 15 | T2: =SUM(Table12[[#This Row],[Premissa 1]:[Premissa 8]]) -> 105 | U2: Muito Alta | V2: Transferência de cargas na RDU de Araguaína (2797 UCs) | X2: (*) | Y2: Não houve ataque do DMSL
A3: 7947203070 | B3: =MID(Table12[[#This Row],[Ativo]],1,2) -> 79 | C3: RIO SONO | D3: TAQUARALTO | E3: CENTRO | F3: =IFERROR(_xlfn.XLOOKUP(Table12[[#This Row],[Ativo]],[2]!Pendentes[COD_RELIGADOR],[2]!Pendentes[SS_ORIGINAL]),"CONCLUÍDA") -> ETO-COEP 00131/2026 | G3: Aguardando atualização de informação DMSL | H3: DMSL verificando sobre as placas em estoque | K3: =IFERROR(_xlfn.XLOOKUP(Table12[[#This Row],[Ativo]],[2]!Pendentes[COD_RELIGADOR],[2]!Pendentes[DESCRICAO]),"") -> 13/07 PARECER COEP: SELECIONADO PARA COMPRA CONTROLE favor verificar RL 7947203070, sem comunicaçao, feito 1° ataque pela equipe 070OP01 e nao retornou a comunicaçao , linformaçao no Scada de bateria.PARECER DMSL: Foi feito análise técnica, a placa do equipamento está queimada nessesario subistituir o equipamento completo -Carliel e Benvindo-05/02 | L3: 10 | M3: 20 | N3: 15 | O3: 15 | P3: 15 | Q3: 10 | R3: 0 | S3: 15 | T3: =SUM(Table12[[#This Row],[Premissa 1]:[Premissa 8]]) -> 100 | U3: Muito Alta | V3: Transferência da RDU de Lizarda (1650 UCs) para fonte alternativa
A4: 7903569004 | B4: =MID(Table12[[#This Row],[Ativo]],1,2) -> 79 | C4: ARAGUAINA | D4: ARAGUAINA | E4: NORTE | F4: =IFERROR(_xlfn.XLOOKUP(Table12[[#This Row],[Ativo]],[2]!Pendentes[COD_RELIGADOR],[2]!Pendentes[SS_ORIGINAL]),"CONCLUÍDA") -> ETO-COEP 00152/2026 | G4: Aguardando atualização de informação DMSL | K4: =IFERROR(_xlfn.XLOOKUP(Table12[[#This Row],[Ativo]],[2]!Pendentes[COD_RELIGADOR],[2]!Pendentes[DESCRICAO]),"") -> PARECER COEP 28/07/2026 : EQUIPAMENTO SELECIONADO PARA COMPRAEquipamento baypassado PARECER DMSL em 12/03: Realizar substituição do equipamento todo e parte ativa. | L4: 15 | M4: 20 | N4: 5 | O4: 15 | P4: 15 | Q4: 10 | R4: 0 | S4: 15 | T4: =SUM(Table12[[#This Row],[Premissa 1]:[Premissa 8]]) -> 95 | U4: Muito Alta | V4: Transferência dos bairros JD Santa Helena, Jd Filadelfiae Setor Caraja em Araguaína (2053 UCs), AL 254R de AR I e AL 214R de AR III
A5: 7927413001 | B5: =MID(Table12[[#This Row],[Ativo]],1,2) -> 79 | C5: PORTO NACIONAL | D5: PORTO NACIONAL | E5: CENTRO | F5: =IFERROR(_xlfn.XLOOKUP(Table12[[#This Row],[Ativo]],[2]!Pendentes[COD_RELIGADOR],[2]!Pendentes[SS_ORIGINAL]),"CONCLUÍDA") -> ETO-COEP 00141/2026 | G5: Aguardando atualização de informação DMSL | H5: DMSL verificando sobre as placas em estoque | K5: =IFERROR(_xlfn.XLOOKUP(Table12[[#This Row],[Ativo]],[2]!Pendentes[COD_RELIGADOR],[2]!Pendentes[DESCRICAO]),"") -> 22/07/2026 EQUIPAMENTO SLEECIONADO PARA COMPRAPARECER DMSL: *Segue feedback**Equipamento:* RLG 7927413001 *RELÉ TAVRIDA*Data:* 16/04/2026*SID:* 1817/2026*Serviço executado:* Placa de alimentação do equipamento com defeito, VERIFICAR SE É POSSIVEL substituir o equipamento completo.*Equipamento ficou em operação?*_Não*Pendência:*_Sim*Bateria(s) substituída(s)?*_Nao *Equipe:* Benvindo e Kaique-------------------------------------------------------------------------------------------------Religador 7927413001 sem comunicação foi realizado primeiro ataque porem a comunicação não retornou. Favor enviar equipe para devidas trattivas | L5: 15 | M5: 5 | N5: 15 | O5: 15 | P5: 15 | Q5: 10 | R5: 0 | S5: 15 | T5: =SUM(Table12[[#This Row],[Premissa 1]:[Premissa 8]]) -> 90 | U5: Muito Alta | V5: Transferência do Distrito Ind de Porto Nacional e GAs
A6: 7925871077 | B6: =MID(Table12[[#This Row],[Ativo]],1,2) -> 79 | C6: GOIATINS | D6: ARAGUAINA | E6: NORTE | F6: =IFERROR(_xlfn.XLOOKUP(Table12[[#This Row],[Ativo]],[2]!Pendentes[COD_RELIGADOR],[2]!Pendentes[SS_ORIGINAL]),"CONCLUÍDA") -> ETO-COEP 00048/2026 | G6: Aguardando atualização de informação DMSL | K6: =IFERROR(_xlfn.XLOOKUP(Table12[[#This Row],[Ativo]],[2]!Pendentes[COD_RELIGADOR],[2]!Pendentes[DESCRICAO]),"") -> 27/07 PARECER COEP: EM PROCESSO DE AQUISIÇÃOPARECER DMSL: A PEDIDO DA PCM DO NORTE LARA SOARES REALIZEI A CRIAÇÃO DESSA SS, EM RAZAO DA ANTIGAETO-TELE 337/2026 QUE FOI BAIXADA POR ENGANO DE TAL FORMA SEGUE A MESMA PARA REALIZAR AS TRATATIVAS. PENDENCIA: Religador continua by passado, equipamento está com defeito na parte ativa | L6: 15 | M6: 10 | N6: 15 | O6: 15 | P6: 15 | Q6: 10 | R6: 0 | S6: 0 | T6: =SUM(Table12[[#This Row],[Premissa 1]:[Premissa 8]]) -> 80 | U6: Muito Alta | V6: Transferência de Goiatins e GAs (2492 UCs)
A7: 7908302256 | B7: =MID(Table12[[#This Row],[Ativo]],1,2) -> 79 | C7: MATEIROS | D7: PONTE ALTA TOCANTINS | E7: CENTRO | F7: =IFERROR(_xlfn.XLOOKUP(Table12[[#This Row],[Ativo]],[2]!Pendentes[COD_RELIGADOR],[2]!Pendentes[SS_ORIGINAL]),"CONCLUÍDA") -> CONCLUÍDA | G7: Aguardando atualização de informação DMSL | H7: ETO-TELE 970/2026 concluída e equipamento fora de operação | K7: =IFERROR(_xlfn.XLOOKUP(Table12[[#This Row],[Ativo]],[2]!Pendentes[COD_RELIGADOR],[2]!Pendentes[DESCRICAO]),"") | L7: 5 | M7: 10 | N7: 5 | O7: 15 | P7: 15 | Q7: 10 | R7: 0 | S7: 15 | T7: =SUM(Table12[[#This Row],[Premissa 1]:[Premissa 8]]) -> 75 | U7: Alta | V7: Isolação de trecho e transferência das cidades de São Felix e Mateiros para gerador, além de atendimento de clientes rurais
A8: 7903112004 | B8: =MID(Table12[[#This Row],[Ativo]],1,2) -> 79 | C8: ARAGUAINA | D8: ARAGUAINA | E8: NORTE | F8: =IFERROR(_xlfn.XLOOKUP(Table12[[#This Row],[Ativo]],[2]!Pendentes[COD_RELIGADOR],[2]!Pendentes[SS_ORIGINAL]),"CONCLUÍDA") -> ETO-COEP 00184/2025 | G8: Aguardando atualização de informação DMSL | H8: 1 tanque NOJA sobrando | I8: Em andamento | J8: Tanque cooper | K8: =IFERROR(_xlfn.XLOOKUP(Table12[[#This Row],[Ativo]],[2]!Pendentes[COD_RELIGADOR],[2]!Pendentes[DESCRICAO]),"") -> 20/07 PARECER COEP: EQUIPAMENTO SELECIONADO PARA COMPRAApós testes no RLG 7903112004 foi constatado defeito no mesmo e como se trata de um modelo COOPER FORM6 que está obsoleto e não possuímos peças sobressalentes, faz-se necessária substituição completa por modelo NOJA RC10. | L8: 15 | M8: 10 | N8: 5 | O8: 15 | P8: 0 | Q8: 10 | R8: 0 | S8: 0 | T8: =SUM(Table12[[#This Row],[Premissa 1]:[Premissa 8]]) -> 55 | U8: Alta | V8: Transferência de Babaçulândia, 4 RLs sendo 2 operando
A9: 7920024127 | B9: =MID(Table12[[#This Row],[Ativo]],1,2) -> 79 | C9: PALMEIRAS DO TOCANTINS | D9: TOCANTINOPOLIS | E9: NORTE | F9: =IFERROR(_xlfn.XLOOKUP(Table12[[#This Row],[Ativo]],[2]!Pendentes[COD_RELIGADOR],[2]!Pendentes[SS_ORIGINAL]),"CONCLUÍDA") -> ETO-COEP 00120/2025 | G9: Aguardando atualização de informação DMSL | H9: DMSL verificando problema na parte ativa e comunicação | J9: Tanque, relé e chave | K9: =IFERROR(_xlfn.XLOOKUP(Table12[[#This Row],[Ativo]],[2]!Pendentes[COD_RELIGADOR],[2]!Pendentes[DESCRICAO]),"") -> 30/06 PARECER COEP: AGUARDANDO O RETORNO DO DMSL , PARA ENTENDER SE O PROBLEMA É NA COMUNICAÇÃO OU PARTE ATIVA, JÁ QUE O EQUIPAMENTO EM QUESTÃO SEGUE COMUNICANDOPARECER DMSL: Após testes, equipe DMSL constatou que o relé e a parte ativa do equipamento 7920024127 estão com defeito, sendo necessária a substituição completa por um modelo NOJA RC 10. Favor, subsituir também a chave de saída da fase A que está com o anel de abertura quebrado.RL 7920024127 está desarmando em campo e no SCADA continua fechado, só sinaliza aberto no SCADA quando a equipe faz o resert no equipamento em campo. | L9: 15 | M9: 10 | N9: 5 | O9: 15 | P9: 0 | Q9: 10 | R9: 0 | S9: 0 | T9: =SUM(Table12[[#This Row],[Premissa 1]:[Premissa 8]]) -> 55 | U9: Alta | V9: Transferência de Palmeiras, 3 fontes operando
A10: 7930428001 | B10: =MID(Table12[[#This Row],[Ativo]],1,2) -> 79 | C10: PORTO NACIONAL | D10: PORTO NACIONAL | E10: CENTRO | F10: =IFERROR(_xlfn.XLOOKUP(Table12[[#This Row],[Ativo]],[2]!Pendentes[COD_RELIGADOR],[2]!Pendentes[SS_ORIGINAL]),"CONCLUÍDA") -> ETO-COEP 00150/2026 | G10: Aguardando atualização de informação DMSL | J10: Tanque | K10: =IFERROR(_xlfn.XLOOKUP(Table12[[#This Row],[Ativo]],[2]!Pendentes[COD_RELIGADOR],[2]!Pendentes[DESCRICAO]),"") -> PARECER DMSL DATA 16/07/2026: será necessário fazer a substituição da parte ativa do equipamento.PARECER COEP: Equipamento Funcionando no SCADA , favor reavaliar a necessidade de substituição e se necessário mandar o modelo do equipamento.Segue nota para substituir Taque do RL-7930428001 na LD Porto Nacional / São João, Identificado pela Int-20253617520441 equipamento dando passagem na fase A ficou bay-passado até substituição, Tensão 34,5kva, Acesso livre. | L10: 5 | M10: 5 | N10: 15 | O10: 0 | P10: 15 | Q10: 10 | R10: 0 | S10: 0 | T10: =SUM(Table12[[#This Row],[Premissa 1]:[Premissa 8]]) -> 50 | U10: Alta | V10: Transferência dos Grupos A - Ramal do Rossato (TF 225kVA e TF 750kVA)
A11: 7936038076 | B11: =MID(Table12[[#This Row],[Ativo]],1,2) -> 79 | C11: DUERE | D11: GURUPI | E11: SUL | F11: =IFERROR(_xlfn.XLOOKUP(Table12[[#This Row],[Ativo]],[2]!Pendentes[COD_RELIGADOR],[2]!Pendentes[SS_ORIGINAL]),"CONCLUÍDA") -> CONCLUÍDA | G11: Aguardando atualização de informação DMSL | J11: Tanque | K11: =IFERROR(_xlfn.XLOOKUP(Table12[[#This Row],[Ativo]],[2]!Pendentes[COD_RELIGADOR],[2]!Pendentes[DESCRICAO]),"") | L11: 5 | M11: 5 | N11: 15 | O11: 0 | P11: 15 | Q11: 10 | R11: 0 | S11: 0 | T11: =SUM(Table12[[#This Row],[Premissa 1]:[Premissa 8]]) -> 50 | U11: Alta | V11: Transferência do Grupo A - Xavante (TF 1087,5 kVA) e outros GA menores
A12: 7943790134 | B12: =MID(Table12[[#This Row],[Ativo]],1,2) -> 79 | C12: ESPERANTINA | D12: AUGUSTINOPOLIS | E12: NORTE | F12: =IFERROR(_xlfn.XLOOKUP(Table12[[#This Row],[Ativo]],[2]!Pendentes[COD_RELIGADOR],[2]!Pendentes[SS_ORIGINAL]),"CONCLUÍDA") -> ETO-TELE 00896/2026 | G12: Aguardando comissionamento | J12: Tanque | K12: =IFERROR(_xlfn.XLOOKUP(Table12[[#This Row],[Ativo]],[2]!Pendentes[COD_RELIGADOR],[2]!Pendentes[DESCRICAO]),"") -> PARECER DCMD:Serviço realizado , substituição da parte ativa do RELIGADOR 7943790134 - Favor realizar comissionamento | L12: 15 | M12: 10 | N12: 5 | O12: 15 | P12: 15 | Q12: 10 | R12: 0 | S12: 15 | T12: =SUM(Table12[[#This Row],[Premissa 1]:[Premissa 8]]) -> 85 | U12: Muito Alta | V12: Transferência de Esperantina, fonte principal operando
A13: 5856070091 | B13: =MID(Table12[[#This Row],[Ativo]],1,2) -> 58 | C13: ALMAS | D13: DIANOPOLIS | E13: SUL | F13: =IFERROR(_xlfn.XLOOKUP(Table12[[#This Row],[Ativo]],[2]!Pendentes[COD_RELIGADOR],[2]!Pendentes[SS_ORIGINAL]),"CONCLUÍDA") -> ETO-RD-DP 00479/2026 | G13: Aguardando confirmação em campo sobre o equipamento | H13: Conexão invertida entre fonte e carga | J13: Conexão invertida | K13: =IFERROR(_xlfn.XLOOKUP(Table12[[#This Row],[Ativo]],[2]!Pendentes[COD_RELIGADOR],[2]!Pendentes[DESCRICAO]),"") -> PARECER DMSL: não foi regularizado a instalação do equipamento, nota repassada conforme alinhado com o supervisor.____________________________________________COCMS 26.03.26. SS REPASSADA PARA COEP PROVIDENCIAR MATERIAL. NÃO TEMOS AS PÇ EM ESTOQUE PARA FAZER A SUBSTITUIÇÃO. Solicitação de serviço para reposição de equipamentos furtados .COEP: Equipamento fornecido ao COCM-S para regularização.COCMS: Equipamento substituido conforme solicitado. Gentileza comissionar.PARECER DA PROTEÇÃO:SEGUE NOTA REPASSADA PARA DMSL COMISSIONAR.ENG° IRLLEY CASTELO BRANCOPARECER DMSL(23/09/2025): Feito a parte de comunicação, fechando enlace, configuração do rádio GE. Feito a medição de aterramento. Após uma inspeção, foi identificado que o regulador de tensão está instalado errado, carga está para o lado de fonte e fonte está do lado de carga. O certo é a fonte vim de almas, atualmente está vindo de natividade. Favor fazer a instalação correta. | L13: 40 | M13: 20 | N13: 20 | O13: 20 | P13: 0 | Q13: - | R13: - | S13: - | T13: =SUM(Table12[[#This Row],[Premissa 1]:[Premissa 8]]) -> 100 | U13: Muito Alta | V13: Atendimento da região da Engegold, Nativa, cidade Natividade e Chapada da Natividade
A14: 5803327001 | B14: =MID(Table12[[#This Row],[Ativo]],1,2) -> 58 | C14: PORTO NACIONAL | D14: PORTO NACIONAL | E14: CENTRO | F14: =IFERROR(_xlfn.XLOOKUP(Table12[[#This Row],[Ativo]],[2]!Pendentes[COD_RELIGADOR],[2]!Pendentes[SS_ORIGINAL]),"CONCLUÍDA") -> ETO-COEP 00149/2026 | G14: Aguardando confirmação em campo sobre o equipamento | H14: Foi realizado os serviços apontados pelo DMSL? | J14: Controle e aterramento | K14: =IFERROR(_xlfn.XLOOKUP(Table12[[#This Row],[Ativo]],[2]!Pendentes[COD_RELIGADOR],[2]!Pendentes[DESCRICAO]),"") -> 01/07 PARECER COEP: FOI CONFIRMADO COM A OPERAÇÃO QUE O EQUIPAMENTO SEGUIU O FLUXO INTEIRO DE COMISSIONAMENTO, PROTEÇÃO, FAVOR EXPLICAR O QUE FOI REALIZADO E SE EQUIPAMENTO ESTÁ OPERANDO, SENÃO ESTIVER EXPLICAR O QUE FOI FEITO NELE30/06PARECER COEP: REPASSAR DIRETAMENTE PARA OS COCM'SRegulador 5803327001 fora de operação, by passado em campo com painel de comunicação com cabos desconectados tensão 13.8.parecer DMSL: Feedback Equip. EspeciaisRT 5803327001RELÉ RUASid: 4844Data: 19/09/2025Serviço realizado:*Equipamento foi remanejado, 7 km da sua localização sentido Palmas necessário comissionamento completo*Equipamento com um dos cabos umbilicais danificado.* aterramento bucha FC não esta interligada corretamente * para-raios estão no mesmo aterramento da bucha FC.* Tranques muito alto e próximo da rede não permitindo o comissionamento com segurança.* Controle alto demais tem que baixar Equipamento ficou em operação?: nãoPendência: sim, precisa comissionar completoOBS | L14: 40 | M14: 0 | N14: 0 | O14: 20 | P14: 20 | Q14: - | R14: - | S14: - | T14: =SUM(Table12[[#This Row],[Premissa 1]:[Premissa 8]]) -> 80 | U14: Alta | V14: Em caso de perca da fonte principal é necessário esse RT para alimentação da Frísia
A15: 5854566043 | B15: =MID(Table12[[#This Row],[Ativo]],1,2) -> 58 | C15: SILVANOPOLIS | D15: PORTO NACIONAL | E15: CENTRO | F15: =IFERROR(_xlfn.XLOOKUP(Table12[[#This Row],[Ativo]],[2]!Pendentes[COD_RELIGADOR],[2]!Pendentes[SS_ORIGINAL]),"CONCLUÍDA") -> ETO-PROT 00158/2026 | G15: Em processo de aquisição | J15: 1 célula | K15: =IFERROR(_xlfn.XLOOKUP(Table12[[#This Row],[Ativo]],[2]!Pendentes[COD_RELIGADOR],[2]!Pendentes[DESCRICAO]),"") -> 24/07/2026 - PARECE COCM: EQUIPAMENTO SUBSTITUIDO NA OBRA 0312600352 OS: ETO-RD-PO 1873/202622/07/2026 PARECER COEP: EQUIPAMENTO ENTREGUE AOS COCM´SPRAZO DE 7 DIAS CONTANDO O SLA.PARECER COEP: EQUIPAMENTO ENTREGUE AOS COCM´S FAVOR SUSBSTTUIR , E AGUARDO O PRAZO DE PREVISÃO DE SUBSTIUIÇÃOboa noite,segue SS para as devidas tratativas com equipe de manutenção com apoio de equipe de linha viva substituir regulador de tensão 5854566043 queimado célula fase c, LD Porto / Silvanópolis mesmo deverá ser substituído com apoio de equipe de linha viva PARECER DMSL: Foi realizado inspeção visual e ensaios de isolação, relação de transformação e resistência de enrolamento. A fase B está danificada e será necessário substituir a mesma. Malha de aterramento está relativamente boa e conectada. Fase A e C passaram nos ensaios. Substituir fase B. | L15: 40 | M15: 20 | N15: 20 | O15: 10 | P15: 20 | Q15: - | R15: - | S15: - | T15: =SUM(Table12[[#This Row],[Premissa 1]:[Premissa 8]]) -> 110 | U15: Muito Alta | V15: Aumento de reclamações no atendimento de Silvanópolis por Porto Nacional no período seco (Outra fonte com defeito também)
A16: 7931608059 | B16: =MID(Table12[[#This Row],[Ativo]],1,2) -> 79 | C16: TAQUARALTO | D16: TAQUARALTO | E16: CENTRO | F16: =IFERROR(_xlfn.XLOOKUP(Table12[[#This Row],[Ativo]],[2]!Pendentes[COD_RELIGADOR],[2]!Pendentes[SS_ORIGINAL]),"CONCLUÍDA") -> ETO-COEP 00040/2026 | G16: Em processo de aquisição | J16: Tanque e rádio | K16: =IFERROR(_xlfn.XLOOKUP(Table12[[#This Row],[Ativo]],[2]!Pendentes[COD_RELIGADOR],[2]!Pendentes[DESCRICAO]),"") -> PARECER COEP: EQUIPAMENTO SELECIONADO PARA COMPRADMSL:Serviço Executado: Foi feita uma análise técnica no equipamento, devido à falta de comunicação. Também foi identificado que o tanque do equipamento está danificado, sendo assim, necessário substituir o tanque e o rádio do equipamento, que está queimado, sendo necessário substituir também. | L16: 15 | M16: 20 | N16: 15 | O16: 15 | P16: 15 | Q16: 10 | R16: 0 | S16: 15 | T16: =SUM(Table12[[#This Row],[Premissa 1]:[Premissa 8]]) -> 105 | U16: Muito Alta | V16: Transferência dos bairros Morada do Sol, Vale do Sol, Morada do Sol II, Nova Esperança, Sõa João, Araras I e II e Jardim Laila em Taquaralto (6033 UCs)
A17: 7925744087 | B17: =MID(Table12[[#This Row],[Ativo]],1,2) -> 79 | C17: GOIANORTE | D17: GUARAI | E17: NORTE | F17: =IFERROR(_xlfn.XLOOKUP(Table12[[#This Row],[Ativo]],[2]!Pendentes[COD_RELIGADOR],[2]!Pendentes[SS_ORIGINAL]),"CONCLUÍDA") -> ETO-COEP 00059/2026 | G17: Em processo de aquisição | K17: =IFERROR(_xlfn.XLOOKUP(Table12[[#This Row],[Ativo]],[2]!Pendentes[COD_RELIGADOR],[2]!Pendentes[DESCRICAO]),"") -> PARECER COEP: EQUIPAMENTO SELECIONADO PARA COMPRAPARECER DMSL: FEEDBACK EQUIP. ESPECIAISNº DO EQUIPAMENTO: 7925744087TIPO EQUIPAMENTO: Noja RC 10TIPO DE COMUNICAÇÃO: Radio GE IPDATA DA MANUTENÇÃO: 19/02/2026SID: 735/2026 DESCRIÇÃO: foi identificado água dentro da parte interna do tanque e cabo umbilical encharcado de água foi passado essas informações para COS.FICOU EM OPERAÇÃO?: Não PENDÊNCIA: Sim substituir tanque e cabo umbilicalDADOS DIVERGENTES DA PROGRAMAÇÃO: NãoBATERIA SUBSTITUÍDA?: Não DATA DA BATERIA: 07/05/2025TIPO DE BATERIA: Lítio EQUIPE: Edeglan e Janio-------------------------------------------------------------------------------------------------RELIGADOR SEM COMUNICAÇÃO, APOS PRIMEIRO ATAQUE RETORNA E FICAR INDEFINIDO. | L17: 15 | M17: 20 | N17: 5 | O17: 15 | P17: 15 | Q17: 10 | R17: 0 | S17: 15 | T17: =SUM(Table12[[#This Row],[Premissa 1]:[Premissa 8]]) -> 95 | U17: Muito Alta | V17: Transferência de Goianorte, fonte principal operando
A18: 7900453110 | B18: =MID(Table12[[#This Row],[Ativo]],1,2) -> 79 | C18: SANTA RITA DO TOCANTINS | D18: PORTO NACIONAL | E18: CENTRO | F18: =IFERROR(_xlfn.XLOOKUP(Table12[[#This Row],[Ativo]],[2]!Pendentes[COD_RELIGADOR],[2]!Pendentes[SS_ORIGINAL]),"CONCLUÍDA") -> ETO-COEP 00087/2026 | G18: Em processo de aquisição | H18: Foi redirecionado para priorizar o RL 7933726256 | J18: Tanque | K18: =IFERROR(_xlfn.XLOOKUP(Table12[[#This Row],[Ativo]],[2]!Pendentes[COD_RELIGADOR],[2]!Pendentes[DESCRICAO]),"") -> 10/07/2026 EQUIPAMENTO SELECIONADO PARA COMPRA PARTE ATIVA30/06.PARECER COEP: ALINHADO COM O ALLAN REMANEJAMOS PARTE ATIVA PARA ATENDER 7933726256PARECER COEP: Aproveitar controle cooper se possível em outro local, previsão de chegada do material dia 01/07 para substituiçãoFavor verificar o RL 7900453110, pois o mesmo aceita comando de fechamento, porém fecha em campo e no SCADA continua aberto e só abre através de equipe em campo. Parecer Dmsl:Equipamento está com defeito na parte ativa, não aceita o comando de fechamento. Será necessário substituir o equipamento completo.Equipamento ficou em operação?: _SIM_a pedido do COS ficou em operação, a operação está ciente da necessidade de substituir.Pendência: Sim, será necessário substituir o equipamento. | L18: 15 | M18: 10 | N18: 5 | O18: 15 | P18: 15 | Q18: 10 | R18: 0 | S18: 15 | T18: =SUM(Table12[[#This Row],[Premissa 1]:[Premissa 8]]) -> 85 | U18: Muito Alta | V18: Transferência de Santa Rita, fonte principal operando
A19: 5800371025 | B19: =MID(Table12[[#This Row],[Ativo]],1,2) -> 58 | C19: ARAPOEMA | D19: COLINAS DO TOCANTINS | E19: NORTE | F19: =IFERROR(_xlfn.XLOOKUP(Table12[[#This Row],[Ativo]],[2]!Pendentes[COD_RELIGADOR],[2]!Pendentes[SS_ORIGINAL]),"CONCLUÍDA") -> ETO-TELE 01040/2026 | G19: Em processo de aquisição | J19: Relé e fiquei em duvida sobre kit | K19: =IFERROR(_xlfn.XLOOKUP(Table12[[#This Row],[Ativo]],[2]!Pendentes[COD_RELIGADOR],[2]!Pendentes[DESCRICAO]),"") -> 16/07/2026 PARECER COEP: ALINHADO COM O KELLITON REALIZAR SUBSTITUIÇÃO DO CONTROLE DE TUPIRAMA, ALINHADO COM O JEAN QUE OS CABOS COMPATIBILIZADORES VÃO CHEGAR 16/08 , ATÉ ESSA DATA MANTER ESSA SS E CONTROLE RUA, DEPOIS REPASSAR PARA O DMSLPARECER COEP: AVALIAR COM O LEANDRO, PROVAVELMENTE SÓ COMPRAPARECER DMSL: Após testes foi constatado defeito nos relés da fase A e B, Modelo Toshiba TBR 1000. Se possível, substituir os relés das 3 fases por controle RUA, disponibilizar os cabos de ligação entre o tanque e o controle para possibilitar a compatibilização do equipamento. Fornecer kit de comunicação, rádio, antena, etc.Segue nota para veriifcar falha em regulador de tensão N: 5800371025 dentro S/E Arapoema , equipamento esta com 2 reles com falha marca toshiba .Parecer DCMD: foi substituido célula 30/07/2026. o mesmo está liberado para ser colocado em operação | L19: 0 | M19: 20 | N19: 20 | O19: 10 | P19: 20 | Q19: - | R19: - | S19: - | T19: =SUM(Table12[[#This Row],[Premissa 1]:[Premissa 8]]) -> 70 | U19: Alta | V19: Aumento de reclamações no atendimento de Arapoema no período seco
A20: 7926089013 | B20: =MID(Table12[[#This Row],[Ativo]],1,2) -> 79 | C20: PARAISO DO TOCANTINS | D20: PARAISO DO TOCANTINS | E20: CENTRO | F20: =IFERROR(_xlfn.XLOOKUP(Table12[[#This Row],[Ativo]],[2]!Pendentes[COD_RELIGADOR],[2]!Pendentes[SS_ORIGINAL]),"CONCLUÍDA") -> ETO-COEP 00078/2026 | G20: Em processo de aquisição | J20: Tanque | K20: =IFERROR(_xlfn.XLOOKUP(Table12[[#This Row],[Ativo]],[2]!Pendentes[COD_RELIGADOR],[2]!Pendentes[DESCRICAO]),"") -> PARECER COEP: EQUIPAMENTO SELECIONADO PARA COMPRAPARECER DMSL: Feedback Equip. EspeciaisRLG 7926089013,RELÉ NOJA RC10SID 1805/2026DATA 15/04/2026Serviço Executado: Favor realizar a troca da parte ativa do equipamento --reprogramar para atualizar a base juntamente com escada Equipamento ficou em operação: Não Pendência: sim atualizar a base e subistituir o tanque Bateria(s) substituída(s)? Não Data de Fabricação/Instalação da(s) bateria(s): Equipe: Carliel e João Vitor Fernando e Elson---------------------------------------------------------------------------------ATUALIZAR AJUSTES DO RL 7926089013 LD PARAISO I A PIUM. IMPLEMENTAÇÃO DA FUNÇÃO 27, SUBTENSÃO.AJUSTES DISPONIVEIS NO APP DA PROTEÇÃO. | L20: 15 | M20: 10 | N20: 5 | O20: 15 | P20: 15 | Q20: 10 | R20: 0 | S20: 0 | T20: =SUM(Table12[[#This Row],[Premissa 1]:[Premissa 8]]) -> 70 | U20: Alta | V20: Transferência da RDU de Chapada de Areia (937 UCs) para fonte alternativa
A21: 7927646026 | B21: =MID(Table12[[#This Row],[Ativo]],1,2) -> 79 | C21: PONTE ALTA TOCANTINS | D21: PONTE ALTA TOCANTINS | E21: CENTRO | F21: =IFERROR(_xlfn.XLOOKUP(Table12[[#This Row],[Ativo]],[2]!Pendentes[COD_RELIGADOR],[2]!Pendentes[SS_ORIGINAL]),"CONCLUÍDA") -> ETO-COEP 00029/2026 | G21: Em processo de aquisição | J21: Tanque | K21: =IFERROR(_xlfn.XLOOKUP(Table12[[#This Row],[Ativo]],[2]!Pendentes[COD_RELIGADOR],[2]!Pendentes[DESCRICAO]),"") -> PARECER COEP: EQUIPAMENTO SELECIONADO PARA COMPRARELIGADOR BY PASSADO POR DEFEITO, NECESSÁRIO AVALIAÇÃO DO PROBLEMA.parecer dmsl:O religador apresenta defeito no tanque, sendo necessário substituir o tanque o mesmo está tirando a linha, e troca os isoladores. Quando retornar, trazer uma fonte para o equipamento, a mesma foi removida.FICOU EM OPERAÇÃO? NãoPENDÊNCIA: Sim, aguardando peças para substituição. | L21: 15 | M21: 10 | N21: 5 | O21: 0 | P21: 15 | Q21: 0 | R21: 10 | S21: 0 | T21: =SUM(Table12[[#This Row],[Premissa 1]:[Premissa 8]]) -> 55 | U21: Alta | V21: Opção de isolação de São Félix e Mateiros para alimentação por gerador
A22: 5800859011 | B22: =MID(Table12[[#This Row],[Ativo]],1,2) -> 58 | C22: TUPIRAMA | D22: GUARAI | E22: NORTE | F22: =IFERROR(_xlfn.XLOOKUP(Table12[[#This Row],[Ativo]],[2]!Pendentes[COD_RELIGADOR],[2]!Pendentes[SS_ORIGINAL]),"CONCLUÍDA") -> CONCLUÍDA | G22: Em processo logístico | H22: Aguardando obra COCM | J22: Controle | K22: =IFERROR(_xlfn.XLOOKUP(Table12[[#This Row],[Ativo]],[2]!Pendentes[COD_RELIGADOR],[2]!Pendentes[DESCRICAO]),"") | L22: 40 | M22: 20 | N22: 20 | O22: 10 | P22: 20 | Q22: - | R22: - | S22: - | T22: =SUM(Table12[[#This Row],[Premissa 1]:[Premissa 8]]) -> 110 | U22: Muito Alta | V22: Atendimento de parte da RDU Guaraí por fonte alternativa
A23: 7900117013 | B23: =MID(Table12[[#This Row],[Ativo]],1,2) -> 79 | C23: PARAISO DO TOCANTINS | D23: PARAISO DO TOCANTINS | E23: CENTRO | F23: =IFERROR(_xlfn.XLOOKUP(Table12[[#This Row],[Ativo]],[2]!Pendentes[COD_RELIGADOR],[2]!Pendentes[SS_ORIGINAL]),"CONCLUÍDA") -> ETO-PROT 00154/2026 | G23: Em processo logístico | H23: Previsão de entrega 07/07 | I23: Em andamento | J23: Relé Cooper | K23: =IFERROR(_xlfn.XLOOKUP(Table12[[#This Row],[Ativo]],[2]!Pendentes[COD_RELIGADOR],[2]!Pendentes[DESCRICAO]),"") -> 15/07 PARECER COCM: EQUIPAMENTO FOI SUBSTITUÍDO OBRA 021260042210/07 PARECER COEP: EQUIPAMENTO ENTREGUE AOS COCM´S FAVOR INFORMAR PRAZO DE SUBSTUIÇÃO PARA O DMSL E REPASSAR DEPOIS PARA PROTEÇÃO REALIZAR OS AJUSTES E DESCREVER NA SS O SERVIÇO REALIZADOPARECER COEP: PREVISÃO DE ENTREGA AOS COCM'S 01/07Segue nota para correção de anomalia e provável substituição de religador , religador 7900117013 -RDU - Paraiso .OBS: equipe DMSL Elisfran estava atualizando firmware no equipamento , porém relé parou de funcionar devido essa atualização , sendo necessário sua substituição .em campo o modelo e cooper Form6 , segundo tecnico deve ser substituído por um Noja .Repassado para o COEP para aquisição do equipamento e posterior repasse para o COCM. | L23: 15 | M23: 20 | N23: 15 | O23: 15 | P23: 15 | Q23: 0 | R23: 0 | S23: 15 | T23: =SUM(Table12[[#This Row],[Premissa 1]:[Premissa 8]]) -> 95 | U23: Muito Alta | V23: Transferência do 214R de Paraíso I, Centro Comercial de Paraíso
A24: 7929376022 | B24: =MID(Table12[[#This Row],[Ativo]],1,2) -> 79 | C24: BABACULANDIA | D24: ARAGUAINA | E24: NORTE | F24: =IFERROR(_xlfn.XLOOKUP(Table12[[#This Row],[Ativo]],[2]!Pendentes[COD_RELIGADOR],[2]!Pendentes[SS_ORIGINAL]),"CONCLUÍDA") -> ETO-TELE 01107/2026 | G24: Em processo logístico | H24: Aproveitar tanque sobrando em Palmeirante | I24: Em andamento | K24: =IFERROR(_xlfn.XLOOKUP(Table12[[#This Row],[Ativo]],[2]!Pendentes[COD_RELIGADOR],[2]!Pendentes[DESCRICAO]),"") -> 13/08/2026 PARECER COEP: EQUIPAMENTO FOI TROCADO A PEÇA , CONFIRMAMOS COM O LEONARDO DE ARAGUAÍNA , LAUDO EM ANEXO , FAVOR REALIZAR COMISSIONAMENTOPARECER COEP: PROBLEMA NO ENVIO COCM'S CONTROLE ENVIADO FOI O NOJA , DEVIDO A FALTA DO MODELO NA SS (GRAVE)PARECER DMSL: *FEEDBACK EQUIP. ESPECIAIS**Nº DO EQUIPAMENTO:* 7929376022 *DATA DA MANUTENÇÃO:* 02/04/2026*SID:* 1677/2026*DESCRIÇÃO:* Trocar controle completo*PENDÊNCIA:* Sim.*DADOS DIVERGENTES DA PROGRAMAÇÃO:* Não*BATERIA SUBSTITUÍDA?:* Não*EQUIPE:* Adeilton e Edicleber __________________________________________________________POR GENTILEZA ATENDER SOLICITAÇÃO PRIMEIRO ATAQUE IDENTIFICOU QUE RELE ESTA EM CURTO NOTA ABERTA 224/2026 FOI BAIXADA POREM NÃO FOI CORRIGIDO PROBLEMA EM CAMPO. | L24: 15 | M24: 20 | N24: 5 | O24: 15 | P24: 15 | Q24: 10 | R24: 0 | S24: 15 | T24: =SUM(Table12[[#This Row],[Premissa 1]:[Premissa 8]]) -> 95 | U24: Muito Alta | V24: Transferência de Babaçulândia, fonte principal operando
A25: 7908686014 | B25: =MID(Table12[[#This Row],[Ativo]],1,2) -> 79 | C25: PIUM | D25: PARAISO DO TOCANTINS | E25: CENTRO | F25: =IFERROR(_xlfn.XLOOKUP(Table12[[#This Row],[Ativo]],[2]!Pendentes[COD_RELIGADOR],[2]!Pendentes[SS_ORIGINAL]),"CONCLUÍDA") -> ETO-PROT 00159/2026 | G25: Em processo logístico | H25: Previsão de entrega 07/07 | I25: Em andamento | J25: Tanque | K25: =IFERROR(_xlfn.XLOOKUP(Table12[[#This Row],[Ativo]],[2]!Pendentes[COD_RELIGADOR],[2]!Pendentes[DESCRICAO]),"") -> 24/07 PARECER COCM: EQUIPAMENTO FOI SUBSTITUIDO OBRA 021260042510/07 PARECER COEP: EQUIPAMENTO ENTREGUE AOS COCM´S FAVOR INFORMAR PRAZO DE SUBSTUIÇÃO PARA O DMSL E REPASSAR DEPOIS PARA PROTEÇÃO REALIZAR OS AJUSTES E DESCREVER NA SS O SERVIÇO REALIZADO06/07 PARECER COEP: PREVISÃO DE ENTREGA DE ACORDO COM CALENDÁRIO LOGISITCO NOVO 06/07NOTA DMSL: Favor substituir o tanque, ele não está efetuando os comandos enviados. Não substituir o controle pois o mesmo funciona como repetidor de outros equipamentos.Segue nota para verificar falha de fechamento religador 7908686014- Pium .OBS: equipamento não fechou local e remoto , fica sinalizando no painel para verificar alarmes ! | L25: 15 | M25: 20 | N25: 0 | O25: 15 | P25: 15 | Q25: 10 | R25: 0 | S25: 15 | T25: =SUM(Table12[[#This Row],[Premissa 1]:[Premissa 8]]) -> 90 | U25: Muito Alta | V25: Fonte principal de Pium, RL de transferência operando
A26: 7925087021 | B26: =MID(Table12[[#This Row],[Ativo]],1,2) -> 79 | C26: PARANA | D26: PEIXE | E26: SUL | F26: =IFERROR(_xlfn.XLOOKUP(Table12[[#This Row],[Ativo]],[2]!Pendentes[COD_RELIGADOR],[2]!Pendentes[SS_ORIGINAL]),"CONCLUÍDA") -> ETO-PROT 00152/2026 | G26: Em processo logístico | H26: Previsão de entrega 07/07 | I26: Em andamento | J26: Tanque | K26: =IFERROR(_xlfn.XLOOKUP(Table12[[#This Row],[Ativo]],[2]!Pendentes[COD_RELIGADOR],[2]!Pendentes[DESCRICAO]),"") -> 10/07 PARECER COEP: EQUIPAMENTO ENTREGUE AOS COCM´S FAVOR INFORMAR PRAZO DE SUBSTUIÇÃO PARA O DMSL E REPASSAR DEPOIS PARA PROTEÇÃO REALIZAR OS AJUSTES E DESCREVER NA SS O SERVIÇO REALIZADOPARECER COEP: EM ROTA DE ENTREGA, VERIFICAR PREVISÃO DE CHEGADARealizar a substituição do tanque do equipamento. | L26: 15 | M26: 10 | N26: 5 | O26: 0 | P26: 15 | Q26: 10 | R26: 0 | S26: 15 | T26: =SUM(Table12[[#This Row],[Premissa 1]:[Premissa 8]]) -> 70 | U26: Alta | V26: Primeiro RL do 414R de Paranã, RL a jusante na LD também está bay-passado (630 UCs)
A27: 5801866013 | B27: =MID(Table12[[#This Row],[Ativo]],1,2) -> 58 | C27: PARAISO DO TOCANTINS | D27: PARAISO DO TOCANTINS | E27: CENTRO | F27: =IFERROR(_xlfn.XLOOKUP(Table12[[#This Row],[Ativo]],[2]!Pendentes[COD_RELIGADOR],[2]!Pendentes[SS_ORIGINAL]),"CONCLUÍDA") -> ETO-PROT 00151/2026 | G27: Em processo logístico | H27: Aguardando EMD para envio do material | J27: 1 célula | K27: =IFERROR(_xlfn.XLOOKUP(Table12[[#This Row],[Ativo]],[2]!Pendentes[COD_RELIGADOR],[2]!Pendentes[DESCRICAO]),"") -> 15/07 PARECER COCM, FOI ATENDIDA PELA OS ETO-RD-PS 1616/2026 OBRA-021260053910/07 PARECER COEP: EQUIPAMENTO ENTREGUE AOS COCM´S FAVOR INFORMAR PRAZO DE SUBSTUIÇÃO PARA O DMSL E REPASSAR DEPOIS PARA PROTEÇÃO REALIZAR OS AJUSTES E DESCREVER NA SS O SERVIÇO REALIZADOPARECER COEP: EM PROCESSO DE ENTREGAPARECER DMSL: RT 5801866013Serviço Executado: Feito a medição da malha de terra. Identificado infiltração na caixa de passagem da célula da fase C do banco regulador de tensão, será necessário fazer a substituição da mesma! Ficar atento na hora da substituição, deverá ser substituída a célula do lado da BR.Obs.: Será necessário baixar todo o banco pelo menos um metro, as buchas estão muito próximas a parte energizada não oferecem segurança para equipe no momento do ensaio elétrico.Equipamento ficou em operação?: Não Possui nobreak: SimPossui antena: SimPossui rádio:SimPendência: SimData da bateria: Equipe: Benvindo e Kaique._______________________________________________RT 5801866013BY PASSADO DEVIDO DEFEITO EM CELULA BEMVINDO ESTEVE NO LOCAL JUNTO AO COD .NECESSARIO TRATATIVA PARA MESMA .FASE DANIFICADO C | L27: 0 | M27: 20 | N27: 20 | O27: 20 | P27: 10 | Q27: - | R27: - | S27: - | T27: =SUM(Table12[[#This Row],[Premissa 1]:[Premissa 8]]) -> 70 | U27: Alta | V27: Atendimento da RDU Luzimangues Industrial por fonte alternativa
A28: 7900573047 | B28: =MID(Table12[[#This Row],[Ativo]],1,2) -> 79 | C28: FIGUEIROPOLIS | D28: ALVORADA | E28: SUL | F28: =IFERROR(_xlfn.XLOOKUP(Table12[[#This Row],[Ativo]],[2]!Pendentes[COD_RELIGADOR],[2]!Pendentes[SS_ORIGINAL]),"CONCLUÍDA") -> ETO-PROT 00153/2026 | G28: Em processo logístico | H28: Previsão de entrega 07/07 | I28: Em andamento | J28: Tanque e relé | K28: =IFERROR(_xlfn.XLOOKUP(Table12[[#This Row],[Ativo]],[2]!Pendentes[COD_RELIGADOR],[2]!Pendentes[DESCRICAO]),"") -> 10/07 PARECER COEP: EQUIPAMENTO ENTREGUE AOS COCM´S FAVOR INFORMAR PRAZO DE SUBSTUIÇÃO PARA O DMSL E REPASSAR DEPOIS PARA PROTEÇÃO REALIZAR OS AJUSTES E DESCREVER NA SS O SERVIÇO REALIZADOPARECER COEP: AGUARDANDO COCM'S GERAREM AS OBRAS PARA PODER ENTREGAR MATERIALFavor providenciar manutenção no RL 7900573047, o mesmo estar em curto conforme fotos anexadas. Equipamento ficou bay passado em campo.PARECER DMSL: Equipe: FABIO AP./JOÃO MARCOSData Executada: 15/10/2025Serviço Executado:Foi constatado que o equipamento esta queimado na parte ativa placa, tanque e relé. Por favor fazer a substituição pelo Noja RC10. | L28: 5 | M28: 5 | N28: 15 | O28: 0 | P28: 15 | Q28: 10 | R28: 0 | S28: 15 | T28: =SUM(Table12[[#This Row],[Premissa 1]:[Premissa 8]]) -> 65 | U28: Alta | V28: Transferência da Bunge, Saneatins e secadora
A29: 7953610256 | B29: =MID(Table12[[#This Row],[Ativo]],1,2) -> 79 | C29: MATEIROS | D29: PONTE ALTA TOCANTINS | E29: CENTRO | F29: =IFERROR(_xlfn.XLOOKUP(Table12[[#This Row],[Ativo]],[2]!Pendentes[COD_RELIGADOR],[2]!Pendentes[SS_ORIGINAL]),"CONCLUÍDA") -> ETO-PROT 00157/2026 | G29: Em processo logístico | H29: Aguardando obra COCM | K29: =IFERROR(_xlfn.XLOOKUP(Table12[[#This Row],[Ativo]],[2]!Pendentes[COD_RELIGADOR],[2]!Pendentes[DESCRICAO]),"") -> 24/07/2026 - PARECE COCM: EQUIPAMENTO SUBSTIUIDO NA OS:ETO-RD-PO 2020/202614/07/2026 - PARECER COEP: REALOCAR TANQUE 34,5 SOBRESSALENTE DE PARAÍSO PARA ATENDER PARECER DMSL: Data: 10/03/2026,Serviço Executado: Foi substituído o relé do equipamento, o mesmo estava danificado. Trocado o DPS, o mesmo estava queimado devido ao tanque estar furado. O equipamento ficou em bypass.Equipamento ficou em operação? NãoPendência? Sim, substituir a parte ativa com cordão umbilical.Equipe: Carliel e João VitorSEGUE SS PARA REGULARIZAR AUTOMAÇÃO DO RL 7953610256 NA INTERLIGAÇÃO COM A COELBA (CHAPADA DA MANGABEIRA) - EQUIPE INFOMOU CURTO INTERNO NO GABINETE DJ AC NÃO FECHA | L29: 5 | M29: 5 | N29: 15 | O29: 15 | P29: 0 | Q29: 0 | R29: 10 | S29: 15 | T29: =SUM(Table12[[#This Row],[Premissa 1]:[Premissa 8]]) -> 65 | U29: Alta | V29: Atenidmento da COELBA (Alto potencial de compensação)
A30: 7927169001 | B30: =MID(Table12[[#This Row],[Ativo]],1,2) -> 79 | C30: PORTO NACIONAL | D30: PORTO NACIONAL | E30: CENTRO | F30: =IFERROR(_xlfn.XLOOKUP(Table12[[#This Row],[Ativo]],[2]!Pendentes[COD_RELIGADOR],[2]!Pendentes[SS_ORIGINAL]),"CONCLUÍDA") -> ETO-PROT 00156/2026 | G30: Em processo logístico | H30: Previsão de entrega 07/07 | I30: Em andamento | J30: Tanque | K30: =IFERROR(_xlfn.XLOOKUP(Table12[[#This Row],[Ativo]],[2]!Pendentes[COD_RELIGADOR],[2]!Pendentes[DESCRICAO]),"") -> PARECER COEP: EQUIPAMENTO ENTREGUE, SEGUE SS PARA O COCM´S , PARA REALIZAR O ATENDIMENTO,FAVOR ADICIONAR O PARECER PARA MANDAR PARA PROTEÇÃOSS ANTIGA: 1500/2025 PARECER DMSL: Serviço Executado: Foi verificado que o tanque do equipamento está danificado, sendo necessário substituir o tanque do equipamento.Equipamento ficou em operação?: NãoPendência: Sim, instalar fonte, disjuntor e DPS, e substituir o tanque.***** Parecer COCM******Subsituido Tranque do RL pela Ordem de Serviço DLP-MPPA01 247/2026 RELATORIO EM ANEXO DA O.S EXECUTORA | L30: 5 | M30: 5 | N30: 15 | O30: 0 | P30: 15 | Q30: 0 | R30: 0 | S30: 15 | T30: =SUM(Table12[[#This Row],[Premissa 1]:[Premissa 8]]) -> 55 | U30: Alta | V30: Transferência dos Grupos A - VLI e Frisia
A31: 7955520116 | B31: =MID(Table12[[#This Row],[Ativo]],1,2) -> 79 | C31: CHAPADA DA NATIVIDADE | D31: DIANOPOLIS | E31: SUL | F31: =IFERROR(_xlfn.XLOOKUP(Table12[[#This Row],[Ativo]],[2]!Pendentes[COD_RELIGADOR],[2]!Pendentes[SS_ORIGINAL]),"CONCLUÍDA") -> CONCLUÍDA | G31: Em processo logístico | H31: Aguardando obra COCM e PARECER DO DMSL | J31: Tanque | K31: =IFERROR(_xlfn.XLOOKUP(Table12[[#This Row],[Ativo]],[2]!Pendentes[COD_RELIGADOR],[2]!Pendentes[DESCRICAO]),"") | L31: 5 | M31: 5 | N31: 15 | O31: 0 | P31: 0 | Q31: 10 | R31: 0 | S31: 15 | T31: =SUM(Table12[[#This Row],[Premissa 1]:[Premissa 8]]) -> 50 | U31: Alta | V31: Transferência do Grupo A - Engegold (TF 7500 kVA)
A32: 7931610122 | B32: =MID(Table12[[#This Row],[Ativo]],1,2) -> 79 | C32: PALMAS | D32: PALMAS | E32: CENTRO | F32: =IFERROR(_xlfn.XLOOKUP(Table12[[#This Row],[Ativo]],[2]!Pendentes[COD_RELIGADOR],[2]!Pendentes[SS_ORIGINAL]),"CONCLUÍDA") -> CONCLUÍDA | G32: Equipamento entregue ao COCM | I32: Em andamento | J32: Tanque e antena | K32: =IFERROR(_xlfn.XLOOKUP(Table12[[#This Row],[Ativo]],[2]!Pendentes[COD_RELIGADOR],[2]!Pendentes[DESCRICAO]),"") | L32: 15 | M32: 20 | N32: 15 | O32: 15 | P32: 15 | Q32: 10 | R32: 0 | S32: 15 | T32: =SUM(Table12[[#This Row],[Premissa 1]:[Premissa 8]]) -> 105 | U32: Muito Alta | V32: Transferência entre 284R SE Palmas IV e 2294R SE Palmas II
A33: 7908705049 | B33: =MID(Table12[[#This Row],[Ativo]],1,2) -> 79 | C33: AURORA DO TOCANTINS | D33: DIANOPOLIS | E33: SUL | F33: =IFERROR(_xlfn.XLOOKUP(Table12[[#This Row],[Ativo]],[2]!Pendentes[COD_RELIGADOR],[2]!Pendentes[SS_ORIGINAL]),"CONCLUÍDA") -> ETO-RD-DP 00409/2026 | G33: Equipamento entregue ao COCM | H33: Previsão para substituição | I33: Em andamento | J33: Tanque e relé | K33: =IFERROR(_xlfn.XLOOKUP(Table12[[#This Row],[Ativo]],[2]!Pendentes[COD_RELIGADOR],[2]!Pendentes[DESCRICAO]),"") -> EQUIPAMENTO ENTREGUE, SOLICITO PREVISÃO PARA SUBSTITUIÇÃO:PARECER COEP: PREVISÃO DE ENTREGA AOS COCM'S 01/07Manutenção no RL 7908705049PARECER DMSL(28/08/2025): Equipe foi fazer manutenção no RL e constatou que o tanque e o relé do mesmo se encontra queimado, providenciar substituição.PARECER COCMS 30/04/2026CRIADO OBRA 0512600135 PARA REQUISIÇÃO MATERIAL | L33: 15 | M33: 20 | N33: 5 | O33: 15 | P33: 15 | Q33: 0 | R33: 10 | S33: 15 | T33: =SUM(Table12[[#This Row],[Premissa 1]:[Premissa 8]]) -> 95 | U33: Muito Alta | V33: Proteção da baixa do TF de força da SE Aurora
A34: 7933726256 | B34: =MID(Table12[[#This Row],[Ativo]],1,2) -> 79 | C34: MATEIROS | D34: PONTE ALTA TOCANTINS | E34: CENTRO | F34: =IFERROR(_xlfn.XLOOKUP(Table12[[#This Row],[Ativo]],[2]!Pendentes[COD_RELIGADOR],[2]!Pendentes[SS_ORIGINAL]),"CONCLUÍDA") -> ETO-SE-PCM 00092/2026 | G34: Equipamento entregue ao COCM | H34: Destinada parte ativa do RL 7900453110 | I34: Em andamento | K34: =IFERROR(_xlfn.XLOOKUP(Table12[[#This Row],[Ativo]],[2]!Pendentes[COD_RELIGADOR],[2]!Pendentes[DESCRICAO]),"") -> 17/08/2026 PARECER DA PROTEÇÃO:NOTA REPASSADA PARA DMSL COMISSIONARENG° IRLLEY CASTELO BRANCO07/07 Equipamento foi substituido na OS: ETO-RD-PO 1859/2026 OBRA 031260035101/07 PARECER COEP: REDIRECIONADO PARA O POSTO DO COCM´S EQUIPAMENTO CHEGOU NO LOCAL, FAVOR ENTRAR EM CONTATO COM O DMSL, DEVIDO A URGÊNCIA DO EQUIPAMENTO EM OPERAÇÃO.30/06 PARECER COEP: DEVIDO A ALINHAMENTO COM COI UTILIZAREMOS PARTE ATIVA QUE ORIGINALMENTE FOI ENCOMENDADA PARA 7933726256PARECER DMSL: N° do Equipamento: _RLG 7933726256 MateirosTipo de Equipamento: _RLG NOJA RC 10 REL IIData: _06/05/2026SID: _2288/2026-Serviço Executado: _Equipamento com defeito na parte ativa, será necessário fazer a substituição da parte ativa e fazer melhoria na malha de terra!Equipamento ficou em operação?: _NaoPendência: _SimBateria(s) substituída(s)? NÃOData Fabricação/Instalação da(s) bateria(s):_06/2025Equipe: _Benvindo e Almir-------------------------------------------------------------------------------Religador 7933726256, sem comunicação apos primeiroa ataque não retornou as comunicação. | L34: 15 | M34: 10 | N34: 15 | O34: 15 | P34: 15 | Q34: 10 | R34: 0 | S34: 15 | T34: =SUM(Table12[[#This Row],[Premissa 1]:[Premissa 8]]) -> 95 | U34: Muito Alta | V34: Transferência da cidade de Mateiros (733 UCs) para o gerador
A35: 7933766059 | B35: =MID(Table12[[#This Row],[Ativo]],1,2) -> 79 | C35: TAQUARALTO | D35: TAQUARALTO | E35: CENTRO | F35: =IFERROR(_xlfn.XLOOKUP(Table12[[#This Row],[Ativo]],[2]!Pendentes[COD_RELIGADOR],[2]!Pendentes[SS_ORIGINAL]),"CONCLUÍDA") -> CONCLUÍDA | G35: Equipamento entregue ao COCM | I35: Em andamento | J35: Tanque | K35: =IFERROR(_xlfn.XLOOKUP(Table12[[#This Row],[Ativo]],[2]!Pendentes[COD_RELIGADOR],[2]!Pendentes[DESCRICAO]),"") | L35: 15 | M35: 20 | N35: 5 | O35: 15 | P35: 15 | Q35: 0 | R35: 10 | S35: 15 | T35: =SUM(Table12[[#This Row],[Premissa 1]:[Premissa 8]]) -> 95 | U35: Muito Alta | V35: Seccionamento de trecho do Setor Taquari
A36: 7900594026 | B36: =MID(Table12[[#This Row],[Ativo]],1,2) -> 79 | C36: PONTE ALTA TOCANTINS | D36: PONTE ALTA TOCANTINS | E36: CENTRO | F36: =IFERROR(_xlfn.XLOOKUP(Table12[[#This Row],[Ativo]],[2]!Pendentes[COD_RELIGADOR],[2]!Pendentes[SS_ORIGINAL]),"CONCLUÍDA") -> ETO-SE-PA 00107/2026 | G36: Equipamento entregue ao COCM | H36: Previsão para substituição 10/07 | I36: Em andamento | K36: =IFERROR(_xlfn.XLOOKUP(Table12[[#This Row],[Ativo]],[2]!Pendentes[COD_RELIGADOR],[2]!Pendentes[DESCRICAO]),"") -> PARECER DA PROTEÇÃO:16/07/2026 AJUSTES DISPONIBILIZADOS NO APP DA PROTEÇÃO15/07/2026 EQUIPAMENTO SUBSTITUIDO NA OS ETO-RD-PO 1860 OBRA 031260035414/07/2026 PARECER COCM/ COEP: DE ACORDO COM O EDSON CURCINO FOI FEITA S SUBSTITUIÇÃO DO EQUIPAMENTO , SEGUE PARA PROTEÇÃO ELABORAR AJUSTE10/07 PARECER COEP: EQUIPAMENTO DESLOCADO QUE ESTAVA EM GUARAÍ FOI ALINHADO COM O VALMOR QUE SERIA SUBSTITUIDO DIA 07/07/2026 , FAVOR PASSAR PARA PROTEÇÃO 7900594026PARECER COEP: AGUARDANDO COCM'S PARA ABRIR REQUISIÇÃOPARECER DMSL 10/06/2026: Tem uma nota aberta para esse equipamento solicitando a substituição desde 20/10/2025, como a nota não foi atendida estamos repassando para área responsável. Nota em aberto repassada ETO-COEP 210/2025.Segue nota para verificar intermitência de comunicação nos religadores 7908301026 , 7911120026, 7947959026 , 7908692026, 7900594026 rural- Ponte Alta . | L36: 15 | M36: 20 | N36: 15 | O36: 15 | P36: 15 | Q36: 0 | R36: 0 | S36: 15 | T36: =SUM(Table12[[#This Row],[Premissa 1]:[Premissa 8]]) -> 95 | U36: Muito Alta | V36: Religador responsável pela proteção da barra da SE Ponte Alta (2381 UCs)
A37: 7900230155 | B37: =MID(Table12[[#This Row],[Ativo]],1,2) -> 79 | C37: PALMEIRANTE | D37: COLINAS DO TOCANTINS | E37: NORTE | F37: =IFERROR(_xlfn.XLOOKUP(Table12[[#This Row],[Ativo]],[2]!Pendentes[COD_RELIGADOR],[2]!Pendentes[SS_ORIGINAL]),"CONCLUÍDA") -> ETO-TELE 01131/2026 | G37: Execução COCM´s | H37: ETO-682/2026 | J37: Tanque e PR do trafo e chave | K37: =IFERROR(_xlfn.XLOOKUP(Table12[[#This Row],[Ativo]],[2]!Pendentes[COD_RELIGADOR],[2]!Pendentes[DESCRICAO]),"") -> PARECER DA PROTEÇÃO - 17/08/2026:SEGUE NOTA PARA COMISSIONAMENTO JUNTO COM TIME SCADA, EQUIPAMENTO JA NO DESENHO ADMS.ENG° IRLLEY CASTELO BRANCO07/07/2026 PARECER COEP: MATERIAL ENVIADO , CONFORME ALINHANDO COM O WANDER REALIZAR SUBSTIUIÇÂO DO EQUIPAMENTO, FAVOR ESCREVER PARECER COCM ANTES DE PASSAR PARA PROTEÇÂO, DO QUE FOI REALIZADO01/07/2026 PARECER COEP: PROBLEMA NO ENVIO DO MATERIAL PARECER DMSL: Religador está com o tanque danificado. Não responde a comandos abertura e fechamento local ou remoto, pois está com sinal de curto circuito. Necessário trocar o equipamento. Para raio do trafo está queimado. Chave de saída da fase C está com o olhal quebrado, necessário substituir a chave. Equipamento ficou bypassado em campo. Aberto entrada e saída, com exceção da fase C de saída que ficou fechada. Favor, substituir equipamento completo por NOJA RC10 e sanar demais pendencias.Senhores Favor verificar RL 7900230155 o mesmo sinalizou aberto no SCADA porem a cidade de Palmeirante estava normal , feito um reset no rl e o mesmo subiu fechado.08/07/2026 PARECER DCMD: EQUIPE ETO-LVGR01 DE GUARAI ESTEVE NO RL 7900230155 DIA 25-06-2026 E FEZ TODAS A PENDENCIAS DO RL, OBS: EQUIPE SO NAO CONECTOU O CABO DO TRAFO NO RL. RL ESTA PRONTO PARA O COMISSIONAMENTO | L37: 15 | M37: 20 | N37: 5 | O37: 15 | P37: 0 | Q37: 10 | R37: 0 | S37: 15 | T37: =SUM(Table12[[#This Row],[Premissa 1]:[Premissa 8]]) -> 80 | U37: Muito Alta | V37: Fonte principal de Palmeirante, RL de transferência operando
A38: 5865120195 | B38: =MID(Table12[[#This Row],[Ativo]],1,2) -> 58 | C38: CENTENARIO | D38: GUARAI | E38: NORTE | F38: =IFERROR(_xlfn.XLOOKUP(Table12[[#This Row],[Ativo]],[2]!Pendentes[COD_RELIGADOR],[2]!Pendentes[SS_ORIGINAL]),"CONCLUÍDA") -> ETO-TELE 01132/2026 | G38: Melhoria de aterramento | J38: Melhoria de aterramento | K38: =IFERROR(_xlfn.XLOOKUP(Table12[[#This Row],[Ativo]],[2]!Pendentes[COD_RELIGADOR],[2]!Pendentes[DESCRICAO]),"") -> PARECER DMSL:PENDÊNCIA: Realizar melhoria no aterramento por ser tratar de um terreno muito arenoso, e há pendências por parte do time da proteção, os ajustes do RT não estão disponíveis para inserção no referido equipamento.DATA DA MANUTENÇÃO: 12/03/202EQUIPE: Brunno e Edeglan.***********************PARECER DA PROTEÇÃO - 17/08/2026:FAVOR COMISSIONAR REGULADOR 5865120195 – LD Santa Maria Ramal Centenário e Recursolândia – 34,5kV. AJUSTE REALIZADO, DISPONÍVEL NO APP DA PROTEÇÃO.*********************** INSTALADO NA OBRA 0702400720 GENTILEZA, REALIZAR O COMISSIONAMENTO.LAUDO EM ANEXO.COORD EO: 889017, 901685708-07-2026 PARECER: FOI FEITO A MELHORIA NO REGULADOR CONFORME FOTOS EM ANEXO. | L38: 20 | M38: 20 | N38: 20 | O38: 10 | P38: 0 | Q38: - | R38: - | S38: - | T38: =SUM(Table12[[#This Row],[Premissa 1]:[Premissa 8]]) -> 70 | U38: Alta | V38: Atendimento das RDUs de Centenário, Recursolândia e clientes rurais
A39: 5853360007 | B39: =MID(Table12[[#This Row],[Ativo]],1,2) -> 58 | C39: MIRACEMA DO TOCANTINS | D39: MIRACEMA DO TOCANTINS | E39: CENTRO | F39: =IFERROR(_xlfn.XLOOKUP(Table12[[#This Row],[Ativo]],[2]!Pendentes[COD_RELIGADOR],[2]!Pendentes[SS_ORIGINAL]),"CONCLUÍDA") -> ETO-RD-PS 00323/2025 | G39: Problema na autorização de passagem | H39: Cliente não autorizou entrar na propriedade | J39: Melhoria de aterramento | K39: =IFERROR(_xlfn.XLOOKUP(Table12[[#This Row],[Ativo]],[2]!Pendentes[COD_RELIGADOR],[2]!Pendentes[DESCRICAO]),"") -> REALIZAR TESTES NO EQUIPAMENTO E CONFERIR MEDIÇÕES DA MALHA DE ATERRAMENTO. ESTANDO OK, COMISSIONAR EQUIPAMENTO E COLOCA-LO EM OPERAÇÃO.AJUSTES DISPONIVEIS NO APP DA PROTEÇÃdmsl : N° do Equipamento:*RT 5853360007 MIRACEMASID: 2493/2025Data: 13/05/2025Serviço Executado Provavelmente ocorreu uma descarga no equipamento comprometendo a malha!Será necessário fazer melhoria da malha de aterramento, fazer toda interligação da mesma! Feito ensaios de isolação das 3 células do equipamento, isolação está ok, quando retornar para colocar em operação levar 3 baterias de 7a.Equipamento ficou em operação?: Não Equipe: Benvindo e Jardel | L39: 0 | M39: 20 | N39: 20 | O39: 10 | P39: 20 | Q39: - | R39: - | S39: - | T39: =SUM(Table12[[#This Row],[Premissa 1]:[Premissa 8]]) -> 70 | U39: Alta | V39: Aumento de reclamações no atendimento de Miracema no período seco
A40: 5800291077 | B40: =MID(Table12[[#This Row],[Ativo]],1,2) -> 58 | C40: GOIATINS | D40: ARAGUAINA | E40: NORTE | F40: =IFERROR(_xlfn.XLOOKUP(Table12[[#This Row],[Ativo]],[2]!Pendentes[COD_RELIGADOR],[2]!Pendentes[SS_ORIGINAL]),"CONCLUÍDA") -> CONCLUÍDA | I40: Ok | K40: =IFERROR(_xlfn.XLOOKUP(Table12[[#This Row],[Ativo]],[2]!Pendentes[COD_RELIGADOR],[2]!Pendentes[DESCRICAO]),"") | L40: 40 | M40: 20 | N40: 20 | O40: 20 | P40: 20 | Q40: - | R40: - | S40: - | T40: =SUM(Table12[[#This Row],[Premissa 1]:[Premissa 8]]) -> 120 | U40: Muito Alta | V40: Aumento de reclamações no atendimento de Goiatins e GAs relevantes na região
...

Sheet BASE SS_OS
A1: NUMERO_SS | B1: NUMERO_OS | C1: NUM_OBRA | D1: ORIGEM_SS | E1: DEFEITO_SS | F1: ORIGEM | G1: DEFEITO | H1: ESQUEMA | I1: TASK | J1: ANO | K1: ORG_SOLIC | L1: COD_EQUIPE | M1: ALIMENTADOR | N1: NUM_TRAFO | O1: COORD_X | P1: COORD_Y | Q1: COD_GIS | R1: CRITICIDADE_SS | S1: SITUACAO_SS | T1: DATA_ABERTURA_SS | U1: DATA_TERMINO_SS | V1: DATA_LIMITE_SS | W1: DESCICAO_DO_ATIVO | X1: LOCALIDADE | Y1: SOLICITANTE | Z1: RURA_URBANO | AA1: TIPOSS | AB1: DESCRIPTION
A2: ETO-COEP 00117/2026 | J2: 2026 | K2: COI | L2: ETO-COEP | M2: LD05028074 | N2: 5800090147 | O2: 941293 | P2: 8659898 | Q2: 190-15787264 | R2: EMERGENCIAL | S2: SS PENDENTE | T2: 46188.582 | V2: 46191.582 | W2: REGULADOR DE TENSAO DE DIST. - 34.5 | X2: TAIPAS DO TOCANTINS | Y2: ZENILSON MOREIRA SANTOS | Z2: RURAL | AA2: INDISPONIBILIDADE PARA OPERAÇÃO | AB2: PARECER COEP: AGUARDANDO RETORNO DO DMSLREGULADOR 5800090147 SEM COMUNICAÇÃO E TRAVANDO TAP´S - REALIZAO PRIMEIRO ATAQUE SEM SUCESSO.PARECER DMSL: Favor, substituir a célula da fase C do RT 5800090147 pois o microswitch que renconhece o neutro do regulador está com defeito.Equipamento ficou operando devido ser possível manobrar de forma manual.
A3: ETO-RD-PO 00097/2026 | J3: 2026 | K3: MANUT | L3: ETO-RD-PO | M3: LD01051035 | N3: 5800291035 | O3: 819396 | P3: 8780710 | Q3: 190-30990216 | R3: PROGRAMAVEL | S3: SS PENDENTE | T3: 46112.442 | V3: 46512.442 | W3: REGULADOR DE TENSAO DE DIST. - 34.5 | X3: MONTE DO CARMO | Y3: JULIA GRAZYELLE BRITO OLIVEIRA | Z3: RURAL | AA3: INDISPONIBILIDADE PARA OPERAÇÃO | AB3: PARECER DMSL: Feito testes funcionais nas 3 células do banco as mesmas corresponderam aos testes. Será necessário fazer a correção da malha de terra, baixar o banco completo pois está muito alto dificultando as atividades da equipe, substituir as 3 chaves facas do lado Fonte e as 3 do lado Carga instalar suporte inclinado das chaves para facilitar as manobras. Colocar cinta no controle RUA abaixar o mesmo, pois está muito alto e fixado com um mosquetão oval, quando retornar para colocar em operação levar 3 baterias de 7a e rele rua.Obs.: Fizeram melhoria na malha de terra, mas não está dentro do aceitável! As outras pendências continuam, favor corrigir. Equipamento ficou em operação?: Não - Equipe: Benvindo e Kaique- SS ANTIGA ETO-TELE 358/2026
A4: ETO-COEP 00187/2025 | D4: REGULADOR DE TENSÃO | E4: ILEGÍVEL | J4: 2025 | K4: COI | L4: ETO-COEP | M4: LD02010153 | N4: 5800371025 | O4: 714151 | P4: 9152942 | Q4: 190-15773574 | R4: EMERGENCIAL | S4: SS PENDENTE | T4: 45905.614 | V4: 45908.614 | W4: REGULADOR DE TENSAO DE DIST. - 34.5 | X4: ARAPOEMA | Y4: DIOMAR FERREIRA PEREIRA | Z4: URBANO | AA4: INDISPONIBILIDADE PARA OPERAÇÃO | AB4: PARECER COEP: AVALIAR COM O LEANDRO, PROVAVELMENTE SÓ COMPRAPARECER DMSL: Após testes foi constatado defeito nos relés da fase A e B, Modelo Toshiba TBR 1000. Se possível, substituir os relés das 3 fases por controle RUA, disponibilizar os cabos de ligação entre o tanque e o controle para possibilitar a compatibilização do equipamento. Fornecer kit de comunicação, rádio, antena, etc.Segue nota para veriifcar falha em regulador de tensão N: 5800371025 dentro S/E Arapoema , equipamento esta com 2 reles com falha marca toshiba .
A5: ETO-RD-DP 00404/2026 | D5: REGULADOR DE TENSÃO | E5: ILEGÍVEL | J5: 2026 | K5: COI | L5: ETO-RD-DP | M5: LD04002091 | N5: 5800438116 | O5: 859820 | P5: 8711174 | Q5: 190-32303850 | R5: PROGRAMAVEL | S5: SS PENDENTE | T5: 46204.504 | V5: 46604.504 | W5: REGULADOR DE TENSAO DE DIST. - 34.5 | X5: CHAPADA DA NATIVIDADE | Y5: DIOMAR FERREIRA PEREIRA | Z5: RURAL | AA5: INDISPONIBILIDADE PARA OPERAÇÃO | AB5: 01/07 PARECER COEP: DENER INFORMOU QUE TEM AS PEÇAS SOBRESSALENTES DE OBRA PARA UTILIZAR, REPASSEREI AO POSTO DO ETO-RD-DP PARA AS TRATATIVAS, FAVOR INFORMAR PREVISÃO DE SUBSTIUIÇÃO E PREENCHER A PLANILHA ASSIM COMO PREENCHER A DESCRIÃO ANTES DE PASSAR PARA PROTEÇÃO FAZER OS AJUSTES30/06PARECER COEP: AGUARDANDO COCM'S CRIAREM OBRA PARA ENTREGA DO MATERIALSegue nota para normalizar falha em regulador N:5800438116 - Chapada da natividade .equipamento está com fase B e C travada .OBS: a fase B esta sinalizando falha , equipamento não insere TAP negativo na fase B e C , o mesmo ficou no TAP zerado e bloqueado .PARECER DMSL (18/08/2025): Foi feito teste de elevar e abaixar nas fases B e C e o mesmo só aceita elevar os taps, constatando que o mercanismo da chave reversoura polaridade está com defeito. Número de série fase B EI7030 e Número de série fase C EI7040. Substituir as fases B e C.Foi constatado que a placa F do controle está com defeito.
A6: ETO-COEP 00115/2026 | D6: DEFEITO ELETRICO | E6: RELÉ REGULADOR DE TENSÃO | J6: 2026 | K6: COI | L6: ETO-COEP | M6: AL01065015 | N6: 5800859011 | O6: 797626 | P6: 9011795 | Q6: 190-15787179 | R6: EMERGENCIAL | S6: SS PENDENTE | T6: 46185.625 | V6: 46188.625 | W6: REGULADOR DE TENSAO DE DIST. - 13.8 | X6: TUPIRAMA | Y6: DELIO NUNES OSCAR | Z6: RURAL | AA6: INDISPONIBILIDADE PARA OPERAÇÃO | AB6: PARECER COEP: EQUIPAMENTO EM ROTA DE ENTREGAPARECER DMSL: *FEEDBACK EQUIP. ESPECIAIS**Nº DO EQUIPAMENTO:* 5800859011*TIPO EQUIPAMENTO:* RT ITB *TIPO DE COMUNICAÇÃO:* Não *DATA DA MANUTENÇÃO:* 09/06/2026*SID:* 3195/2026*DESCRIÇÃO:* _ Foi identificado relé da fase C com defeito conforme orientação da supervisão e necessário realiza retrofit para instalação de controle rua.*FICOU EM OPERAÇÃO* Não*PENDÊNCIA:* Realizado Retrofit *DADOS DIVERGENTES DA PROGRAMAÇÃO:* Não*BATERIA SUBSTITUÍDA?:* Não*TIPO DE BATERIA:**EQUIPE:* Edeglan e Brunno.Observação: trocar por um controle RUA.------------------------------------------------------------------------------------------Enviar equipe do DMSL, para fazer correção no RT 5800859011, o mesmo está com o displey da fase C apagado , dificutando realizar manobras no mesmo, emvirtude disso o mesmo ficou BAY PASSADO EM CAMPO
A7: ETO-COEP 00221/2025 | J7: 2025 | K7: SCADA | L7: ETO-COEP | M7: LD03028074 | N7: 5800961074 | O7: 971526 | P7: 8714400 | Q7: 190-15814905 | R7: PROGRAMAVEL | S7: SS PENDENTE | T7: 45996.663 | V7: 46396.663 | W7: REGULADOR DE TENSAO DE DIST. - 34.5 | X7: DIANOPOLIS | Y7: LARA SOARES FARIAS | Z7: RURAL | AA7: INDISPONIBILIDADE PARA OPERAÇÃO | AB7: PARECER COEP: EQUIPAMENTO SELECIONADO PARA COMPRASubstituir as 3 células- Melhoria na malha de aterramento - Melhoria no circuito de aterramento qua aterra as células.- Substituir conectores paralelos
A8: ETO-COEP 00077/2026 | D8: EQUIPAMENTO | E8: QUEIMADO | J8: 2026 | K8: COI | L8: ETO-COEP | M8: AL03062013 | N8: 5801866013 | O8: 733022 | P8: 8870961 | Q8: 190-35644534 | R8: EMERGENCIAL | S8: SS PENDENTE | T8: 46132.325 | V8: 46135.325 | W8: REGULADOR DE TENSAO DE DIST. - 13.8 | X8: PARAISO DO TOCANTINS | Y8: Felipe Batista Ferrreira | Z8: RURAL | AA8: INDISPONIBILIDADE PARA OPERAÇÃO | AB8: PARECER COEP: EM PROCESSO DE ENTREGAPARECER DMSL: RT 5801866013Serviço Executado: Feito a medição da malha de terra. Identificado infiltração na caixa de passagem da célula da fase C do banco regulador de tensão, será necessário fazer a substituição da mesma! Ficar atento na hora da substituição, deverá ser substituída a célula do lado da BR.Obs.: Será necessário baixar todo o banco pelo menos um metro, as buchas estão muito próximas a parte energizada não oferecem segurança para equipe no momento do ensaio elétrico.Equipamento ficou em operação?: Não Possui nobreak: SimPossui antena: SimPossui rádio:SimPendência: SimData da bateria: Equipe: Benvindo e Kaique._______________________________________________RT 5801866013BY PASSADO DEVIDO DEFEITO EM CELULA BEMVINDO ESTEVE NO LOCAL JUNTO AO COD .NECESSARIO TRATATIVA PARA MESMA .FASE DANIFICADO C
A9: ETO-RD-PA 00434/2026 | D9: FORA DE SERVIÇO | E9: RELÉ REGULADOR DE TENSÃO | J9: 2026 | K9: COI | L9: ETO-RD-PA | M9: AL01102271 | N9: 5803327001 | O9: 770823 | P9: 8872358 | Q9: 190-15851809 | R9: EMERGENCIAL | S9: SS PENDENTE | T9: 46204.507 | V9: 46207.507 | W9: REGULADOR DE TENSAO DE DIST. - 13.8 | X9: PORTO NACIONAL | Y9: HELDER SILVA CARVALHO | Z9: RURAL | AA9: INDISPONIBILIDADE PARA OPERAÇÃO | AB9: 01/07 PARECER COEP: FOI CONFIRMADO COM A OPERAÇÃO QUE O EQUIPAMENTO SEGUIU O FLUXO INTEIRO DE COMISSIONAMENTO, PROTEÇÃO, FAVOR EXPLICAR O QUE FOI REALIZADO E SE EQUIPAMENTO ESTÁ OPERANDO, SENÃO ESTIVER EXPLICAR O QUE FOI FEITO NELE30/06PARECER COEP: REPASSAR DIRETAMENTE PARA OS COCM'SRegulador 5803327001 fora de operação, by passado em campo com painel de comunicação com cabos desconectados tensão 13.8.parecer DMSL: Feedback Equip. EspeciaisRT 5803327001RELÉ RUASid: 4844Data: 19/09/2025Serviço realizado:*Equipamento foi remanejado, 7 km da sua localização sentido Palmas necessário comissionamento completo*Equipamento com um dos cabos umbilicais danificado.* aterramento bucha FC não esta interligada corretamente * para-raios estão no mesmo aterramento da bucha FC.* Tranques muito alto e próximo da rede não permitindo o comissionamento com segurança.* Controle alto demais tem que baixar Equipamento ficou em operação?: nãoPendência: sim, precisa comissionar completoOBS; reprogramar equipamento.Bateria(s) substituída(s) NÃOEquipe: Ellisfran, Ana Maria PARECER DMSL: Data 03/12/2025-Equipe: Carliel e BenvindoServiço executado foi ensaiado as três células Equipamento ficou em operação: Não Pendência: sim, Instalar controle completo, e fazer melhoria na malhar de aterramento
A10: ETO-RD-PS 00289/2026 | D10: OUTROS | J10: 2026 | K10: MANUT | L10: ETO-RD-PS | M10: LD01062013 | N10: 5827102054 | O10: 730120 | P10: 8847453 | Q10: 190-15843147 | R10: ALTA | S10: SS PENDENTE | T10: 46202.723 | V10: 46262.723 | W10: REGULADOR DE TENSAO DE DIST. - 34.5 | X10: PUGMIL | Y10: JULIA GRAZYELLE BRITO OLIVEIRA | Z10: RURAL | AA10: INDISPONIBILIDADE PARA OPERAÇÃO | AB10: PARECER COEP:NÃO É POSSÍVEL RETORNAR COM O CONTROLE COMPLETO , MAS DARIA PARA FAZER A MELHORIA NA MALHA DE ATERRAMENTO , ENCAMINHANDO PARA OS COCM'S PARA REALIZAREM A MELHORIAparecer DMSL: :Nobreack com defeito, rele queimado, cabo de comunicação entre o rádio e o rele danificado, malha de aterramento está com a resistência alta!Feito reparo no cabo, substituído nobreack, e rele. Se possível retornar com controle completo pq o q está em campo teve infiltração de água, abrir chamado no scada para atualizar base do equipamento pois o mesmo está com a base antiga, fazer correção da malha de aterramento.Equipamento ficou em operação?: Não Pendência: sim, levar controle novo, fazer correção da malha de terra, levar suporte para fixar antena. OBS; reprogramar equipamento.Bateria(s) substituída(s) simEquipe: Benvindo e Carliel SOLICITAMOS CONTROLE COMPLETO
A11: ETO-COEP 00095/2026 | D11: REGULADOR DE TENSÃO | E11: ILEGÍVEL | J11: 2026 | K11: COI | L11: ETO-COEP | M11: LD01066094 | N11: 5836786094 | O11: 782353 | P11: 8664418 | Q11: 190-34648613 | R11: EMERGENCIAL | S11: SS PENDENTE | T11: 46160.578 | V11: 46163.578 | W11: REGULADOR DE TENSAO DE DIST. - 34.5 | X11: PEIXE | Y11: IZAIAS SANTOS BRAGA JUNIOR | Z11: RURAL | AA11: INDISPONIBILIDADE PARA OPERAÇÃO | AB11: PARECER COEP: EQUIPAMENTO FURTADO LEVAR PARA ANÁLISE COM O LEANDRO, NO ENTANTO SEGUE NA CATEGORIA DE COMPRA.Favor levar outro regulador de tensão, pois o mesmo foi furtado em campo.
A12: ETO-COEP 00167/2025 | J12: 2025 | K12: COI | L12: ETO-COEP | M12: AL01054060 | N12: 5844630060 | O12: 792803 | P12: 9144437 | Q12: 190-29126245 | R12: EMERGENCIAL | S12: SS PENDENTE | T12: 45877.703 | V12: 45880.703 | W12: REGULADOR DE TENSAO DE DIST. - 13.8 | X12: NOVA OLINDA | Y12: CASSIO GOMES BONFIM | Z12: RURAL | AA12: INDISPONIBILIDADE PARA OPERAÇÃO | AB12: PARECER COEP: EQUIPAMENTO EM ROTA DE ENTREGAPARECER DMSL: Célula da fase A encontra-se com vazamento de óleo no pé da torneira. Necessário substituição da célula.Aberto nota para verificar vazamento de óleo fase A no RT 5844630060 - RDU Nova Olinda
