Workbook

Sheet Orçamento
A1: Criticidade | B1: (Tudo) | K1: DCMD
L2: Baclog | M2: Saiu | N2: Entrou | O2: Pendente
A3: Tipo | B3: Status | C3: Contagem de Ativo | D3: Soma de Orçamento Total | K3: RL
A4: 58 | B4: Avaliar compra | C4: 2 | D4: 989173.2 | K4: RT
B5: Em logistica (N1>N3) | C5: 6 | D5: 691664.7 | G5: Compras | O5: 53
B6: Reforma | C6: 2 | D6: 213808.1 | G6: 94500
B7: Em execução | C7: 2 | D7: 509586.6 | G7: 87683
A8: 79 | B8: Avaliar compra | C8: 20 | D8: 1229422.1 | E8: 1229422.1 | G8: 398547
B9: Gerado PMA | C9: 20 | D9: 1320983.7 | G9: =SUM(G6:G8) -> 580730
B10: Em execução | C10: 1 | D10: 15000
A11: Total Geral | C11: 53 | D11: 4969638.5
C13: BC | D13: 310372.4 | H13: 946651.72 | I13: 8481
H14: 959988.26 | I14: 8495
H15: =SUM(H13:H14) -> 1906640
B16: 8481 | D16: 45 | E16: RL | G16: 2465983.7
B17: 8495 | E17: RT | G17: 1597242.4
C18: =1605000*1.0001745 -> 1605280.1 | D18: 143 | E18: BC | G18: 315372.4
B19: Orçamento | C19: 6100000 | G19: =SUM(G16:G18) -> 4378598.5
C20: 5983226.1
C21: =C19-C20 -> 116773.88 | D21: 839786.22 | E21: =C18-D21 -> 765493.86
E22: 765493.86
C23: Execução | D23: 524586.6
C24: Logistica | D24: 691664.7
E25: 1605280.1
D27: 6062323.8
D28: 6083299.3
D29: =D27-D28 -> -20975.48
C30: 315372.4
D36: 310372.4 | E36: 23
E37: =10/E36 -> 0.43478261 | F37: 134944.52 | M37: =SUM(J46:J51) -> 3980465.3
A39: OUTUBRO | B39: NOVEMBRO | F39: 175427.88
A40: 10 | B40: 13 | J40: =SUM(D58:G58) -> 4473019.2
E45: 58 | F45: JANEIRO DE 2027 | H45: Avaliar compra | I45: 2 | J45: 989173.2
E46: 58 | F46: Outubro | H46: Em logistica (N1>N3) | I46: 6 | J46: 691664.7
E47: 58 | F47: Novembro | H47: Reforma | I47: 2 | J47: 213808.1
A48: Valor médio RL | E48: 58 | F48: Setembro | H48: Em execução | I48: 2 | J48: 509586.6
A49: Valor Médio RT | E49: 79 | F49: Novembro | H49: Avaliar compra | I49: 20 | J49: 1229422.1 | K49: 1443230.2
E50: 79 | F50: Dezembro | H50: Gerado PMA | I50: 20 | J50: 1320983.7
E51: 79 | F51: Setembro | H51: Em execução | I51: 1 | J51: 15000
C56: 46266 | D56: Setembro | E56: Outubro | F56: Novembro | G56: Dezembro | H56: Forecast Quantidade de Resolvidos | I56: 2027
...

Sheet Apresentação
B1: Realizado | C1: Em Execução | D1: Em logistica (N1>N3) | E1: Gerado PMA | F1: Reforma | G1: Emitir compra
A2: RL | B2: 839786.21 | C2: 15000 | D2: - | E2: 1320983.3 | F2: - | G2: 1229422.1
A3: RT | B3: 765493.85 | C3: 509585.6 | D3: 691664.7 | E3: - | F3: 375991.1 | G3: -
A4: BC | B4: - | C4: - | D4: - | E4: 310372.4 | F4: - | G4: -
B5: =SUM(B2:B4) -> 1605280.1 | C5: =SUM(C2:C4) -> 524585.6 | D5: =SUM(D2:D4) -> 691664.7 | E5: =SUM(E2:E4) -> 1631355.7 | F5: =SUM(F2:F4) -> 375991.1 | G5: =SUM(G2:G4) -> 1229422.1
A6: Soma (acumulada) | B6: =B5 -> 1605280.1 | C6: =B6+C5 -> 2129865.7 | D6: =C6+D5 -> 2821530.4 | E6: =D6+E5 -> 4452886.1 | F6: =E6+F5 -> 4828877.2 | G6: =F6+G5 -> 6058299.3
G7: 6062323.8
G8: =G7-G6 -> 4024.52
A9: TIPO | B9: STATUS | C9: CONTAGEM | D9: VALOR PREVISTO
A10: RL | B10: Em execução | C10: 1 | D10: 15000
B11: Gerado PMA | C11: 20 | D11: 1320983.3
B12: Gerar compra | C12: 20 | D12: 1229422.1
C13: 41 | D13: 2565405.5
A14: RT | B14: Em execução | C14: 2 | D14: 509585.6
B15: Em logistica (N1>N3) | C15: 6 | D15: 691664.7
B16: Reforma | C16: 2 | D16: 375991.1
C17: 10 | D17: 1597241.4
A18: BC | B18: Gerado PMA | C18: 23 | D18: 310372.4
A19: Total Geral | C19: 51 | D19: =D13+D17+D18 -> 4473019.3 | E19: 4478019.3

Sheet Gestão
A1: Ativo | B1: Tipo | C1: SS SGM | D1: Criticidade | E1: Status | F1: Defeito | G1: Orçamento MO | H1: Orçamento MAT | I1: Orçamento Total | J1: PMA | K1: Entregue N1? | L1: Gerado Obra? | M1: Gerado EMD? | N1: Entregue N3? | O1: Concluído COCM? | P1: Enviado para Cadastro | Q1: Estudo Proteção | R1: Repassado ao DMSL? | S1: Comissionado? | T1: Índice | U1: SLA_Total | V1: Dias Pendente | W1: Status Atendimento | X1: Responsável | Y1: Status Prazo | Z1: Coluna1 | AA1: Alimentador | AB1: Município | AC1: Polo | AD1: Regional
A2: 7923673004 | B2: =LEFT(Table1[[#This Row],[Ativo]],2) -> 79 | C2: ETO-COEP 00124/2026 | D2: Muito Alta | E2: Gerado PMA | F2: =_xlfn.XLOOKUP(_xlfn.NUMBERVALUE(Table1[[#This Row],[Ativo]]),'[1]Criticidade por Equipamento'!$A:$A,'[1]Criticidade por Equipamento'!$AS:$AS) -> RL Completo 13,8 | G2: =_xlfn.XLOOKUP(_xlfn.NUMBERVALUE(Table1[[#This Row],[Ativo]]),'[1]Criticidade por Equipamento'!$A:$A,'[1]Criticidade por Equipamento'!$AU:$AU) -> 11016.94 | H2: =_xlfn.XLOOKUP(_xlfn.NUMBERVALUE(Table1[[#This Row],[Ativo]]),'[1]Criticidade por Equipamento'!$A:$A,'[1]Criticidade por Equipamento'!$AT:$AT) -> 55602.54 | I2: =Table1[[#This Row],[Orçamento MAT]]+Table1[[#This Row],[Orçamento MO]] -> 66619.48 | T2: 5 | U2: 12 | V2: 144 | W2: 40 - DIAS AGUARDANDO DCMD | X2: COEP | Y2: 132 - DIAS FORA DO PRAZO | AA2: AL04010004 - AL 4 SE ARAGUAINA I | AB2: ARAGUAINA | AC2: ARAGUAINA | AD2: NORTE
A3: 7931608059 | B3: =LEFT(Table1[[#This Row],[Ativo]],2) -> 79 | C3: ETO-COEP 00040/2026 | D3: Muito Alta | E3: Gerado PMA | F3: =_xlfn.XLOOKUP(_xlfn.NUMBERVALUE(Table1[[#This Row],[Ativo]]),'[1]Criticidade por Equipamento'!$A:$A,'[1]Criticidade por Equipamento'!$AS:$AS) -> Tanque 13,8 | G3: =_xlfn.XLOOKUP(_xlfn.NUMBERVALUE(Table1[[#This Row],[Ativo]]),'[1]Criticidade por Equipamento'!$A:$A,'[1]Criticidade por Equipamento'!$AU:$AU) -> 11016.94 | H3: =_xlfn.XLOOKUP(_xlfn.NUMBERVALUE(Table1[[#This Row],[Ativo]]),'[1]Criticidade por Equipamento'!$A:$A,'[1]Criticidade por Equipamento'!$AT:$AT) -> 21785.72 | I3: =Table1[[#This Row],[Orçamento MAT]]+Table1[[#This Row],[Orçamento MO]] -> 32802.66 | T3: 6 | U3: 12 | V3: 201 | W3: 174 - DIAS AGUARDANDO DCMD | X3: COEP | Y3: 189 - DIAS FORA DO PRAZO | AA3: AL05099059 - AL 5 SE TAQUARALTO I I | AB3: PALMAS | AC3: TAQUARALTO | AD3: CENTRO
A4: 7947203070 | B4: =LEFT(Table1[[#This Row],[Ativo]],2) -> 79 | C4: ETO-COEP 00131/2026 | D4: Muito Alta | E4: Gerado PMA | F4: =_xlfn.XLOOKUP(_xlfn.NUMBERVALUE(Table1[[#This Row],[Ativo]]),'[1]Criticidade por Equipamento'!$A:$A,'[1]Criticidade por Equipamento'!$AS:$AS) -> RL Completo 34,5 | G4: =_xlfn.XLOOKUP(_xlfn.NUMBERVALUE(Table1[[#This Row],[Ativo]]),'[1]Criticidade por Equipamento'!$A:$A,'[1]Criticidade por Equipamento'!$AU:$AU) -> 13209.34 | H4: =_xlfn.XLOOKUP(_xlfn.NUMBERVALUE(Table1[[#This Row],[Ativo]]),'[1]Criticidade por Equipamento'!$A:$A,'[1]Criticidade por Equipamento'!$AT:$AT) -> 76246.2 | I4: =Table1[[#This Row],[Orçamento MAT]]+Table1[[#This Row],[Orçamento MO]] -> 89455.54 | T4: 9 | U4: 12 | V4: 267 | W4: 40 - DIAS AGUARDANDO DCMD | X4: COEP | Y4: 255 - DIAS FORA DO PRAZO | AB4: RIO SONO | AC4: PALMAS | AD4: CENTRO
A5: 5856070091 | B5: =LEFT(Table1[[#This Row],[Ativo]],2) -> 58 | C5: ETO-RD-DP 00479/2026 | D5: Muito Alta | E5: Em execução | F5: =_xlfn.XLOOKUP(_xlfn.NUMBERVALUE(Table1[[#This Row],[Ativo]]),'[1]Criticidade por Equipamento'!$A:$A,'[1]Criticidade por Equipamento'!$AS:$AS) -> RT Completo 400 34,5 | G5: =_xlfn.XLOOKUP(_xlfn.NUMBERVALUE(Table1[[#This Row],[Ativo]]),'[1]Criticidade por Equipamento'!$A:$A,'[1]Criticidade por Equipamento'!$AU:$AU) -> 200637 | H5: =_xlfn.XLOOKUP(_xlfn.NUMBERVALUE(Table1[[#This Row],[Ativo]]),'[1]Criticidade por Equipamento'!$A:$A,'[1]Criticidade por Equipamento'!$AT:$AT) -> 293949.6 | I5: =Table1[[#This Row],[Orçamento MAT]]+Table1[[#This Row],[Orçamento MO]] -> 494586.6 | T5: 10 | U5: 12 | V5: 395 | W5: 20 - DIAS AGUARDANDO DCMD | X5: COCM-S | Y5: 383 - DIAS FORA DO PRAZO | AA5: LD04002091 - LD 04 ALMAS NATIVIDADE AO POV PRINCIPE | AB5: ALMAS | AC5: DIANOPOLIS | AD5: SUL
A6: 7903569004 | B6: =LEFT(Table1[[#This Row],[Ativo]],2) -> 79 | C6: ETO-COEP 00152/2026 | D6: Muito Alta | E6: Gerado PMA | F6: =_xlfn.XLOOKUP(_xlfn.NUMBERVALUE(Table1[[#This Row],[Ativo]]),'[1]Criticidade por Equipamento'!$A:$A,'[1]Criticidade por Equipamento'!$AS:$AS) -> RL Completo 13,8 | G6: =_xlfn.XLOOKUP(_xlfn.NUMBERVALUE(Table1[[#This Row],[Ativo]]),'[1]Criticidade por Equipamento'!$A:$A,'[1]Criticidade por Equipamento'!$AU:$AU) -> 11016.94 | H6: =_xlfn.XLOOKUP(_xlfn.NUMBERVALUE(Table1[[#This Row],[Ativo]]),'[1]Criticidade por Equipamento'!$A:$A,'[1]Criticidade por Equipamento'!$AT:$AT) -> 55602.54 | I6: =Table1[[#This Row],[Orçamento MAT]]+Table1[[#This Row],[Orçamento MO]] -> 66619.48 | T6: 11 | U6: 12 | V6: 28 | W6: 27 - DIAS AGUARDANDO DCMD | X6: COEP | Y6: 16 - DIAS FORA DO PRAZO | AA6: AL05010004 - AL 5 SE ARAGUAINA I | AB6: ARAGUAINA | AC6: ARAGUAINA | AD6: NORTE
A7: 7925744087 | B7: =LEFT(Table1[[#This Row],[Ativo]],2) -> 79 | C7: ETO-COEP 00059/2026 | D7: Muito Alta | E7: Gerado PMA | F7: =_xlfn.XLOOKUP(_xlfn.NUMBERVALUE(Table1[[#This Row],[Ativo]]),'[1]Criticidade por Equipamento'!$A:$A,'[1]Criticidade por Equipamento'!$AS:$AS) -> Tanque 34,5 | G7: =_xlfn.XLOOKUP(_xlfn.NUMBERVALUE(Table1[[#This Row],[Ativo]]),'[1]Criticidade por Equipamento'!$A:$A,'[1]Criticidade por Equipamento'!$AU:$AU) -> 13209.34 | H7: =_xlfn.XLOOKUP(_xlfn.NUMBERVALUE(Table1[[#This Row],[Ativo]]),'[1]Criticidade por Equipamento'!$A:$A,'[1]Criticidade por Equipamento'!$AT:$AT) -> 38151.48 | I7: =Table1[[#This Row],[Orçamento MAT]]+Table1[[#This Row],[Orçamento MO]] -> 51360.82 | T7: 12 | U7: 12 | V7: 189 | W7: 140 - DIAS AGUARDANDO DCMD | X7: COEP | Y7: 177 - DIAS FORA DO PRAZO | AA7: LD02022033 - LD COLMEIA A COUTO MAGALHAES | AB7: GOIANORTE | AC7: GUARAI | AD7: NORTE
A8: 7908705049 | B8: =LEFT(Table1[[#This Row],[Ativo]],2) -> 79 | C8: ETO-RD-DP 00409/2026 | D8: Muito Alta | E8: Gerado PMA | F8: =_xlfn.XLOOKUP(_xlfn.NUMBERVALUE(Table1[[#This Row],[Ativo]]),'[1]Criticidade por Equipamento'!$A:$A,'[1]Criticidade por Equipamento'!$AS:$AS) -> RL Completo 13,8 | G8: =_xlfn.XLOOKUP(_xlfn.NUMBERVALUE(Table1[[#This Row],[Ativo]]),'[1]Criticidade por Equipamento'!$A:$A,'[1]Criticidade por Equipamento'!$AU:$AU) -> 11016.94 | H8: =_xlfn.XLOOKUP(_xlfn.NUMBERVALUE(Table1[[#This Row],[Ativo]]),'[1]Criticidade por Equipamento'!$A:$A,'[1]Criticidade por Equipamento'!$AT:$AT) -> 55602.54 | I8: =Table1[[#This Row],[Orçamento MAT]]+Table1[[#This Row],[Orçamento MO]] -> 66619.48 | T8: 15 | U8: 12 | V8: 397 | W8: 41 - DIAS AGUARDANDO DCMD | X8: COCM-S | Y8: 385 - DIAS FORA DO PRAZO | AA8: AL01015049 - AL 1 SE AURORA | AB8: AURORA DO TOCANTINS | AC8: DIANOPOLIS | AD8: SUL
A9: 7927413001 | B9: =LEFT(Table1[[#This Row],[Ativo]],2) -> 79 | C9: ETO-COEP 00141/2026 | D9: Muito Alta | E9: Gerado PMA | F9: =_xlfn.XLOOKUP(_xlfn.NUMBERVALUE(Table1[[#This Row],[Ativo]]),'[1]Criticidade por Equipamento'!$A:$A,'[1]Criticidade por Equipamento'!$AS:$AS) -> RL Completo 34,5 | G9: =_xlfn.XLOOKUP(_xlfn.NUMBERVALUE(Table1[[#This Row],[Ativo]]),'[1]Criticidade por Equipamento'!$A:$A,'[1]Criticidade por Equipamento'!$AU:$AU) -> 13209.34 | H9: =_xlfn.XLOOKUP(_xlfn.NUMBERVALUE(Table1[[#This Row],[Ativo]]),'[1]Criticidade por Equipamento'!$A:$A,'[1]Criticidade por Equipamento'!$AT:$AT) -> 76246.2 | I9: =Table1[[#This Row],[Orçamento MAT]]+Table1[[#This Row],[Orçamento MO]] -> 89455.54 | T9: 21 | U9: 12 | V9: 140 | W9: 34 - DIAS AGUARDANDO DCMD | X9: COEP | Y9: 128 - DIAS FORA DO PRAZO | AA9: LD01072001 - LD PORTO NACIONAL A SE PROJETO SAO JOAO | AB9: PORTO NACIONAL | AC9: PORTO NACIONAL | AD9: CENTRO
A10: 5800440256 | B10: =LEFT(Table1[[#This Row],[Ativo]],2) -> 58 | C10: ETO-COEP 00169/2026 | D10: Muito Alta | E10: Em logistica (N1>N3) | F10: =_xlfn.XLOOKUP(_xlfn.NUMBERVALUE(Table1[[#This Row],[Ativo]]),'[1]Criticidade por Equipamento'!$A:$A,'[1]Criticidade por Equipamento'!$AS:$AS) -> Célula 200 34,5 | G10: =_xlfn.XLOOKUP(_xlfn.NUMBERVALUE(Table1[[#This Row],[Ativo]]),'[1]Criticidade por Equipamento'!$A:$A,'[1]Criticidade por Equipamento'!$AU:$AU) -> 80318.5 | H10: =_xlfn.XLOOKUP(_xlfn.NUMBERVALUE(Table1[[#This Row],[Ativo]]),'[1]Criticidade por Equipamento'!$A:$A,'[1]Criticidade por Equipamento'!$AT:$AT) -> 51705.75 | I10: =Table1[[#This Row],[Orçamento MAT]]+Table1[[#This Row],[Orçamento MO]] -> 132024.25 | T10: 23 | U10: 12 | V10: 21 | W10: 10 - DIAS AGUARDANDO DCMD | X10: COEP | Y10: 9 - DIAS FORA DO PRAZO | AA10: LD03046026 - LD UHE ISAMU A PONTE ALTA | AB10: MATEIROS | AC10: PONTE ALTA TOCANTINS | AD10: CENTRO
A11: 7900453110 | B11: =LEFT(Table1[[#This Row],[Ativo]],2) -> 79 | C11: ETO-COEP 00087/2026 | D11: Muito Alta | E11: Gerado PMA | F11: =_xlfn.XLOOKUP(_xlfn.NUMBERVALUE(Table1[[#This Row],[Ativo]]),'[1]Criticidade por Equipamento'!$A:$A,'[1]Criticidade por Equipamento'!$AS:$AS) -> RL Completo 34,5 | G11: =_xlfn.XLOOKUP(_xlfn.NUMBERVALUE(Table1[[#This Row],[Ativo]]),'[1]Criticidade por Equipamento'!$A:$A,'[1]Criticidade por Equipamento'!$AU:$AU) -> 13209.34 | H11: =_xlfn.XLOOKUP(_xlfn.NUMBERVALUE(Table1[[#This Row],[Ativo]]),'[1]Criticidade por Equipamento'!$A:$A,'[1]Criticidade por Equipamento'!$AT:$AT) -> 76246.2 | I11: =Table1[[#This Row],[Orçamento MAT]]+Table1[[#This Row],[Orçamento MO]] -> 89455.54 | T11: 25 | U11: 12 | V11: 482 | W11: 111 - DIAS AGUARDANDO DCMD | X11: COEP | Y11: 470 - DIAS FORA DO PRAZO | AA11: LD03040003 - LD GURUPI A ALIANCA E TREVO DA PRAIA | AB11: SANTA RITA DO TOCANTINS | AC11: PORTO NACIONAL | AD11: CENTRO
A12: 7925871077 | B12: =LEFT(Table1[[#This Row],[Ativo]],2) -> 79 | C12: ETO-COEP 00048/2026 | D12: Muito Alta | E12: Gerado PMA | F12: =_xlfn.XLOOKUP(_xlfn.NUMBERVALUE(Table1[[#This Row],[Ativo]]),'[1]Criticidade por Equipamento'!$A:$A,'[1]Criticidade por Equipamento'!$AS:$AS) -> Tanque 34,5 | G12: =_xlfn.XLOOKUP(_xlfn.NUMBERVALUE(Table1[[#This Row],[Ativo]]),'[1]Criticidade por Equipamento'!$A:$A,'[1]Criticidade por Equipamento'!$AU:$AU) -> 13209.34 | H12: =_xlfn.XLOOKUP(_xlfn.NUMBERVALUE(Table1[[#This Row],[Ativo]]),'[1]Criticidade por Equipamento'!$A:$A,'[1]Criticidade por Equipamento'!$AT:$AT) -> 38151.48 | I12: =Table1[[#This Row],[Orçamento MAT]]+Table1[[#This Row],[Orçamento MO]] -> 51360.82 | T12: 26 | U12: 12 | V12: 154 | W12: 154 - DIAS AGUARDANDO DCMD | X12: COEP | Y12: 142 - DIAS FORA DO PRAZO | AA12: LD03105019 - LD POV BIELANDIA A CAMPOS LINDOS | AB12: GOIATINS | AC12: COLINAS DO TOCANTINS | AD12: NORTE
A13: 5803327001 | B13: =LEFT(Table1[[#This Row],[Ativo]],2) -> 58 | C13: ETO-COEP 00149/2026 | D13: Alta | E13: Em logistica (N1>N3) | F13: =_xlfn.XLOOKUP(_xlfn.NUMBERVALUE(Table1[[#This Row],[Ativo]]),'[1]Criticidade por Equipamento'!$A:$A,'[1]Criticidade por Equipamento'!$AS:$AS) -> Controle 167 13,8 | G13: =_xlfn.XLOOKUP(_xlfn.NUMBERVALUE(Table1[[#This Row],[Ativo]]),'[1]Criticidade por Equipamento'!$A:$A,'[1]Criticidade por Equipamento'!$AU:$AU) -> 20000 | H13: =_xlfn.XLOOKUP(_xlfn.NUMBERVALUE(Table1[[#This Row],[Ativo]]),'[1]Criticidade por Equipamento'!$A:$A,'[1]Criticidade por Equipamento'!$AT:$AT) -> 23259.6 | I13: =Table1[[#This Row],[Orçamento MAT]]+Table1[[#This Row],[Orçamento MO]] -> 43259.6 | T13: 27 | U13: 26 | V13: 347 | W13: 28 - DIAS AGUARDANDO DCMD | X13: COEP | Y13: 321 - DIAS FORA DO PRAZO | AA13: AL01102271 - AL 01 SE LUZIMANGUES INDUSTRIAL | AB13: PORTO NACIONAL | AC13: PORTO NACIONAL | AD13: CENTRO
A14: 7926089013 | B14: =LEFT(Table1[[#This Row],[Ativo]],2) -> 79 | C14: ETO-COEP 00078/2026 | D14: Alta | E14: Gerado PMA | F14: =_xlfn.XLOOKUP(_xlfn.NUMBERVALUE(Table1[[#This Row],[Ativo]]),'[1]Criticidade por Equipamento'!$A:$A,'[1]Criticidade por Equipamento'!$AS:$AS) -> Controle 34,5 | G14: =_xlfn.XLOOKUP(_xlfn.NUMBERVALUE(Table1[[#This Row],[Ativo]]),'[1]Criticidade por Equipamento'!$A:$A,'[1]Criticidade por Equipamento'!$AU:$AU) -> 13209.34 | H14: =_xlfn.XLOOKUP(_xlfn.NUMBERVALUE(Table1[[#This Row],[Ativo]]),'[1]Criticidade por Equipamento'!$A:$A,'[1]Criticidade por Equipamento'!$AT:$AT) -> 38094.72 | I14: =Table1[[#This Row],[Orçamento MAT]]+Table1[[#This Row],[Orçamento MO]] -> 51304.06 | T14: 34 | U14: 26 | V14: 143 | W14: 116 - DIAS AGUARDANDO DCMD | X14: COEP | Y14: 117 - DIAS FORA DO PRAZO | AA14: LD03062013 - LD PARAISO I A PIUM | AB14: PARAISO DO TOCANTINS | AC14: PARAISO DO TOCANTINS | AD14: CENTRO
A15: 5853360007 | B15: =LEFT(Table1[[#This Row],[Ativo]],2) -> 58 | C15: ETO-RD-PS 00323/2025 | D15: Alta | E15: Em execução | F15: =_xlfn.XLOOKUP(_xlfn.NUMBERVALUE(Table1[[#This Row],[Ativo]]),'[1]Criticidade por Equipamento'!$A:$A,'[1]Criticidade por Equipamento'!$AS:$AS) -> Acessório 400 34,5 | G15: =_xlfn.XLOOKUP(_xlfn.NUMBERVALUE(Table1[[#This Row],[Ativo]]),'[1]Criticidade por Equipamento'!$A:$A,'[1]Criticidade por Equipamento'!$AU:$AU) -> 0 | H15: =_xlfn.XLOOKUP(_xlfn.NUMBERVALUE(Table1[[#This Row],[Ativo]]),'[1]Criticidade por Equipamento'!$A:$A,'[1]Criticidade por Equipamento'!$AT:$AT) -> 15000 | I15: =Table1[[#This Row],[Orçamento MAT]]+Table1[[#This Row],[Orçamento MO]] -> 15000 | T15: 38 | U15: 26 | V15: 475 | W15: 304 - DIAS AGUARDANDO DCMD | X15: COCM-C | Y15: 449 - DIAS FORA DO PRAZO | AA15: LD05050008 - LD MIRANORTE A MIRACEMA | AB15: MIRACEMA DO TOCANTINS | AC15: MIRACEMA DO TOCANTINS | AD15: CENTRO
A16: 5840227063 | B16: =LEFT(Table1[[#This Row],[Ativo]],2) -> 58 | C16: ETO-COEP 00151/2026 | D16: Média | E16: Em logistica (N1>N3) | F16: =_xlfn.XLOOKUP(_xlfn.NUMBERVALUE(Table1[[#This Row],[Ativo]]),'[1]Criticidade por Equipamento'!$A:$A,'[1]Criticidade por Equipamento'!$AS:$AS) -> Célula 400 34,5 | G16: =_xlfn.XLOOKUP(_xlfn.NUMBERVALUE(Table1[[#This Row],[Ativo]]),'[1]Criticidade por Equipamento'!$A:$A,'[1]Criticidade por Equipamento'!$AU:$AU) -> 80318.5 | H16: =_xlfn.XLOOKUP(_xlfn.NUMBERVALUE(Table1[[#This Row],[Ativo]]),'[1]Criticidade por Equipamento'!$A:$A,'[1]Criticidade por Equipamento'!$AT:$AT) -> 90230 | I16: =Table1[[#This Row],[Orçamento MAT]]+Table1[[#This Row],[Orçamento MO]] -> 170548.5 | T16: 45 | U16: 86 | V16: 206 | W16: 28 - DIAS AGUARDANDO DCMD | X16: COEP | Y16: 120 - DIAS FORA DO PRAZO | AA16: LD01054060 - LD NOVA OLINDA A ARAPOEMA | AB16: BANDEIRANTES DO TOCANTINS | AC16: COLINAS DO TOCANTINS | AD16: NORTE
... A26: 7908249152 | B26: =LEFT(Table1[[#This Row],[Ativo]],2) -> 79 | C26: ETO-COEP 00038/2026 | D26: Média | E26: Gerado PMA | F26: =_xlfn.XLOOKUP(_xlfn.NUMBERVALUE(Table1[[#This Row],[Ativo]]),'[1]Criticidade por Equipamento'!$A:$A,'[1]Criticidade por Equipamento'!$AS:$AS) -> RL Completo 34,5 | G26: =_xlfn.XLOOKUP(_xlfn.NUMBERVALUE(Table1[[#This Row],[Ativo]]),'[1]Criticidade por Equipamento'!$A:$A,'[1]Criticidade por Equipamento'!$AU:$AU) -> 13209.34 | H26: =_xlfn.XLOOKUP(_xlfn.NUMBERVALUE(Table1[[#This Row],[Ativo]]),'[1]Criticidade por Equipamento'!$A:$A,'[1]Criticidade por Equipamento'!$AT:$AT) -> 76246.2 | I26: =Table1[[#This Row],[Orçamento MAT]]+Table1[[#This Row],[Orçamento MO]] -> 89455.54 | T26: 65 | U26: 86 | V26: 207 | W26: 174 - DIAS AGUARDANDO DCMD | X26: COEP | Y26: 121 - DIAS FORA DO PRAZO | AA26: LD02072001 - LD PORTO NACIONAL A SILVANOPOLIS | AB26: SANTA ROSA DO TOCANTINS | AC26: PORTO NACIONAL | AD26: CENTRO
A27: 7925733015 | B27: =LEFT(Table1[[#This Row],[Ativo]],2) -> 79 | C27: ETO-COEP 00058/2026 | D27: Média | E27: Gerado PMA | F27: =_xlfn.XLOOKUP(_xlfn.NUMBERVALUE(Table1[[#This Row],[Ativo]]),'[1]Criticidade por Equipamento'!$A:$A,'[1]Criticidade por Equipamento'!$AS:$AS) -> Tanque 34,5 | G27: =_xlfn.XLOOKUP(_xlfn.NUMBERVALUE(Table1[[#This Row],[Ativo]]),'[1]Criticidade por Equipamento'!$A:$A,'[1]Criticidade por Equipamento'!$AU:$AU) -> 13209.34 | H27: =_xlfn.XLOOKUP(_xlfn.NUMBERVALUE(Table1[[#This Row],[Ativo]]),'[1]Criticidade por Equipamento'!$A:$A,'[1]Criticidade por Equipamento'!$AT:$AT) -> 38151.48 | I27: =Table1[[#This Row],[Orçamento MAT]]+Table1[[#This Row],[Orçamento MO]] -> 51360.82 | T27: 67 | U27: 86 | V27: 157 | W27: 140 - DIAS AGUARDANDO DCMD | X27: COEP | Y27: 71 - DIAS FORA DO PRAZO | AB27: PEDRO AFONSO | AC27: GUARAI | AD27: NORTE
A28: 7927396052 | B28: =LEFT(Table1[[#This Row],[Ativo]],2) -> 79 | C28: ETO-COEP 00045/2026 | D28: Média | E28: Avaliar compra | F28: =_xlfn.XLOOKUP(_xlfn.NUMBERVALUE(Table1[[#This Row],[Ativo]]),'[1]Criticidade por Equipamento'!$A:$A,'[1]Criticidade por Equipamento'!$AS:$AS) -> Tanque 34,5 | G28: =_xlfn.XLOOKUP(_xlfn.NUMBERVALUE(Table1[[#This Row],[Ativo]]),'[1]Criticidade por Equipamento'!$A:$A,'[1]Criticidade por Equipamento'!$AU:$AU) -> 13209.34 | H28: =_xlfn.XLOOKUP(_xlfn.NUMBERVALUE(Table1[[#This Row],[Ativo]]),'[1]Criticidade por Equipamento'!$A:$A,'[1]Criticidade por Equipamento'!$AT:$AT) -> 38151.48 | I28: =Table1[[#This Row],[Orçamento MAT]]+Table1[[#This Row],[Orçamento MO]] -> 51360.82 | T28: 68 | U28: 86 | V28: 181 | W28: 167 - DIAS AGUARDANDO DCMD | X28: COEP | Y28: 95 - DIAS FORA DO PRAZO | AA28: LD03036052 - LD FORMOSO A COOPERFORMOSO | AB28: FORMOSO DO ARAGUAIA | AC28: ALVORADA | AD28: SUL
A29: 7933585074 | B29: =LEFT(Table1[[#This Row],[Ativo]],2) -> 79 | C29: ETO-COEP 00024/2026 | D29: Média | E29: Avaliar compra | F29: =_xlfn.XLOOKUP(_xlfn.NUMBERVALUE(Table1[[#This Row],[Ativo]]),'[1]Criticidade por Equipamento'!$A:$A,'[1]Criticidade por Equipamento'!$AS:$AS) -> Tanque 34,5 | G29: =_xlfn.XLOOKUP(_xlfn.NUMBERVALUE(Table1[[#This Row],[Ativo]]),'[1]Criticidade por Equipamento'!$A:$A,'[1]Criticidade por Equipamento'!$AU:$AU) -> 13209.34 | H29: =_xlfn.XLOOKUP(_xlfn.NUMBERVALUE(Table1[[#This Row],[Ativo]]),'[1]Criticidade por Equipamento'!$A:$A,'[1]Criticidade por Equipamento'!$AT:$AT) -> 38151.48 | I29: =Table1[[#This Row],[Orçamento MAT]]+Table1[[#This Row],[Orçamento MO]] -> 51360.82 | T29: 69 | U29: 86 | V29: 202 | W29: 201 - DIAS AGUARDANDO DCMD | X29: COEP | Y29: 116 - DIAS FORA DO PRAZO | AA29: LD03028074 - LD DIANOPOLIS A REGIAO GERAIS | AB29: DIANOPOLIS | AC29: DIANOPOLIS | AD29: SUL
A30: 7955986084 | B30: =LEFT(Table1[[#This Row],[Ativo]],2) -> 79 | C30: ETO-COEP 00133/2026 | D30: Média | E30: Avaliar compra | F30: =_xlfn.XLOOKUP(_xlfn.NUMBERVALUE(Table1[[#This Row],[Ativo]]),'[1]Criticidade por Equipamento'!$A:$A,'[1]Criticidade por Equipamento'!$AS:$AS) -> Controle 34,5 | G30: =_xlfn.XLOOKUP(_xlfn.NUMBERVALUE(Table1[[#This Row],[Ativo]]),'[1]Criticidade por Equipamento'!$A:$A,'[1]Criticidade por Equipamento'!$AU:$AU) -> 13209.34 | H30: =_xlfn.XLOOKUP(_xlfn.NUMBERVALUE(Table1[[#This Row],[Ativo]]),'[1]Criticidade por Equipamento'!$A:$A,'[1]Criticidade por Equipamento'!$AT:$AT) -> 38094.72 | I30: =Table1[[#This Row],[Orçamento MAT]]+Table1[[#This Row],[Orçamento MO]] -> 51304.06 | T30: 72 | U30: 86 | V30: 40 | W30: 40 - DIAS AGUARDANDO DCMD | X30: COEP | Y30: VENCE EM: 46 DIAS | AA30: LD04062013 - LD SE PARAISO I A DIVINOPOLIS | AB30: DIVINOPOLIS | AC30: DIVINOPOLIS | AD30: CENTRO
A31: 7900525015 | B31: =LEFT(Table1[[#This Row],[Ativo]],2) -> 79 | C31: ETO-COEP 00125/2026 | D31: Média | E31: Avaliar compra | F31: =_xlfn.XLOOKUP(_xlfn.NUMBERVALUE(Table1[[#This Row],[Ativo]]),'[1]Criticidade por Equipamento'!$A:$A,'[1]Criticidade por Equipamento'!$AS:$AS) -> RL Completo 34,5 | G31: =_xlfn.XLOOKUP(_xlfn.NUMBERVALUE(Table1[[#This Row],[Ativo]]),'[1]Criticidade por Equipamento'!$A:$A,'[1]Criticidade por Equipamento'!$AU:$AU) -> 13209.34 | H31: =_xlfn.XLOOKUP(_xlfn.NUMBERVALUE(Table1[[#This Row],[Ativo]]),'[1]Criticidade por Equipamento'!$A:$A,'[1]Criticidade por Equipamento'!$AT:$AT) -> 76246.2 | I31: =Table1[[#This Row],[Orçamento MAT]]+Table1[[#This Row],[Orçamento MO]] -> 89455.54 | T31: 74 | U31: 86 | V31: 126 | W31: 40 - DIAS AGUARDANDO DCMD | X31: COEP | Y31: 40 - DIAS FORA DO PRAZO | AB31: PEDRO AFONSO | AC31: GUARAI | AD31: NORTE
A32: 7928564039 | B32: =LEFT(Table1[[#This Row],[Ativo]],2) -> 79 | C32: ETO-COEP 00123/2026 | D32: Média | E32: Avaliar compra | F32: =_xlfn.XLOOKUP(_xlfn.NUMBERVALUE(Table1[[#This Row],[Ativo]]),'[1]Criticidade por Equipamento'!$A:$A,'[1]Criticidade por Equipamento'!$AS:$AS) -> RL Completo 34,5 | G32: =_xlfn.XLOOKUP(_xlfn.NUMBERVALUE(Table1[[#This Row],[Ativo]]),'[1]Criticidade por Equipamento'!$A:$A,'[1]Criticidade por Equipamento'!$AU:$AU) -> 13209.34 | H32: =_xlfn.XLOOKUP(_xlfn.NUMBERVALUE(Table1[[#This Row],[Ativo]]),'[1]Criticidade por Equipamento'!$A:$A,'[1]Criticidade por Equipamento'!$AT:$AT) -> 76246.2 | I32: =Table1[[#This Row],[Orçamento MAT]]+Table1[[#This Row],[Orçamento MO]] -> 89455.54 | T32: 75 | U32: 86 | V32: 445 | W32: 40 - DIAS AGUARDANDO DCMD | X32: COEP | Y32: 359 - DIAS FORA DO PRAZO | AA32: LD02109039 - LD ARAGUATINS A POV SOCO | AB32: ARAGUATINS | AC32: AUGUSTINOPOLIS | AD32: NORTE
A33: 5855411017 | B33: =LEFT(Table1[[#This Row],[Ativo]],2) -> 58 | C33: ETO-COEP 00156/2026 | D33: Baixa | E33: Em logistica (N1>N3) | F33: =_xlfn.XLOOKUP(_xlfn.NUMBERVALUE(Table1[[#This Row],[Ativo]]),'[1]Criticidade por Equipamento'!$A:$A,'[1]Criticidade por Equipamento'!$AS:$AS) -> Controle 200 13,8 | G33: =_xlfn.XLOOKUP(_xlfn.NUMBERVALUE(Table1[[#This Row],[Ativo]]),'[1]Criticidade por Equipamento'!$A:$A,'[1]Criticidade por Equipamento'!$AU:$AU) -> 20000 | H33: =_xlfn.XLOOKUP(_xlfn.NUMBERVALUE(Table1[[#This Row],[Ativo]]),'[1]Criticidade por Equipamento'!$A:$A,'[1]Criticidade por Equipamento'!$AT:$AT) -> 23259.6 | I33: =Table1[[#This Row],[Orçamento MAT]]+Table1[[#This Row],[Orçamento MO]] -> 43259.6 | T33: 79 | U33: 134 | V33: 348 | W33: 23 - DIAS AGUARDANDO DCMD | X33: COEP | Y33: 214 - DIAS FORA DO PRAZO | AA33: AL02017017 - AL 2 SE BARROLANDIA | AB33: BARROLANDIA | AC33: MIRACEMA DO TOCANTINS | AD33: CENTRO
A34: 7908196047 | B34: =LEFT(Table1[[#This Row],[Ativo]],2) -> 79 | C34: ETO-COEP 00168/2026 | D34: Baixa | E34: Avaliar compra | F34: =_xlfn.XLOOKUP(_xlfn.NUMBERVALUE(Table1[[#This Row],[Ativo]]),'[1]Criticidade por Equipamento'!$A:$A,'[1]Criticidade por Equipamento'!$AS:$AS) -> RL Completo 13,8 | G34: =_xlfn.XLOOKUP(_xlfn.NUMBERVALUE(Table1[[#This Row],[Ativo]]),'[1]Criticidade por Equipamento'!$A:$A,'[1]Criticidade por Equipamento'!$AU:$AU) -> 11016.94 | H34: =_xlfn.XLOOKUP(_xlfn.NUMBERVALUE(Table1[[#This Row],[Ativo]]),'[1]Criticidade por Equipamento'!$A:$A,'[1]Criticidade por Equipamento'!$AT:$AT) -> 55602.54 | I34: =Table1[[#This Row],[Orçamento MAT]]+Table1[[#This Row],[Orçamento MO]] -> 66619.48 | T34: 81 | U34: 134 | V34: 322 | W34: 13 - DIAS AGUARDANDO DCMD | X34: COEP | Y34: 188 - DIAS FORA DO PRAZO | AA34: AL02033047 - AL 2 SE FIGUEIROPOLIS | AB34: FIGUEIROPOLIS | AC34: ALVORADA | AD34: SUL
A35: 7921202014 | B35: =LEFT(Table1[[#This Row],[Ativo]],2) -> 79 | C35: ETO-COEP 00132/2026 | D35: Baixa | E35: Avaliar compra | F35: =_xlfn.XLOOKUP(_xlfn.NUMBERVALUE(Table1[[#This Row],[Ativo]]),'[1]Criticidade por Equipamento'!$A:$A,'[1]Criticidade por Equipamento'!$AS:$AS) -> Tanque 34,5 | G35: =_xlfn.XLOOKUP(_xlfn.NUMBERVALUE(Table1[[#This Row],[Ativo]]),'[1]Criticidade por Equipamento'!$A:$A,'[1]Criticidade por Equipamento'!$AU:$AU) -> 13209.34 | H35: =_xlfn.XLOOKUP(_xlfn.NUMBERVALUE(Table1[[#This Row],[Ativo]]),'[1]Criticidade por Equipamento'!$A:$A,'[1]Criticidade por Equipamento'!$AT:$AT) -> 38151.48 | I35: =Table1[[#This Row],[Orçamento MAT]]+Table1[[#This Row],[Orçamento MO]] -> 51360.82 | T35: 82 | U35: 134 | V35: 183 | W35: 40 - DIAS AGUARDANDO DCMD | X35: COEP | Y35: 49 - DIAS FORA DO PRAZO | AA35: LD01025012 - LD CRISTALANDIA A LAGOA DA CONFUSAO | AB35: PIUM | AC35: PARAISO DO TOCANTINS | AD35: CENTRO
A36: 7923927122 | B36: =LEFT(Table1[[#This Row],[Ativo]],2) -> 79 | C36: ETO-COEP 00148/2026 | D36: Baixa | E36: Avaliar compra | F36: =_xlfn.XLOOKUP(_xlfn.NUMBERVALUE(Table1[[#This Row],[Ativo]]),'[1]Criticidade por Equipamento'!$A:$A,'[1]Criticidade por Equipamento'!$AS:$AS) -> Tanque 34,5 | G36: =_xlfn.XLOOKUP(_xlfn.NUMBERVALUE(Table1[[#This Row],[Ativo]]),'[1]Criticidade por Equipamento'!$A:$A,'[1]Criticidade por Equipamento'!$AU:$AU) -> 13209.34 | H36: =_xlfn.XLOOKUP(_xlfn.NUMBERVALUE(Table1[[#This Row],[Ativo]]),'[1]Criticidade por Equipamento'!$A:$A,'[1]Criticidade por Equipamento'!$AT:$AT) -> 38151.48 | I36: =Table1[[#This Row],[Orçamento MAT]]+Table1[[#This Row],[Orçamento MO]] -> 51360.82 | T36: 83 | U36: 134 | V36: 477 | W36: 32 - DIAS AGUARDANDO DCMD | X36: COEP | Y36: 343 - DIAS FORA DO PRAZO | AA36: LD02059122 - LD PALMAS I I A TAQUARALTO | AB36: PALMAS | AC36: PALMAS | AD36: CENTRO
A37: 7927446001 | B37: =LEFT(Table1[[#This Row],[Ativo]],2) -> 79 | C37: ETO-COEP 00143/2025 | D37: Baixa | E37: Avaliar compra | F37: =_xlfn.XLOOKUP(_xlfn.NUMBERVALUE(Table1[[#This Row],[Ativo]]),'[1]Criticidade por Equipamento'!$A:$A,'[1]Criticidade por Equipamento'!$AS:$AS) -> RL Completo 34,5 | G37: =_xlfn.XLOOKUP(_xlfn.NUMBERVALUE(Table1[[#This Row],[Ativo]]),'[1]Criticidade por Equipamento'!$A:$A,'[1]Criticidade por Equipamento'!$AU:$AU) -> 13209.34 | H37: =_xlfn.XLOOKUP(_xlfn.NUMBERVALUE(Table1[[#This Row],[Ativo]]),'[1]Criticidade por Equipamento'!$A:$A,'[1]Criticidade por Equipamento'!$AT:$AT) -> 76246.2 | I37: =Table1[[#This Row],[Orçamento MAT]]+Table1[[#This Row],[Orçamento MO]] -> 89455.54 | T37: 84 | U37: 134 | V37: 417 | W37: 404 - DIAS AGUARDANDO DCMD | X37: COEP | Y37: 283 - DIAS FORA DO PRAZO | AA37: LD02072001 - LD PORTO NACIONAL A SILVANOPOLIS | AB37: PORTO NACIONAL | AC37: PORTO NACIONAL | AD37: CENTRO
A38: 7928241200 | B38: =LEFT(Table1[[#This Row],[Ativo]],2) -> 79 | C38: ETO-COEP 00128/2026 | D38: Baixa | E38: Avaliar compra | F38: =_xlfn.XLOOKUP(_xlfn.NUMBERVALUE(Table1[[#This Row],[Ativo]]),'[1]Criticidade por Equipamento'!$A:$A,'[1]Criticidade por Equipamento'!$AS:$AS) -> Tanque 34,5 | G38: =_xlfn.XLOOKUP(_xlfn.NUMBERVALUE(Table1[[#This Row],[Ativo]]),'[1]Criticidade por Equipamento'!$A:$A,'[1]Criticidade por Equipamento'!$AU:$AU) -> 13209.34 | H38: =_xlfn.XLOOKUP(_xlfn.NUMBERVALUE(Table1[[#This Row],[Ativo]]),'[1]Criticidade por Equipamento'!$A:$A,'[1]Criticidade por Equipamento'!$AT:$AT) -> 38151.48 | I38: =Table1[[#This Row],[Orçamento MAT]]+Table1[[#This Row],[Orçamento MO]] -> 51360.82 | T38: 85 | U38: 134 | V38: 409 | W38: 40 - DIAS AGUARDANDO DCMD | X38: COEP | Y38: 275 - DIAS FORA DO PRAZO | AA38: LD02066094 - LD UHE PEIXE A SAO SALVADOR | AB38: SAO SALVADOR DO TOCANTINS | AC38: PEIXE | AD38: SUL
A39: 7942485096 | B39: =LEFT(Table1[[#This Row],[Ativo]],2) -> 79 | C39: ETO-COEP 00158/2025 | D39: Baixa | E39: Avaliar compra | F39: =_xlfn.XLOOKUP(_xlfn.NUMBERVALUE(Table1[[#This Row],[Ativo]]),'[1]Criticidade por Equipamento'!$A:$A,'[1]Criticidade por Equipamento'!$AS:$AS) -> Tanque 34,5 | G39: =_xlfn.XLOOKUP(_xlfn.NUMBERVALUE(Table1[[#This Row],[Ativo]]),'[1]Criticidade por Equipamento'!$A:$A,'[1]Criticidade por Equipamento'!$AU:$AU) -> 13209.34 | H39: =_xlfn.XLOOKUP(_xlfn.NUMBERVALUE(Table1[[#This Row],[Ativo]]),'[1]Criticidade por Equipamento'!$A:$A,'[1]Criticidade por Equipamento'!$AT:$AT) -> 38151.48 | I39: =Table1[[#This Row],[Orçamento MAT]]+Table1[[#This Row],[Orçamento MO]] -> 51360.82 | T39: 86 | U39: 134 | V39: 521 | W39: 390 - DIAS AGUARDANDO DCMD | X39: COEP | Y39: 387 - DIAS FORA DO PRAZO | AA39: LD03046026 - LD UHE ISAMU A PONTE ALTA | AB39: PINDORAMA DO TOCANTINS | AC39: PONTE ALTA TOCANTINS | AD39: CENTRO
A40: 7955946007 | B40: =LEFT(Table1[[#This Row],[Ativo]],2) -> 79 | C40: ETO-COEP 00134/2026 | D40: Baixa | E40: Avaliar compra | F40: =_xlfn.XLOOKUP(_xlfn.NUMBERVALUE(Table1[[#This Row],[Ativo]]),'[1]Criticidade por Equipamento'!$A:$A,'[1]Criticidade por Equipamento'!$AS:$AS) -> Controle 34,5 | G40: =_xlfn.XLOOKUP(_xlfn.NUMBERVALUE(Table1[[#This Row],[Ativo]]),'[1]Criticidade por Equipamento'!$A:$A,'[1]Criticidade por Equipamento'!$AU:$AU) -> 13209.34 | H40: =_xlfn.XLOOKUP(_xlfn.NUMBERVALUE(Table1[[#This Row],[Ativo]]),'[1]Criticidade por Equipamento'!$A:$A,'[1]Criticidade por Equipamento'!$AT:$AT) -> 38094.72 | I40: =Table1[[#This Row],[Orçamento MAT]]+Table1[[#This Row],[Orçamento MO]] -> 51304.06 | T40: 89 | U40: 134 | V40: 40 | W40: 40 - DIAS AGUARDANDO DCMD | X40: COEP | Y40: VENCE EM: 94 DIAS | AA40: LD05050008 - LD MIRANORTE A MIRACEMA | AB40: MIRACEMA DO TOCANTINS | AC40: MIRACEMA DO TOCANTINS | AD40: CENTRO
A41: 7901110084 | B41: =LEFT(Table1[[#This Row],[Ativo]],2) -> 79 | C41: ETO-COEP 00061/2026 | D41: Baixa | E41: Avaliar compra | F41: =_xlfn.XLOOKUP(_xlfn.NUMBERVALUE(Table1[[#This Row],[Ativo]]),'[1]Criticidade por Equipamento'!$A:$A,'[1]Criticidade por Equipamento'!$AS:$AS) -> Tanque 34,5 | G41: =_xlfn.XLOOKUP(_xlfn.NUMBERVALUE(Table1[[#This Row],[Ativo]]),'[1]Criticidade por Equipamento'!$A:$A,'[1]Criticidade por Equipamento'!$AU:$AU) -> 13209.34 | H41: =_xlfn.XLOOKUP(_xlfn.NUMBERVALUE(Table1[[#This Row],[Ativo]]),'[1]Criticidade por Equipamento'!$A:$A,'[1]Criticidade por Equipamento'!$AT:$AT) -> 38151.48 | I41: =Table1[[#This Row],[Orçamento MAT]]+Table1[[#This Row],[Orçamento MO]] -> 51360.82 | T41: 90 | U41: 134 | V41: 243 | W41: 139 - DIAS AGUARDANDO DCMD | X41: COEP | Y41: 109 - DIAS FORA DO PRAZO | AA41: LD04062013 - LD SE PARAISO I A DIVINOPOLIS | AB41: DIVINOPOLIS | AC41: DIVINOPOLIS | AD41: CENTRO
A42: 7910027196 | B42: =LEFT(Table1[[#This Row],[Ativo]],2) -> 79 | C42: ETO-COEP 00154/2026 | D42: Baixa | E42: Avaliar compra | F42: =_xlfn.XLOOKUP(_xlfn.NUMBERVALUE(Table1[[#This Row],[Ativo]]),'[1]Criticidade por Equipamento'!$A:$A,'[1]Criticidade por Equipamento'!$AS:$AS) -> RL Completo 34,5 | G42: =_xlfn.XLOOKUP(_xlfn.NUMBERVALUE(Table1[[#This Row],[Ativo]]),'[1]Criticidade por Equipamento'!$A:$A,'[1]Criticidade por Equipamento'!$AU:$AU) -> 13209.34 | H42: =_xlfn.XLOOKUP(_xlfn.NUMBERVALUE(Table1[[#This Row],[Ativo]]),'[1]Criticidade por Equipamento'!$A:$A,'[1]Criticidade por Equipamento'!$AT:$AT) -> 76246.2 | I42: =Table1[[#This Row],[Orçamento MAT]]+Table1[[#This Row],[Orçamento MO]] -> 89455.54 | T42: 93 | U42: 134 | V42: 40 | W42: 26 - DIAS AGUARDANDO DCMD | X42: COEP | Y42: VENCE EM: 94 DIAS | AA42: LD02059122 - LD PALMAS I I A TAQUARALTO | AB42: LAGOA DO TOCANTINS | AC42: TAQUARALTO | AD42: CENTRO
A43: 7913662076 | B43: =LEFT(Table1[[#This Row],[Ativo]],2) -> 79 | C43: ETO-COEP 00114/2026 | D43: Baixa | E43: Avaliar compra | F43: =_xlfn.XLOOKUP(_xlfn.NUMBERVALUE(Table1[[#This Row],[Ativo]]),'[1]Criticidade por Equipamento'!$A:$A,'[1]Criticidade por Equipamento'!$AS:$AS) -> Tanque 13,8 | G43: =_xlfn.XLOOKUP(_xlfn.NUMBERVALUE(Table1[[#This Row],[Ativo]]),'[1]Criticidade por Equipamento'!$A:$A,'[1]Criticidade por Equipamento'!$AU:$AU) -> 11016.94 | H43: =_xlfn.XLOOKUP(_xlfn.NUMBERVALUE(Table1[[#This Row],[Ativo]]),'[1]Criticidade por Equipamento'!$A:$A,'[1]Criticidade por Equipamento'!$AT:$AT) -> 21785.72 | I43: =Table1[[#This Row],[Orçamento MAT]]+Table1[[#This Row],[Orçamento MO]] -> 32802.66 | T43: 94 | U43: 134 | V43: 70 | W43: 67 - DIAS AGUARDANDO DCMD | X43: COEP | Y43: VENCE EM: 64 DIAS | AA43: AL01031076 - AL 1 SE DUERE | AB43: DUERE | AC43: GURUPI | AD43: SUL
... A50: 5858783119 | B50: =LEFT(Table1[[#This Row],[Ativo]],2) -> 58 | C50: ETO-COEP 00164/2026 | D50: Baixa | E50: Avaliar compra | F50: =_xlfn.XLOOKUP(_xlfn.NUMBERVALUE(Table1[[#This Row],[Ativo]]),'[1]Criticidade por Equipamento'!$A:$A,'[1]Criticidade por Equipamento'!$AS:$AS) -> RT Completo 400 34,5 | G50: =_xlfn.XLOOKUP(_xlfn.NUMBERVALUE(Table1[[#This Row],[Ativo]]),'[1]Criticidade por Equipamento'!$A:$A,'[1]Criticidade por Equipamento'!$AU:$AU) -> 200637 | H50: =_xlfn.XLOOKUP(_xlfn.NUMBERVALUE(Table1[[#This Row],[Ativo]]),'[1]Criticidade por Equipamento'!$A:$A,'[1]Criticidade por Equipamento'!$AT:$AT) -> 293949.6 | I50: =Table1[[#This Row],[Orçamento MAT]]+Table1[[#This Row],[Orçamento MO]] -> 494586.6 | T50: 102 | U50: 134 | V50: 511 | W50: 16 - DIAS AGUARDANDO DCMD | X50: COEP | Y50: 377 - DIAS FORA DO PRAZO | AA50: LD03005098 - LD ANANAS A CACHOEIRINHA | AB50: SAO BENTO DO TOCANTINS | AC50: TOCANTINOPOLIS | AD50: NORTE
A51: 7930359149 | B51: =LEFT(Table1[[#This Row],[Ativo]],2) -> 79 | C51: ETO-COEP 00138/2026 | D51: Falta definir | E51: Avaliar compra | F51: =_xlfn.XLOOKUP(_xlfn.NUMBERVALUE(Table1[[#This Row],[Ativo]]),'[1]Criticidade por Equipamento'!$A:$A,'[1]Criticidade por Equipamento'!$AS:$AS) -> RL Completo 34,5 | G51: =_xlfn.XLOOKUP(_xlfn.NUMBERVALUE(Table1[[#This Row],[Ativo]]),'[1]Criticidade por Equipamento'!$A:$A,'[1]Criticidade por Equipamento'!$AU:$AU) -> 13209.34 | H51: =_xlfn.XLOOKUP(_xlfn.NUMBERVALUE(Table1[[#This Row],[Ativo]]),'[1]Criticidade por Equipamento'!$A:$A,'[1]Criticidade por Equipamento'!$AT:$AT) -> 76246.2 | I51: =Table1[[#This Row],[Orçamento MAT]]+Table1[[#This Row],[Orçamento MO]] -> 89455.54 | T51: 107 | V51: 54 | W51: 35 - DIAS AGUARDANDO DCMD | X51: COEP | AA51: LD03414149 - LD CASEARA A MARIANOPOLIS | AB51: CASEARA | AC51: DIVINOPOLIS | AD51: CENTRO
A52: 7953211079 | B52: =LEFT(Table1[[#This Row],[Ativo]],2) -> 79 | C52: ETO-COEP 00147/2026 | D52: Falta definir | E52: Avaliar compra | F52: =_xlfn.XLOOKUP(_xlfn.NUMBERVALUE(Table1[[#This Row],[Ativo]]),'[1]Criticidade por Equipamento'!$A:$A,'[1]Criticidade por Equipamento'!$AS:$AS) -> Controle 34,5 | G52: =_xlfn.XLOOKUP(_xlfn.NUMBERVALUE(Table1[[#This Row],[Ativo]]),'[1]Criticidade por Equipamento'!$A:$A,'[1]Criticidade por Equipamento'!$AU:$AU) -> 13209.34 | H52: =_xlfn.XLOOKUP(_xlfn.NUMBERVALUE(Table1[[#This Row],[Ativo]]),'[1]Criticidade por Equipamento'!$A:$A,'[1]Criticidade por Equipamento'!$AT:$AT) -> 38094.72 | I52: =Table1[[#This Row],[Orçamento MAT]]+Table1[[#This Row],[Orçamento MO]] -> 51304.06 | T52: 109 | V52: 33 | W52: 32 - DIAS AGUARDANDO DCMD | X52: COEP | AA52: LD03038009 - LD GUARAI I I A PRES KENNEDY | AB52: ITAPIRATINS | AC52: GUARAI | AD52: NORTE
A53: 5825703064 | B53: =LEFT(Table1[[#This Row],[Ativo]],2) -> 58 | C53: ETO-COEP 00153/2026 | D53: Falta definir | E53: Reforma | F53: =_xlfn.XLOOKUP(_xlfn.NUMBERVALUE(Table1[[#This Row],[Ativo]]),'[1]Criticidade por Equipamento'!$A:$A,'[1]Criticidade por Equipamento'!$AS:$AS) -> Controle 200 34,5 | G53: =_xlfn.XLOOKUP(_xlfn.NUMBERVALUE(Table1[[#This Row],[Ativo]]),'[1]Criticidade por Equipamento'!$A:$A,'[1]Criticidade por Equipamento'!$AU:$AU) -> 20000 | H53: =_xlfn.XLOOKUP(_xlfn.NUMBERVALUE(Table1[[#This Row],[Ativo]]),'[1]Criticidade por Equipamento'!$A:$A,'[1]Criticidade por Equipamento'!$AT:$AT) -> 23259.6 | I53: =Table1[[#This Row],[Orçamento MAT]]+Table1[[#This Row],[Orçamento MO]] -> 43259.6 | T53: 137 | V53: 56 | W53: 26 - DIAS AGUARDANDO DCMD | X53: COEP | AA53: LD02020023 - LD COLINAS A PRES. KENNEDY | AB53: BRASILANDIA DO TOCANTINS | AC53: GUARAI | AD53: NORTE
A54: 7931219078 | B54: =LEFT(Table1[[#This Row],[Ativo]],2) -> 79 | C54: ETO-RD-PO 00183/2026 | D54: Falta definir | E54: Em execução | F54: =_xlfn.XLOOKUP(_xlfn.NUMBERVALUE(Table1[[#This Row],[Ativo]]),'[1]Criticidade por Equipamento'!$A:$A,'[1]Criticidade por Equipamento'!$AS:$AS) -> Acessório 34,5 | G54: =_xlfn.XLOOKUP(_xlfn.NUMBERVALUE(Table1[[#This Row],[Ativo]]),'[1]Criticidade por Equipamento'!$A:$A,'[1]Criticidade por Equipamento'!$AU:$AU) -> 0 | H54: =_xlfn.XLOOKUP(_xlfn.NUMBERVALUE(Table1[[#This Row],[Ativo]]),'[1]Criticidade por Equipamento'!$A:$A,'[1]Criticidade por Equipamento'!$AT:$AT) -> 15000 | I54: =Table1[[#This Row],[Orçamento MAT]]+Table1[[#This Row],[Orçamento MO]] -> 15000 | T54: 145 | V54: 420 | W54: 40 - DIAS AGUARDANDO DCMD | X54: COCM-C | AA54: LD01065015 - LD PEDRO AFONSO A SANTA.MARIA | AB54: ITACAJA | AC54: GUARAI | AD54: NORTE

Sheet Taxa de Falha
A1: Ano | B1: 2025
A2: Equipamento | B2: (Tudo)
A3: Tensão | B3: (Tudo)
A5: Rótulos de Coluna
A6: fevereiro | B6: março | C6: abril | D6: maio | E6: junho | F6: julho | G6: agosto | H6: setembro | I6: outubro | J6: novembro | K6: dezembro | L6: Total Geral
B68: janeiro | C68: fevereiro | D68: março | E68: abril | F68: maio | G68: junho | H68: julho | I68: agosto | J68: setembro | K68: outubro | L68: novembro | M68: dezembro
A69: % falha - mensal
A70: % falha - acumulada
A71: Taxa de Falha Mensal - RL - 2025
B72: Jan | C72: Fev | D72: Mar | E72: Abr | F72: Mai | G72: Jun | H72: Jul | I72: Ago | J72: Set | K72: Out | L72: Nov | M72: Dez
A73: Novos ativos | B73: 0 | C73: 0 | D73: 0 | E73: 0 | F73: 0 | G73: 0 | H73: 0 | I73: 0 | J73: 0 | K73: 0 | L73: 0 | M73: 0
A74: Parque | B74: 1281 | C74: 1281 | D74: 1281 | E74: 1281 | F74: 1281 | G74: 1281 | H74: 1281 | I74: 1281 | J74: 1281 | K74: 1281 | L74: 1281 | M74: 1281
A75: Falha mês | B75: 1 | C75: 1 | D75: 2 | E75: 2 | F75: 7 | G75: 4 | H75: 5 | I75: 2 | J75: 2 | K75: 4 | L75: 1 | M75: 4
B76: =B75/B74 -> 0.00078064012 | C76: =C75/C74 -> 0.00078064012 | D76: =D75/D74 -> 0.0015612802 | E76: =E75/E74 -> 0.0015612802 | F76: =F75/F74 -> 0.0054644809 | G76: =G75/G74 -> 0.0031225605 | H76: =H75/H74 -> 0.0039032006 | I76: =I75/I74 -> 0.0015612802 | ... M76: =M75/M74 -> 0.0031225605
A77: Taxa de Falha Mensal - RT - 2025
B78: Jan | C78: Fev | D78: Mar | E78: Abr | F78: Mai | G78: Jun | H78: Jul | I78: Ago | J78: Set | K78: Out | L78: Nov | M78: Dez
A79: Novos ativos | B79: 0 | C79: 0 | D79: 0 | E79: 0 | F79: 0 | G79: 0 | H79: 0 | I79: 0 | J79: 0 | K79: 0 | L79: 0 | M79: 0
A80: Parque | B80: 180 | C80: 180 | D80: 180 | E80: 180 | F80: 180 | G80: 180 | H80: 180 | I80: 180 | J80: 180 | K80: 180 | L80: 180 | M80: 180
A81: Falha mês | B81: 0 | C81: 1 | D81: 2 | E81: 0 | F81: 0 | G81: 1 | H81: 3 | I81: 5 | J81: 3 | L81: 1 | M81: 2
B82: =B81/B80 -> 0 | C82: =C81/C80 -> 0.0055555556 | D82: =D81/D80 -> 0.011111111 | E82: =E81/E80 -> 0 | F82: =F81/F80 -> 0 | G82: =G81/G80 -> 0.0055555556 | H82: =H81/H80 -> 0.016666667 | I82: =I81/I80 -> 0.027777778 | ... M82: =M81/M80 -> 0.011111111
A84: Taxa de Falha Mensal - RL - 2026
B85: Jan | C85: Fev | D85: Mar | E85: Abr | F85: Mai | G85: Jun | H85: Jul | I85: Ago | J85: Set | K85: Out | L85: Nov | M85: Dez
A86: Novos ativos | B86: {='[2]Expansão EE'!$E$51:$P$51} -> 2 | C86: 0 | D86: 2 | E86: 2 | F86: 3 | G86: 1 | H86: 3 | I86: 0 | J86: 0 | K86: 0 | L86: 0 | M86: 0
A87: Parque | B87: =$M$74+B86 -> 1283 | C87: =B87+C86 -> 1283 | D87: =C87+D86 -> 1285 | E87: =D87+E86 -> 1287 | F87: =E87+F86 -> 1290 | G87: =F87+G86 -> 1291 | H87: =G87+H86 -> 1294 | I87: =H87+I86 -> 1294 | J87: =I87+J86 -> 1294 | ... M87: =L87+M86 -> 1294
A88: Falha mês | B88: 6 | C88: 7 | D88: 8 | E88: 3 | F88: 0 | G88: 1 | H88: 3 | I88: 0
B89: =B88/B87 -> 0.0046765394 | C89: =C88/C87 -> 0.0054559626 | D89: =D88/D87 -> 0.0062256809 | E89: =E88/E87 -> 0.0023310023 | F89: =F88/F87 -> 0 | G89: =G88/G87 -> 0.00077459334 | H89: =H88/H87 -> 0.0023183926 | I89: =I88/I87 -> 0 | ... M89: =M88/M87 -> 0
B90: =B88/B87 -> 0.0046765394 | C90: =C88/C87 -> 0.0054559626 | D90: =D88/D87 -> 0.0062256809 | E90: =E88/E87 -> 0.0023310023 | F90: =F88/F87 -> 0 | G90: =G88/G87 -> 0.00077459334 | H90: =H88/H87 -> 0.0023183926 | I90: =I88/I87 -> 0
A91: Taxa de Falha Mensal - RT - 2026
B92: Jan | C92: Fev | D92: Mar | E92: Abr | F92: Mai | G92: Jun | H92: Jul | I92: Ago | J92: Set | K92: Out | L92: Nov | M92: Dez
A93: Novos ativos | B93: {='[2]Expansão EE'!$E$51:$P$51} -> 2 | C93: 0 | D93: 2 | E93: 2 | F93: 3 | G93: 1 | H93: 3 | I93: 0 | J93: 0 | K93: 0 | L93: 0 | M93: 0
A94: Parque | B94: =$M$80+B93 -> 182 | C94: =B94+C93 -> 182 | D94: =C94+D93 -> 184 | E94: =D94+E93 -> 186 | F94: =E94+F93 -> 189 | G94: =F94+G93 -> 190 | H94: =G94+H93 -> 193 | I94: =H94+I93 -> 193 | J94: =I94+J93 -> 193 | ... M94: =L94+M93 -> 193
A95: Falha mês | B95: 1 | C95: 1 | D95: 1 | E95: 2 | F95: 1 | G95: 1 | H95: 1 | I95: 1
B96: =B95/B94 -> 0.0054945055 | C96: =C95/C94 -> 0.0054945055 | D96: =D95/D94 -> 0.0054347826 | E96: =E95/E94 -> 0.010752688 | F96: =F95/F94 -> 0.0052910053 | G96: =G95/G94 -> 0.0052631579 | H96: =H95/H94 -> 0.0051813472 | I96: =I95/I94 -> 0.0051813472 | ... M96: =M95/M94 -> 0
A99: Taxa de Falha Acumulado- RL - 2025
B100: Jan | C100: Fev | D100: Mar | E100: Abr | F100: Mai | G100: Jun | H100: Jul | I100: Ago | J100: Set | K100: Out | L100: Nov | M100: Dez
A101: Novos ativos | B101: =B73 -> 0 | C101: =C73 -> 0 | D101: =D73 -> 0 | E101: =E73 -> 0 | F101: =F73 -> 0 | G101: =G73 -> 0 | H101: =H73 -> 0 | I101: =I73 -> 0 | ... M101: =M73 -> 0
A102: Parque | B102: =B74 -> 1281 | C102: =C74 -> 1281 | D102: =D74 -> 1281 | E102: =E74 -> 1281 | F102: =F74 -> 1281 | G102: =G74 -> 1281 | H102: =H74 -> 1281 | I102: =I74 -> 1281 | ... M102: =M74 -> 1281
A103: Falha mês | B103: =B75 -> 1 | C103: =C75+B103 -> 2 | D103: =D75+C103 -> 4 | E103: =E75+D103 -> 6 | F103: =F75+E103 -> 13 | G103: =G75+F103 -> 17 | H103: =H75+G103 -> 22 | I103: =I75+H103 -> 24 | J103: =J75+I103 -> 26 | ... M103: =M75+L103 -> 35
B104: =B103/B102 -> 0.00078064012 | C104: =C103/C102 -> 0.0015612802 | D104: =D103/D102 -> 0.0031225605 | E104: =E103/E102 -> 0.0046838407 | F104: =F103/F102 -> 0.010148322 | G104: =G103/G102 -> 0.013270882 | H104: =H103/H102 -> 0.017174083 | I104: =I103/I102 -> 0.018735363 | ... M104: =M103/M102 -> 0.027322404
A105: Taxa de Falha Acumulado - RT - 2025
...

Sheet SLA por equipe
A1: SLA DE MANUTENÇÃO — POR EQUIPE DE CAMPO
A2: Equipe é o posto do COCM que recebeu a demanda. A mediana diz o ritmo normal; o pior atraso diz a cauda.
A4: 2025
A5: Equipe | B5: Entregas | C5: No prazo | D5: Estourou | E5: Em curso | F5: Cumprimento | G5: Mediana de dias | H5: SLA (dias ÷ prazo) | I5: Pior atraso
A6: ETO-RD-PO | B6: 11 | C6: 7 | D6: 4 | E6: 0 | F6: 0.63636364 | G6: 7 | H6: 1.4513619 | I6: 148
A7: ETO-RD-AG | B7: 7 | C7: 6 | D7: 1 | E7: 0 | F7: 0.85714286 | G7: 0 | H7: 0.24725275 | I7: 3
A8: ETO-RD-GU | B8: 7 | C8: 5 | D8: 2 | E8: 0 | F8: 0.71428571 | G8: 4 | H8: 0.76923077 | I8: 53
A9: ETO-RD-PS | B9: 7 | C9: 4 | D9: 3 | E9: 0 | F9: 0.57142857 | G9: 0 | H9: 4.1318681 | I9: 232
A10: DOLP-RD-PA | B10: 6 | C10: 5 | D10: 1 | E10: 0 | F10: 0.83333333 | G10: 13 | H10: 0.50641026 | I10: 12
A11: ETO-RD-AR | B11: 6 | C11: 5 | D11: 1 | E11: 1 | F11: 0.83333333 | G11: 2 | H11: 3.275641 | I11: 468
A12: ETO-RD-GR | B12: 6 | C12: 4 | D12: 2 | E12: 0 | F12: 0.66666667 | G12: 23 | H12: 1.0833333 | I12: 59
A13: ETO-RD-PA | B13: 6 | C13: 3 | D13: 3 | E13: 0 | F13: 0.5 | G13: 35 | H13: 2.4423077 | I13: 236
A14: ETO-RD-DP | B14: 3 | C14: 1 | D14: 2 | E14: 0 | F14: 0.33333333 | G14: 74 | H14: 6.5166667 | I14: 308
A15: ENC-RD-PS | B15: 1 | C15: 1 | D15: 0 | E15: 0 | F15: 1 | G15: 1 | H15: 0.038461538 | I15: 0
A16: TOTAL | B16: 60 | C16: 41 | D16: 19 | E16: 1 | F16: 0.68333333 | G16: 6 | H16: 1.8783873 | I16: 468
A18: 2026
A19: Equipe | B19: Entregas | C19: No prazo | D19: Estourou | E19: Em curso | F19: Cumprimento | G19: Mediana de dias | H19: SLA (dias ÷ prazo) | I19: Pior atraso
A20: ETO-RD-AR | B20: 13 | C20: 11 | D20: 2 | E20: 0 | F20: 0.84615385 | G20: 1 | H20: 0.43122677 | I20: 36
A21: ETO-RD-PS | B21: 13 | C21: 10 | D21: 3 | E21: 0 | F21: 0.76923077 | G21: 1 | H21: 1.0132013 | I21: 87
A22: ETO-RD-PO | B22: 12 | C22: 7 | D22: 5 | E22: 1 | F22: 0.58333333 | G22: 10 | H22: 1.1840796 | I22: 59
A23: ETO-RD-PA | B23: 11 | C23: 7 | D23: 4 | E23: 1 | F23: 0.63636364 | G23: 1 | H23: 1.75 | I23: 100
A24: ETO-RD-DP | B24: 8 | C24: 2 | D24: 6 | E24: 2 | F24: 0.25 | G24: 67 | H24: 2.2473684 | I24: 84
A25: ETO-RD-GR | B25: 6 | C25: 3 | D25: 3 | E25: 0 | F25: 0.5 | G25: 38 | H25: 1.9565217 | I25: 32
A26: ETO-RD-AG | B26: 5 | C26: 5 | D26: 0 | E26: 0 | F26: 1 | G26: 8 | H26: 0.25892857 | I26: 0
A27: ETO-RD-GU | B27: 2 | C27: 1 | D27: 1 | E27: 0 | F27: 0.5 | G27: 87 | H27: 3.7826087 | I27: 72
A28: DG-RD-PO | B28: 1 | C28: 1 | D28: 0 | E28: 0 | F28: 1 | G28: 14 | H28: 0.53846154 | I28: 0
A29: TOTAL | B29: 71 | C29: 47 | D29: 24 | E29: 4 | F29: 0.66197183 | G29: 4 | H29: 1.2300071 | I29: 100
A31: 2025 + 2026
A32: Equipe | B32: Entregas | C32: No prazo | D32: Estourou | E32: Em curso | F32: Cumprimento | G32: Mediana de dias | H32: SLA (dias ÷ prazo) | I32: Pior atraso
A33: ETO-RD-PO | B33: 23 | C33: 14 | D33: 9 | E33: 1 | F33: 0.60869565 | G33: 9 | H33: 1.3340611 | I33: 148
A34: ETO-RD-PS | B34: 20 | C34: 14 | D34: 6 | E34: 0 | F34: 0.7 | G34: 1 | H34: 2.1835052 | I34: 232
A35: ETO-RD-AR | B35: 19 | C35: 16 | D35: 3 | E35: 1 | F35: 0.84210526 | G35: 1 | H35: 1.4752941 | I35: 468
A36: ETO-RD-PA | B36: 17 | C36: 10 | D36: 7 | E36: 1 | F36: 0.58823529 | G36: 1 | H36: 2.037234 | I36: 236
A37: ETO-RD-AG | B37: 12 | C37: 11 | D37: 1 | E37: 0 | F37: 0.91666667 | G37: 1 | H37: 0.25170068 | I37: 3
A38: ETO-RD-GR | B38: 12 | C38: 7 | D38: 5 | E38: 0 | F38: 0.58333333 | G38: 23 | H38: 1.3511111 | I38: 59
A39: ETO-RD-DP | B39: 11 | C39: 3 | D39: 8 | E39: 2 | F39: 0.27272727 | G39: 67 | H39: 3.272 | I39: 308
A40: ETO-RD-GU | B40: 9 | C40: 6 | D40: 3 | E40: 0 | F40: 0.66666667 | G40: 4 | H40: 1.1073171 | I40: 72
A41: DOLP-RD-PA | B41: 6 | C41: 5 | D41: 1 | E41: 0 | F41: 0.83333333 | G41: 13 | H41: 0.50641026 | I41: 12
A42: DG-RD-PO | B42: 1 | C42: 1 | D42: 0 | E42: 0 | F42: 1 | G42: 14 | H42: 0.53846154 | I42: 0
A43: ENC-RD-PS | B43: 1 | C43: 1 | D43: 0 | E43: 0 | F43: 1 | G43: 1 | H43: 0.038461538 | I43: 0
...

Sheet Falha Equipamentos
A1: Ano/TIPO | B1: Equipamento | C1: Mensal | D1: Parque | E1: Ativo | F1: SS | G1: Tensão | H1: Data | I1: Mês | J1: Ano | K1: Concat | L1: Peça (modo) | M1: Troca feita | N1: Causa raiz | O1: Citação do texto da SS | P1: Nota do analista | Q1: Revisão | R1: Coluna1
A2: RL 2025 | B2: =LEFT(Tabela3[[#This Row],[Ano/TIPO]],2) -> RL | D2: =_xlfn.XLOOKUP(K2,Base!G:G,Base!I:I) -> #N/A | E2: 7900230155 | F2: ETO-COEP 00056/2025 | G2: =_xlfn.XLOOKUP(_xlfn.NUMBERVALUE(Tabela3[[#This Row],[Ativo]]),'[3]Ajustes Reguladores de Tensão'!$A:$A,'[3]Ajustes Reguladores de Tensão'!$I:$I,_xlfn.XLOOKUP(_xlfn.NUMBERVALUE(Tabela3[[#This Row],[Ativo]]),'[3]Ajustes RL Poste'!$A:$A,'[3]Ajustes RL Poste'!$M:$M)) -> 34.500 | H2: 29/03/2025 | I2: =TEXT(Tabela3[[#This Row],[Data]],"mmmm") -> março | J2: =YEAR(Tabela3[[#This Row],[Data]]) -> 2025 | K2: =_xlfn.CONCAT(Tabela3[[#This Row],[Ano]],Tabela3[[#This Row],[Mês]]) -> 2025março | L2: completo | M2: sim | N2: CURTO-CIRCUITO INTERNO | O2: «Não responde a comandos abertura e fechamento local ou remoto, pois está com sinal de curto circuito» | P2: Tanque danificado com sinal de curto-circuito bloqueando comandos; o para-raios do trafo queimado junto sugere surto, mas o laudo não afirma descarga.
A3: RL 2025 | B3: =LEFT(Tabela3[[#This Row],[Ano/TIPO]],2) -> RL | D3: =_xlfn.XLOOKUP(K3,Base!G:G,Base!I:I) -> #N/A | E3: 7900573047 | F3: ETO-COEP 00080/2026 | G3: =_xlfn.XLOOKUP(_xlfn.NUMBERVALUE(Tabela3[[#This Row],[Ativo]]),'[3]Ajustes Reguladores de Tensão'!$A:$A,'[3]Ajustes Reguladores de Tensão'!$I:$I,_xlfn.XLOOKUP(_xlfn.NUMBERVALUE(Tabela3[[#This Row],[Ativo]]),'[3]Ajustes RL Poste'!$A:$A,'[3]Ajustes RL Poste'!$M:$M)) -> 13.800 | H3: 09/10/2025 | I3: =TEXT(Tabela3[[#This Row],[Data]],"mmmm") -> outubro | J3: =YEAR(Tabela3[[#This Row],[Data]]) -> 2025 | K3: =_xlfn.CONCAT(Tabela3[[#This Row],[Ano]],Tabela3[[#This Row],[Mês]]) -> 2025outubro | L3: completo | M3: não | N3: CURTO-CIRCUITO INTERNO | O3: «o mesmo estar em curto conforme fotos anexadas» | P3: Relato de campo com fotos dá o equipamento em curto e o DMSL constata parte ativa, placa, tanque e relé queimados — curto como mecanismo; origem não descrita. | Y3: Rótulos de Linha | Z3: Contagem de Data
A4: RL 2025 | B4: =LEFT(Tabela3[[#This Row],[Ano/TIPO]],2) -> RL | D4: =_xlfn.XLOOKUP(K4,Base!G:G,Base!I:I) -> #N/A | E4: 7908196047 | F4: ETO-COEP 00215/2025 | G4: =_xlfn.XLOOKUP(_xlfn.NUMBERVALUE(Tabela3[[#This Row],[Ativo]]),'[3]Ajustes Reguladores de Tensão'!$A:$A,'[3]Ajustes Reguladores de Tensão'!$I:$I,_xlfn.XLOOKUP(_xlfn.NUMBERVALUE(Tabela3[[#This Row],[Ativo]]),'[3]Ajustes RL Poste'!$A:$A,'[3]Ajustes RL Poste'!$M:$M)) -> 13.800 | H4: 29/09/2025 | I4: =TEXT(Tabela3[[#This Row],[Data]],"mmmm") -> setembro | J4: =YEAR(Tabela3[[#This Row],[Data]]) -> 2025 | K4: =_xlfn.CONCAT(Tabela3[[#This Row],[Ano]],Tabela3[[#This Row],[Mês]]) -> 2025setembro | L4: completo | M4: não | N4: CURTO-CIRCUITO INTERNO | O4: «Constatado curto-circuito no tanque do religador, impedindo as operações de abertura e fechamento do equipamento» | P4: Diagnóstico DMSL explícito de curto-circuito no tanque travando abertura/fechamento; a origem do curto não é detalhada. | Y4: RL 2025 | Z4: 35
A5: RL 2025 | B5: =LEFT(Tabela3[[#This Row],[Ano/TIPO]],2) -> RL | D5: =_xlfn.XLOOKUP(K5,Base!G:G,Base!I:I) -> #N/A | E5: 7923927122 | F5: ETO-COEP 00079/2025 | G5: =_xlfn.XLOOKUP(_xlfn.NUMBERVALUE(Tabela3[[#This Row],[Ativo]]),'[3]Ajustes Reguladores de Tensão'!$A:$A,'[3]Ajustes Reguladores de Tensão'!$I:$I,_xlfn.XLOOKUP(_xlfn.NUMBERVALUE(Tabela3[[#This Row],[Ativo]]),'[3]Ajustes RL Poste'!$A:$A,'[3]Ajustes RL Poste'!$M:$M)) -> 34.500 | H5: 27/04/2025 | I5: =TEXT(Tabela3[[#This Row],[Data]],"mmmm") -> abril | J5: =YEAR(Tabela3[[#This Row],[Data]]) -> 2025 | K5: =_xlfn.CONCAT(Tabela3[[#This Row],[Ano]],Tabela3[[#This Row],[Mês]]) -> 2025abril | L5: tanque | M5: não | N5: CURTO-CIRCUITO INTERNO | O5: «substituir tanque do RL-7923927122 em curto, Anomalia identificada desarme das LD» | P5: Tanque em curto derrubando as LDs Palmas/Aparecida e Taquaruçu — curto interno como mecanismo; origem não descrita. | Y5: RL 2026 | Z5: 28
A6: RL 2025 | B6: =LEFT(Tabela3[[#This Row],[Ano/TIPO]],2) -> RL | D6: =_xlfn.XLOOKUP(K6,Base!G:G,Base!I:I) -> #N/A | E6: 7928241200 | F6: ETO-COEP 00139/2025 | G6: =_xlfn.XLOOKUP(_xlfn.NUMBERVALUE(Tabela3[[#This Row],[Ativo]]),'[3]Ajustes Reguladores de Tensão'!$A:$A,'[3]Ajustes Reguladores de Tensão'!$I:$I,_xlfn.XLOOKUP(_xlfn.NUMBERVALUE(Tabela3[[#This Row],[Ativo]]),'[3]Ajustes RL Poste'!$A:$A,'[3]Ajustes RL Poste'!$M:$M)) -> 34.500 | H6: 04/07/2025 | I6: =TEXT(Tabela3[[#This Row],[Data]],"mmmm") -> julho | J6: =YEAR(Tabela3[[#This Row],[Data]]) -> 2025 | K6: =_xlfn.CONCAT(Tabela3[[#This Row],[Ano]],Tabela3[[#This Row],[Mês]]) -> 2025julho | L6: tanque | M6: não | N6: CURTO-CIRCUITO INTERNO | O6: «fizemos ensaios elétricos e foi constatado que o tanque está em curto» | P6: Ensaios elétricos constataram o tanque em curto depois de o equipamento tirar a linha — curto interno como mecanismo; origem não descrita. | Y6: RT 2025 | Z6: 18
A7: RL 2025 | B7: =LEFT(Tabela3[[#This Row],[Ano/TIPO]],2) -> RL | D7: =_xlfn.XLOOKUP(K7,Base!G:G,Base!I:I) -> #N/A | E7: 7931610122 | F7: ETO-COEP 00083/2026 | G7: =_xlfn.XLOOKUP(_xlfn.NUMBERVALUE(Tabela3[[#This Row],[Ativo]]),'[3]Ajustes Reguladores de Tensão'!$A:$A,'[3]Ajustes Reguladores de Tensão'!$I:$I,_xlfn.XLOOKUP(_xlfn.NUMBERVALUE(Tabela3[[#This Row],[Ativo]]),'[3]Ajustes RL Poste'!$A:$A,'[3]Ajustes RL Poste'!$M:$M)) -> 13.800 | H7: 10/10/2025 | I7: =TEXT(Tabela3[[#This Row],[Data]],"mmmm") -> outubro | J7: =YEAR(Tabela3[[#This Row],[Data]]) -> 2025 | K7: =_xlfn.CONCAT(Tabela3[[#This Row],[Ano]],Tabela3[[#This Row],[Mês]]) -> 2025outubro | L7: tanque | M7: sim | N7: CURTO-CIRCUITO INTERNO | O7: «Houve um curto no equipamento danificando a parte ativa, e antena!» | P7: Curto no equipamento danificou parte ativa e antena; o texto não localiza a origem (dano simultâneo na antena até sugere surto externo, não afirmado). | Y7: RT 2026 | Z7: 9
A8: RL 2025 | B8: =LEFT(Tabela3[[#This Row],[Ano/TIPO]],2) -> RL | D8: =_xlfn.XLOOKUP(K8,Base!G:G,Base!I:I) -> #N/A | E8: 7933766059 | F8: ETO-COEP 00082/2026 | G8: =_xlfn.XLOOKUP(_xlfn.NUMBERVALUE(Tabela3[[#This Row],[Ativo]]),'[3]Ajustes Reguladores de Tensão'!$A:$A,'[3]Ajustes Reguladores de Tensão'!$I:$I,_xlfn.XLOOKUP(_xlfn.NUMBERVALUE(Tabela3[[#This Row],[Ativo]]),'[3]Ajustes RL Poste'!$A:$A,'[3]Ajustes RL Poste'!$M:$M)) -> 13.800 | H8: 08/10/2025 | I8: =TEXT(Tabela3[[#This Row],[Data]],"mmmm") -> outubro | J8: =YEAR(Tabela3[[#This Row],[Data]]) -> 2025 | K8: =_xlfn.CONCAT(Tabela3[[#This Row],[Ano]],Tabela3[[#This Row],[Mês]]) -> 2025outubro | L8: tanque | M8: sim | N8: CURTO-CIRCUITO INTERNO | O8: «Houve um curto na parte ativa do equipamento danificando a mesma, será necessário fazer a substituição somente do tanque, parte ativa.» | P8: O DMSL afirma curto na própria parte ativa danificando-a — mecanismo explícito; a origem do curto não é detalhada. | Q8: Causa mantida (CURTO-CIRCUITO INTERNO); confiança rebaixada de alta para media: 'Houve um curto na parte ativa do equipamento danificando a mesma' é narrativa de evento sem dizer como se constatou — mesmo fraseado e mesmo formato de laudo DMSL do 7931610122, classificado media. Alta fica reservada a curto constatado por ensaio (7928241200, 7908196047). | Y8: Total Geral | Z8: 90
A9: RL 2025 | B9: =LEFT(Tabela3[[#This Row],[Ano/TIPO]],2) -> RL | D9: =_xlfn.XLOOKUP(K9,Base!G:G,Base!I:I) -> #N/A | E9: 7900594026 | F9: ETO-COEP 00210/2025 | G9: =_xlfn.XLOOKUP(_xlfn.NUMBERVALUE(Tabela3[[#This Row],[Ativo]]),'[3]Ajustes Reguladores de Tensão'!$A:$A,'[3]Ajustes Reguladores de Tensão'!$I:$I,_xlfn.XLOOKUP(_xlfn.NUMBERVALUE(Tabela3[[#This Row],[Ativo]]),'[3]Ajustes RL Poste'!$A:$A,'[3]Ajustes RL Poste'!$M:$M)) -> 34.500 | H9: 15/10/2025 | I9: =TEXT(Tabela3[[#This Row],[Data]],"mmmm") -> outubro | J9: =YEAR(Tabela3[[#This Row],[Data]]) -> 2025 | K9: =_xlfn.CONCAT(Tabela3[[#This Row],[Ano]],Tabela3[[#This Row],[Mês]]) -> 2025outubro | L9: controle | M9: sim | N9: DEFEITO ELETRÔNICO (CONTROLE/PLACA/RELÉ) | O9: «o equipamento está com falha na porta de comunicação serial RS 232» | P9: Falha localizada na porta serial RS-232 do relé Cooper Form 6 — defeito de hardware do controle; o porquê da falha não é descrito.
A10: RL 2025 | B10: =LEFT(Tabela3[[#This Row],[Ano/TIPO]],2) -> RL | D10: =_xlfn.XLOOKUP(K10,Base!G:G,Base!I:I) -> #N/A | E10: 7936038076 | F10: ETO-TELE 00074/2025 | G10: =_xlfn.XLOOKUP(_xlfn.NUMBERVALUE(Tabela3[[#This Row],[Ativo]]),'[3]Ajustes Reguladores de Tensão'!$A:$A,'[3]Ajustes Reguladores de Tensão'!$I:$I,_xlfn.XLOOKUP(_xlfn.NUMBERVALUE(Tabela3[[#This Row],[Ativo]]),'[3]Ajustes RL Poste'!$A:$A,'[3]Ajustes RL Poste'!$M:$M)) -> 34.500 | H10: 03/02/2025 | I10: =TEXT(Tabela3[[#This Row],[Data]],"mmmm") -> fevereiro | J10: =YEAR(Tabela3[[#This Row],[Data]]) -> 2025 | K10: =_xlfn.CONCAT(Tabela3[[#This Row],[Ano]],Tabela3[[#This Row],[Mês]]) -> 2025fevereiro | L10: controle | M10: sim | N10: DEFEITO ELETRÔNICO (CONTROLE/PLACA/RELÉ) | O10: «FOI IDENTIFICADO DISPLAY DO RELE APAGADO - ALIMENTAÇÃO CA NORMAL» | P10: Alimentação CA normal com display do relé apagado aponta falha intrínseca da eletrônica do controle; a OS trocou o relé e atualizou o firmware.
A11: RL 2025 | B11: =LEFT(Tabela3[[#This Row],[Ano/TIPO]],2) -> RL | D11: =_xlfn.XLOOKUP(K11,Base!G:G,Base!I:I) -> #N/A | E11: 7957126085 | F11: ETO-COEP 00156/2025 | G11: =_xlfn.XLOOKUP(_xlfn.NUMBERVALUE(Tabela3[[#This Row],[Ativo]]),'[3]Ajustes Reguladores de Tensão'!$A:$A,'[3]Ajustes Reguladores de Tensão'!$I:$I,_xlfn.XLOOKUP(_xlfn.NUMBERVALUE(Tabela3[[#This Row],[Ativo]]),'[3]Ajustes RL Poste'!$A:$A,'[3]Ajustes RL Poste'!$M:$M)) -> 34.500 | H11: 05/06/2025 | I11: =TEXT(Tabela3[[#This Row],[Data]],"mmmm") -> junho | J11: =YEAR(Tabela3[[#This Row],[Data]]) -> 2025 | K11: =_xlfn.CONCAT(Tabela3[[#This Row],[Ano]],Tabela3[[#This Row],[Mês]]) -> 2025junho | L11: controle | M11: não | N11: FALHA DE INSTALAÇÃO / MONTAGEM | O11: «Os para raios da fase B e C estão fechando arco na cruzeta. Curto desceu para o controle danificando os componentes.» | P11: Causa explícita: para-raios arqueando na cruzeta por distância inadequada — o curto desceu e danificou o controle; a correção pede abaixar o tanque para afastar das cruzetas.
A12: RL 2025 | B12: =LEFT(Tabela3[[#This Row],[Ano/TIPO]],2) -> RL | D12: =_xlfn.XLOOKUP(K12,Base!G:G,Base!I:I) -> #N/A | E12: 7957620015 | F12: ETO-COEP 00081/2026 | G12: =_xlfn.XLOOKUP(_xlfn.NUMBERVALUE(Tabela3[[#This Row],[Ativo]]),'[3]Ajustes Reguladores de Tensão'!$A:$A,'[3]Ajustes Reguladores de Tensão'!$I:$I,_xlfn.XLOOKUP(_xlfn.NUMBERVALUE(Tabela3[[#This Row],[Ativo]]),'[3]Ajustes RL Poste'!$A:$A,'[3]Ajustes RL Poste'!$M:$M)) -> 13.800 | H12: 08/05/2025 | I12: =TEXT(Tabela3[[#This Row],[Data]],"mmmm") -> maio | J12: =YEAR(Tabela3[[#This Row],[Data]]) -> 2025 | K12: =_xlfn.CONCAT(Tabela3[[#This Row],[Ano]],Tabela3[[#This Row],[Mês]]) -> 2025maio | L12: controle | M12: sim | N12: FALHA DE INSTALAÇÃO / MONTAGEM | O12: «A antena do rádio do RLG 7957620015 fica próximo da BT, onde a mesma veio a encostar no cabo da fase o que ocasionou um curto-circuito no rádio, que passou para todos os componentes do controle» | P12: Causa explícita: antena instalada próxima da BT encostou no cabo da fase e o curto propagou do rádio para todo o controle — erro de montagem.
