Workbook

Sheet Orçamento
A1: Criticidade | B1: (Tudo) | K1: Equipamento | L1: Backlog | M1: Resolvidos | O1: Entrantes | P1: Pendentes | Q1: Forecast
K2: Religador | L2: 53 | M2: 45 | O2: 35 | P2: =O2+L2-M2 -> 43
A3: Tipo | B3: Status | C3: Contagem de Ativo | D3: Soma de Orçamento Total | K3: Regulador | L3: 27 | M3: 26 | O3: 10 | P3: =O3+L3-M3 -> 11
A4: 58 | B4: Avaliar compra | C4: 2 | D4: 989173.2 | K4: Banco Capacitor | L4: 47 | M4: 1 | O4: 0 | P4: 46
B5: Em logistica (N1>N3) | C5: 6 | D5: 691664.7 | G5: Compras
B6: Reforma | C6: 2 | D6: 213808.1 | G6: 94500
B7: Em execução | C7: 2 | D7: 509586.6 | G7: 87683
A8: 79 | B8: Avaliar compra | C8: 20 | D8: 1229422.1 | E8: 1229422.1 | G8: 398547
B9: Gerado PMA | C9: 20 | D9: 1320983.7 | G9: =SUM(G6:G8) -> 580730 | J9: RL
B10: Em execução | C10: 1 | D10: 15000
A11: Total Geral | C11: 53 | D11: 4969638.5 | M11: Colunas | N11: Setembro | O11: Outubro | P11: Novembro | Q11: Dezembro | R11: Total
M12: Orçado | N12: 5206065 | O12: 5579287.5 | P12: 5821193 | Q12: 6062323.8
C13: BC | D13: 310372.4 | H13: 946651.72 | I13: 8481 | M13: Realizado | T13: RL Pendetes | U13: 43
H14: 959988.26 | I14: 8495 | M14: Forecast | N14: 524586.6 | O14: =691664.7+134944.52 -> 826609.22 | P14: =1443230.22+82181.59+175427.87 -> 1700839.7 | Q14: =1320983.74+100000 -> 1420983.7 | R14: =SUM(M14:Q14) -> 4473019.2 | T14: RT Pendetes | U14: 11
H15: =SUM(H13:H14) -> 1906640 | M15: RL Forecast Backlog Resolvidos | N15: 2 | P15: 20 | Q15: 20 | T15: BC | U15: 46
B16: 8481 | D16: 45 | E16: RL | G16: 2465983.7 | M16: RT Forecast backlog Resolvidos | N16: 1 | O16: 6 | P16: 2
B17: 8495 | E17: RT | G17: 1597242.4 | M17: BC Forecast backog Resolvidos | N17: 3 | O17: 23
C18: =1605000*1.0001745 -> 1605280.1 | D18: 143 | E18: BC | G18: 315372.4 | M18: RL Forecast Entrantes | N18: 2 | O18: 4 | P18: 1 | Q18: 4
B19: Orçamento | C19: 6100000 | G19: =SUM(G16:G18) -> 4378598.5 | M19: RT Forecast Entrantes | N19: 3 | O19: 0 | P19: 1 | Q19: 2
C20: 5983226.1 | M20: BC Forecast Entrantes | N20: 3 | O20: 1 | P20: 2 | Q20: 0 | R20: 0
C21: =C19-C20 -> 116773.88 | D21: 839786.22 | E21: =C18-D21 -> 765493.86 | K21: 1605280.1 | M21: RL Forecast | N21: =43+N18-N15 -> 43 | O21: =N21+O18-O15 -> 47 | P21: =O21+P18-P15 -> 28 | Q21: =P21+Q18-Q15 -> 12 | R21: 12
E22: 765493.86 | M22: RT Forecast | N22: =11-N16+N19 -> 13 | O22: =N22-O16+O19 -> 7 | P22: =O22-P16+P19 -> 6 | Q22: =P22-Q16+Q19 -> 8 | R22: 8
C23: Execução | D23: 524586.6 | M23: BC Forecast | N23: =46 -> 46 | O23: =N23-O17+O20 -> 24 | P23: =O23-P17+P20 -> 26 | Q23: =P23-Q17+Q20 -> 26 | R23: 23
C24: Logistica | D24: 691664.7 | M24: Sem BC | N24: =SUM(N21:N22) -> 56 | O24: =SUM(O21:O22) -> 54 | P24: =SUM(P21:P22) -> 34 | Q24: =SUM(Q21:Q22) -> 20 | R24: =SUM(R21:R22) -> 20
E25: 1605280.1 | M25: Forecast Entrantes Pentes | N25: =SUM(N18:N20)+100 -> 108 | O25: =N25+SUM(O18:O20) -> 113 | P25: =O25+SUM(P18:P20) -> 117 | Q25: =P25+SUM(Q18:Q20) -> 123
M26: Forecast resolvidos | N26: =SUM(N15:N17) -> 6 | O26: =N26+SUM(O15:O17) -> 35 | P26: =O26+SUM(P15:P17) -> 57 | Q26: =P26+SUM(Q15:Q17) -> 77
D27: 6062323.8 | M27: Quantidades Total | N27: =SUM(N21:N23) -> 102 | O27: =SUM(O21:O23) -> 78 | P27: =SUM(P21:P23) -> 60 | Q27: =SUM(Q21:Q23) -> 46 | R27: =SUM(R21:R23) -> 43
D28: 6083299.3 | M28: Orçado | N28: 5206065 | O28: 5579287.5 | P28: 5821193 | Q28: 6062323.8
D29: =D27-D28 -> -20975.48 | M29: Forecast Desembolso | N29: =1605280.07+N14 -> 2129866.7 | O29: =O14+N29-20000 -> 2936475.9 | P29: =P14+O29 -> 4637315.6 | Q29: =Q14+P29 -> 6058299.3 | R29: 6058299.3
C30: 315372.4 | I30: =SUM(J46:J51) -> 3980465.3
M31: Colunas | N31: Setembro | O31: Outubro | P31: Novembro | Q31: Dezembro
M32: BACKLOG | N32: =SUM(P2:P4) -> 100 | O32: =N35 -> 102 | P32: =O35 -> 78 | Q32: =P35 -> 60
M33: ENTRANTE | N33: =SUM(N18:N20) -> 8 | O33: =SUM(O18:O20) -> 5 | P33: =SUM(P18:P20) -> 4 | Q33: =SUM(Q18:Q20) -> 6
M34: RESOLVIDOS | N34: =SUM(N15:N17) -> 6 | O34: =SUM(O15:O17) -> 29 | P34: =SUM(P15:P17) -> 22 | Q34: =SUM(Q15:Q17) -> 20
M35: PENDENTES | N35: =N32+N33-N34 -> 102 | O35: =O32+O33-O34 -> 78 | P35: =P32+P33-P34 -> 60 | Q35: =Q32+Q33-Q34 -> 46
D36: 310372.4 | E36: 23 | M36: ORÇADO | N36: 5206065 | O36: 5579287.5 | P36: 5821193 | Q36: 6062323.8
E37: =10/E36 -> 0.43478261 | F37: 134944.52 | M37: FORECAST DESEMBOLSO | N37: 2129866.7 | O37: 2936475.9 | P37: 4637315.6 | Q37: 6058299.3
A39: OUTUBRO | B39: NOVEMBRO | F39: 175427.88
A40: 10 | B40: 13 | J40: =SUM(D58:G58) -> 4473019.2
E45: 58 | F45: JANEIRO DE 2027 | H45: Avaliar compra | I45: 2 | J45: 989173.2
...

Sheet Apresentação
B1: Realizado | C1: Em Execução | D1: Em logistica (N1>N3) | E1: Gerado PMA | F1: Reforma | G1: Emitir compra
A2: RL | B2: 839786.21 | C2: 15000 | D2: - | E2: 1320983.3 | F2: - | G2: 1229422.1
A3: RT | B3: 765493.85 | C3: 509585.6 | D3: 691664.7 | E3: - | F3: 375991.1 | G3: -
A4: BC | B4: - | C4: - | D4: - | E4: 310372.4 | F4: - | G4: -
B5: =SUM(B2:B4) -> 1605280.1 | C5: =SUM(C2:C4) -> 524585.6 | D5: =SUM(D2:D4) -> 691664.7 | E5: =SUM(E2:E4) -> 1631355.7 | F5: =SUM(F2:F4) -> 375991.1 | G5: =SUM(G2:G4) -> 1229422.1
A6: Soma (acumulada) | B6: =B5 -> 1605280.1 | C6: =B6+C5 -> 2129865.7 | D6: =C6+D5 -> 2821530.4 | E6: =D6+E5 -> 4452886.1 | F6: =E6+F5 -> 4828877.2 | G6: =F6+G5 -> 6058299.3
G7: 6062323.8
G8: =G7-G6 -> 4024.52
A9: TIPO | B9: STATUS | C9: CONTAGEM | D9: VALOR PREVISTO
A10: RL | B10: Em execução | C10: 1 | D10: 15000
B11: Gerado PMA | C11: 20 | D11: 1320983.3
B12: Gerar compra | C12: 20 | D12: 1229422.1
C13: 41 | D13: 2565405.5
A14: RT | B14: Em execução | C14: 2 | D14: 509585.6
B15: Em logistica (N1>N3) | C15: 6 | D15: 691664.7
B16: Reforma | C16: 2 | D16: 375991.1
C17: 10 | D17: 1597241.4
A18: BC | B18: Gerado PMA | C18: 23 | D18: 310372.4
A19: Total Geral | C19: 51 | D19: =D13+D17+D18 -> 4473019.3 | E19: 4478019.3
A24: TIPO | B24: STATUS | C24: CONTAGEM | D24: VALOR PREVISTO
A25: RL | B25: Em execução | C25: 1 | D25: 15000
B26: Gerado PMA | C26: 20 | D26: 1320983.3
B27: Gerar compra | C27: 20 | D27: 1229422.1
C28: 41 | D28: 2565405.9
A29: RT | B29: Em execução | C29: 2 | D29: 509585.6
B30: Em logistica (N1>N3) | C30: 6 | D30: 691664.7
B31: Reforma | C31: 2 | D31: 375991.1
C32: 10 | D32: 1577241.4
A33: BC | B33: Gerado PMA | C33: 23 | D33: 310372.4
A34: Total Geral | C34: 74 | D34: 4453019.7
B39: Realizado | C39: Em Execução | D39: Em logistica (N1>N3) | E39: Gerado PMA | F39: Reforma | G39: Emitir compra
A40: RL | B40: 839786.21 | C40: 15000 | D40: - | E40: 1320983.3 | F40: - | G40: 1229422.1
A41: RT | B41: 765493.85 | C41: 509585.6 | D41: 691664.7 | E41: - | F41: 375991.1 | G41: -
A42: BC | B42: - | C42: - | D42: - | E42: 310372.4 | F42: - | G42: -
A43: Soma (acumulada) | B43: 1605280.1 | C43: 2129865.7 | D43: 2821530.4 | E43: 4452886.1 | F43: 4828877.2 | G43: 6058299.3

Sheet Gestão
A1: Ativo | B1: Marca | C1: Faixa de Tensão | D1: Tipo | E1: Potencia | F1: SS SGM | G1: Criticidade | H1: Status | I1: Defeito | J1: Orçamento MO | K1: Orçamento MAT | L1: Orçamento Total | M1: PMA | N1: Entregue N1? | O1: Gerado Obra? | P1: Gerado EMD? | Q1: Entregue N3? | R1: Concluído COCM? | S1: Enviado para Cadastro | T1: Estudo Proteção | U1: Repassado ao DMSL? | V1: Comissionado? | W1: Índice | X1: SLA_Total | Y1: Dias Pendente | Z1: Status Atendimento | AA1: Responsável | AB1: Status Prazo | AC1: Coluna1 | AD1: Alimentador | AE1: Município | AF1: Polo | AG1: Regional
A2: 7926089013 | B2: NOJA RC10 | C2: 34,5 kV | D2: =LEFT(Table1[[#This Row],[Ativo]],2) -> 79 | F2: ETO-COEP 00078/2026 | G2: Alta | H2: Gerado PMA | I2: Controle 34,5 | J2: 13209.34 | K2: 38094.72 | L2: 51304.06 | M2: 38297 | W2: 34 | X2: 26 | Y2: 143 | Z2: 116 - DIAS AGUARDANDO DCMD | AA2: COEP | AB2: 117 - DIAS FORA DO PRAZO | AD2: LD03062013 - LD PARAISO I A PIUM | AE2: PARAISO DO TOCANTINS | AF2: PARAISO DO TOCANTINS | AG2: CENTRO
A3: 7923673004 | B3: ARTECHE P500 | C3: 13,8 kV | D3: =LEFT(Table1[[#This Row],[Ativo]],2) -> 79 | F3: ETO-COEP 00124/2026 | G3: Muito Alta | H3: Gerado PMA | I3: RL Completo 13,8 | J3: 11016.94 | K3: 55602.54 | L3: 66619.48 | M3: 38294+38296 | W3: 5 | X3: 12 | Y3: 144 | Z3: 40 - DIAS AGUARDANDO DCMD | AA3: COEP | AB3: 132 - DIAS FORA DO PRAZO | AD3: AL04010004 - AL 4 SE ARAGUAINA I | AE3: ARAGUAINA | AF3: ARAGUAINA | AG3: NORTE
A4: 7903569004 | B4: NOJA RC10 | C4: 13,8 kV | D4: =LEFT(Table1[[#This Row],[Ativo]],2) -> 79 | F4: ETO-COEP 00152/2026 | G4: Muito Alta | H4: Gerado PMA | I4: RL Completo 13,8 | J4: 11016.94 | K4: 55602.54 | L4: 66619.48 | M4: 38294+38296 | W4: 11 | X4: 12 | Y4: 28 | Z4: 27 - DIAS AGUARDANDO DCMD | AA4: COEP | AB4: 16 - DIAS FORA DO PRAZO | AD4: AL05010004 - AL 5 SE ARAGUAINA I | AE4: ARAGUAINA | AF4: ARAGUAINA | AG4: NORTE
A5: 5856070091 | B5: ITB | C5: 34,5 kV | D5: =LEFT(Table1[[#This Row],[Ativo]],2) -> 58 | E5: 400 kVA | F5: ETO-RD-DP 00479/2026 | G5: Muito Alta | H5: Em execução | I5: RT Completo 400 34,5 | J5: 200637 | K5: 293949.6 | L5: 494586.6 | M5: 38291+38292 | W5: 10 | X5: 12 | Y5: 395 | Z5: 20 - DIAS AGUARDANDO DCMD | AA5: COCM-S | AB5: 383 - DIAS FORA DO PRAZO | AD5: LD04002091 - LD 04 ALMAS NATIVIDADE AO POV PRINCIPE | AE5: ALMAS | AF5: DIANOPOLIS | AG5: SUL
A6: 7908705049 | B6: COOPER F6 | C6: 13,8 kV | D6: =LEFT(Table1[[#This Row],[Ativo]],2) -> 79 | F6: ETO-RD-DP 00409/2026 | G6: Muito Alta | H6: Gerado PMA | I6: RL Completo 13,8 | J6: 11016.94 | K6: 55602.54 | L6: 66619.48 | M6: 38294+38296 | W6: 15 | X6: 12 | Y6: 397 | Z6: 41 - DIAS AGUARDANDO DCMD | AA6: COCM-S | AB6: 385 - DIAS FORA DO PRAZO | AD6: AL01015049 - AL 1 SE AURORA | AE6: AURORA DO TOCANTINS | AF6: DIANOPOLIS | AG6: SUL
A7: 7947203070 | B7: TAVRIDA | C7: 34,5 kV | D7: =LEFT(Table1[[#This Row],[Ativo]],2) -> 79 | F7: ETO-COEP 00131/2026 | G7: Muito Alta | H7: Gerado PMA | I7: RL Completo 34,5 | J7: 13209.34 | K7: 76246.2 | L7: 89455.54 | M7: 38295+38297 | W7: 9 | X7: 12 | Y7: 267 | Z7: 40 - DIAS AGUARDANDO DCMD | AA7: COEP | AB7: 255 - DIAS FORA DO PRAZO | AD7: LD02065015 | AE7: RIO SONO | AF7: PALMAS | AG7: CENTRO
A8: 7927413001 | B8: NOJA RC10 | C8: 34,5 kV | D8: =LEFT(Table1[[#This Row],[Ativo]],2) -> 79 | F8: ETO-COEP 00141/2026 | G8: Muito Alta | H8: Gerado PMA | I8: RL Completo 34,5 | J8: 13209.34 | K8: 76246.2 | L8: 89455.54 | M8: 38295+38297 | W8: 21 | X8: 12 | Y8: 140 | Z8: 34 - DIAS AGUARDANDO DCMD | AA8: COEP | AB8: 128 - DIAS FORA DO PRAZO | AD8: LD01072001 - LD PORTO NACIONAL A SE PROJETO SAO JOAO | AE8: PORTO NACIONAL | AF8: PORTO NACIONAL | AG8: CENTRO
A9: 7900453110 | B9: COOPER F6 | C9: 34,5 kV | D9: =LEFT(Table1[[#This Row],[Ativo]],2) -> 79 | F9: ETO-COEP 00087/2026 | G9: Muito Alta | H9: Gerado PMA | I9: RL Completo 34,5 | J9: 13209.34 | K9: 76246.2 | L9: 89455.54 | M9: 38295+38297 | W9: 25 | X9: 12 | Y9: 482 | Z9: 111 - DIAS AGUARDANDO DCMD | AA9: COEP | AB9: 470 - DIAS FORA DO PRAZO | AD9: LD03040003 - LD GURUPI A ALIANCA E TREVO DA PRAIA | AE9: SANTA RITA DO TOCANTINS | AF9: PORTO NACIONAL | AG9: CENTRO
A10: 5800440256 | B10: ITB E TOSHIBA | C10: 34,5 kV | D10: =LEFT(Table1[[#This Row],[Ativo]],2) -> 58 | E10: 200 kVA | F10: ETO-COEP 00169/2026 | G10: Muito Alta | H10: Realizado | I10: Célula 200 34,5 | J10: 80318.5 | K10: 51705.75 | L10: 132024.25 | M10: Sem PMA | N10: Sim | O10: 0312600408 | P10: 521995 | Q10: Sim | R10: Sim | S10: Não | W10: 23 | X10: 12 | Y10: 21 | Z10: 10 - DIAS AGUARDANDO DCMD | AA10: COEP | AB10: 9 - DIAS FORA DO PRAZO | AD10: LD03046026 - LD UHE ISAMU A PONTE ALTA | AE10: MATEIROS | AF10: PONTE ALTA TOCANTINS | AG10: CENTRO
A11: 7903112004 | B11: COOPER F6 | C11: 34,5 kV | D11: =LEFT(Table1[[#This Row],[Ativo]],2) -> 79 | F11: ETO-COEP 00184/2025 | G11: Alta | H11: Gerado PMA | I11: RL Completo 34,5 | J11: 13209.34 | K11: 76246.2 | L11: 89455.54 | M11: 38295+38297 | W11: 48 | X11: 26 | Y11: 348 | Z11: 347 - DIAS AGUARDANDO DCMD | AA11: COEP | AB11: 322 - DIAS FORA DO PRAZO | AD11: LD05010004 - LD ARAGUAINA I A BABACULANDIA | AE11: ARAGUAINA | AF11: ARAGUAINA | AG11: NORTE
A12: 7920024127 | B12: SCHNEIDER ADVC | C12: 34,5 kV | D12: =LEFT(Table1[[#This Row],[Ativo]],2) -> 79 | F12: ETO-COEP 00120/2025 | G12: Alta | H12: Gerado PMA | I12: RL Completo 34,5 | J12: 13209.34 | K12: 76246.2 | L12: 89455.54 | M12: 38295+38297 | W12: 49 | X12: 26 | Y12: 441 | Z12: 411 - DIAS AGUARDANDO DCMD | AA12: COEP | AB12: 415 - DIAS FORA DO PRAZO | AD12: LD01084002 - LD TOCANTINOPOLIS A ANANAS | AE12: PALMEIRAS DO TOCANTINS | AF12: TOCANTINOPOLIS | AG12: NORTE
A13: 5803327001 | B13: TOSHIBA | C13: 13,8 kV | D13: =LEFT(Table1[[#This Row],[Ativo]],2) -> 58 | E13: 167 kVA | F13: ETO-COEP 00149/2026 | G13: Alta | H13: Em logistica (N1>N3) | I13: Controle 167 13,8 | J13: 20000 | K13: 23259.6 | L13: 43259.6 | M13: Controle Rua que voltou de dianopólis | N13: Sim | O13: 0712600591 | P13: Ainda Não | Q13: Ainda não | R13: Não | S13: Não | T13: Não | U13: Não | V13: Não | W13: 27 | X13: 26 | Y13: 347 | Z13: 28 - DIAS AGUARDANDO DCMD | AA13: COEP | AB13: 321 - DIAS FORA DO PRAZO | AD13: AL01102271 - AL 01 SE LUZIMANGUES INDUSTRIAL | AE13: PORTO NACIONAL | AF13: PORTO NACIONAL | AG13: CENTRO
A14: 7931608059 | B14: NOJA RC10 | C14: 13,8 kV | D14: =LEFT(Table1[[#This Row],[Ativo]],2) -> 79 | F14: ETO-COEP 00040/2026 | G14: Muito Alta | H14: Gerado PMA | I14: Tanque 13,8 | J14: 11016.94 | K14: 21785.72 | L14: 32802.66 | M14: 38294 | W14: 6 | X14: 12 | Y14: 201 | Z14: 174 - DIAS AGUARDANDO DCMD | AA14: COEP | AB14: 189 - DIAS FORA DO PRAZO | AD14: AL05099059 - AL 5 SE TAQUARALTO I I | AE14: PALMAS | AF14: TAQUARALTO | AG14: CENTRO
A15: 5853360007 | B15: ITB | C15: 34,5 kV | D15: =LEFT(Table1[[#This Row],[Ativo]],2) -> 58 | E15: 400 kVA | F15: ETO-RD-PS 00323/2025 | G15: Alta | H15: Em execução | I15: Acessório 400 34,5 | J15: 0 | K15: 15000 | L15: 15000 | M15: Sem PMA | N15: NA | O15: NA | W15: 38 | X15: 26 | Y15: 475 | Z15: 304 - DIAS AGUARDANDO DCMD | AA15: COCM-C | AB15: 449 - DIAS FORA DO PRAZO | AD15: LD05050008 - LD MIRANORTE A MIRACEMA | AE15: MIRACEMA DO TOCANTINS | AF15: MIRACEMA DO TOCANTINS | AG15: CENTRO
A16: 5840227063 | B16: ITB | C16: 34,5 kV | D16: =LEFT(Table1[[#This Row],[Ativo]],2) -> 58 | E16: 398/400 kVA | F16: ETO-COEP 00151/2026 | G16: Média | H16: Em logistica (N1>N3) | I16: Célula 400 34,5 | J16: 80318.5 | K16: 90230 | L16: 170548.5 | M16: 38292 | N16: Sim | O16: 0612600861 | P16: Ainda Não | Q16: Ainda não | R16: Não | S16: Não | T16: Não | U16: Não | V16: Não | W16: 45 | X16: 86 | Y16: 206 | Z16: 28 - DIAS AGUARDANDO DCMD | AA16: COEP | AB16: 120 - DIAS FORA DO PRAZO | AD16: LD01054060 - LD NOVA OLINDA A ARAPOEMA | AE16: BANDEIRANTES DO TOCANTINS | AF16: COLINAS DO TOCANTINS | AG16: NORTE
A17: 7925744087 | B17: NOJA RC10 | C17: 34,5 kV | D17: =LEFT(Table1[[#This Row],[Ativo]],2) -> 79 | F17: ETO-COEP 00059/2026 | G17: Muito Alta | H17: Gerado PMA | I17: Tanque 34,5 | J17: 13209.34 | K17: 38151.48 | L17: 51360.82 | M17: 38295 | W17: 12 | X17: 12 | Y17: 189 | Z17: 140 - DIAS AGUARDANDO DCMD | AA17: COEP | AB17: 177 - DIAS FORA DO PRAZO | AD17: LD02022033 - LD COLMEIA A COUTO MAGALHAES | AE17: GOIANORTE | AF17: GUARAI | AG17: NORTE
A18: 7925871077 | B18: NOJA RC10 | C18: 34,5 kV | D18: =LEFT(Table1[[#This Row],[Ativo]],2) -> 79 | F18: ETO-COEP 00048/2026 | G18: Muito Alta | H18: Gerado PMA | I18: Tanque 34,5 | J18: 13209.34 | K18: 38151.48 | L18: 51360.82 | M18: 38295 | W18: 26 | X18: 12 | Y18: 154 | Z18: 154 - DIAS AGUARDANDO DCMD | AA18: COEP | AB18: 142 - DIAS FORA DO PRAZO | AD18: LD03105019 - LD POV BIELANDIA A CAMPOS LINDOS | AE18: GOIATINS | AF18: COLINAS DO TOCANTINS | AG18: NORTE
A19: 7927646026 | B19: NOJA RC10 | C19: 34,5 kV | D19: =LEFT(Table1[[#This Row],[Ativo]],2) -> 79 | F19: ETO-COEP 00029/2026 | G19: Alta | H19: Gerado PMA | I19: Tanque 34,5 | J19: 13209.34 | K19: 38151.48 | L19: 51360.82 | M19: 38295 | W19: 50 | X19: 26 | Y19: 220 | Z19: 194 - DIAS AGUARDANDO DCMD | AA19: COEP | AB19: 194 - DIAS FORA DO PRAZO | AD19: LD03046026 - LD UHE ISAMU A PONTE ALTA | AE19: PONTE ALTA TOCANTINS | AF19: PONTE ALTA TOCANTINS | AG19: CENTRO
A20: 7930428001 | B20: NOJA RC10 | C20: 34,5 kV | D20: =LEFT(Table1[[#This Row],[Ativo]],2) -> 79 | F20: ETO-COEP 00150/2026 | G20: Alta | H20: Gerado PMA | I20: Tanque 34,5 | J20: 13209.34 | K20: 38151.48 | L20: 51360.82 | M20: 38295 | W20: 54 | X20: 26 | Y20: 412 | Z20: 28 - DIAS AGUARDANDO DCMD | AA20: COEP | AB20: 386 - DIAS FORA DO PRAZO | AD20: LD01100001 - LD PROJETO SAO JOAO IRRIGACAO | AE20: PORTO NACIONAL | AF20: PORTO NACIONAL | AG20: CENTRO
A21: 7944559149 | B21: NOJA RC10 | C21: 34,5 kV | D21: =LEFT(Table1[[#This Row],[Ativo]],2) -> 79 | F21: ETO-COEP 00063/2026 | G21: Média | H21: Gerado PMA | I21: Controle 34,5 | J21: 13209.34 | K21: 38094.72 | L21: 51304.06 | M21: Sem PMA | W21: 63 | X21: 86 | Y21: 153 | Z21: 139 - DIAS AGUARDANDO DCMD | AA21: COEP | AB21: 67 - DIAS FORA DO PRAZO | AD21: LD01434149 - LD CASEARA A ARAGUACEMA | AE21: CASEARA | AF21: DIVINOPOLIS | AG21: CENTRO
A22: 7955986084 | B22: NOJA RC10 | C22: 34,5 kV | D22: =LEFT(Table1[[#This Row],[Ativo]],2) -> 79 | F22: ETO-COEP 00133/2026 | G22: Média | H22: Avaliar compra | I22: Controle 34,5 | J22: 13209.34 | K22: 38094.72 | L22: 51304.06 | M22: Sem PMA | W22: 72 | X22: 86 | Y22: 40 | Z22: 40 - DIAS AGUARDANDO DCMD | AA22: COEP | AB22: VENCE EM: 46 DIAS | AD22: LD04062013 - LD SE PARAISO I A DIVINOPOLIS | AE22: DIVINOPOLIS | AF22: DIVINOPOLIS | AG22: CENTRO
A23: 7900535058 | B23: COOPER F6 | C23: 34,5 kV | D23: =LEFT(Table1[[#This Row],[Ativo]],2) -> 79 | F23: ETO-COEP 00173/2025 | G23: Média | H23: Gerado PMA | I23: RL Completo 34,5 | J23: 13209.34 | K23: 76246.2 | L23: 89455.54 | M23: Sem PMA | W23: 60 | X23: 86 | Y23: 374 | Z23: 357 - DIAS AGUARDANDO DCMD | AA23: COEP | AB23: 288 - DIAS FORA DO PRAZO | AD23: LD03010004 - LD ARAGUAINA A CARMOLA E ARAGUANA | AE23: SANTA FE DO ARAGUAIA | AF23: ARAGUAINA | AG23: NORTE
A24: 7908249152 | B24: COOPER F6 | C24: 34,5 kV | D24: =LEFT(Table1[[#This Row],[Ativo]],2) -> 79 | F24: ETO-COEP 00038/2026 | G24: Média | H24: Gerado PMA | I24: RL Completo 34,5 | J24: 13209.34 | K24: 76246.2 | L24: 89455.54 | M24: Sem PMA | W24: 65 | X24: 86 | Y24: 207 | Z24: 174 - DIAS AGUARDANDO DCMD | AA24: COEP | AB24: 121 - DIAS FORA DO PRAZO | AD24: LD02072001 - LD PORTO NACIONAL A SILVANOPOLIS | AE24: SANTA ROSA DO TOCANTINS | AF24: PORTO NACIONAL | AG24: CENTRO
A25: 5800961074 | B25: ITB | C25: 34,5 kV | D25: =LEFT(Table1[[#This Row],[Ativo]],2) -> 58 | E25: 200 kVA | F25: ETO-COEP 00221/2025 | G25: Média | H25: Em compra | I25: Célula 200 34,5 | J25: 80318.5 | K25: 51705.75 | L25: 132024.25 | M25: Sem PMA | W25: 64 | X25: 86 | Y25: 255 | Z25: 254 - DIAS AGUARDANDO DCMD | AA25: COEP | AB25: 169 - DIAS FORA DO PRAZO | AD25: LD03028074 - LD DIANOPOLIS A REGIAO GERAIS | AE25: DIANOPOLIS | AF25: DIANOPOLIS | AG25: SUL
A26: 7900525015 | B26: COOPER F6 | C26: 34,5 kV | D26: =LEFT(Table1[[#This Row],[Ativo]],2) -> 79 | F26: ETO-COEP 00125/2026 | G26: Média | H26: Avaliar compra | I26: RL Completo 34,5 | J26: 13209.34 | K26: 76246.2 | L26: 89455.54 | M26: Sem PMA | W26: 74 | X26: 86 | Y26: 126 | Z26: 40 - DIAS AGUARDANDO DCMD | AA26: COEP | AB26: 40 - DIAS FORA DO PRAZO | AD26: LD02065015 | AE26: PEDRO AFONSO | AF26: GUARAI | AG26: NORTE
A27: 7928564039 | B27: NOJA RC10 | C27: 34,5 kV | D27: =LEFT(Table1[[#This Row],[Ativo]],2) -> 79 | F27: ETO-COEP 00123/2026 | G27: Média | H27: Avaliar compra | I27: RL Completo 34,5 | J27: 13209.34 | K27: 76246.2 | L27: 89455.54 | M27: 38295+38297 | W27: 75 | X27: 86 | Y27: 445 | Z27: 40 - DIAS AGUARDANDO DCMD | AA27: COEP | AB27: 359 - DIAS FORA DO PRAZO | AD27: LD02109039 - LD ARAGUATINS A POV SOCO | AE27: ARAGUATINS | AF27: AUGUSTINOPOLIS | AG27: NORTE
A28: 7927713200 | B28: NOJA RC10 | C28: 34,5 kV | D28: =LEFT(Table1[[#This Row],[Ativo]],2) -> 79 | F28: ETO-COEP 00157/2026 | G28: Média | H28: Gerado PMA | I28: Tanque 34,5 | J28: 13209.34 | K28: 38151.48 | L28: 51360.82 | M28: Sem PMA | W28: 61 | X28: 86 | Y28: 21 | Z28: 20 - DIAS AGUARDANDO DCMD | AA28: COEP | AB28: VENCE EM: 65 DIAS | AD28: LD02010021 - LD PARANA A PALMEIROPOLIS | AE28: SAO SALVADOR DO TOCANTINS | AF28: PEIXE | AG28: SUL
A29: 7937102148 | B29: NOJA RC10 | C29: 34,5 kV | D29: =LEFT(Table1[[#This Row],[Ativo]],2) -> 79 | F29: ETO-COEP 00129/2026 | G29: Média | H29: Gerado PMA | I29: Tanque 34,5 | J29: 13209.34 | K29: 38151.48 | L29: 51360.82 | M29: Sem PMA | W29: 62 | X29: 86 | Y29: 242 | Z29: 40 - DIAS AGUARDANDO DCMD | AA29: COEP | AB29: 156 - DIAS FORA DO PRAZO | AD29: LD01066094 - LD UHE PEIXE A SAO VALERIO | AE29: SAO VALERIO DA NATIVIDADE | AF29: PEIXE | AG29: SUL
A30: 7925733015 | B30: NOJA RC10 | C30: 34,5 kV | D30: =LEFT(Table1[[#This Row],[Ativo]],2) -> 79 | F30: ETO-COEP 00058/2026 | G30: Média | H30: Gerado PMA | I30: Tanque 34,5 | J30: 13209.34 | K30: 38151.48 | L30: 51360.82 | M30: 38295 | W30: 67 | X30: 86 | Y30: 157 | Z30: 140 - DIAS AGUARDANDO DCMD | AA30: COEP | AB30: 71 - DIAS FORA DO PRAZO | AD30: LD02065015 | AE30: PEDRO AFONSO | AF30: GUARAI | AG30: NORTE
A31: 7927396052 | B31: NOJA RC10 | C31: 34,5 kV | D31: =LEFT(Table1[[#This Row],[Ativo]],2) -> 79 | F31: ETO-COEP 00045/2026 | G31: Média | H31: Avaliar compra | I31: Tanque 34,5 | J31: 13209.34 | K31: 38151.48 | L31: 51360.82 | M31: 38295 | W31: 68 | X31: 86 | Y31: 181 | Z31: 167 - DIAS AGUARDANDO DCMD | AA31: COEP | AB31: 95 - DIAS FORA DO PRAZO | AD31: LD03036052 - LD FORMOSO A COOPERFORMOSO | AE31: FORMOSO DO ARAGUAIA | AF31: ALVORADA | AG31: SUL
A32: 7933585074 | B32: NOJA RC10 | C32: 34,5 kV | D32: =LEFT(Table1[[#This Row],[Ativo]],2) -> 79 | F32: ETO-COEP 00024/2026 | G32: Média | H32: Avaliar compra | I32: Tanque 34,5 | J32: 13209.34 | K32: 38151.48 | L32: 51360.82 | M32: 38295 | W32: 69 | X32: 86 | Y32: 202 | Z32: 201 - DIAS AGUARDANDO DCMD | AA32: COEP | AB32: 116 - DIAS FORA DO PRAZO | AD32: LD03028074 - LD DIANOPOLIS A REGIAO GERAIS | AE32: DIANOPOLIS | AF32: DIANOPOLIS | AG32: SUL
A33: 5855411017 | B33: ROMAGNOLE | C33: 13,8 kV | D33: =LEFT(Table1[[#This Row],[Ativo]],2) -> 58 | E33: 250 kVA | F33: ETO-COEP 00156/2026 | G33: Baixa | H33: Em logistica (N1>N3) | I33: Controle 200 13,8 | J33: 20000 | K33: 23259.6 | L33: 43259.6 | M33: 38291 | N33: Ainda não | O33: 0212600671 | W33: 79 | X33: 134 | Y33: 348 | Z33: 23 - DIAS AGUARDANDO DCMD | AA33: COEP | AB33: 214 - DIAS FORA DO PRAZO | AD33: AL02017017 - AL 2 SE BARROLANDIA | AE33: BARROLANDIA | AF33: MIRACEMA DO TOCANTINS | AG33: CENTRO
A34: 7908196047 | B34: COOPER F6 | C34: 13,8 kV | D34: =LEFT(Table1[[#This Row],[Ativo]],2) -> 79 | F34: ETO-COEP 00168/2026 | G34: Baixa | H34: Avaliar compra | I34: RL Completo 13,8 | J34: 11016.94 | K34: 55602.54 | L34: 66619.48 | M34: 38294+38296 | W34: 81 | X34: 134 | Y34: 322 | Z34: 13 - DIAS AGUARDANDO DCMD | AA34: COEP | AB34: 188 - DIAS FORA DO PRAZO | AD34: AL02033047 - AL 2 SE FIGUEIROPOLIS | AE34: FIGUEIROPOLIS | AF34: ALVORADA | AG34: SUL
A35: 7921202014 | B35: NOJA RC10 | C35: 34,5 kV | D35: =LEFT(Table1[[#This Row],[Ativo]],2) -> 79 | F35: ETO-COEP 00132/2026 | G35: Baixa | H35: Avaliar compra | I35: Tanque 34,5 | J35: 13209.34 | K35: 38151.48 | L35: 51360.82 | M35: Sem PMA | W35: 82 | X35: 134 | Y35: 183 | Z35: 40 - DIAS AGUARDANDO DCMD | AA35: COEP | AB35: 49 - DIAS FORA DO PRAZO | AD35: LD01025012 - LD CRISTALANDIA A LAGOA DA CONFUSAO | AE35: PIUM | AF35: PARAISO DO TOCANTINS | AG35: CENTRO
A36: 7923927122 | B36: NOJA RC10 | C36: 34,5 kV | D36: =LEFT(Table1[[#This Row],[Ativo]],2) -> 79 | F36: ETO-COEP 00148/2026 | G36: Baixa | H36: Avaliar compra | I36: Tanque 34,5 | J36: 13209.34 | K36: 38151.48 | L36: 51360.82 | M36: Sem PMA | W36: 83 | X36: 134 | Y36: 477 | Z36: 32 - DIAS AGUARDANDO DCMD | AA36: COEP | AB36: 343 - DIAS FORA DO PRAZO | AD36: LD02059122 - LD PALMAS I I A TAQUARALTO | AE36: PALMAS | AF36: PALMAS | AG36: CENTRO
A37: 7927446001 | B37: TAVRIDA | C37: 34,5 kV | D37: =LEFT(Table1[[#This Row],[Ativo]],2) -> 79 | F37: ETO-COEP 00143/2025 | G37: Baixa | H37: Avaliar compra | I37: RL Completo 34,5 | J37: 13209.34 | K37: 76246.2 | L37: 89455.54 | M37: Sem PMA | W37: 84 | X37: 134 | Y37: 417 | Z37: 404 - DIAS AGUARDANDO DCMD | AA37: COEP | AB37: 283 - DIAS FORA DO PRAZO | AD37: LD02072001 - LD PORTO NACIONAL A SILVANOPOLIS | AE37: PORTO NACIONAL | AF37: PORTO NACIONAL | AG37: CENTRO
A38: 7928241200 | B38: NOJA RC10 | C38: 34,5 kV | D38: =LEFT(Table1[[#This Row],[Ativo]],2) -> 79 | F38: ETO-COEP 00128/2026 | G38: Baixa | H38: Avaliar compra | I38: Tanque 34,5 | J38: 13209.34 | K38: 38151.48 | L38: 51360.82 | M38: Sem PMA | W38: 85 | X38: 134 | Y38: 409 | Z38: 40 - DIAS AGUARDANDO DCMD | AA38: COEP | AB38: 275 - DIAS FORA DO PRAZO | AD38: LD02066094 - LD UHE PEIXE A SAO SALVADOR | AE38: SAO SALVADOR DO TOCANTINS | AF38: PEIXE | AG38: SUL
A39: 7942485096 | B39: NOJA RC10 | C39: 34,5 kV | D39: =LEFT(Table1[[#This Row],[Ativo]],2) -> 79 | F39: ETO-COEP 00158/2025 | G39: Baixa | H39: Avaliar compra | I39: Tanque 34,5 | J39: 13209.34 | K39: 38151.48 | L39: 51360.82 | M39: Sem PMA | W39: 86 | X39: 134 | Y39: 521 | Z39: 390 - DIAS AGUARDANDO DCMD | AA39: COEP | AB39: 387 - DIAS FORA DO PRAZO | AD39: LD03046026 - LD UHE ISAMU A PONTE ALTA | AE39: PINDORAMA DO TOCANTINS | AF39: PONTE ALTA TOCANTINS | AG39: CENTRO
A40: 7955946007 | B40: NOJA RC10 | C40: 34,5 kV | D40: =LEFT(Table1[[#This Row],[Ativo]],2) -> 79 | F40: ETO-COEP 00134/2026 | G40: Baixa | H40: Avaliar compra | I40: Controle 34,5 | J40: 13209.34 | K40: 38094.72 | L40: 51304.06 | M40: Sem PMA | W40: 89 | X40: 134 | Y40: 40 | Z40: 40 - DIAS AGUARDANDO DCMD | AA40: COEP | AB40: VENCE EM: 94 DIAS | AD40: LD05050008 - LD MIRANORTE A MIRACEMA | AE40: MIRACEMA DO TOCANTINS | AF40: MIRACEMA DO TOCANTINS | AG40: CENTRO
...

Sheet Base
A1: Status | C1: FAIXA DE TENSÃO | D1: TIPO | E1: Ano2 | F1: Mês | G1: Concat | H1: Qtd RL Fora | I1: Parque RL | J1: RL 13 | K1: RL 34 | L1: Qtd RT 13 | M1: RT13 | N1: RT 34 | O1: Acumulado | Q1: RL 34,5 | R1: RL 13,5
A2: Concluído | C2: 34.500 | D2: RL | E2: 2025 | F2: janeiro | G2: =_xlfn.CONCAT(Tabela17[[#This Row],[FAIXA DE TENSÃO]],Tabela17[[#This Row],[TIPO]],Tabela17[[#This Row],[Ano2]],Tabela17[[#This Row],[Mês]]) -> 34.500RL2025janeiro | H2: 1 | I2: 1281 | J2: 200 | K2: 1081 | L2: 180 | Q2: 1081 | R2: 200 | S2: =Q2/1291 -> 0.8373354 | T2: =1-S2 -> 0.1626646
A3: Em execução | C3: 34.500 | D3: RL | E3: 2025 | F3: fevereiro | G3: =_xlfn.CONCAT(Tabela17[[#This Row],[FAIXA DE TENSÃO]],Tabela17[[#This Row],[TIPO]],Tabela17[[#This Row],[Ano2]],Tabela17[[#This Row],[Mês]]) -> 34.500RL2025fevereiro | H3: 1 | I3: 1281 | J3: 200 | K3: 1081 | L3: 180 | Q3: RT 34,5 | R3: RT 13,8
A4: Em logistica (N1>N3) | C4: 34.500 | D4: RL | E4: 2025 | F4: março | G4: =_xlfn.CONCAT(Tabela17[[#This Row],[FAIXA DE TENSÃO]],Tabela17[[#This Row],[TIPO]],Tabela17[[#This Row],[Ano2]],Tabela17[[#This Row],[Mês]]) -> 34.500RL2025março | H4: 2 | I4: 1281 | J4: 200 | K4: 1081 | L4: 180 | Q4: 137 | R4: =291-137 -> 154
A5: Gerado PMA | C5: 34.500 | D5: RL | E5: 2025 | F5: abril | G5: =_xlfn.CONCAT(Tabela17[[#This Row],[FAIXA DE TENSÃO]],Tabela17[[#This Row],[TIPO]],Tabela17[[#This Row],[Ano2]],Tabela17[[#This Row],[Mês]]) -> 34.500RL2025abril | H5: 2 | I5: 1281 | J5: 200 | K5: 1081 | L5: 180
A6: Reforma | C6: 34.500 | D6: RL | E6: 2025 | F6: maio | G6: =_xlfn.CONCAT(Tabela17[[#This Row],[FAIXA DE TENSÃO]],Tabela17[[#This Row],[TIPO]],Tabela17[[#This Row],[Ano2]],Tabela17[[#This Row],[Mês]]) -> 34.500RL2025maio | H6: 7 | I6: 1281 | J6: 200 | K6: 1081 | L6: 180
A7: Avaliar compra | C7: 34.500 | D7: RL | E7: 2025 | F7: junho | G7: =_xlfn.CONCAT(Tabela17[[#This Row],[FAIXA DE TENSÃO]],Tabela17[[#This Row],[TIPO]],Tabela17[[#This Row],[Ano2]],Tabela17[[#This Row],[Mês]]) -> 34.500RL2025junho | H7: 4 | I7: 1281 | J7: 200 | K7: 1081 | L7: 180 | Q7: Categoria | R7: Tensão (kV) | S7: Valor Material | T7: Mão de obra | U7: Total | V7: Composição | W7: Códigos
C8: 34.500 | D8: RL | E8: 2025 | F8: julho | G8: =_xlfn.CONCAT(Tabela17[[#This Row],[FAIXA DE TENSÃO]],Tabela17[[#This Row],[TIPO]],Tabela17[[#This Row],[Ano2]],Tabela17[[#This Row],[Mês]]) -> 34.500RL2025julho | H8: 5 | I8: 1281 | J8: 200 | K8: 1081 | L8: 180 | Q8: RL Completo 13,8 | R8: 13,8 | S8: 55602.54 | T8: 11016.94 | U8: =SUM(S8:T8) -> 66619.48 | V8: Religador + Controle | W8: 690001 + 690916
C9: 34.500 | D9: RL | E9: 2025 | F9: agosto | G9: =_xlfn.CONCAT(Tabela17[[#This Row],[FAIXA DE TENSÃO]],Tabela17[[#This Row],[TIPO]],Tabela17[[#This Row],[Ano2]],Tabela17[[#This Row],[Mês]]) -> 34.500RL2025agosto | H9: 2 | I9: 1281 | J9: 200 | K9: 1081 | L9: 180 | Q9: RL Completo 34,5 | R9: 34,5 | S9: 76246.2 | T9: 13209.34 | U9: =SUM(S9:T9) -> 89455.54 | V9: Religador + Controle | W9: 690005 + 692263
C10: 34.500 | D10: RL | E10: 2025 | F10: setembro | G10: =_xlfn.CONCAT(Tabela17[[#This Row],[FAIXA DE TENSÃO]],Tabela17[[#This Row],[TIPO]],Tabela17[[#This Row],[Ano2]],Tabela17[[#This Row],[Mês]]) -> 34.500RL2025setembro | H10: 2 | I10: 1281 | J10: 200 | K10: 1081 | L10: 180 | Q10: Tanque 13,8 | R10: 13,8 | S10: 21785.72 | T10: 11016.94 | U10: =SUM(S10:T10) -> 32802.66 | V10: Só religador | W10: 690001
C11: 34.500 | D11: RL | E11: 2025 | F11: outubro | G11: =_xlfn.CONCAT(Tabela17[[#This Row],[FAIXA DE TENSÃO]],Tabela17[[#This Row],[TIPO]],Tabela17[[#This Row],[Ano2]],Tabela17[[#This Row],[Mês]]) -> 34.500RL2025outubro | H11: 4 | I11: 1281 | J11: 200 | K11: 1081 | L11: 180 | Q11: Tanque 34,5 | R11: 34,5 | S11: 38151.48 | T11: 13209.34 | U11: =SUM(S11:T11) -> 51360.82 | V11: Só religador | W11: 690005
C12: 34.500 | D12: RL | E12: 2025 | F12: novembro | G12: =_xlfn.CONCAT(Tabela17[[#This Row],[FAIXA DE TENSÃO]],Tabela17[[#This Row],[TIPO]],Tabela17[[#This Row],[Ano2]],Tabela17[[#This Row],[Mês]]) -> 34.500RL2025novembro | H12: 1 | I12: 1281 | J12: 200 | K12: 1081 | L12: 180 | Q12: Controle 13,8 | R12: 13,8 | S12: 33816.82 | T12: 11016.94 | U12: =SUM(S12:T12) -> 44833.76 | V12: Só controle | W12: 690916
C13: 34.500 | D13: RL | E13: 2025 | F13: dezembro | G13: =_xlfn.CONCAT(Tabela17[[#This Row],[FAIXA DE TENSÃO]],Tabela17[[#This Row],[TIPO]],Tabela17[[#This Row],[Ano2]],Tabela17[[#This Row],[Mês]]) -> 34.500RL2025dezembro | H13: 4 | I13: 1281 | J13: 200 | K13: 1081 | L13: 180 | Q13: Controle 34,5 | R13: 34,5 | S13: 38094.72 | T13: 13209.34 | U13: =SUM(S13:T13) -> 51304.06 | V13: Só controle | W13: 692263
C14: 34.500 | D14: RL | E14: 2026 | F14: janeiro | G14: =_xlfn.CONCAT(Tabela17[[#This Row],[FAIXA DE TENSÃO]],Tabela17[[#This Row],[TIPO]],Tabela17[[#This Row],[Ano2]],Tabela17[[#This Row],[Mês]]) -> 34.500RL2026janeiro | H14: 6 | I14: 1283 | J14: 200 | K14: 1081 | L14: 180
C15: 34.500 | D15: RL | E15: 2026 | F15: fevereiro | G15: =_xlfn.CONCAT(Tabela17[[#This Row],[FAIXA DE TENSÃO]],Tabela17[[#This Row],[TIPO]],Tabela17[[#This Row],[Ano2]],Tabela17[[#This Row],[Mês]]) -> 34.500RL2026fevereiro | H15: 7 | I15: 1283 | J15: 200 | K15: 1081 | L15: 180
C16: 34.500 | D16: RL | E16: 2026 | F16: março | G16: =_xlfn.CONCAT(Tabela17[[#This Row],[FAIXA DE TENSÃO]],Tabela17[[#This Row],[TIPO]],Tabela17[[#This Row],[Ano2]],Tabela17[[#This Row],[Mês]]) -> 34.500RL2026março | H16: 8 | I16: 1285 | J16: 200 | K16: 1081 | L16: 180
C17: 34.500 | D17: RL | E17: 2026 | F17: abril | G17: =_xlfn.CONCAT(Tabela17[[#This Row],[FAIXA DE TENSÃO]],Tabela17[[#This Row],[TIPO]],Tabela17[[#This Row],[Ano2]],Tabela17[[#This Row],[Mês]]) -> 34.500RL2026abril | H17: 3 | I17: 1287 | J17: 200 | K17: 1081 | L17: 180 | Q17: Categoria | R17: Tensão / kVA | S17: R$ por célula | T17: Mão de obra | U17: Total | V17: Composição | W17: Código
C18: 34.500 | D18: RL | E18: 2026 | F18: maio | G18: =_xlfn.CONCAT(Tabela17[[#This Row],[FAIXA DE TENSÃO]],Tabela17[[#This Row],[TIPO]],Tabela17[[#This Row],[Ano2]],Tabela17[[#This Row],[Mês]]) -> 34.500RL2026maio | H18: 0 | I18: 1290 | J18: 200 | K18: 1081 | L18: 180 | Q18: Célula 200 13,8 | R18: 13,8 / 239 kVA | S18: 62113.2 | T18: 51402.14 | U18: =SUM(S18:T18) -> 113515.34 | V18: Celula | W18: 690236
C19: 34.500 | D19: RL | E19: 2026 | F19: junho | G19: =_xlfn.CONCAT(Tabela17[[#This Row],[FAIXA DE TENSÃO]],Tabela17[[#This Row],[TIPO]],Tabela17[[#This Row],[Ano2]],Tabela17[[#This Row],[Mês]]) -> 34.500RL2026junho | H19: 1 | I19: 1291 | J19: 200 | K19: 1081 | L19: 180 | Q19: Célula 167 13,8 | R19: 13,8 / 167 kVA | S19: 27616.62 | T19: 51402.14 | U19: =SUM(S19:T19) -> 79018.76 | W19: 690669
C20: 34.500 | D20: RL | E20: 2026 | F20: julho | G20: =_xlfn.CONCAT(Tabela17[[#This Row],[FAIXA DE TENSÃO]],Tabela17[[#This Row],[TIPO]],Tabela17[[#This Row],[Ano2]],Tabela17[[#This Row],[Mês]]) -> 34.500RL2026julho | H20: 3 | I20: 1294 | J20: 200 | K20: 1081 | L20: 180 | Q20: Célula 200 13,8 | R20: 34,5 / 200 kVA | S20: 51705.75 | T20: 80318.5 | U20: =SUM(S20:T20) -> 132024.25 | W20: 690240
C21: 34.500 | D21: RL | E21: 2026 | F21: agosto | G21: =_xlfn.CONCAT(Tabela17[[#This Row],[FAIXA DE TENSÃO]],Tabela17[[#This Row],[TIPO]],Tabela17[[#This Row],[Ano2]],Tabela17[[#This Row],[Mês]]) -> 34.500RL2026agosto | H21: 0 | I21: 1294 | J21: 200 | K21: 1081 | L21: 180 | Q21: Célula 400 34,5 | R21: 34,5 / 400 kVA | S21: 90230 | T21: 80318.5 | U21: =SUM(S21:T21) -> 170548.5 | W21: 690241
C22: 34.500 | D22: RL | E22: 2026 | F22: setembro | G22: =_xlfn.CONCAT(Tabela17[[#This Row],[FAIXA DE TENSÃO]],Tabela17[[#This Row],[TIPO]],Tabela17[[#This Row],[Ano2]],Tabela17[[#This Row],[Mês]]) -> 34.500RL2026setembro | I22: 1294 | J22: 200 | K22: 1081 | L22: 180 | Q22: Controle 200 13,8 | R22: Relé de Sincronismo | S22: 23259.6 | T22: 20000 | U22: =SUM(S22:T22) -> 43259.6 | V22: Controle (relé sincronismo) | W22: 616033
C23: 34.500 | D23: RL | E23: 2026 | F23: outubro | G23: =_xlfn.CONCAT(Tabela17[[#This Row],[FAIXA DE TENSÃO]],Tabela17[[#This Row],[TIPO]],Tabela17[[#This Row],[Ano2]],Tabela17[[#This Row],[Mês]]) -> 34.500RL2026outubro | I23: 1294 | J23: 200 | K23: 1081 | L23: 180 | Q23: Célula 200 34,5 | R23: 13,8 / 200 kVA | S23: 51705.75 | T23: 80318.5 | U23: =SUM(S23:T23) -> 132024.25 | W23: 690240
C24: 34.500 | D24: RL | E24: 2026 | F24: novembro | G24: =_xlfn.CONCAT(Tabela17[[#This Row],[FAIXA DE TENSÃO]],Tabela17[[#This Row],[TIPO]],Tabela17[[#This Row],[Ano2]],Tabela17[[#This Row],[Mês]]) -> 34.500RL2026novembro | I24: 1294 | J24: 200 | K24: 1081 | L24: 180 | Q24: Controle 167 13,8 | R24: Relé de Sincronismo | S24: 23259.6 | T24: 20000 | U24: =SUM(S24:T24) -> 43259.6
C25: 34.500 | D25: RL | E25: 2026 | F25: dezembro | G25: =_xlfn.CONCAT(Tabela17[[#This Row],[FAIXA DE TENSÃO]],Tabela17[[#This Row],[TIPO]],Tabela17[[#This Row],[Ano2]],Tabela17[[#This Row],[Mês]]) -> 34.500RL2026dezembro | I25: 1294 | J25: 200 | K25: 1081 | L25: 180 | Q25: Controle 200 13,8 | R25: Relé de Sincronismo | S25: 23259.6 | T25: 20000 | U25: =SUM(S25:T25) -> 43259.6
C26: 34.500 | D26: RT | E26: 2025 | F26: janeiro | G26: =_xlfn.CONCAT(Tabela17[[#This Row],[FAIXA DE TENSÃO]],Tabela17[[#This Row],[TIPO]],Tabela17[[#This Row],[Ano2]],Tabela17[[#This Row],[Mês]]) -> 34.500RT2025janeiro | J26: 200 | K26: 1081 | L26: 180 | Q26: Controle 400 34,5 | R26: Relé de Sincronismo | S26: 23259.6 | T26: 20000 | U26: =SUM(S26:T26) -> 43259.6
C27: 34.500 | D27: RT | E27: 2025 | F27: fevereiro | G27: =_xlfn.CONCAT(Tabela17[[#This Row],[FAIXA DE TENSÃO]],Tabela17[[#This Row],[TIPO]],Tabela17[[#This Row],[Ano2]],Tabela17[[#This Row],[Mês]]) -> 34.500RT2025fevereiro | J27: 200 | K27: 1081 | L27: 180 | Q27: RT Completo 400 34,5 | R27: Controle+Célula 34,5 400KVA | S27: 293949.6 | T27: 200637 | U27: =SUM(S27:T27) -> 494586.6
C28: 34.500 | D28: RT | E28: 2025 | F28: março | G28: =_xlfn.CONCAT(Tabela17[[#This Row],[FAIXA DE TENSÃO]],Tabela17[[#This Row],[TIPO]],Tabela17[[#This Row],[Ano2]],Tabela17[[#This Row],[Mês]]) -> 34.500RT2025março | J28: 200 | K28: 1081 | L28: 180 | Q28: Acessório 400 34,5 | R28: Aterramento | S28: 15000 | U28: =SUM(S28:T28) -> 15000
C29: 34.500 | D29: RT | E29: 2025 | F29: abril | G29: =_xlfn.CONCAT(Tabela17[[#This Row],[FAIXA DE TENSÃO]],Tabela17[[#This Row],[TIPO]],Tabela17[[#This Row],[Ano2]],Tabela17[[#This Row],[Mês]]) -> 34.500RT2025abril | J29: 200 | K29: 1081 | L29: 180 | Q29: Aterramento 34,5 | R29: Aterramento | S29: 15000 | U29: =SUM(S29:T29) -> 15000
C30: 34.500 | D30: RT | E30: 2025 | F30: maio | G30: =_xlfn.CONCAT(Tabela17[[#This Row],[FAIXA DE TENSÃO]],Tabela17[[#This Row],[TIPO]],Tabela17[[#This Row],[Ano2]],Tabela17[[#This Row],[Mês]]) -> 34.500RT2025maio | J30: 200 | K30: 1081 | L30: 180 | Q30: Acessório 34,5 | R30: Aterramento | S30: 15000 | U30: =SUM(S30:T30) -> 15000
C31: 34.500 | D31: RT | E31: 2025 | F31: junho | G31: =_xlfn.CONCAT(Tabela17[[#This Row],[FAIXA DE TENSÃO]],Tabela17[[#This Row],[TIPO]],Tabela17[[#This Row],[Ano2]],Tabela17[[#This Row],[Mês]]) -> 34.500RT2025junho | J31: 200 | K31: 1081 | L31: 180 | Q31: Controle 200 34,5 | R31: Relé de Sincronismo | S31: 23259.6 | T31: 20000 | U31: =SUM(S31:T31) -> 43259.6
C32: 34.500 | D32: RT | E32: 2025 | F32: julho | G32: =_xlfn.CONCAT(Tabela17[[#This Row],[FAIXA DE TENSÃO]],Tabela17[[#This Row],[TIPO]],Tabela17[[#This Row],[Ano2]],Tabela17[[#This Row],[Mês]]) -> 34.500RT2025julho | J32: 200 | K32: 1081 | L32: 180
C33: 34.500 | D33: RT | E33: 2025 | F33: agosto | G33: =_xlfn.CONCAT(Tabela17[[#This Row],[FAIXA DE TENSÃO]],Tabela17[[#This Row],[TIPO]],Tabela17[[#This Row],[Ano2]],Tabela17[[#This Row],[Mês]]) -> 34.500RT2025agosto | J33: 200 | K33: 1081 | L33: 180
C34: 34.500 | D34: RT | E34: 2025 | F34: setembro | G34: =_xlfn.CONCAT(Tabela17[[#This Row],[FAIXA DE TENSÃO]],Tabela17[[#This Row],[TIPO]],Tabela17[[#This Row],[Ano2]],Tabela17[[#This Row],[Mês]]) -> 34.500RT2025setembro | J34: 200 | K34: 1081 | L34: 180
C35: 34.500 | D35: RT | E35: 2025 | F35: outubro | G35: =_xlfn.CONCAT(Tabela17[[#This Row],[FAIXA DE TENSÃO]],Tabela17[[#This Row],[TIPO]],Tabela17[[#This Row],[Ano2]],Tabela17[[#This Row],[Mês]]) -> 34.500RT2025outubro | J35: 200 | K35: 1081 | L35: 180
C36: 34.500 | D36: RT | E36: 2025 | F36: novembro | G36: =_xlfn.CONCAT(Tabela17[[#This Row],[FAIXA DE TENSÃO]],Tabela17[[#This Row],[TIPO]],Tabela17[[#This Row],[Ano2]],Tabela17[[#This Row],[Mês]]) -> 34.500RT2025novembro | J36: 200 | K36: 1081 | L36: 180
C37: 34.500 | D37: RT | E37: 2025 | F37: dezembro | G37: =_xlfn.CONCAT(Tabela17[[#This Row],[FAIXA DE TENSÃO]],Tabela17[[#This Row],[TIPO]],Tabela17[[#This Row],[Ano2]],Tabela17[[#This Row],[Mês]]) -> 34.500RT2025dezembro | J37: 200 | K37: 1081 | L37: 180
C38: 34.500 | D38: RT | E38: 2026 | F38: janeiro | G38: =_xlfn.CONCAT(Tabela17[[#This Row],[FAIXA DE TENSÃO]],Tabela17[[#This Row],[TIPO]],Tabela17[[#This Row],[Ano2]],Tabela17[[#This Row],[Mês]]) -> 34.500RT2026janeiro | J38: 200 | K38: 1081
C39: 34.500 | D39: RT | E39: 2026 | F39: fevereiro | G39: =_xlfn.CONCAT(Tabela17[[#This Row],[FAIXA DE TENSÃO]],Tabela17[[#This Row],[TIPO]],Tabela17[[#This Row],[Ano2]],Tabela17[[#This Row],[Mês]]) -> 34.500RT2026fevereiro | J39: 200 | K39: 1081
C40: 34.500 | D40: RT | E40: 2026 | F40: março | G40: =_xlfn.CONCAT(Tabela17[[#This Row],[FAIXA DE TENSÃO]],Tabela17[[#This Row],[TIPO]],Tabela17[[#This Row],[Ano2]],Tabela17[[#This Row],[Mês]]) -> 34.500RT2026março | J40: 200 | K40: 1081
...

Sheet Estoque
A1: Saldo
A5: Status PMA
A6: Status PMA | B6: Data Requisição | C6: Requisição Web Supply | D6: Status
A7: 38291
A35: PMA | B35: Código | C35: Descrição | D35: Unidade | E35: QT. | F35: Valor Unitário | G35: Valor Total | H35: Finalidade | I35: Data Requisição | J35: Requisição Web Supply | K35: Ativo | L35: Status | M35: Previsão de Chegada no N1
A36: 38291 | B36: 651638 | C36: CONTROLE DE REGULADOR DE TENSAO COM NOBREAK | D36: UN | E36: 3 | F36: 29227.78 | G36: 87683.34 | H36: Material para Manutenção | I36: 46232 | J36: 29734478 | L36: Ex: Em aprovação , Cotação,Aprovação Técnica
A37: 38291 | B37: 651638 | C37: CONTROLE DE REGULADOR DE TENSAO COM NOBREAK | D37: UN | E37: 3 | F37: 29227.78 | G37: 87683.34 | H37: Material para Manutenção | I37: 46232 | J37: 29734478
A38: 38291 | B38: 651638 | C38: CONTROLE DE REGULADOR DE TENSAO COM NOBREAK | D38: UN | E38: 3 | F38: 29227.78 | G38: 87683.34 | H38: Material para Manutenção | I38: 46232 | J38: 29734478
A39: 38292 | B39: 690241 | C39: REGUL TENS AUTOM SIMET RD 1F 19,919KV 400KVA 201A ESTR CL2 | D39: UN | E39: 4 | F39: 99636.75 | G39: 398547 | H39: Material para Manutenção | I39: 46232 | J39: 29734478
A40: 38292 | B40: 690241 | C40: REGUL TENS AUTOM SIMET RD 1F 19,919KV 400KVA 201A ESTR CL2 | D40: UN | E40: 4 | F40: 99636.75 | G40: 398547 | H40: Material para Manutenção | I40: 46232 | J40: 29734478
A41: 38292 | B41: 690241 | C41: REGUL TENS AUTOM SIMET RD 1F 19,919KV 400KVA 201A ESTR CL2 | D41: UN | E41: 4 | F41: 99636.75 | G41: 398547 | H41: Material para Manutenção | I41: 46232 | J41: 29734478
A42: 38292 | B42: 690241 | C42: REGUL TENS AUTOM SIMET RD 1F 19,919KV 400KVA 201A ESTR CL2 | D42: UN | E42: 4 | F42: 99636.75 | G42: 398547 | H42: Material para Manutenção | I42: 46232 | J42: 29734478
A43: 38294 | B43: 690001 | C43: RELIGADOR AUTO EXT 3F LIN VAC 15KV 630A 12,5KA 127VCA | D43: UN | E43: 8 | F43: 21785.72 | G43: 174285.76 | H43: Material para Manutenção | I43: 46232 | J43: 29734495
A44: 38294 | B44: 690001 | C44: RELIGADOR AUTO EXT 3F LIN VAC 15KV 630A 12,5KA 127VCA | D44: UN | E44: 8 | F44: 21785.72 | G44: 174285.76 | H44: Material para Manutenção | I44: 46232 | J44: 29734495
A45: 38294 | B45: 690001 | C45: RELIGADOR AUTO EXT 3F LIN VAC 15KV 630A 12,5KA 127VCA | D45: UN | E45: 8 | F45: 21785.72 | G45: 174285.76 | H45: Material para Manutenção | I45: 46232 | J45: 29734495
A46: 38294 | B46: 690001 | C46: RELIGADOR AUTO EXT 3F LIN VAC 15KV 630A 12,5KA 127VCA | D46: UN | E46: 8 | F46: 21785.72 | G46: 174285.76 | H46: Material para Manutenção | I46: 46232 | J46: 29734495
A47: 38294 | B47: 690001 | C47: RELIGADOR AUTO EXT 3F LIN VAC 15KV 630A 12,5KA 127VCA | D47: UN | E47: 8 | F47: 21785.72 | G47: 174285.76 | H47: Material para Manutenção | I47: 46232 | J47: 29734495
A48: 38294 | B48: 690001 | C48: RELIGADOR AUTO EXT 3F LIN VAC 15KV 630A 12,5KA 127VCA | D48: UN | E48: 8 | F48: 21785.72 | G48: 174285.76 | H48: Material para Manutenção | I48: 46232 | J48: 29734495
... A75: 38297 | B75: 692263 | C75: CONTROLE P/ RELIGADOR LINHA DISTR 36,2KV 115VCA | D75: UN | E75: 7 | F75: 37493.6 | G75: 262455.2 | H75: Material para Manutenção | I75: 46232 | J75: 29734495

Sheet Taxa de Falha
A1: Ano | B1: 2026
A2: Equipamento | B2: (Tudo)
A3: Tensão | B3: (Tudo)
A5: Rótulos de Coluna
A6: janeiro | B6: fevereiro | C6: março | D6: abril | E6: maio | F6: junho | G6: julho | H6: agosto | I6: Total Geral
B68: janeiro | C68: fevereiro | D68: março | E68: abril | F68: maio | G68: junho | H68: julho | I68: agosto | J68: setembro | K68: outubro | L68: novembro | M68: dezembro
A69: % falha - mensal
A70: % falha - acumulada
A71: Taxa de Falha Mensal - RL - 2025
B72: Jan | C72: Fev | D72: Mar | E72: Abr | F72: Mai | G72: Jun | H72: Jul | I72: Ago | J72: Set | K72: Out | L72: Nov | M72: Dez
A73: Novos ativos | B73: 0 | C73: 0 | D73: 0 | E73: 0 | F73: 0 | G73: 0 | H73: 0 | I73: 0 | J73: 0 | K73: 0 | L73: 0 | M73: 0
A74: Parque | B74: 1281 | C74: 1281 | D74: 1281 | E74: 1281 | F74: 1281 | G74: 1281 | H74: 1281 | I74: 1281 | J74: 1281 | K74: 1281 | L74: 1281 | M74: 1281
A75: Falha mês | B75: 1 | C75: 1 | D75: 2 | E75: 2 | F75: 7 | G75: 4 | H75: 5 | I75: 2 | J75: 2 | K75: 4 | L75: 1 | M75: 4
B76: =B75/B74 -> 0.00078064012 | C76: =C75/C74 -> 0.00078064012 | D76: =D75/D74 -> 0.0015612802 | E76: =E75/E74 -> 0.0015612802 | F76: =F75/F74 -> 0.0054644809 | G76: =G75/G74 -> 0.0031225605 | H76: =H75/H74 -> 0.0039032006 | I76: =I75/I74 -> 0.0015612802 | ... M76: =M75/M74 -> 0.0031225605
A77: Taxa de Falha Mensal - RT - 2025
B78: Jan | C78: Fev | D78: Mar | E78: Abr | F78: Mai | G78: Jun | H78: Jul | I78: Ago | J78: Set | K78: Out | L78: Nov | M78: Dez
A79: Novos ativos | B79: 0 | C79: 0 | D79: 0 | E79: 0 | F79: 0 | G79: 0 | H79: 0 | I79: 0 | J79: 0 | K79: 0 | L79: 0 | M79: 0
A80: Parque | B80: 180 | C80: 180 | D80: 180 | E80: 180 | F80: 180 | G80: 180 | H80: 180 | I80: 180 | J80: 180 | K80: 180 | L80: 180 | M80: 180
A81: Falha mês | B81: 0 | C81: 1 | D81: 2 | E81: 0 | F81: 0 | G81: 1 | H81: 3 | I81: 5 | J81: 3 | L81: 1 | M81: 2 | N81: =J81+J75 -> 5 | O81: =K81+K75 -> 4 | P81: =L81+L75 -> 2 | Q81: =M81+M75 -> 6
B82: =B81/B80 -> 0 | C82: =C81/C80 -> 0.0055555556 | D82: =D81/D80 -> 0.011111111 | E82: =E81/E80 -> 0 | F82: =F81/F80 -> 0 | G82: =G81/G80 -> 0.0055555556 | H82: =H81/H80 -> 0.016666667 | I82: =I81/I80 -> 0.027777778 | ... M82: =M81/M80 -> 0.011111111
A84: Taxa de Falha Mensal - RL - 2026
B85: Jan | C85: Fev | D85: Mar | E85: Abr | F85: Mai | G85: Jun | H85: Jul | I85: Ago | J85: Set | K85: Out | L85: Nov | M85: Dez
A86: Novos ativos | B86: {='[1]Expansão EE'!$E$51:$P$51} -> 2 | C86: 0 | D86: 2 | E86: 2 | F86: 3 | G86: 1 | H86: 3 | I86: 3 | J86: 0 | K86: 0 | L86: 0 | M86: 0
A87: Parque | B87: =$M$74+B86 -> 1283 | C87: =B87+C86 -> 1283 | D87: =C87+D86 -> 1285 | E87: =D87+E86 -> 1287 | F87: =E87+F86 -> 1290 | G87: =F87+G86 -> 1291 | H87: =G87+H86 -> 1294 | I87: =H87+I86 -> 1297 | J87: =I87+J86 -> 1297 | ... M87: =L87+M86 -> 1297
A88: Falha mês | B88: 6 | C88: 7 | D88: 8 | E88: 3 | F88: 0 | G88: 1 | H88: 3 | I88: 0
B89: =B88/B87 -> 0.0046765394 | C89: =C88/C87 -> 0.0054559626 | D89: =D88/D87 -> 0.0062256809 | E89: =E88/E87 -> 0.0023310023 | F89: =F88/F87 -> 0 | G89: =G88/G87 -> 0.00077459334 | H89: =H88/H87 -> 0.0023183926 | I89: =I88/I87 -> 0 | ... M89: =M88/M87 -> 0
B90: =B88/B87 -> 0.0046765394 | C90: =C88/C87 -> 0.0054559626 | D90: =D88/D87 -> 0.0062256809 | E90: =E88/E87 -> 0.0023310023 | F90: =F88/F87 -> 0 | G90: =G88/G87 -> 0.00077459334 | H90: =H88/H87 -> 0.0023183926 | I90: =I88/I87 -> 0 | O90: =J81+J75 -> 5 | P90: =K81+K75 -> 4 | Q90: =L81+L75 -> 2 | R90: =M81+M75 -> 6
A91: Taxa de Falha Mensal - RT - 2026
B92: Jan | C92: Fev | D92: Mar | E92: Abr | F92: Mai | G92: Jun | H92: Jul | I92: Ago | J92: Set | K92: Out | L92: Nov | M92: Dez
A93: Novos ativos | B93: {='[1]Expansão EE'!$E$51:$P$51} -> 2 | C93: 0 | D93: 2 | E93: 2 | F93: 3 | G93: 1 | H93: 3 | I93: 3 | J93: 0 | K93: 0 | L93: 0 | M93: 0
A94: Parque | B94: =$M$80+B93 -> 182 | C94: =B94+C93 -> 182 | D94: =C94+D93 -> 184 | E94: =D94+E93 -> 186 | F94: =E94+F93 -> 189 | G94: =F94+G93 -> 190 | H94: =G94+H93 -> 193 | I94: =H94+I93 -> 196 | J94: =I94+J93 -> 196 | ... M94: =L94+M93 -> 196
A95: Falha mês | B95: 1 | C95: 1 | D95: 1 | E95: 2 | F95: 1 | G95: 1 | H95: 1 | I95: 1
B96: =B95/B94 -> 0.0054945055 | C96: =C95/C94 -> 0.0054945055 | D96: =D95/D94 -> 0.0054347826 | E96: =E95/E94 -> 0.010752688 | F96: =F95/F94 -> 0.0052910053 | G96: =G95/G94 -> 0.0052631579 | H96: =H95/H94 -> 0.0051813472 | I96: =I95/I94 -> 0.0051020408 | ... M96: =M95/M94 -> 0
B97: =B95+B88 -> 7 | C97: =C95+C88 -> 8 | D97: =D95+D88 -> 9 | E97: =E95+E88 -> 5 | F97: =F95+F88 -> 1 | G97: =G95+G88 -> 2 | H97: =H95+H88 -> 4 | I97: =I95+I88 -> 1 | ... M97: =M95+M88 -> 0
A99: Taxa de Falha Acumulado- RL - 2025
B100: Jan | C100: Fev | D100: Mar | E100: Abr | F100: Mai | G100: Jun | H100: Jul | I100: Ago | J100: Set | K100: Out | L100: Nov | M100: Dez
A101: Novos ativos | B101: =B73 -> 0 | C101: =C73 -> 0 | D101: =D73 -> 0 | E101: =E73 -> 0 | F101: =F73 -> 0 | G101: =G73 -> 0 | H101: =H73 -> 0 | I101: =I73 -> 0 | ... M101: =M73 -> 0
A102: Parque | B102: =B74 -> 1281 | C102: =C74 -> 1281 | D102: =D74 -> 1281 | E102: =E74 -> 1281 | F102: =F74 -> 1281 | G102: =G74 -> 1281 | H102: =H74 -> 1281 | I102: =I74 -> 1281 | ... M102: =M74 -> 1281
A103: Falha mês | B103: =B75 -> 1 | C103: =C75+B103 -> 2 | D103: =D75+C103 -> 4 | E103: =E75+D103 -> 6 | F103: =F75+E103 -> 13 | G103: =G75+F103 -> 17 | H103: =H75+G103 -> 22 | I103: =I75+H103 -> 24 | J103: =J75+I103 -> 26 | ... M103: =M75+L103 -> 35
B104: =B103/B102 -> 0.00078064012 | C104: =C103/C102 -> 0.0015612802 | D104: =D103/D102 -> 0.0031225605 | E104: =E103/E102 -> 0.0046838407 | F104: =F103/F102 -> 0.010148322 | G104: =G103/G102 -> 0.013270882 | H104: =H103/H102 -> 0.017174083 | I104: =I103/I102 -> 0.018735363 | ... M104: =M103/M102 -> 0.027322404
...

Sheet SLA por equipe
A1: SLA DE MANUTENÇÃO — POR EQUIPE DE CAMPO
A2: Equipe é o posto do COCM que recebeu a demanda. A mediana diz o ritmo normal; o pior atraso diz a cauda.
A4: 2025
A5: Equipe | B5: Entregas | C5: No prazo | D5: Estourou | E5: Em curso | F5: Cumprimento | G5: Mediana de dias | H5: SLA (dias ÷ prazo) | I5: Pior atraso
A6: ETO-RD-PO | B6: 11 | C6: 7 | D6: 4 | E6: 0 | F6: 0.63636364 | G6: 7 | H6: 1.4513619 | I6: 148
A7: ETO-RD-AG | B7: 7 | C7: 6 | D7: 1 | E7: 0 | F7: 0.85714286 | G7: 0 | H7: 0.24725275 | I7: 3
A8: ETO-RD-GU | B8: 7 | C8: 5 | D8: 2 | E8: 0 | F8: 0.71428571 | G8: 4 | H8: 0.76923077 | I8: 53
A9: ETO-RD-PS | B9: 7 | C9: 4 | D9: 3 | E9: 0 | F9: 0.57142857 | G9: 0 | H9: 4.1318681 | I9: 232
A10: DOLP-RD-PA | B10: 6 | C10: 5 | D10: 1 | E10: 0 | F10: 0.83333333 | G10: 13 | H10: 0.50641026 | I10: 12
A11: ETO-RD-AR | B11: 6 | C11: 5 | D11: 1 | E11: 1 | F11: 0.83333333 | G11: 2 | H11: 3.275641 | I11: 468
A12: ETO-RD-GR | B12: 6 | C12: 4 | D12: 2 | E12: 0 | F12: 0.66666667 | G12: 23 | H12: 1.0833333 | I12: 59
A13: ETO-RD-PA | B13: 6 | C13: 3 | D13: 3 | E13: 0 | F13: 0.5 | G13: 35 | H13: 2.4423077 | I13: 236
A14: ETO-RD-DP | B14: 3 | C14: 1 | D14: 2 | E14: 0 | F14: 0.33333333 | G14: 74 | H14: 6.5166667 | I14: 308
A15: ENC-RD-PS | B15: 1 | C15: 1 | D15: 0 | E15: 0 | F15: 1 | G15: 1 | H15: 0.038461538 | I15: 0
A16: TOTAL | B16: 60 | C16: 41 | D16: 19 | E16: 1 | F16: 0.68333333 | G16: 6 | H16: 1.8783873 | I16: 468
A18: 2026
A19: Equipe | B19: Entregas | C19: No prazo | D19: Estourou | E19: Em curso | F19: Cumprimento | G19: Mediana de dias | H19: SLA (dias ÷ prazo) | I19: Pior atraso
A20: ETO-RD-AR | B20: 13 | C20: 11 | D20: 2 | E20: 0 | F20: 0.84615385 | G20: 1 | H20: 0.43122677 | I20: 36
A21: ETO-RD-PS | B21: 13 | C21: 10 | D21: 3 | E21: 0 | F21: 0.76923077 | G21: 1 | H21: 1.0132013 | I21: 87
A22: ETO-RD-PO | B22: 12 | C22: 7 | D22: 5 | E22: 1 | F22: 0.58333333 | G22: 10 | H22: 1.1840796 | I22: 59
A23: ETO-RD-PA | B23: 11 | C23: 7 | D23: 4 | E23: 1 | F23: 0.63636364 | G23: 1 | H23: 1.75 | I23: 100
A24: ETO-RD-DP | B24: 8 | C24: 2 | D24: 6 | E24: 2 | F24: 0.25 | G24: 67 | H24: 2.2473684 | I24: 84
A25: ETO-RD-GR | B25: 6 | C25: 3 | D25: 3 | E25: 0 | F25: 0.5 | G25: 38 | H25: 1.9565217 | I25: 32
A26: ETO-RD-AG | B26: 5 | C26: 5 | D26: 0 | E26: 0 | F26: 1 | G26: 8 | H26: 0.25892857 | I26: 0
A27: ETO-RD-GU | B27: 2 | C27: 1 | D27: 1 | E27: 0 | F27: 0.5 | G27: 87 | H27: 3.7826087 | I27: 72
A28: DG-RD-PO | B28: 1 | C28: 1 | D28: 0 | E28: 0 | F28: 1 | G28: 14 | H28: 0.53846154 | I28: 0
A29: TOTAL | B29: 71 | C29: 47 | D29: 24 | E29: 4 | F29: 0.66197183 | G29: 4 | H29: 1.2300071 | I29: 100
A31: 2025 + 2026
A32: Equipe | B32: Entregas | C32: No prazo | D32: Estourou | E32: Em curso | F32: Cumprimento | G32: Mediana de dias | H32: SLA (dias ÷ prazo) | I32: Pior atraso
A33: ETO-RD-PO | B33: 23 | C33: 14 | D33: 9 | E33: 1 | F33: 0.60869565 | G33: 9 | H33: 1.3340611 | I33: 148
A34: ETO-RD-PS | B34: 20 | C34: 14 | D34: 6 | E34: 0 | F34: 0.7 | G34: 1 | H34: 2.1835052 | I34: 232
A35: ETO-RD-AR | B35: 19 | C35: 16 | D35: 3 | E35: 1 | F35: 0.84210526 | G35: 1 | H35: 1.4752941 | I35: 468
A36: ETO-RD-PA | B36: 17 | C36: 10 | D36: 7 | E36: 1 | F36: 0.58823529 | G36: 1 | H36: 2.037234 | I36: 236
A37: ETO-RD-AG | B37: 12 | C37: 11 | D37: 1 | E37: 0 | F37: 0.91666667 | G37: 1 | H37: 0.25170068 | I37: 3
A38: ETO-RD-GR | B38: 12 | C38: 7 | D38: 5 | E38: 0 | F38: 0.58333333 | G38: 23 | H38: 1.3511111 | I38: 59
A39: ETO-RD-DP | B39: 11 | C39: 3 | D39: 8 | E39: 2 | F39: 0.27272727 | G39: 67 | H39: 3.272 | I39: 308
A40: ETO-RD-GU | B40: 9 | C40: 6 | D40: 3 | E40: 0 | F40: 0.66666667 | G40: 4 | H40: 1.1073171 | I40: 72
A41: DOLP-RD-PA | B41: 6 | C41: 5 | D41: 1 | E41: 0 | F41: 0.83333333 | G41: 13 | H41: 0.50641026 | I41: 12
A42: DG-RD-PO | B42: 1 | C42: 1 | D42: 0 | E42: 0 | F42: 1 | G42: 14 | H42: 0.53846154 | I42: 0
A43: ENC-RD-PS | B43: 1 | C43: 1 | D43: 0 | E43: 0 | F43: 1 | G43: 1 | H43: 0.038461538 | I43: 0
...

Sheet Falha Equipamentos
A1: Ano/TIPO | B1: Equipamento | C1: Mensal | D1: Parque | E1: Ativo | F1: SS | G1: Tensão | H1: Data | I1: Mês | J1: Ano | K1: Concat | L1: Peça (modo) | M1: Troca feita | N1: Causa raiz | O1: Citação do texto da SS | P1: Nota do analista | Q1: Revisão | R1: Coluna1
A2: RL 2025 | B2: =LEFT(Tabela3[[#This Row],[Ano/TIPO]],2) -> RL | D2: =_xlfn.XLOOKUP(K2,Base!G:G,Base!I:I) -> #N/A | E2: 7900230155 | F2: ETO-COEP 00056/2025 | G2: =_xlfn.XLOOKUP(_xlfn.NUMBERVALUE(Tabela3[[#This Row],[Ativo]]),'[2]Ajustes Reguladores de Tensão'!$A:$A,'[2]Ajustes Reguladores de Tensão'!$I:$I,_xlfn.XLOOKUP(_xlfn.NUMBERVALUE(Tabela3[[#This Row],[Ativo]]),'[2]Ajustes RL Poste'!$A:$A,'[2]Ajustes RL Poste'!$M:$M)) -> 34.500 | H2: 29/03/2025 | I2: =TEXT(Tabela3[[#This Row],[Data]],"mmmm") -> março | J2: =YEAR(Tabela3[[#This Row],[Data]]) -> 2025 | K2: =_xlfn.CONCAT(Tabela3[[#This Row],[Ano]],Tabela3[[#This Row],[Mês]]) -> 2025março | L2: completo | M2: sim | N2: CURTO-CIRCUITO INTERNO | O2: «Não responde a comandos abertura e fechamento local ou remoto, pois está com sinal de curto circuito» | P2: Tanque danificado com sinal de curto-circuito bloqueando comandos; o para-raios do trafo queimado junto sugere surto, mas o laudo não afirma descarga.
A3: RL 2025 | B3: =LEFT(Tabela3[[#This Row],[Ano/TIPO]],2) -> RL | D3: =_xlfn.XLOOKUP(K3,Base!G:G,Base!I:I) -> #N/A | E3: 7900573047 | F3: ETO-COEP 00080/2026 | G3: =_xlfn.XLOOKUP(_xlfn.NUMBERVALUE(Tabela3[[#This Row],[Ativo]]),'[2]Ajustes Reguladores de Tensão'!$A:$A,'[2]Ajustes Reguladores de Tensão'!$I:$I,_xlfn.XLOOKUP(_xlfn.NUMBERVALUE(Tabela3[[#This Row],[Ativo]]),'[2]Ajustes RL Poste'!$A:$A,'[2]Ajustes RL Poste'!$M:$M)) -> 13.800 | H3: 09/10/2025 | I3: =TEXT(Tabela3[[#This Row],[Data]],"mmmm") -> outubro | J3: =YEAR(Tabela3[[#This Row],[Data]]) -> 2025 | K3: =_xlfn.CONCAT(Tabela3[[#This Row],[Ano]],Tabela3[[#This Row],[Mês]]) -> 2025outubro | L3: completo | M3: não | N3: CURTO-CIRCUITO INTERNO | O3: «o mesmo estar em curto conforme fotos anexadas» | P3: Relato de campo com fotos dá o equipamento em curto e o DMSL constata parte ativa, placa, tanque e relé queimados — curto como mecanismo; origem não descrita. | Y3: Rótulos de Linha | Z3: Contagem de Data
A4: RL 2025 | B4: =LEFT(Tabela3[[#This Row],[Ano/TIPO]],2) -> RL | D4: =_xlfn.XLOOKUP(K4,Base!G:G,Base!I:I) -> #N/A | E4: 7908196047 | F4: ETO-COEP 00215/2025 | G4: =_xlfn.XLOOKUP(_xlfn.NUMBERVALUE(Tabela3[[#This Row],[Ativo]]),'[2]Ajustes Reguladores de Tensão'!$A:$A,'[2]Ajustes Reguladores de Tensão'!$I:$I,_xlfn.XLOOKUP(_xlfn.NUMBERVALUE(Tabela3[[#This Row],[Ativo]]),'[2]Ajustes RL Poste'!$A:$A,'[2]Ajustes RL Poste'!$M:$M)) -> 13.800 | H4: 29/09/2025 | I4: =TEXT(Tabela3[[#This Row],[Data]],"mmmm") -> setembro | J4: =YEAR(Tabela3[[#This Row],[Data]]) -> 2025 | K4: =_xlfn.CONCAT(Tabela3[[#This Row],[Ano]],Tabela3[[#This Row],[Mês]]) -> 2025setembro | L4: completo | M4: não | N4: CURTO-CIRCUITO INTERNO | O4: «Constatado curto-circuito no tanque do religador, impedindo as operações de abertura e fechamento do equipamento» | P4: Diagnóstico DMSL explícito de curto-circuito no tanque travando abertura/fechamento; a origem do curto não é detalhada. | Y4: RL 2025 | Z4: 35
A5: RL 2025 | B5: =LEFT(Tabela3[[#This Row],[Ano/TIPO]],2) -> RL | D5: =_xlfn.XLOOKUP(K5,Base!G:G,Base!I:I) -> #N/A | E5: 7923927122 | F5: ETO-COEP 00079/2025 | G5: =_xlfn.XLOOKUP(_xlfn.NUMBERVALUE(Tabela3[[#This Row],[Ativo]]),'[2]Ajustes Reguladores de Tensão'!$A:$A,'[2]Ajustes Reguladores de Tensão'!$I:$I,_xlfn.XLOOKUP(_xlfn.NUMBERVALUE(Tabela3[[#This Row],[Ativo]]),'[2]Ajustes RL Poste'!$A:$A,'[2]Ajustes RL Poste'!$M:$M)) -> 34.500 | H5: 27/04/2025 | I5: =TEXT(Tabela3[[#This Row],[Data]],"mmmm") -> abril | J5: =YEAR(Tabela3[[#This Row],[Data]]) -> 2025 | K5: =_xlfn.CONCAT(Tabela3[[#This Row],[Ano]],Tabela3[[#This Row],[Mês]]) -> 2025abril | L5: tanque | M5: não | N5: CURTO-CIRCUITO INTERNO | O5: «substituir tanque do RL-7923927122 em curto, Anomalia identificada desarme das LD» | P5: Tanque em curto derrubando as LDs Palmas/Aparecida e Taquaruçu — curto interno como mecanismo; origem não descrita. | Y5: RL 2026 | Z5: 28
A6: RL 2025 | B6: =LEFT(Tabela3[[#This Row],[Ano/TIPO]],2) -> RL | D6: =_xlfn.XLOOKUP(K6,Base!G:G,Base!I:I) -> #N/A | E6: 7928241200 | F6: ETO-COEP 00139/2025 | G6: =_xlfn.XLOOKUP(_xlfn.NUMBERVALUE(Tabela3[[#This Row],[Ativo]]),'[2]Ajustes Reguladores de Tensão'!$A:$A,'[2]Ajustes Reguladores de Tensão'!$I:$I,_xlfn.XLOOKUP(_xlfn.NUMBERVALUE(Tabela3[[#This Row],[Ativo]]),'[2]Ajustes RL Poste'!$A:$A,'[2]Ajustes RL Poste'!$M:$M)) -> 34.500 | H6: 04/07/2025 | I6: =TEXT(Tabela3[[#This Row],[Data]],"mmmm") -> julho | J6: =YEAR(Tabela3[[#This Row],[Data]]) -> 2025 | K6: =_xlfn.CONCAT(Tabela3[[#This Row],[Ano]],Tabela3[[#This Row],[Mês]]) -> 2025julho | L6: tanque | M6: não | N6: CURTO-CIRCUITO INTERNO | O6: «fizemos ensaios elétricos e foi constatado que o tanque está em curto» | P6: Ensaios elétricos constataram o tanque em curto depois de o equipamento tirar a linha — curto interno como mecanismo; origem não descrita. | Y6: RT 2025 | Z6: 18
A7: RL 2025 | B7: =LEFT(Tabela3[[#This Row],[Ano/TIPO]],2) -> RL | D7: =_xlfn.XLOOKUP(K7,Base!G:G,Base!I:I) -> #N/A | E7: 7931610122 | F7: ETO-COEP 00083/2026 | G7: =_xlfn.XLOOKUP(_xlfn.NUMBERVALUE(Tabela3[[#This Row],[Ativo]]),'[2]Ajustes Reguladores de Tensão'!$A:$A,'[2]Ajustes Reguladores de Tensão'!$I:$I,_xlfn.XLOOKUP(_xlfn.NUMBERVALUE(Tabela3[[#This Row],[Ativo]]),'[2]Ajustes RL Poste'!$A:$A,'[2]Ajustes RL Poste'!$M:$M)) -> 13.800 | H7: 10/10/2025 | I7: =TEXT(Tabela3[[#This Row],[Data]],"mmmm") -> outubro | J7: =YEAR(Tabela3[[#This Row],[Data]]) -> 2025 | K7: =_xlfn.CONCAT(Tabela3[[#This Row],[Ano]],Tabela3[[#This Row],[Mês]]) -> 2025outubro | L7: tanque | M7: sim | N7: CURTO-CIRCUITO INTERNO | O7: «Houve um curto no equipamento danificando a parte ativa, e antena!» | P7: Curto no equipamento danificou parte ativa e antena; o texto não localiza a origem (dano simultâneo na antena até sugere surto externo, não afirmado). | Y7: RT 2026 | Z7: 9
A8: RL 2025 | B8: =LEFT(Tabela3[[#This Row],[Ano/TIPO]],2) -> RL | D8: =_xlfn.XLOOKUP(K8,Base!G:G,Base!I:I) -> #N/A | E8: 7933766059 | F8: ETO-COEP 00082/2026 | G8: =_xlfn.XLOOKUP(_xlfn.NUMBERVALUE(Tabela3[[#This Row],[Ativo]]),'[2]Ajustes Reguladores de Tensão'!$A:$A,'[2]Ajustes Reguladores de Tensão'!$I:$I,_xlfn.XLOOKUP(_xlfn.NUMBERVALUE(Tabela3[[#This Row],[Ativo]]),'[2]Ajustes RL Poste'!$A:$A,'[2]Ajustes RL Poste'!$M:$M)) -> 13.800 | H8: 08/10/2025 | I8: =TEXT(Tabela3[[#This Row],[Data]],"mmmm") -> outubro | J8: =YEAR(Tabela3[[#This Row],[Data]]) -> 2025 | K8: =_xlfn.CONCAT(Tabela3[[#This Row],[Ano]],Tabela3[[#This Row],[Mês]]) -> 2025outubro | L8: tanque | M8: sim | N8: CURTO-CIRCUITO INTERNO | O8: «Houve um curto na parte ativa do equipamento danificando a mesma, será necessário fazer a substituição somente do tanque, parte ativa.» | P8: O DMSL afirma curto na própria parte ativa danificando-a — mecanismo explícito; a origem do curto não é detalhada. | Q8: Causa mantida (CURTO-CIRCUITO INTERNO); confiança rebaixada de alta para media: 'Houve um curto na parte ativa do equipamento danificando a mesma' é narrativa de evento sem dizer como se constatou — mesmo fraseado e mesmo formato de laudo DMSL do 7931610122, classificado media. Alta fica reservada a curto constatado por ensaio (7928241200, 7908196047). | Y8: Total Geral | Z8: 90
