Workbook

Sheet Dinâmica
A1: DINÂMICA — ORÇAMENTO EQUIPAMENTOS ESPECIAIS
A2: Custo para consertar, por projeto (religador / regulador / banco de capacitor) e total geral.
A4: ORÇAMENTO POR PROJETO (custo para consertar) | H4: 8495 -Religador | I4: 8481- regulador | J4: Total
A5: Projeto | B5: Material (R$) | C5: Mão de Obra (R$) | D5: Custo Total (R$) | E5: Nº SS | G5: Orçado | H5: 4497155.3 | I5: 1565168.5 | J5: =SUM(H5:I5) -> 6062323.8
A6: Religadores | B6: =SUM(C14:C16) -> 2104478 | C6: =SUM(D14:D16) -> 645175.14 | D6: =SUM(E14:E16) -> 2749653.2 | E6: 51 | G6: Realizado | H6: 262922.35 | I6: 498815.47 | J6: =SUM(H6:I6) -> 761737.82
A7: Reguladores | B7: =Reguladores!O17 -> 1280548.6 | C7: =Reguladores!P17 -> 526882.56 | D7: =SUM(B7:C7) -> 1807431.1 | E7: =COUNTA(Reguladores!$A$5:$A$16) -> 12 | G7: N1 | H7: =E11 -> 0
A8: Banco de capacitor | E8: (a definir) | G8: N3 | H8: =E12 -> 0
A9: TOTAL GERAL | B9: =SUM(B6:B8) -> 3385026.6 | C9: =SUM(C6:C8) -> 1172057.7 | D9: =SUM(D6:D8) -> 4557084.3 | E9: =SUM(E6:E8) -> 63
A11: ═══ RELIGADORES ═══
A12: Religadores — por status de tratativa
B13: Nº SS | C13: Material (R$) | D13: Mão de Obra (R$) | E13: Custo Total (R$)
A14: Em tratativa - N1 (pendente) | B14: =COUNTIFS('Detalhe Religadores'!$O$5:$O$64,$A14) -> 13 | C14: =SUMIFS('Detalhe Religadores'!$M$5:$M$64,'Detalhe Religadores'!$O$5:$O$64,$A14) -> 551818.42 | D14: =SUMIFS('Detalhe Religadores'!$N$5:$N$64,'Detalhe Religadores'!$O$5:$O$64,$A14) -> 156374.62 | E14: =SUMIFS('Detalhe Religadores'!$T$5:$T$64,'Detalhe Religadores'!$O$5:$O$64,$A14) -> 708193.04
A15: Em tratativa - N3 (concluído) | B15: =COUNTIFS('Detalhe Religadores'!$O$5:$O$64,$A15) -> 6 | C15: =SUMIFS('Detalhe Religadores'!$M$5:$M$64,'Detalhe Religadores'!$O$5:$O$64,$A15) -> 258277.52 | D15: =SUMIFS('Detalhe Religadores'!$N$5:$N$64,'Detalhe Religadores'!$O$5:$O$64,$A15) -> 74871.24 | E15: =SUMIFS('Detalhe Religadores'!$T$5:$T$64,'Detalhe Religadores'!$O$5:$O$64,$A15) -> 333148.76
A16: Para avançar | B16: =COUNTIFS('Detalhe Religadores'!$O$5:$O$64,$A16) -> 32 | C16: =SUMIFS('Detalhe Religadores'!$M$5:$M$64,'Detalhe Religadores'!$O$5:$O$64,$A16) -> 1294382.1 | D16: =SUMIFS('Detalhe Religadores'!$N$5:$N$64,'Detalhe Religadores'!$O$5:$O$64,$A16) -> 413929.28 | E16: =SUMIFS('Detalhe Religadores'!$T$5:$T$64,'Detalhe Religadores'!$O$5:$O$64,$A16) -> 1708311.4
A17: Reavaliar | B17: =COUNTIFS('Detalhe Religadores'!$O$5:$O$64,$A17) -> 9 | C17: =SUMIFS('Detalhe Religadores'!$M$5:$M$64,'Detalhe Religadores'!$O$5:$O$64,$A17) -> 551287.98 | D17: =SUMIFS('Detalhe Religadores'!$N$5:$N$64,'Detalhe Religadores'!$O$5:$O$64,$A17) -> 116691.66 | E17: =SUMIFS('Detalhe Religadores'!$T$5:$T$64,'Detalhe Religadores'!$O$5:$O$64,$A17) -> 667979.64
A18: TOTAL | B18: =SUM(B14:B16) -> 51 | C18: =SUM(C14:C16) -> 2104478 | D18: =SUM(D14:D16) -> 645175.14 | E18: =SUM(E14:E16) -> 2749653.2
A20: Religadores — por categoria
B21: Nº SS | C21: Material (R$) | D21: Mão de Obra (R$) | E21: Custo Total (R$)
A22: Equipamento completo | B22: =COUNTIFS('Detalhe Religadores'!$H$5:$H$64,$A22) -> 20 | C22: =SUMIFS('Detalhe Religadores'!$M$5:$M$64,'Detalhe Religadores'!$H$5:$H$64,$A22) -> 1401062 | D22: =SUMIFS('Detalhe Religadores'!$N$5:$N$64,'Detalhe Religadores'!$H$5:$H$64,$A22) -> 251032.4 | E22: =SUMIFS('Detalhe Religadores'!$T$5:$T$64,'Detalhe Religadores'!$H$5:$H$64,$A22) -> 1652094.4
A23: Parte ativa (Tanque) | B23: =COUNTIFS('Detalhe Religadores'!$H$5:$H$64,$A23) -> 30 | C23: =SUMIFS('Detalhe Religadores'!$M$5:$M$64,'Detalhe Religadores'!$H$5:$H$64,$A23) -> 1079081.4 | D23: =SUMIFS('Detalhe Religadores'!$N$5:$N$64,'Detalhe Religadores'!$H$5:$H$64,$A23) -> 387510.6 | E23: =SUMIFS('Detalhe Religadores'!$T$5:$T$64,'Detalhe Religadores'!$H$5:$H$64,$A23) -> 1466592
A24: Controle completo | B24: =COUNTIFS('Detalhe Religadores'!$H$5:$H$64,$A24) -> 4 | C24: =SUMIFS('Detalhe Religadores'!$M$5:$M$64,'Detalhe Religadores'!$H$5:$H$64,$A24) -> 143823.08 | D24: =SUMIFS('Detalhe Religadores'!$N$5:$N$64,'Detalhe Religadores'!$H$5:$H$64,$A24) -> 48452.56 | E24: =SUMIFS('Detalhe Religadores'!$T$5:$T$64,'Detalhe Religadores'!$H$5:$H$64,$A24) -> 192275.64
A25: Placa de alimentação CA | B25: =COUNTIFS('Detalhe Religadores'!$H$5:$H$64,$A25) -> 3 | C25: =SUMIFS('Detalhe Religadores'!$M$5:$M$64,'Detalhe Religadores'!$H$5:$H$64,$A25) -> 5997 | D25: =SUMIFS('Detalhe Religadores'!$N$5:$N$64,'Detalhe Religadores'!$H$5:$H$64,$A25) -> 39628.02 | E25: =SUMIFS('Detalhe Religadores'!$T$5:$T$64,'Detalhe Religadores'!$H$5:$H$64,$A25) -> 45625.02
A26: Relé | B26: =COUNTIFS('Detalhe Religadores'!$H$5:$H$64,$A26) -> 1 | C26: =SUMIFS('Detalhe Religadores'!$M$5:$M$64,'Detalhe Religadores'!$H$5:$H$64,$A26) -> 10454.01 | D26: =SUMIFS('Detalhe Religadores'!$N$5:$N$64,'Detalhe Religadores'!$H$5:$H$64,$A26) -> 11016.94 | E26: =SUMIFS('Detalhe Religadores'!$T$5:$T$64,'Detalhe Religadores'!$H$5:$H$64,$A26) -> 21470.95
A27: Componentes/Acessórios | B27: =COUNTIFS('Detalhe Religadores'!$H$5:$H$64,$A27) -> 2 | C27: =SUMIFS('Detalhe Religadores'!$M$5:$M$64,'Detalhe Religadores'!$H$5:$H$64,$A27) -> 15348.51 | D27: =SUMIFS('Detalhe Religadores'!$N$5:$N$64,'Detalhe Religadores'!$H$5:$H$64,$A27) -> 24226.28 | E27: =SUMIFS('Detalhe Religadores'!$T$5:$T$64,'Detalhe Religadores'!$H$5:$H$64,$A27) -> 39574.79
A28: TOTAL | B28: =SUM(B22:B27) -> 60 | C28: =SUM(C22:C27) -> 2655766 | D28: =SUM(D22:D27) -> 761866.8 | E28: =SUM(E22:E27) -> 3417632.8
A30: Religadores — por criticidade
B31: Nº SS | C31: Material (R$) | D31: Mão de Obra (R$) | E31: Custo Total (R$)
A32: Muito Alta | B32: =COUNTIFS('Detalhe Religadores'!$E$5:$E$64,$A32) -> 8 | C32: =SUMIFS('Detalhe Religadores'!$M$5:$M$64,'Detalhe Religadores'!$E$5:$E$64,$A32) -> 341142.5 | D32: =SUMIFS('Detalhe Religadores'!$N$5:$N$64,'Detalhe Religadores'!$E$5:$E$64,$A32) -> 94712.72 | E32: =SUMIFS('Detalhe Religadores'!$T$5:$T$64,'Detalhe Religadores'!$E$5:$E$64,$A32) -> 435855.22
A33: Alta | B33: =COUNTIFS('Detalhe Religadores'!$E$5:$E$64,$A33) -> 11 | C33: =SUMIFS('Detalhe Religadores'!$M$5:$M$64,'Detalhe Religadores'!$E$5:$E$64,$A33) -> 530701.08 | D33: =SUMIFS('Detalhe Religadores'!$N$5:$N$64,'Detalhe Religadores'!$E$5:$E$64,$A33) -> 138725.54 | E33: =SUMIFS('Detalhe Religadores'!$T$5:$T$64,'Detalhe Religadores'!$E$5:$E$64,$A33) -> 669426.62
A34: Média | B34: =COUNTIFS('Detalhe Religadores'!$E$5:$E$64,$A34) -> 6 | C34: =SUMIFS('Detalhe Religadores'!$M$5:$M$64,'Detalhe Religadores'!$E$5:$E$64,$A34) -> 343136.28 | D34: =SUMIFS('Detalhe Religadores'!$N$5:$N$64,'Detalhe Religadores'!$E$5:$E$64,$A34) -> 79256.04 | E34: =SUMIFS('Detalhe Religadores'!$T$5:$T$64,'Detalhe Religadores'!$E$5:$E$64,$A34) -> 422392.32
A35: Baixa | B35: =COUNTIFS('Detalhe Religadores'!$E$5:$E$64,$A35) -> 8 | C35: =SUMIFS('Detalhe Religadores'!$M$5:$M$64,'Detalhe Religadores'!$E$5:$E$64,$A35) -> 375312.94 | D35: =SUMIFS('Detalhe Religadores'!$N$5:$N$64,'Detalhe Religadores'!$E$5:$E$64,$A35) -> 101289.92 | E35: =SUMIFS('Detalhe Religadores'!$T$5:$T$64,'Detalhe Religadores'!$E$5:$E$64,$A35) -> 476602.86
A36: Falta definir | B36: =COUNTIFS('Detalhe Religadores'!$E$5:$E$64,$A36) -> 27 | C36: =SUMIFS('Detalhe Religadores'!$M$5:$M$64,'Detalhe Religadores'!$E$5:$E$64,$A36) -> 1065473.2 | D36: =SUMIFS('Detalhe Religadores'!$N$5:$N$64,'Detalhe Religadores'!$E$5:$E$64,$A36) -> 347882.58 | E36: =SUMIFS('Detalhe Religadores'!$T$5:$T$64,'Detalhe Religadores'!$E$5:$E$64,$A36) -> 1413355.8
A37: TOTAL | B37: =SUM(B32:B36) -> 60 | C37: =SUM(C32:C36) -> 2655766 | D37: =SUM(D32:D36) -> 761866.8 | E37: =SUM(E32:E36) -> 3417632.8
A39: ═══ REGULADORES ═══
A40: Reguladores — por categoria
B41: Nº SS | C41: Material (R$) | D41: Mão de Obra (R$) | E41: Custo Total (R$)
A42: Controle completo | B42: =COUNTIFS(Reguladores!$H$5:$H$16,$A42) -> 4 | C42: =SUMIFS(Reguladores!$O$5:$O$16,Reguladores!$H$5:$H$16,$A42) -> 117781.56 | D42: =SUMIFS(Reguladores!$P$5:$P$16,Reguladores!$H$5:$H$16,$A42) -> 0 | E42: =SUMIFS(Reguladores!$Q$5:$Q$16,Reguladores!$H$5:$H$16,$A42) -> 117781.56
A43: Célula de regulador | B43: =COUNTIFS(Reguladores!$H$5:$H$16,$A43) -> 8 | C43: =SUMIFS(Reguladores!$O$5:$O$16,Reguladores!$H$5:$H$16,$A43) -> 1162767 | D43: =SUMIFS(Reguladores!$P$5:$P$16,Reguladores!$H$5:$H$16,$A43) -> 526882.56 | E43: =SUMIFS(Reguladores!$Q$5:$Q$16,Reguladores!$H$5:$H$16,$A43) -> 1689649.5
A44: TOTAL | B44: =SUM(B42:B43) -> 12 | C44: =SUM(C42:C43) -> 1280548.6 | D44: =SUM(D42:D43) -> 526882.56 | E44: =SUM(E42:E43) -> 1807431.1
A46: Reguladores — por criticidade
...

Sheet Premissas e Preços
A1: PREMISSAS E PREÇOS UNITÁRIOS
A2: Fonte: abas "Religadores"/"Reguladores" e "VALOR EM ESTOQUE". Altere aqui para recalcular tudo.
A4: 1) Preço por categoria (religadores)
A5: Categoria | B5: Tensão (kV) | C5: Valor Unitário | D5: Composição | E5: Códigos
A6: Equipamento completo | B6: 13,8 | C6: 55602.54 | D6: Religador + Controle | E6: 690001 + 690916
A7: Equipamento completo | B7: 34,5 | C7: 76246.2 | D7: Religador + Controle | E7: 690005 + 692263
A8: Parte ativa (Tanque) | B8: 13,8 | C8: 21785.72 | D8: Só religador | E8: 690001
A9: Parte ativa (Tanque) | B9: 34,5 | C9: 38151.48 | D9: Só religador | E9: 690005
A10: Controle completo | B10: 13,8 | C10: 33816.82 | D10: Só controle | E10: 690916
A11: Controle completo | B11: 34,5 | C11: 38094.72 | D11: Só controle | E11: 692263
A13: 2) Preço de itens granulares (por SS) — buscados na aba VALOR EM ESTOQUE
A14: SS | B14: Cód. Material | C14: Descrição (estoque) | D14: Valor Unitário | E14: Confiança
A15: ETO-COEP 00057/2026 | B15: 625510 | C15: RELE PROT MULTIFUN 50/51 (relé do religador) | D15: 10454.01 | E15: VERIFICAR
A16: ETO-COEP 00062/2026 | B16: 647641 | C16: PLACA RELIGADOR CIRC IMPRESSO RC10 | D16: 1999 | E16: VERIFICAR
A17: ETO-COEP 00063/2026 | B17: 647641 | C17: PLACA RELIGADOR CIRC IMPRESSO RC10 | D17: 1999 | E17: VERIFICAR
A18: ETO-COEP 00064/2026 | B18: 647641 | C18: PLACA RELIGADOR CIRC IMPRESSO RC10 | D18: 1999 | E18: VERIFICAR
A19: ETO-COEP 00073/2026 | B19: 90556 | C19: CHAVE SECC DISTR FACA 36,2KV 630A (fase C) | D19: 736.43 | E19: OK
A20: ETO-COEP 00085/2026 | B20: 647877+649399 | C20: Bateria lítio + Rádio GE Orbit (bucha/trafo s/ código) | D20: 14612.08 | E20: VERIFICAR
A22: 3) Mão de obra — serviço de campo (valor fixo por equipamento/tensão)
A23: Fonte: aba BASE INDISPONIBILIDADE (Relação de Equipamentos Indisponíveis ETO), coluna "Custo MO"
A24: Equipamento | B24: Tensão (kV) | C24: Valor MO | D24: Observação
A25: Religador | B25: 13,8 | C25: 11016.94 | D25: Substituição/instalação em campo
A26: Religador | B26: 34,5 | C26: 13209.34 | D26: Substituição/instalação em campo
A27: Regulador | B27: 13,8 | C27: 51402.14 | D27: Serviço de campo (parte ativa/comissionamento)
A28: Regulador | B28: 34,5 | C28: 80318.5 | D28: Serviço de campo (parte ativa/comissionamento)
A30: 4) Reguladores — preço POR CÉLULA (material = nº células × preço; completo = 3 células)
A31: Código | B31: Tensão / kVA | C31: R$ por célula
A32: 690236 | B32: 13,8 / 239 kVA | C32: 61098.29
A33: 690669 | B33: 13,8 / 167 kVA | C33: 27616.62
A34: 690240 | B34: 34,5 / 200 kVA | C34: 57720.41
A35: 690241 | B35: 34,5 / 400 kVA | C35: 126893.8
A36: 651638 | B36: Controle de regulador c/ nobreak | C36: 29445.39

Sheet Detalhe Religadores
A1: DETALHE — RELIGADORES (SS PENDENTE)
A2: Custo = Qtd × Valor Unitário. Valor Unitário puxado de "Premissas e Preços". Repassados e Em análise estão em abas próprias.
A4: SS | B4: Cód. Equip. | C4: Localidade | D4: Polo | E4: Criticidade | F4: tempo fora de operação | G4: Tensão (kV) | H4: Categoria de Compra | I4: Item a Comprar | J4: Qtd | K4: Cód. Material | L4: Valor Unitário | M4: Custo Material | N4: Custo Mão de Obra | O4: Status Tratativa | P4: OPERAÇÂO | Q4: Programação COCM | R4: OBRA | S4: Preço | T4: Custo Total (Mat + MO)
A5: ETO-COEP 00085/2026 | B5: 7938137007 | C5: Miracema Do Tocantins | D5: Miracema Do Tocantins | E5: Baixa | F5: =_xlfn.XLOOKUP(B5,[1]Sheet1!$A:$A,[1]Sheet1!$F:$F) -> 159 | G5: 13,8 | H5: Componentes/Acessórios | I5: Bateria, rádio, bucha fase A, trafo serv. auxiliar | J5: 1 | K5: 647877+649399 | L5: =IFERROR(VLOOKUP(A5,'Premissas e Preços'!$A$15:$D$20,4,FALSE()),SUMIFS('Premissas e Preços'!$C$6:$C$11,'Premissas e Preços'!$A$6:$A$11,H5,'Premissas e Preços'!$B$6:$B$11,G5)) -> 14612.08 | M5: =J5*L5 -> 14612.08 | N5: =IF($G5="34,5",'Premissas e Preços'!$C$26,'Premissas e Preços'!$C$25) -> 11016.94 | O5: Em tratativa - N1 (pendente) | P5: Em comissionamento | R5: 0212600423 | S5: VERIFICAR | T5: =M5+N5 -> 25629.02
A6: ETO-COEP 00068/2026 | B6: 7929376022 | C6: Babaculandia | D6: Araguaina | E6: Falta definir | F6: =_xlfn.XLOOKUP(B6,[1]Sheet1!$A:$A,[1]Sheet1!$F:$F) -> 70 | G6: 34,5 | H6: Controle completo | I6: Controle completo | J6: 1 | K6: (ver Premissas) | L6: =IFERROR(VLOOKUP(A6,'Premissas e Preços'!$A$15:$D$20,4,FALSE()),SUMIFS('Premissas e Preços'!$C$6:$C$11,'Premissas e Preços'!$A$6:$A$11,H6,'Premissas e Preços'!$B$6:$B$11,G6)) -> 38094.72 | M6: =J6*L6 -> 38094.72 | N6: =IF($G6="34,5",'Premissas e Preços'!$C$26,'Premissas e Preços'!$C$25) -> 13209.34 | O6: Em tratativa - N3 (concluído) | P6: Erro controle DMSL | S6: OK | T6: =M6+N6 -> 51304.06
A7: ETO-COEP 00156/2025 | B7: 7957126085 | C7: Monte Santo Do Tocantins | D7: Paraiso Do Tocantins | E7: Média | F7: =_xlfn.XLOOKUP(B7,[1]Sheet1!$A:$A,[1]Sheet1!$F:$F) -> 363 | G7: 34,5 | H7: Controle completo | I7: Controle completo + cabo BT | J7: 1 | K7: (ver Premissas) | L7: =IFERROR(VLOOKUP(A7,'Premissas e Preços'!$A$15:$D$20,4,FALSE()),SUMIFS('Premissas e Preços'!$C$6:$C$11,'Premissas e Preços'!$A$6:$A$11,H7,'Premissas e Preços'!$B$6:$B$11,G7)) -> 38094.72 | M7: =J7*L7 -> 38094.72 | N7: =IF($G7="34,5",'Premissas e Preços'!$C$26,'Premissas e Preços'!$C$25) -> 13209.34 | O7: Em tratativa - N1 (pendente) | R7: 0212600428 | S7: OK | T7: =M7+N7 -> 51304.06
A8: ETO-COEP 00080/2026 | B8: 7900573047 | C8: Figueiropolis | D8: Formoso Do Araguaia | E8: Alta | F8: =_xlfn.XLOOKUP(B8,[1]Sheet1!$A:$A,[1]Sheet1!$F:$F) -> 237 | G8: 13,8 | H8: Equipamento completo | I8: Religador completo (→ Noja RC10) | J8: 1 | K8: (ver Premissas) | L8: =IFERROR(VLOOKUP(A8,'Premissas e Preços'!$A$15:$D$20,4,FALSE()),SUMIFS('Premissas e Preços'!$C$6:$C$11,'Premissas e Preços'!$A$6:$A$11,H8,'Premissas e Preços'!$B$6:$B$11,G8)) -> 55602.54 | M8: =J8*L8 -> 55602.54 | N8: =IF($G8="34,5",'Premissas e Preços'!$C$26,'Premissas e Preços'!$C$25) -> 11016.94 | O8: Em tratativa - N1 (pendente) | R8: 0412600391 | S8: OK | T8: =M8+N8 -> 66619.48
A9: ETO-COEP 00184/2025 | B9: 7903112004 | C9: Araguaina | D9: Araguaina | E9: Alta | F9: =_xlfn.XLOOKUP(B9,[1]Sheet1!$A:$A,[1]Sheet1!$F:$F) -> 273 | G9: 34,5 | H9: Equipamento completo | I9: Religador completo (Cooper Form6 → Noja RC10) | J9: 1 | K9: (ver Premissas) | L9: =IFERROR(VLOOKUP(A9,'Premissas e Preços'!$A$15:$D$20,4,FALSE()),SUMIFS('Premissas e Preços'!$C$6:$C$11,'Premissas e Preços'!$A$6:$A$11,H9,'Premissas e Preços'!$B$6:$B$11,G9)) -> 76246.2 | M9: =J9*L9 -> 76246.2 | N9: =IF($G9="34,5",'Premissas e Preços'!$C$26,'Premissas e Preços'!$C$25) -> 13209.34 | O9: Em tratativa - N1 (pendente) | S9: OK | T9: =M9+N9 -> 89455.54
A10: ETO-COEP 00036/2026 | B10: 7927169001 | C10: Porto Nacional | D10: Porto Nacional | E10: Alta | F10: =_xlfn.XLOOKUP(B10,[1]Sheet1!$A:$A,[1]Sheet1!$F:$F) -> 138 | G10: 13,8 | H10: Parte ativa (Tanque) | I10: Tanque (parte ativa) | J10: 1 | K10: (ver Premissas) | L10: =IFERROR(VLOOKUP(A10,'Premissas e Preços'!$A$15:$D$20,4,FALSE()),SUMIFS('Premissas e Preços'!$C$6:$C$11,'Premissas e Preços'!$A$6:$A$11,H10,'Premissas e Preços'!$B$6:$B$11,G10)) -> 21785.72 | M10: =J10*L10 -> 21785.72 | N10: =IF($G10="34,5",'Premissas e Preços'!$C$26,'Premissas e Preços'!$C$25) -> 11016.94 | O10: Em tratativa - N1 (pendente) | R10: 0112600425 | S10: OK | T10: =M10+N10 -> 32802.66
A11: ETO-COEP 00222/2025 | B11: 7925087021 | C11: Parana | D11: Peixe | E11: Alta | F11: =_xlfn.XLOOKUP(B11,[1]Sheet1!$A:$A,[1]Sheet1!$F:$F) -> 177 | G11: 34,5 | H11: Parte ativa (Tanque) | I11: Tanque (parte ativa) | J11: 1 | K11: (ver Premissas) | L11: =IFERROR(VLOOKUP(A11,'Premissas e Preços'!$A$15:$D$20,4,FALSE()),SUMIFS('Premissas e Preços'!$C$6:$C$11,'Premissas e Preços'!$A$6:$A$11,H11,'Premissas e Preços'!$B$6:$B$11,G11)) -> 38151.48 | M11: =J11*L11 -> 38151.48 | N11: =IF($G11="34,5",'Premissas e Preços'!$C$26,'Premissas e Preços'!$C$25) -> 13209.34 | O11: Em tratativa - N1 (pendente) | R11: 0412600392 | S11: OK | T11: =M11+N11 -> 51360.82
A12: ETO-COEP 00094/2025 | B12: 7934698002 | C12: Tocantinopolis | D12: Tocantinopolis | E12: Alta | F12: =_xlfn.XLOOKUP(B12,[1]Sheet1!$A:$A,[1]Sheet1!$F:$F) -> #N/A | G12: 13,8 | H12: Controle completo | I12: Controle completo (caixa) | J12: 1 | K12: (ver Premissas) | L12: =IFERROR(VLOOKUP(A12,'Premissas e Preços'!$A$15:$D$20,4,FALSE()),SUMIFS('Premissas e Preços'!$C$6:$C$11,'Premissas e Preços'!$A$6:$A$11,H12,'Premissas e Preços'!$B$6:$B$11,G12)) -> 33816.82 | M12: =J12*L12 -> 33816.82 | N12: =IF($G12="34,5",'Premissas e Preços'!$C$26,'Premissas e Preços'!$C$25) -> 11016.94 | O12: Em tratativa - N3 (concluído) | P12: Concluído | R12: 0662600265 | S12: OK | T12: =M12+N12 -> 44833.76
A13: ETO-COEP 00120/2025 | B13: 7920024127 | C13: Palmeiras Do Tocantins | D13: Tocantinopolis | E13: Alta | F13: 387 | G13: 34,5 | H13: Equipamento completo | I13: Religador completo (→ Noja RC 10) | J13: 1 | K13: (ver Premissas) | L13: =IFERROR(VLOOKUP(A13,'Premissas e Preços'!$A$15:$D$20,4,FALSE()),SUMIFS('Premissas e Preços'!$C$6:$C$11,'Premissas e Preços'!$A$6:$A$11,H13,'Premissas e Preços'!$B$6:$B$11,G13)) -> 76246.2 | M13: =J13*L13 -> 76246.2 | N13: =IF($G13="34,5",'Premissas e Preços'!$C$26,'Premissas e Preços'!$C$25) -> 13209.34 | O13: Reavaliar | S13: OK | T13: =M13+N13 -> 89455.54
A14: ETO-COEP 00029/2026 | B14: 7927646026 | C14: Ponte Alta Tocantins | D14: Ponte Alta Tocantins | E14: Alta | F14: =_xlfn.XLOOKUP(B14,[1]Sheet1!$A:$A,[1]Sheet1!$F:$F) -> 145 | G14: 34,5 | H14: Parte ativa (Tanque) | I14: Tanque (parte ativa) + isoladores | J14: 1 | K14: (ver Premissas) | L14: =IFERROR(VLOOKUP(A14,'Premissas e Preços'!$A$15:$D$20,4,FALSE()),SUMIFS('Premissas e Preços'!$C$6:$C$11,'Premissas e Preços'!$A$6:$A$11,H14,'Premissas e Preços'!$B$6:$B$11,G14)) -> 38151.48 | M14: =J14*L14 -> 38151.48 | N14: =IF($G14="34,5",'Premissas e Preços'!$C$26,'Premissas e Preços'!$C$25) -> 13209.34 | O14: Em tratativa - N1 (pendente) | S14: OK | T14: =M14+N14 -> 51360.82
A15: ETO-COEP 00149/2025 | B15: 7955520116 | C15: Chapada Da Natividade | D15: Dianopolis | E15: Alta | F15: =_xlfn.XLOOKUP(B15,[1]Sheet1!$A:$A,[1]Sheet1!$F:$F) -> 327 | G15: 34,5 | H15: Parte ativa (Tanque) | I15: Tanque (parte ativa) | J15: 1 | K15: (ver Premissas) | L15: =IFERROR(VLOOKUP(A15,'Premissas e Preços'!$A$15:$D$20,4,FALSE()),SUMIFS('Premissas e Preços'!$C$6:$C$11,'Premissas e Preços'!$A$6:$A$11,H15,'Premissas e Preços'!$B$6:$B$11,G15)) -> 38151.48 | M15: =J15*L15 -> 38151.48 | N15: =IF($G15="34,5",'Premissas e Preços'!$C$26,'Premissas e Preços'!$C$25) -> 13209.34 | O15: Para avançar | P15: Em processo de compra | S15: OK | T15: =M15+N15 -> 51360.82
A16: ETO-COEP 00151/2025 | B16: 7930428001 | C16: Porto Nacional | D16: Porto Nacional | E16: Alta | F16: =_xlfn.XLOOKUP(B16,[1]Sheet1!$A:$A,[1]Sheet1!$F:$F) -> 337 | G16: 34,5 | H16: Parte ativa (Tanque) | I16: Tanque (parte ativa) | J16: 1 | K16: (ver Premissas) | L16: =IFERROR(VLOOKUP(A16,'Premissas e Preços'!$A$15:$D$20,4,FALSE()),SUMIFS('Premissas e Preços'!$C$6:$C$11,'Premissas e Preços'!$A$6:$A$11,H16,'Premissas e Preços'!$B$6:$B$11,G16)) -> 38151.48 | M16: =J16*L16 -> 38151.48 | N16: =IF($G16="34,5",'Premissas e Preços'!$C$26,'Premissas e Preços'!$C$25) -> 13209.34 | O16: Para avançar | P16: Em processo de compra | S16: OK | T16: =M16+N16 -> 51360.82
A17: ETO-COEP 00073/2026 | B17: 7967181127 | C17: Palmeiras Do Tocantins | D17: Tocantinopolis | E17: Falta definir | F17: =_xlfn.XLOOKUP(B17,[1]Sheet1!$A:$A,[1]Sheet1!$F:$F) -> 131 | G17: 34,5 | H17: Componentes/Acessórios | I17: Chave faca fase C | J17: 1 | K17: 90556 | L17: =IFERROR(VLOOKUP(A17,'Premissas e Preços'!$A$15:$D$20,4,FALSE()),SUMIFS('Premissas e Preços'!$C$6:$C$11,'Premissas e Preços'!$A$6:$A$11,H17,'Premissas e Preços'!$B$6:$B$11,G17)) -> 736.43 | M17: =J17*L17 -> 736.43 | N17: =IF($G17="34,5",'Premissas e Preços'!$C$26,'Premissas e Preços'!$C$25) -> 13209.34 | O17: Para avançar | P17: COCM | Q17: 46199 | S17: OK | T17: =M17+N17 -> 13945.77
A18: ETO-COEP 00181/2025 | B18: 7943790134 | C18: Esperantina | D18: Augustinopolis | E18: Alta | F18: =_xlfn.XLOOKUP(B18,[1]Sheet1!$A:$A,[1]Sheet1!$F:$F) -> 370 | G18: 34,5 | H18: Parte ativa (Tanque) | I18: Tanque (parte ativa) + comunicação | J18: 1 | K18: (ver Premissas) | L18: =IFERROR(VLOOKUP(A18,'Premissas e Preços'!$A$15:$D$20,4,FALSE()),SUMIFS('Premissas e Preços'!$C$6:$C$11,'Premissas e Preços'!$A$6:$A$11,H18,'Premissas e Preços'!$B$6:$B$11,G18)) -> 38151.48 | M18: =J18*L18 -> 38151.48 | N18: =IF($G18="34,5",'Premissas e Preços'!$C$26,'Premissas e Preços'!$C$25) -> 13209.34 | O18: Em tratativa - N3 (concluído) | P18: Concluído | R18: 0662600266 | S18: OK | T18: =M18+N18 -> 51360.82
A19: ETO-COEP 00020/2026 | B19: 7908708116 | C19: Chapada Da Natividade | D19: Dianopolis | E19: Falta definir | F19: =_xlfn.XLOOKUP(B19,[1]Sheet1!$A:$A,[1]Sheet1!$F:$F) -> 132 | G19: 34,5 | H19: Equipamento completo | I19: Religador completo (tanque + controle) | J19: 1 | K19: (ver Premissas) | L19: =IFERROR(VLOOKUP(A19,'Premissas e Preços'!$A$15:$D$20,4,FALSE()),SUMIFS('Premissas e Preços'!$C$6:$C$11,'Premissas e Preços'!$A$6:$A$11,H19,'Premissas e Preços'!$B$6:$B$11,G19)) -> 76246.2 | M19: =J19*L19 -> 76246.2 | N19: =IF($G19="34,5",'Premissas e Preços'!$C$26,'Premissas e Preços'!$C$25) -> 13209.34 | O19: Para avançar | P19: Em processo de compra | S19: OK | T19: =M19+N19 -> 89455.54
A20: ETO-COEP 00033/2026 | B20: 7947203070 | C20: Rio Sono | D20: Taquaralto | E20: Falta definir | F20: =_xlfn.XLOOKUP(B20,[1]Sheet1!$A:$A,[1]Sheet1!$F:$F) -> 192 | G20: 34,5 | H20: Equipamento completo | I20: Religador completo | J20: 1 | K20: (ver Premissas) | L20: =IFERROR(VLOOKUP(A20,'Premissas e Preços'!$A$15:$D$20,4,FALSE()),SUMIFS('Premissas e Preços'!$C$6:$C$11,'Premissas e Preços'!$A$6:$A$11,H20,'Premissas e Preços'!$B$6:$B$11,G20)) -> 76246.2 | M20: =J20*L20 -> 76246.2 | N20: =IF($G20="34,5",'Premissas e Preços'!$C$26,'Premissas e Preços'!$C$25) -> 13209.34 | O20: Para avançar | P20: Em processo de compra | S20: OK | T20: =M20+N20 -> 89455.54
A21: ETO-COEP 00038/2026 | B21: 7908249152 | C21: Santa Rosa Do Tocantins | D21: Porto Nacional | E21: Média | F21: =_xlfn.XLOOKUP(B21,[1]Sheet1!$A:$A,[1]Sheet1!$F:$F) -> 132 | G21: 34,5 | H21: Equipamento completo | I21: Religador completo (parte ativa + controle) | J21: 1 | K21: (ver Premissas) | L21: =IFERROR(VLOOKUP(A21,'Premissas e Preços'!$A$15:$D$20,4,FALSE()),SUMIFS('Premissas e Preços'!$C$6:$C$11,'Premissas e Preços'!$A$6:$A$11,H21,'Premissas e Preços'!$B$6:$B$11,G21)) -> 76246.2 | M21: =J21*L21 -> 76246.2 | N21: =IF($G21="34,5",'Premissas e Preços'!$C$26,'Premissas e Preços'!$C$25) -> 13209.34 | O21: Para avançar | P21: Em processo de compra | S21: OK | T21: =M21+N21 -> 89455.54
A22: ETO-COEP 00042/2026 | B22: 7900505026 | C22: Ponte Alta Tocantins | D22: Ponte Alta Tocantins | E22: Baixa | F22: =_xlfn.XLOOKUP(B22,[1]Sheet1!$A:$A,[1]Sheet1!$F:$F) -> #N/A | G22: 34,5 | H22: Equipamento completo | I22: Religador completo | J22: 1 | K22: (ver Premissas) | L22: =IFERROR(VLOOKUP(A22,'Premissas e Preços'!$A$15:$D$20,4,FALSE()),SUMIFS('Premissas e Preços'!$C$6:$C$11,'Premissas e Preços'!$A$6:$A$11,H22,'Premissas e Preços'!$B$6:$B$11,G22)) -> 76246.2 | M22: =J22*L22 -> 76246.2 | N22: =IF($G22="34,5",'Premissas e Preços'!$C$26,'Premissas e Preços'!$C$25) -> 13209.34 | O22: Reavaliar | P22: Em processo de compra | S22: OK | T22: =M22+N22 -> 89455.54
A23: ETO-COEP 00060/2026 | B23: 7903569004 | C23: Araguaina | D23: Araguaina | E23: Falta definir | F23: =_xlfn.XLOOKUP(B23,[1]Sheet1!$A:$A,[1]Sheet1!$F:$F) -> 84 | G23: 13,8 | H23: Equipamento completo | I23: Religador completo | J23: 1 | K23: (ver Premissas) | L23: =IFERROR(VLOOKUP(A23,'Premissas e Preços'!$A$15:$D$20,4,FALSE()),SUMIFS('Premissas e Preços'!$C$6:$C$11,'Premissas e Preços'!$A$6:$A$11,H23,'Premissas e Preços'!$B$6:$B$11,G23)) -> 55602.54 | M23: =J23*L23 -> 55602.54 | N23: =IF($G23="34,5",'Premissas e Preços'!$C$26,'Premissas e Preços'!$C$25) -> 11016.94 | O23: Para avançar | P23: Em processo de compra | S23: OK | T23: =M23+N23 -> 66619.48
A24: ETO-COEP 00074/2026 | B24: 7919270014 | C24: Pium | D24: Paraiso Do Tocantins | E24: Falta definir | F24: =_xlfn.XLOOKUP(B24,[1]Sheet1!$A:$A,[1]Sheet1!$F:$F) -> 98 | G24: 34,5 | H24: Equipamento completo | I24: Religador completo | J24: 1 | K24: (ver Premissas) | L24: =IFERROR(VLOOKUP(A24,'Premissas e Preços'!$A$15:$D$20,4,FALSE()),SUMIFS('Premissas e Preços'!$C$6:$C$11,'Premissas e Preços'!$A$6:$A$11,H24,'Premissas e Preços'!$B$6:$B$11,G24)) -> 76246.2 | M24: =J24*L24 -> 76246.2 | N24: =IF($G24="34,5",'Premissas e Preços'!$C$26,'Premissas e Preços'!$C$25) -> 13209.34 | O24: Para avançar | P24: Em processo de compra | S24: OK | T24: =M24+N24 -> 89455.54
A25: ETO-COEP 00102/2025 | B25: 7900532053 | C25: Piraque | D25: Tocantinopolis | E25: Falta definir | F25: =_xlfn.XLOOKUP(B25,[1]Sheet1!$A:$A,[1]Sheet1!$F:$F) -> 373 | G25: 34,5 | H25: Equipamento completo | I25: Religador completo + rádio | J25: 1 | K25: (ver Premissas) | L25: =IFERROR(VLOOKUP(A25,'Premissas e Preços'!$A$15:$D$20,4,FALSE()),SUMIFS('Premissas e Preços'!$C$6:$C$11,'Premissas e Preços'!$A$6:$A$11,H25,'Premissas e Preços'!$B$6:$B$11,G25)) -> 76246.2 | M25: =J25*L25 -> 76246.2 | N25: =IF($G25="34,5",'Premissas e Preços'!$C$26,'Premissas e Preços'!$C$25) -> 13209.34 | O25: Reavaliar | S25: OK | T25: =M25+N25 -> 89455.54
A26: ETO-COEP 00103/2025 | B26: 7910027196 | C26: Lagoa Do Tocantins | D26: Taquaralto | E26: Falta definir | F26: =_xlfn.XLOOKUP(B26,[1]Sheet1!$A:$A,[1]Sheet1!$F:$F) -> 391 | G26: 34,5 | H26: Equipamento completo | I26: Religador completo (exceto rádio) | J26: 1 | K26: (ver Premissas) | L26: =IFERROR(VLOOKUP(A26,'Premissas e Preços'!$A$15:$D$20,4,FALSE()),SUMIFS('Premissas e Preços'!$C$6:$C$11,'Premissas e Preços'!$A$6:$A$11,H26,'Premissas e Preços'!$B$6:$B$11,G26)) -> 76246.2 | M26: =J26*L26 -> 76246.2 | N26: =IF($G26="34,5",'Premissas e Preços'!$C$26,'Premissas e Preços'!$C$25) -> 13209.34 | O26: Reavaliar | S26: OK | T26: =M26+N26 -> 89455.54
A27: ETO-COEP 00178/2025 | B27: 7900018004 | C27: Araguaina | D27: Araguaina | E27: Alta | F27: =_xlfn.XLOOKUP(B27,[1]Sheet1!$A:$A,[1]Sheet1!$F:$F) -> 286 | G27: 34,5 | H27: Equipamento completo | I27: Religador completo | J27: 1 | K27: (ver Premissas) | L27: =IFERROR(VLOOKUP(A27,'Premissas e Preços'!$A$15:$D$20,4,FALSE()),SUMIFS('Premissas e Preços'!$C$6:$C$11,'Premissas e Preços'!$A$6:$A$11,H27,'Premissas e Preços'!$B$6:$B$11,G27)) -> 76246.2 | M27: =J27*L27 -> 76246.2 | N27: =IF($G27="34,5",'Premissas e Preços'!$C$26,'Premissas e Preços'!$C$25) -> 13209.34 | O27: Em tratativa - N3 (concluído) | P27: Concluído | R27: 0612600439 | S27: OK (Planilha3) | T27: =M27+N27 -> 89455.54
A28: ETO-COEP 00143/2025 | B28: 7927446001 | C28: Porto Nacional | D28: Porto Nacional | E28: Baixa | F28: =_xlfn.XLOOKUP(B28,[1]Sheet1!$A:$A,[1]Sheet1!$F:$F) -> 342 | G28: 34,5 | H28: Equipamento completo | I28: Religador completo | J28: 1 | K28: (ver Premissas) | L28: =IFERROR(VLOOKUP(A28,'Premissas e Preços'!$A$15:$D$20,4,FALSE()),SUMIFS('Premissas e Preços'!$C$6:$C$11,'Premissas e Preços'!$A$6:$A$11,H28,'Premissas e Preços'!$B$6:$B$11,G28)) -> 76246.2 | M28: =J28*L28 -> 76246.2 | N28: =IF($G28="34,5",'Premissas e Preços'!$C$26,'Premissas e Preços'!$C$25) -> 13209.34 | O28: Para avançar | P28: Em processo de compra | S28: OK | T28: =M28+N28 -> 89455.54
A29: ETO-COEP 00162/2025 | B29: 7928564039 | C29: Araguatins | D29: Augustinopolis | E29: Média | F29: =_xlfn.XLOOKUP(B29,[1]Sheet1!$A:$A,[1]Sheet1!$F:$F) -> 370 | G29: 34,5 | H29: Equipamento completo | I29: Religador completo | J29: 1 | K29: (ver Premissas) | L29: =IFERROR(VLOOKUP(A29,'Premissas e Preços'!$A$15:$D$20,4,FALSE()),SUMIFS('Premissas e Preços'!$C$6:$C$11,'Premissas e Preços'!$A$6:$A$11,H29,'Premissas e Preços'!$B$6:$B$11,G29)) -> 76246.2 | M29: =J29*L29 -> 76246.2 | N29: =IF($G29="34,5",'Premissas e Preços'!$C$26,'Premissas e Preços'!$C$25) -> 13209.34 | O29: Reavaliar | S29: OK | T29: =M29+N29 -> 89455.54
A30: ETO-COEP 00168/2025 | B30: 7908196047 | C30: Figueiropolis | D30: Formoso Do Araguaia | E30: Baixa | F30: =_xlfn.XLOOKUP(B30,[1]Sheet1!$A:$A,[1]Sheet1!$F:$F) -> 308 | G30: 13,8 | H30: Equipamento completo | I30: Religador completo | J30: 1 | K30: (ver Premissas) | L30: =IFERROR(VLOOKUP(A30,'Premissas e Preços'!$A$15:$D$20,4,FALSE()),SUMIFS('Premissas e Preços'!$C$6:$C$11,'Premissas e Preços'!$A$6:$A$11,H30,'Premissas e Preços'!$B$6:$B$11,G30)) -> 55602.54 | M30: =J30*L30 -> 55602.54 | N30: =IF($G30="34,5",'Premissas e Preços'!$C$26,'Premissas e Preços'!$C$25) -> 11016.94 | O30: Para avançar | P30: Em processo de compra | S30: OK | T30: =M30+N30 -> 66619.48
A31: ETO-COEP 00173/2025 | B31: 7900535058 | C31: Santa Fe Do Araguaia | D31: Araguaina | E31: Média | F31: =_xlfn.XLOOKUP(B31,[1]Sheet1!$A:$A,[1]Sheet1!$F:$F) -> 299 | G31: 34,5 | H31: Equipamento completo | I31: Religador completo (Cooper → Noja RC10) | J31: 1 | K31: (ver Premissas) | L31: =IFERROR(VLOOKUP(A31,'Premissas e Preços'!$A$15:$D$20,4,FALSE()),SUMIFS('Premissas e Preços'!$C$6:$C$11,'Premissas e Preços'!$A$6:$A$11,H31,'Premissas e Preços'!$B$6:$B$11,G31)) -> 76246.2 | M31: =J31*L31 -> 76246.2 | N31: =IF($G31="34,5",'Premissas e Preços'!$C$26,'Premissas e Preços'!$C$25) -> 13209.34 | O31: Para avançar | P31: Em processo de compra | S31: OK | T31: =M31+N31 -> 89455.54
A32: ETO-COEP 00179/2025 | B32: 7922995039 | C32: Araguatins | D32: Augustinopolis | E32: Falta definir | F32: =_xlfn.XLOOKUP(B32,[1]Sheet1!$A:$A,[1]Sheet1!$F:$F) -> 370 | G32: 13,8 | H32: Equipamento completo | I32: Religador completo | J32: 1 | K32: (ver Premissas) | L32: =IFERROR(VLOOKUP(A32,'Premissas e Preços'!$A$15:$D$20,4,FALSE()),SUMIFS('Premissas e Preços'!$C$6:$C$11,'Premissas e Preços'!$A$6:$A$11,H32,'Premissas e Preços'!$B$6:$B$11,G32)) -> 55602.54 | M32: =J32*L32 -> 55602.54 | N32: =IF($G32="34,5",'Premissas e Preços'!$C$26,'Premissas e Preços'!$C$25) -> 11016.94 | O32: Reavaliar | S32: OK | T32: =M32+N32 -> 66619.48
A33: ETO-COEP 00024/2026 | B33: 7933585074 | C33: Dianopolis | D33: Dianopolis | E33: Falta definir | F33: =_xlfn.XLOOKUP(B33,[1]Sheet1!$A:$A,[1]Sheet1!$F:$F) -> 127 | G33: 34,5 | H33: Parte ativa (Tanque) | I33: Tanque (parte ativa) | J33: 1 | K33: (ver Premissas) | L33: =IFERROR(VLOOKUP(A33,'Premissas e Preços'!$A$15:$D$20,4,FALSE()),SUMIFS('Premissas e Preços'!$C$6:$C$11,'Premissas e Preços'!$A$6:$A$11,H33,'Premissas e Preços'!$B$6:$B$11,G33)) -> 38151.48 | M33: =J33*L33 -> 38151.48 | N33: =IF($G33="34,5",'Premissas e Preços'!$C$26,'Premissas e Preços'!$C$25) -> 13209.34 | O33: Para avançar | P33: Em processo de compra | S33: OK | T33: =M33+N33 -> 51360.82
A34: ETO-COEP 00084/2026 | B34: 7900117013 | C34: Paraiso Do Tocantins | D34: Paraiso Do Tocantins | E34: Muito Alta | F34: =_xlfn.XLOOKUP(B34,[1]Sheet1!$A:$A,[1]Sheet1!$F:$F) -> 336 | G34: 13,8 | H34: Equipamento completo | I34: Religador completo (Cooper Form6 → Noja) | J34: 1 | K34: (ver Premissas) | L34: =IFERROR(VLOOKUP(A34,'Premissas e Preços'!$A$15:$D$20,4,FALSE()),SUMIFS('Premissas e Preços'!$C$6:$C$11,'Premissas e Preços'!$A$6:$A$11,H34,'Premissas e Preços'!$B$6:$B$11,G34)) -> 55602.54 | M34: =J34*L34 -> 55602.54 | N34: =IF($G34="34,5",'Premissas e Preços'!$C$26,'Premissas e Preços'!$C$25) -> 11016.94 | O34: Em tratativa - N1 (pendente) | P34: Em processo de compra | R34: 0212600422 | S34: OK | T34: =M34+N34 -> 66619.48
A35: ETO-COEP 00039/2026 | B35: 7926089013 | C35: Paraiso Do Tocantins | D35: Paraiso Do Tocantins | E35: Falta definir | F35: =_xlfn.XLOOKUP(B35,[1]Sheet1!$A:$A,[1]Sheet1!$F:$F) -> 167 | G35: 34,5 | H35: Parte ativa (Tanque) | I35: Tanque (parte ativa) | J35: 1 | K35: (ver Premissas) | L35: =IFERROR(VLOOKUP(A35,'Premissas e Preços'!$A$15:$D$20,4,FALSE()),SUMIFS('Premissas e Preços'!$C$6:$C$11,'Premissas e Preços'!$A$6:$A$11,H35,'Premissas e Preços'!$B$6:$B$11,G35)) -> 38151.48 | M35: =J35*L35 -> 38151.48 | N35: =IF($G35="34,5",'Premissas e Preços'!$C$26,'Premissas e Preços'!$C$25) -> 13209.34 | O35: Para avançar | P35: Em processo de compra | S35: OK | T35: =M35+N35 -> 51360.82
A36: ETO-COEP 00040/2026 | B36: 7931608059 | C36: Taquaralto | D36: Taquaralto | E36: Falta definir | F36: =_xlfn.XLOOKUP(B36,[1]Sheet1!$A:$A,[1]Sheet1!$F:$F) -> 147 | G36: 13,8 | H36: Parte ativa (Tanque) | I36: Tanque (parte ativa) + rádio | J36: 1 | K36: (ver Premissas) | L36: =IFERROR(VLOOKUP(A36,'Premissas e Preços'!$A$15:$D$20,4,FALSE()),SUMIFS('Premissas e Preços'!$C$6:$C$11,'Premissas e Preços'!$A$6:$A$11,H36,'Premissas e Preços'!$B$6:$B$11,G36)) -> 21785.72 | M36: =J36*L36 -> 21785.72 | N36: =IF($G36="34,5",'Premissas e Preços'!$C$26,'Premissas e Preços'!$C$25) -> 11016.94 | O36: Para avançar | P36: Em processo de compra | S36: OK | T36: =M36+N36 -> 32802.66
A37: ETO-COEP 00044/2026 | B37: 7936038076 | C37: Duere | D37: Gurupi | E37: Falta definir | F37: =_xlfn.XLOOKUP(B37,[1]Sheet1!$A:$A,[1]Sheet1!$F:$F) -> 93 | G37: 34,5 | H37: Parte ativa (Tanque) | I37: Tanque (parte ativa) | J37: 1 | K37: (ver Premissas) | L37: =IFERROR(VLOOKUP(A37,'Premissas e Preços'!$A$15:$D$20,4,FALSE()),SUMIFS('Premissas e Preços'!$C$6:$C$11,'Premissas e Preços'!$A$6:$A$11,H37,'Premissas e Preços'!$B$6:$B$11,G37)) -> 38151.48 | M37: =J37*L37 -> 38151.48 | N37: =IF($G37="34,5",'Premissas e Preços'!$C$26,'Premissas e Preços'!$C$25) -> 13209.34 | O37: Para avançar | P37: Em processo de compra | S37: OK | T37: =M37+N37 -> 51360.82
A38: ETO-COEP 00045/2026 | B38: 7927396052 | C38: Formoso Do Araguaia | D38: Formoso Do Araguaia | E38: Falta definir | F38: =_xlfn.XLOOKUP(B38,[1]Sheet1!$A:$A,[1]Sheet1!$F:$F) -> 106 | G38: 34,5 | H38: Parte ativa (Tanque) | I38: Tanque (parte ativa) | J38: 1 | K38: (ver Premissas) | L38: =IFERROR(VLOOKUP(A38,'Premissas e Preços'!$A$15:$D$20,4,FALSE()),SUMIFS('Premissas e Preços'!$C$6:$C$11,'Premissas e Preços'!$A$6:$A$11,H38,'Premissas e Preços'!$B$6:$B$11,G38)) -> 38151.48 | M38: =J38*L38 -> 38151.48 | N38: =IF($G38="34,5",'Premissas e Preços'!$C$26,'Premissas e Preços'!$C$25) -> 13209.34 | O38: Para avançar | P38: Em processo de compra | S38: OK | T38: =M38+N38 -> 51360.82
A39: ETO-COEP 00048/2026 | B39: 7925871077 | C39: Goiatins | D39: Araguaina | E39: Falta definir | F39: =_xlfn.XLOOKUP(B39,[1]Sheet1!$A:$A,[1]Sheet1!$F:$F) -> 79 | G39: 34,5 | H39: Parte ativa (Tanque) | I39: Tanque (parte ativa) | J39: 1 | K39: (ver Premissas) | L39: =IFERROR(VLOOKUP(A39,'Premissas e Preços'!$A$15:$D$20,4,FALSE()),SUMIFS('Premissas e Preços'!$C$6:$C$11,'Premissas e Preços'!$A$6:$A$11,H39,'Premissas e Preços'!$B$6:$B$11,G39)) -> 38151.48 | M39: =J39*L39 -> 38151.48 | N39: =IF($G39="34,5",'Premissas e Preços'!$C$26,'Premissas e Preços'!$C$25) -> 13209.34 | O39: Para avançar | P39: Em processo de compra | S39: OK | T39: =M39+N39 -> 51360.82
A40: ETO-COEP 00050/2026 | B40: 7953610256 | C40: Mateiros | D40: Ponte Alta Tocantins | E40: Falta definir | F40: =_xlfn.XLOOKUP(B40,[1]Sheet1!$A:$A,[1]Sheet1!$F:$F) -> 107 | G40: 34,5 | H40: Parte ativa (Tanque) | I40: Tanque (parte ativa) + cordão umbilical | J40: 1 | K40: (ver Premissas) | L40: =IFERROR(VLOOKUP(A40,'Premissas e Preços'!$A$15:$D$20,4,FALSE()),SUMIFS('Premissas e Preços'!$C$6:$C$11,'Premissas e Preços'!$A$6:$A$11,H40,'Premissas e Preços'!$B$6:$B$11,G40)) -> 38151.48 | M40: =J40*L40 -> 38151.48 | N40: =IF($G40="34,5",'Premissas e Preços'!$C$26,'Premissas e Preços'!$C$25) -> 13209.34 | O40: Para avançar | P40: Em processo de compra | S40: OK | T40: =M40+N40 -> 51360.82
A41: ETO-COEP 00051/2026 | B41: 7926442035 | C41: Monte Do Carmo | D41: Ponte Alta Tocantins | E41: Falta definir | F41: =_xlfn.XLOOKUP(B41,[1]Sheet1!$A:$A,[1]Sheet1!$F:$F) -> 105 | G41: 34,5 | H41: Parte ativa (Tanque) | I41: Tanque (parte ativa) + trafo | J41: 1 | K41: (ver Premissas) | L41: =IFERROR(VLOOKUP(A41,'Premissas e Preços'!$A$15:$D$20,4,FALSE()),SUMIFS('Premissas e Preços'!$C$6:$C$11,'Premissas e Preços'!$A$6:$A$11,H41,'Premissas e Preços'!$B$6:$B$11,G41)) -> 38151.48 | M41: =J41*L41 -> 38151.48 | N41: =IF($G41="34,5",'Premissas e Preços'!$C$26,'Premissas e Preços'!$C$25) -> 13209.34 | O41: Para avançar | P41: Em processo de compra | S41: OK | T41: =M41+N41 -> 51360.82
...

Sheet dSeg_Territorial (3)
A1: COD_LOC | B1: DES_LOC | C1: COD_SECC | D1: DES_SECC | E1: COD_DIST | F1: DES_DIST | G1: COD_REGI | H1: DES_REGI | I1: LATITUDE | J1: LONGITUDE | K1: Responsável 1 | L1: Responsável 2 | M1: Responsável 3 | N1: Responsável 4
A2: 1 | B2: PORTO NACIONAL | C2: 1 | D2: PORTO NACIONAL | E2: 1 | F2: PORTO NACIONAL | G2: 122 | H2: PALMAS | I2: -10.70265 | J2: -48.398505 | K2: FELIPE DIVINO | L2: WALLESON DE OLIVEIRA NUNES | M2: JAILTON | N2: MARCELO PRIMO
A3: 2 | B3: TOCANTINOPOLIS | C3: 2 | D3: TOCANTINOPOLIS | E3: 2 | F3: TOCANTINOPOLIS | G3: 4 | H3: ARAGUAINA | I3: -6.3299196 | J3: -47.420836 | K3: LEONARDO SANTOS DA SILVA | L3: RICARDO DA CONCEICAO MOURA
A4: 3 | B4: GURUPI | C4: 3 | D4: GURUPI | E4: 3 | F4: GURUPI | G4: 3 | H4: GURUPI | I4: -11.712138 | J4: -49.055893 | K4: DIONE SOUSA MARQUES | L4: ALMIR JOSE GOMES
A5: 4 | B5: ARAGUAINA | C5: 4 | D5: ARAGUAINA | E5: 4 | F5: ARAGUAINA | G5: 4 | H5: ARAGUAINA | I5: -7.1886007 | J5: -48.209284 | K5: LEONARDO SANTOS DA SILVA | L5: RICARDO DA CONCEICAO MOURA
A6: 5 | B6: ARRAIAS | C6: 5 | D6: ARRAIAS | E6: 74 | F6: DIANOPOLIS | G6: 3 | H6: GURUPI | I6: -12.935069 | J6: -46.935685 | K6: DIONE SOUSA MARQUES | L6: ALMIR JOSE GOMES
A7: 6 | B7: TOCANTINIA | C7: 6 | D7: TOCANTINIA | E7: 122 | F7: TAQUARALTO | G7: 122 | H7: PALMAS | I7: -9.5645886 | J7: -48.375645 | K7: FELIPE DIVINO | L7: WALLESON DE OLIVEIRA NUNES | M7: JAILTON | N7: MARCELO PRIMO
A8: 7 | B8: MIRACEMA DO TOCANTINS | C8: 7 | D8: MIRACEMA DO TOCANTINS | E8: 7 | F8: MIRACEMA DO TOCANTINS | G8: 122 | H8: PALMAS | I8: -9.5682592 | J8: -48.391512 | K8: FELIPE DIVINO | L8: WALLESON DE OLIVEIRA NUNES | M8: JAILTON | N8: MARCELO PRIMO
A9: 8 | B9: MIRANORTE | C9: 8 | D9: MIRANORTE | E9: 7 | F9: MIRACEMA DO TOCANTINS | G9: 122 | H9: PALMAS | I9: -9.5246642 | J9: -48.590293 | K9: FELIPE DIVINO | L9: WALLESON DE OLIVEIRA NUNES | M9: JAILTON | N9: MARCELO PRIMO
A10: 9 | B10: GUARAI | C10: 9 | D10: GUARAI | E10: 9 | F10: GUARAI | G10: 4 | H10: ARAGUAINA | I10: -8.8420771 | J10: -48.506495 | K10: LEONARDO SANTOS DA SILVA | L10: RICARDO DA CONCEICAO MOURA
A11: 10 | B11: LAJEADO | C11: 10 | D11: LAJEADO | E11: 122 | F11: TAQUARALTO | G11: 122 | H11: PALMAS | I11: -9.757002 | J11: -48.353633 | K11: FELIPE DIVINO | L11: WALLESON DE OLIVEIRA NUNES | M11: JAILTON | N11: MARCELO PRIMO
A12: 11 | B12: TUPIRAMA | C12: 15 | D12: PEDRO AFONSO | E12: 9 | F12: GUARAI | G12: 4 | H12: ARAGUAINA | I12: -8.996161 | J12: -48.1899 | K12: LEONARDO SANTOS DA SILVA | L12: RICARDO DA CONCEICAO MOURA
A13: 12 | B13: CRISTALANDIA | C13: 12 | D13: CRISTALANDIA | E13: 13 | F13: PARAISO DO TOCANTINS | G13: 122 | H13: PALMAS | I13: -10.599733 | J13: -49.19434 | K13: FELIPE DIVINO | L13: WALLESON DE OLIVEIRA NUNES | M13: JAILTON | N13: MARCELO PRIMO
A14: 13 | B14: PARAISO DO TOCANTINS | C14: 13 | D14: PARAISO DO TOCANTINS | E14: 13 | F14: PARAISO DO TOCANTINS | G14: 122 | H14: PALMAS | I14: -10.173287 | J14: -48.881288 | K14: FELIPE DIVINO | L14: WALLESON DE OLIVEIRA NUNES | M14: JAILTON | N14: MARCELO PRIMO
A15: 14 | B15: PIUM | C15: 14 | D15: PIUM | E15: 13 | F15: PARAISO DO TOCANTINS | G15: 122 | H15: PALMAS | I15: -10.44158 | J15: -49.175688 | K15: FELIPE DIVINO | L15: WALLESON DE OLIVEIRA NUNES | M15: JAILTON | N15: MARCELO PRIMO
A16: 15 | B16: PEDRO AFONSO | C16: 15 | D16: PEDRO AFONSO | E16: 9 | F16: GUARAI | G16: 4 | H16: ARAGUAINA | I16: -8.9745545 | J16: -48.174876 | K16: LEONARDO SANTOS DA SILVA | L16: RICARDO DA CONCEICAO MOURA
A17: 16 | B17: WANDERLANDIA | C17: 16 | D17: WANDERLANDIA | E17: 2 | F17: TOCANTINOPOLIS | G17: 4 | H17: ARAGUAINA | I17: -6.8531521 | J17: -47.961098 | K17: LEONARDO SANTOS DA SILVA | L17: RICARDO DA CONCEICAO MOURA
A18: 17 | B18: BARROLANDIA | C18: 17 | D18: BARROLANDIA | E18: 7 | F18: MIRACEMA DO TOCANTINS | G18: 122 | H18: PALMAS | I18: -9.8335615 | J18: -48.724532 | K18: FELIPE DIVINO | L18: WALLESON DE OLIVEIRA NUNES | M18: JAILTON | N18: MARCELO PRIMO
A19: 18 | B19: BOM JESUS DO TOCANTINS | C19: 15 | D19: PEDRO AFONSO | E19: 9 | F19: GUARAI | G19: 4 | H19: ARAGUAINA | I19: -8.966282 | J19: -48.166195 | K19: LEONARDO SANTOS DA SILVA | L19: RICARDO DA CONCEICAO MOURA
A20: 19 | B20: FILADELFIA | C20: 19 | D20: FILADELFIA | E20: 4 | F20: ARAGUAINA | G20: 4 | H20: ARAGUAINA | I20: -7.333677 | J20: -47.495825 | K20: LEONARDO SANTOS DA SILVA | L20: RICARDO DA CONCEICAO MOURA
A21: 20 | B21: NOVO ALEGRE | C21: 50 | D21: COMBINADO | E21: 74 | F21: DIANOPOLIS | G21: 3 | H21: GURUPI | I21: -12.911456 | J21: -46.572515 | K21: DIONE SOUSA MARQUES | L21: ALMIR JOSE GOMES
A22: 21 | B22: PARANA | C22: 21 | D22: PARANA | E22: 94 | F22: PEIXE | G22: 3 | H22: GURUPI | I22: -13.122635 | J22: -47.767712 | K22: DIONE SOUSA MARQUES | L22: ALMIR JOSE GOMES
A23: 22 | B23: BABACULANDIA | C23: 22 | D23: BABACULANDIA | E23: 2 | F23: TOCANTINOPOLIS | G23: 4 | H23: ARAGUAINA | I23: -7.2032774 | J23: -47.758941 | K23: LEONARDO SANTOS DA SILVA | L23: RICARDO DA CONCEICAO MOURA
A24: 23 | B24: COLINAS DO TOCANTINS | C24: 23 | D24: COLINAS DO TOCANTINS | E24: 23 | F24: COLINAS DO TOCANTINS | G24: 4 | H24: ARAGUAINA | I24: -8.0520135 | J24: -48.483321 | K24: LEONARDO SANTOS DA SILVA | L24: RICARDO DA CONCEICAO MOURA
A25: 24 | B25: ITAPORA DO TOCANTINS | C25: 34 | D25: PRESIDENTE KENNEDY | E25: 9 | F25: GUARAI | G25: 4 | H25: ARAGUAINA | I25: -8.571522 | J25: -48.689113 | K25: LEONARDO SANTOS DA SILVA | L25: RICARDO DA CONCEICAO MOURA
A26: 25 | B26: ARAPOEMA | C26: 25 | D26: ARAPOEMA | E26: 23 | F26: COLINAS DO TOCANTINS | G26: 4 | H26: ARAGUAINA | I26: -7.6576597 | J26: -49.06594 | K26: LEONARDO SANTOS DA SILVA | L26: RICARDO DA CONCEICAO MOURA
A27: 26 | B27: PONTE ALTA TOCANTINS | C27: 26 | D27: PONTE ALTA DO TOCANTINS | E27: 26 | F27: PONTE ALTA TOCANTINS | G27: 122 | H27: PALMAS | I27: -10.750268 | J27: -47.538086 | K27: FELIPE DIVINO | L27: WALLESON DE OLIVEIRA NUNES | M27: JAILTON | N27: MARCELO PRIMO
A28: 27 | B28: PONTE ALTA BOM JESUS | C28: 27 | D28: PONTE ALTA DO BOM JESUS | E28: 74 | F28: DIANOPOLIS | G28: 3 | H28: GURUPI | I28: -12.090182 | J28: -46.481515 | K28: DIONE SOUSA MARQUES | L28: ALMIR JOSE GOMES
A29: 28 | B29: NATIVIDADE | C29: 28 | D29: NATIVIDADE | E29: 74 | F29: DIANOPOLIS | G29: 3 | H29: GURUPI | I29: -11.701318 | J29: -47.721822 | K29: DIONE SOUSA MARQUES | L29: ALMIR JOSE GOMES
A30: 29 | B30: PALMEIROPOLIS | C30: 29 | D30: PALMEIROPOLIS | E30: 94 | F30: PEIXE | G30: 3 | H30: GURUPI | I30: -13.043749 | J30: -48.402881 | K30: DIONE SOUSA MARQUES | L30: ALMIR JOSE GOMES
A31: 30 | B31: XAMBIOA | C31: 30 | D31: XAMBIOA | E31: 2 | F31: TOCANTINOPOLIS | G31: 4 | H31: ARAGUAINA | I31: -6.4084444 | J31: -48.535016 | K31: LEONARDO SANTOS DA SILVA | L31: RICARDO DA CONCEICAO MOURA
A32: 31 | B32: RIO DOS BOIS | C32: 8 | D32: MIRANORTE | E32: 7 | F32: MIRACEMA DO TOCANTINS | G32: 122 | H32: PALMAS | I32: -9.339803 | J32: -48.534218 | K32: FELIPE DIVINO | L32: WALLESON DE OLIVEIRA NUNES | M32: JAILTON | N32: MARCELO PRIMO
A33: 32 | B33: ARAGUACU | C33: 32 | D33: ARAGUACU | E33: 36 | F33: ALVORADA | G33: 3 | H33: GURUPI | I33: -12.927731 | J33: -49.828659 | K33: DIONE SOUSA MARQUES | L33: ALMIR JOSE GOMES
A34: 33 | B34: COLMEIA | C34: 33 | D34: COLMEIA | E34: 9 | F34: GUARAI | G34: 4 | H34: ARAGUAINA | I34: -8.73109 | J34: -48.759134 | K34: LEONARDO SANTOS DA SILVA | L34: RICARDO DA CONCEICAO MOURA
A35: 34 | B35: PRESIDENTE KENNEDY | C35: 34 | D35: PRESIDENTE KENNEDY | E35: 9 | F35: GUARAI | G35: 4 | H35: ARAGUAINA | I35: -8.536023 | J35: -48.505448 | K35: LEONARDO SANTOS DA SILVA | L35: RICARDO DA CONCEICAO MOURA
A36: 35 | B36: MONTE DO CARMO | C36: 35 | D36: MONTE DO CARMO | E36: 26 | F36: PONTE ALTA TOCANTINS | G36: 122 | H36: PALMAS | I36: -10.763723 | J36: -48.110157 | K36: FELIPE DIVINO | L36: WALLESON DE OLIVEIRA NUNES | M36: JAILTON | N36: MARCELO PRIMO
A37: 36 | B37: ALVORADA | C37: 36 | D37: ALVORADA | E37: 36 | F37: ALVORADA | G37: 3 | H37: GURUPI | I37: -12.486493 | J37: -49.121524 | K37: DIONE SOUSA MARQUES | L37: ALMIR JOSE GOMES
A38: 37 | B38: ALIANCA DO TOCANTINS | C38: 37 | D38: ALIANCA DO TOCANTINS | E38: 3 | F38: GURUPI | G38: 3 | H38: GURUPI | I38: -11.303374 | J38: -48.930512 | K38: DIONE SOUSA MARQUES | L38: ALMIR JOSE GOMES
A39: 38 | B39: TAGUATINGA | C39: 38 | D39: TAGUATINGA | E39: 74 | F39: DIANOPOLIS | G39: 3 | H39: GURUPI | I39: -12.416606 | J39: -46.429531 | K39: DIONE SOUSA MARQUES | L39: ALMIR JOSE GOMES
A40: 39 | B40: ARAGUATINS | C40: 39 | D40: ARAGUATINS | E40: 45 | F40: AUGUSTINOPOLIS | G40: 4 | H40: ARAGUAINA | I40: -5.6538555 | J40: -48.122381 | K40: LEONARDO SANTOS DA SILVA | L40: RICARDO DA CONCEICAO MOURA
...

Sheet Reguladores
A1: REGULADORES DE TENSÃO (SS PENDENTE) — fora do orçamento de religadores
A2: Listados para visibilidade. Preço a definir (célula/controle de regulador depende do tipo/tensão).
A4: SS | B4: Cód. Equip. | C4: Localidade | D4: Polo | E4: Criticidade | G4: Tensão (kV) | H4: Categoria | I4: Item a Comprar | J4: Qtd | K4: Status Tratativa | L4: OBRA | M4: Observação | N4: Preço unit. (R$) | O4: Custo Material (R$) | P4: Custo Mão de Obra (R$) | Q4: Custo Total (R$) | R4: Confiança / Obs
A5: ETO-COEP 00160/2025 | B5: 5854566043 | C5: Silvanopolis | D5: Porto Nacional | E5: Muito Alta | F5: 1 | G5: 34,5 | H5: Célula de regulador | I5: Célula fase B | J5: 1 | K5: Será resolvido | M5: Regulador — campo indicou fase C, DMSL fase B | N5: 126893.8 | O5: =J5*N5 -> 126893.8 | P5: 80318.5 | Q5: =O5+P5 -> 207212.3 | R5: Célula 34,5 kV 400 kVA (cód 690241)
A6: ETO-COEP 00187/2025 | B6: 5800371025 | C6: Arapoema | D6: Colinas Do Tocantins | E6: Alta | F6: 2 | G6: 34,5 | H6: Controle completo | I6: Controle + kit comunicação | J6: 1 | K6: Será resolvido | M6: Regulador — relés Toshiba A/B com falha | N6: 29445.39 | O6: =J6*N6 -> 29445.39 | P6: 0 | Q6: =O6+P6 -> 29445.39 | R6: Controle de regulador c/ nobreak (cód 651638)
A7: ETO-COEP 00187/2025 | B7: 5800371025 | C7: Arapoema | D7: Colinas Do Tocantins | E7: Alta | F7: 3 | G7: 34,5 | H7: Célula de regulador | I7: 3 Celulas | J7: 3 | K7: Será resolvido | M7: Regulador — relés Toshiba A/B com falha | N7: 57720.41 | O7: =J7*N7 -> 173161.23 | P7: 80318.5 | Q7: =O7+P7 -> 253479.73 | R7: Células 34,5 kV 200 kVA (cód 690240) — categoria corrigida
A8: ETO-COEP 00216/2025 | B8: 5827102054 | C8: Pugmil | D8: Paraiso Do Tocantins | E8: Média | G8: 34,5 | H8: Controle completo | I8: Controle completo | J8: 1 | K8: Será resolvido | M8: Nobreak e relé já substituídos em campo | N8: 29445.39 | O8: =J8*N8 -> 29445.39 | P8: 0 | Q8: =O8+P8 -> 29445.39 | R8: Controle de regulador c/ nobreak (cód 651638)
A9: ETO-COEP 00171/2025 | B9: 5800438116 | C9: Chapada Da Natividade | D9: Dianopolis | E9: Média | G9: 34,5 | H9: Célula de regulador | I9: Células fases B e C | J9: 2 | K9: Será resolvido | M9: Regulador + placa F do controle | N9: 57720.41 | O9: =J9*N9 -> 115440.82 | P9: 80318.5 | Q9: =O9+P9 -> 195759.32 | R9: Células 34,5 kV 200 kVA (cód 690240) — controle não orçado
A10: ETO-COEP 00180/2025 | B10: 5850308009 | C10: Guarai | D10: Guarai | E10: Falta definir | G10: 13,8 | H10: Controle completo | I10: Controle completo | J10: 1 | K10: Será resolvido | M10: Regulador | N10: 29445.39 | O10: =J10*N10 -> 29445.39 | P10: 0 | Q10: =O10+P10 -> 29445.39 | R10: Controle de regulador c/ nobreak (cód 651638)
A11: ETO-COEP 00077/2026 | B11: 5801866013 | C11: Paraiso Do Tocantins | D11: Paraiso Do Tocantins | E11: Falta definir | G11: 13,8 | H11: Célula de regulador | I11: Célula fase C | J11: 1 | K11: Será resolvido | M11: Regulador — infiltração | N11: 61098.29 | O11: =J11*N11 -> 61098.29 | P11: 51402.14 | Q11: =O11+P11 -> 112500.43 | R11: VERIFICAR kVA — sem base (assumido 13,8 / 239 kVA, cód 690236)
A12: ETO-COEP 00221/2025 | B12: 5800961074 | C12: Dianopolis | D12: Dianopolis | E12: Falta definir | G12: 13,8 | H12: Célula de regulador | I12: 3 células | J12: 3 | M12: Regulador + melhorias aterramento | N12: 61098.29 | O12: =J12*N12 -> 183294.87 | P12: 51402.14 | Q12: =O12+P12 -> 234697.01 | R12: VERIFICAR kVA — sem base (assumido 13,8 / 239 kVA, cód 690236)
A13: ETO-COEP 00199/2025 | B13: 5855411017 | C13: Barrolandia | D13: Miracema Do Tocantins | E13: Baixa | G13: 13,8 | H13: Controle completo | I13: Controle completo | J13: 1 | K13: Será resolvido | N13: 29445.39 | O13: =J13*N13 -> 29445.39 | P13: 0 | Q13: =O13+P13 -> 29445.39 | R13: Controle de regulador c/ nobreak (cód 651638)
A14: ETO-COEP 00123/2025 | B14: 5858783119 | C14: Sao Bento Do Tocantins | D14: Tocantinopolis | E14: Baixa | G14: 34,5 | H14: Célula de regulador | I14: 3 células | J14: 3 | K14: Será resolvido | M14: Regulador — furto de óleo isolante | N14: 126893.8 | O14: =J14*N14 -> 380681.4 | P14: 80318.5 | Q14: =O14+P14 -> 460999.9 | R14: Células 34,5 kV 400 kVA (cód 690241)
A15: ETO-COEP 00167/2025 | B15: 5844630060 | C15: Nova Olinda | D15: Colinas Do Tocantins | E15: Baixa | G15: 13,8 | H15: Célula de regulador | I15: Célula fase A | J15: 1 | K15: Será resolvido | M15: Regulador — vazamento de óleo | N15: 61098.29 | O15: =J15*N15 -> 61098.29 | P15: 51402.14 | Q15: =O15+P15 -> 112500.43 | R15: Célula 13,8 kV 239 kVA (cód 690236)
A16: ETO-COEP 00223/2025 | B16: 5862236091 | C16: Almas | D16: Dianopolis | E16: Baixa | G16: 13,8 | H16: Célula de regulador | I16: Célula fase B | J16: 1 | K16: Será resolvido | M16: Regulador | N16: 61098.29 | O16: =J16*N16 -> 61098.29 | P16: 51402.14 | Q16: =O16+P16 -> 112500.43 | R16: VERIFICAR kVA — sem base (assumido 13,8 / 239 kVA, cód 690236)
M17: TOTAL | O17: =SUM(O5:O16) -> 1280548.6 | P17: =SUM(P5:P16) -> 526882.56 | Q17: =SUM(Q5:Q16) -> 1807431.1
M18: Regra: material = nº de células × preço por célula (regulador completo = 3 células). Controle orçado à parte.

Sheet Em Análise
A1: EM ANÁLISE — DECIDIR MANUALMENTE
A2: Sem definição clara de compra. Não entram no orçamento até você classificar.Lebrando que a classificação foi por meio apenas da descrição da SS
A4: SS | B4: Cód. Equip. | C4: Localidade | D4: Polo | E4: Criticidade | F4: Item/Observação | G4: Por que está em análise
A5: ETO-COEP 00021/2026 | B5: 5803327001 | C5: Porto Nacional | D5: Porto Nacional | E5: Alta | F5: Comissionamento completo; cabo umbilical danificado — confirmar compra | G5: Instalação errada dos COCM´s
A6: ETO-COEP 00028/2026 | B6: 7954668084 | C6: Divinopolis | D6: Divinopolis | E6: Falta definir | F6: Display queimado, sem parecer DMSL — provável controle, confirmar | G6: Sem o Parecer do DMSL
A7: ETO-COEP 00055/2026 | B7: 5856156091 | C7: Almas | D7: Dianopolis | E7: Falta definir | F7: Furto — aquisição de células de reposição a confirmar (equip. já fornecido) | G7: —
A8: ETO-COEP 00056/2026 | B8: 5856070091 | C8: Almas | D8: Dianopolis | E8: Muito Alta | F8: Furto — equipamento já fornecido/substituído; confirmar pendência de compra | G8: —
A9: ETO-COEP 00072/2026 | B9: 7900525015 | C9: Pedro Afonso | D9: Guarai | E9: Falta definir | F9: 'Substituir religador' porém defeito é nas buchas (A,B,C) — confirmar escopo | G9: Dá a entender que apenas as buchas estão danificadas
A10: ETO-COEP 00201/2025 | B10: 7944319149 | C10: Caseara | D10: Divinopolis | E10: Falta definir | F10: Parecer pertence a outro equipamento (7955430075) — verificar | G10: Substituir a parte ativa

Sheet Repassados
A1: REPASSADOS — DESCONSIDERADOS DO ORÇAMENTO
A2: Já resolvidos / repassados. Mantidos só para referência.
A4: SS | B4: Cód. Equip. | C4: Localidade | D4: Polo | E4: Criticidade | F4: Categoria | G4: Item | H4: Observação
A5: ETO-COEP 00056/2025 | B5: 7900230155 | C5: Palmeirante | D5: Colinas Do Tocantins | E5: Muito Alta | F5: Equipamento completo | G5: Religador completo (→ Noja RC10) | H5: + para-raio trafo + chave saída fase C | I5: Entra apenas o Tanque | J5: Tanque
A6: ETO-COEP 00178/2025 | B6: 7900018004 | C6: Araguaina | D6: Araguaina | E6: Alta | F6: Equipamento completo | G6: Religador completo (Cooper → Noja RC10) | H6: Modernização — defeito no controle | I6: Entra o Religador completo | J6: 3 celulas
A7: ETO-COEP 00081/2026 | B7: 7957620015 | C7: Pedro Afonso | D7: Guarai | E7: Muito Alta | F7: Controle completo | G7: Controle completo + antena + cabo umbilical | H7: Rádio, módulo SIM, relé e fonte danificados | I7: Entra o Rádio,módulo SIM, relé e fontes danificados
A8: ETO-COEP 00066/2026 | B8: 5800291077 | C8: Goiatins | D8: Araguaina | E8: Falta definir | F8: Célula de regulador | G8: Célula fase B | H8: Regulador — fase B em curto | I8: Verificar o repasse
A9: ETO-COEP 00067/2026 | B9: 7925737080 | C9: Darcinopolis | D9: Tocantinopolis | E9: Falta definir | F9: Componentes/Acessórios | G9: 2 para-raios (fases B e C) | H9: Visor apagado — verificar controle | I9: Não entra no orçamento
A10: ETO-COEP 00076/2026 | B10: 7962635060 | C10: Nova Olinda | D10: Colinas Do Tocantins | E10: Falta definir | F10: Componentes/Acessórios | G10: Transformador (furtado) | H10: Restante é comissionamento | I10: Não entra no orçamento

Sheet Banco de capacitor
A1: MÊS | B1: ANO_SS | C1: SS_ORIGINAL | D1: POSTO_SGM | E1: EQUIPAMENTO | F1: COD_ELE | G1: TIPO_ATIVO | H1: DTA_OCORRENCIA | I1: DTA_ABERTURA | J1: DTA_LIMITE | K1: PRIORIDADE | L1: RESP_ABERTURA | M1: STATUS | N1: DTA_REPASSE | O1: COD_LOC | P1: COD_ALIMENTADOR | Q1: DESCRIÇÃO | R1: PENDENCIA_DO_ATIVO | S1: QTD_CELULAS_TROCAR | T1: FASES_IDENTIFICADAS | U1: CRITERIO_LEITURA
A2: Jan | B2: 2026 | C2: ETO-COEP 00002/2026 | D2: ETO-COEP | E2: 5900038047 | F2: 59 | G2: CAPACITOR | H2: 46028 | I2: 46028 | J2: 46031 | K2: EMERGENCIAL | L2: JONATAN ALVES DE SOUZA | M2: SS PENDENTE | N2: 46028 | O2: 47 | P2: AL01033047 | Q2: SEGUE SOLICITAÇÃO DE SERVIÇO PARA BANCO CAPACITOR COM CÉLULA DA FASE B QUEIMADA EQUIPE 047OP01 INFORMOU QUE JA FIZERAM TESTE E NÃO ACEITOU ID#81133777 RDU DE FIGUEIROPOLIS | R2: INDISPONIBILIDADE PARA OPERAÇÃO | S2: 1 | T2: B | U2: Quantidade inferida pelas fases citadas na descrição
A3: Fev | B3: 2024 | C3: ETO-COEP 00018/2024 | D3: ETO-COEP | E3: 5952243122 | F3: 59 | G3: CAPACITOR | H3: 45340 | I3: 45341 | J3: 45344 | K3: EMERGENCIAL | L3: NATANAEL MELQUIADES DOS SANTOS | M3: SS PENDENTE | N3: 45341 | O3: 122 | P3: AL04059122 | Q3: Favor enviar equipe para verificar banco de capacitor :5952243122 danificado fase B e C na quadra 606 Sul | R3: INDISPONIBILIDADE PARA OPERAÇÃO | S3: 2 | T3: B,C | U3: Quantidade inferida pelas fases citadas na descrição
A4: Mar | B4: 2023 | C4: ETO-COEP 00030/2023 | D4: ETO-COEP | E4: 5900438097 | F4: 59 | G4: CAPACITOR | H4: 44948 | I4: 45003 | J4: 45006 | K4: EMERGENCIAL | L4: CRISTIANO WAGNER DA SILVA ROSA | M4: SS PENDENTE | N4: 45003 | O4: 97 | P4: AL02003036 | Q4: Boa Noite ! Segue SS para verificar anomalia no banco capacitor 5900438097. o mesmo não está aceitando fechamento desarmando RL 7924621097. | R4: INDISPONIBILIDADE PARA OPERAÇÃO | T4: Repassar para Operação novamente | U4: Sem indicação clara da quantidade de células na descrição
A5: Mar | B5: 2026 | C5: ETO-COEP 00047/2026 | D5: ETO-COEP | E5: 5950106122 | F5: 59 | G5: CAPACITOR | H5: 45920 | I5: 46092 | J5: 46095 | K5: EMERGENCIAL | L5: LAISON OLIVEIRA CARVALHO | M5: SS PENDENTE | N5: 46092 | O5: 122 | P5: AL05097122 | Q5: favor verificar banco de capacitor 5950106122, com defeito interno, o mesmo nao foi indentificado aparentemente, porem foi a causa da ocorrencia 20253842360922 | R5: AVISO DE ANOMALIA | T5: Repassar para Operação novamente | U5: Sem indicação clara da quantidade de células na descrição
A6: Abr | B6: 2024 | C6: ETO-COEP 00058/2024 | D6: ETO-COEP | E6: 5924849004 | F6: 59 | G6: CAPACITOR | H6: 45406 | I6: 45412 | J6: 45472 | K6: ALTA | L6: SIRDEIS ALVES MONTEIRO | M6: SS PENDENTE | N6: 45412 | O6: 4 | P6: AL03103004 | Q6: por favor deslocar equipe da manutenção pesada nos bancos capacitor 5900326004 , 5900383004 com vazamento de óleo e os 5924849004 inspecionado com defeito nas fases A,B,C, e o 5900600004 fases A,C com defeito foi informado pela equipe DEC de Araguaína telefone 6399250-4970 | R6: INDISPONIBILIDADE PARA OPERAÇÃO | S6: 3 | T6: A,B,C | U6: Quantidade inferida pelas fases citadas na descrição
A7: Abr | B7: 2024 | C7: ETO-COEP 00060/2024 | D7: ETO-COEP | E7: 5913313004 | F7: 59 | G7: CAPACITOR | H7: 45408 | I7: 45412 | J7: 45415 | K7: EMERGENCIAL | L7: CLEIDSON RODRIGUES VIEIRA | M7: SS PENDENTE | N7: 45412 | O7: 4 | P7: AL05010004 | Q7: Nota para manutenção substituir banco capacitor 5913313004 na RDU de Araguina o mesmo não aceitou fechamento | R7: INDISPONIBILIDADE PARA OPERAÇÃO | T7: Repassar para Operação novamente | U7: Sem indicação clara da quantidade de células na descrição
A8: Abr | B8: 2025 | C8: ETO-COEP 00064/2025 | D8: ETO-COEP | E8: 5900293123 | F8: 59 | G8: CAPACITOR | H8: 45759 | I8: 45763 | J8: 45823 | K8: ALTA | L8: ANTONIO FAGNER ALVES RIBEIRO | M8: SS PENDENTE | N8: 45763 | O8: 123 | P8: AL02055123 | Q8: Corrigir anomalia no BC 5900293123 que atende a Bonasa em Aguiarnopolis. Ao fazer teste no mesmo a fase A não aceitou. | R8: INDISPONIBILIDADE PARA OPERAÇÃO | S8: 1 | T8: A | U8: Quantidade inferida pelas fases citadas na descrição
A9: Abr | B9: 2025 | C9: ETO-COEP 00073/2025 | D9: ETO-COEP | E9: 5900489122 | F9: 59 | G9: CAPACITOR | H9: 45770 | I9: 45775 | J9: 45778 | K9: EMERGENCIAL | L9: SAMUEL PINTO GOMES | M9: SS PENDENTE | N9: 45775 | O9: 122 | P9: AL02060122 | Q9: Segue nota para envia equipe linha viva substituir às 3 células do BC-5900489122 de 600 kVAr, Tensão 13.8kv, Cabo AA / 4/0, Local AVE. NS-01, Obs. Foi identificado fase C com elo queimado após fechamento fase B queimou elo, não foi possível identificar qual celular está danificada devido mesmo ser muito antigos favor substituir às 3 do mesmo. | R9: INDISPONIBILIDADE PARA OPERAÇÃO | S9: 3 | T9: A,B,C | U9: Quantidade explícita: substituir 3 células
A10: Abr | B10: 2025 | C10: ETO-COEP 00074/2025 | D10: ETO-COEP | E10: 5952202122 | F10: 59 | G10: CAPACITOR | H10: 45771 | I10: 45775 | J10: 45778 | K10: EMERGENCIAL | L10: SAMUEL PINTO GOMES | M10: SS PENDENTE | N10: 45775 | O10: 122 | P10: AL06059122 | Q10: Segue nota para envia equipe linha viva substituir fase A e B do BC-5952202122 de 300 kVAr, Tensão 13.8kv, Local AVE NS-02 Praça dos Girassóis. | R10: INDISPONIBILIDADE PARA OPERAÇÃO | S10: 2 | T10: A,B | U10: Quantidade inferida pelas fases citadas na descrição
A11: Abr | B11: 2025 | C11: ETO-COEP 00075/2025 | D11: ETO-COEP | E11: 5952327122 | F11: 59 | G11: CAPACITOR | H11: 45771 | I11: 45775 | J11: 45778 | K11: EMERGENCIAL | L11: SAMUEL PINTO GOMES | M11: SS PENDENTE | N11: 45775 | O11: 122 | P11: AL07060122 | Q11: Segue nota para envia equipe linha viva substituir às 3 células do BC-5952327122, Obs. Identificada fase A e C aberta e em campo e curto na fase B, Equipamento ficou isolado para substituição, Tensão 13.8kv, Local próximo QD-409 Norte. | R11: INDISPONIBILIDADE PARA OPERAÇÃO | S11: 3 | T11: A,B,C | U11: Quantidade explícita: substituir 3 células; descrição cita defeito nas três fases
A12: Abr | B12: 2025 | C12: ETO-COEP 00076/2025 | D12: ETO-COEP | E12: 5951650122 | F12: 59 | G12: CAPACITOR | H12: 45772 | I12: 45775 | J12: 45778 | K12: EMERGENCIAL | L12: JANES FERREIRA DA SILVA | M12: SS PENDENTE | N12: 45775 | O12: 122 | P12: AL08059122 | Q12: Segue SS para substituição do banco capacitor com defeito fase B,C 5951650122 | R12: INDISPONIBILIDADE PARA OPERAÇÃO | S12: 2 | T12: B,C | U12: Quantidade inferida pelas fases citadas na descrição
